File: icepp/data/250308/250308_3D_mh_photolitho_IV_minus_fineDown1.dat
[Header]
TITLE, IV scan -10 to -5 (0.033 scan)
FILEOPENTIME,13903285.39,3/8/2025,9:13 PM
BYAPP, Resistivity, 2.1, 1.0
INFO, APPNAME, PPMS MultiVu Application, 1.5.11
INFO, , Sample1 Name
INFO, 1, Sample1 Cross Section
INFO, 1, Sample1 Length
INFO, Ohm, Sample1 Units
INFO, , Sample2 Name
INFO, 1, Sample2 Cross Section
INFO, 1, Sample2 Length
INFO, Ohm, Sample2 Units
INFO, , Sample3 Name
INFO, 1, Sample3 Cross Section
INFO, 1, Sample3 Length
INFO, Ohm, Sample3 Units
INFO, , Sample4 Name
INFO, 1, Sample4 Cross Section
INFO, 1, Sample4 Length
INFO, Ohm, Sample4 Units
FIELDGROUP, Resistivity,2,3,4,5,6,7,8,9,10,11,12,13,14,15,16,17,18,19,20,21,22,23,24,25,26,27,28,29,30,31,32,33,34,35,36,37,38,39,40,41
STARTUPGROUP, Resistivity
STARTUPAXIS, X, 2, LINEAR, AUTO
STARTUPAXIS, Y1, 7, LINEAR, AUTO
STARTUPAXIS, Y2, 9, LINEAR, AUTO
STARTUPAXIS, Y3, 11, LINEAR, AUTO
PLOT_APPEARANCE, ALL, HORZ_GRID_ON, VERT_GRID_ON, MARKERS_AND_LINES, ALL_LINES
DATATYPE, TIME, 2
DATATYPE, COMMENT, 1
[Data]
Comment,Time Stamp (sec),Status (code),Temperature (K),Magnetic Field (Oe),Sample Position (deg),Bridge 1 Resistivity (Ohm),Bridge 1 Excitation (uA),Bridge 2 Resistivity (Ohm),Bridge 2 Excitation (uA),Bridge 3 Resistivity (Ohm),Bridge 3 Excitation (uA),Bridge 4 Resistivity (Ohm),Bridge 4 Excitation (uA),Bridge 1 Std. Dev. (Ohm),Bridge 2 Std. Dev. (Ohm),Bridge 3 Std. Dev. (Ohm),Bridge 4 Std. Dev. (Ohm),Number of Readings,Bridge 1 Resistance (Ohms),Bridge 2 Resistance (Ohms),Bridge 3 Resistance (Ohms),Bridge 4 Resistance (Ohms),Signal 1 Vin (V),Signal 2 Vin (V),Digital Inputs (code),Drive 1 Iout (mA),Drive 1 Ipower (watts),Drive 2 Iout (mA),Drive 2 Ipower (watts),Pressure (),Map 20 (),Map 21 (),Map 22 (),Map 23 (),Map 24 (),Map 25 (),Map 26 (),Map 27 (),Map 28 (),Map 29 ()
,13907741.52,4369,2.99980008602142,0.13400000333786,0,794.8419921875,-9.98999977111816,628.089868164063,-9.98999977111816,640.711296386719,-9.98999977111816,,,0.384861699020959,51.9135558686368,0.559811047877633,,25,794.8419921875,628.089868164063,640.711296386719,
,13907750.69,4369,3.00020003318787,0.13400000333786,0,792.859360351562,-9.96599960327148,606.437077636719,-9.96599960327148,639.037839355469,-9.96599960327148,,,0.23873833465187,37.7333036574436,0.515908833365438,,25,792.859360351562,606.437077636719,639.037839355469,
,13907759.77,4369,3.00029993057251,0.13400000333786,0,790.748874511719,-9.91699981689453,584.218461914062,-9.91699981689453,637.070388183594,-9.91699981689453,,,0.304324595536296,37.0262915158487,0.678935082862005,,25,790.748874511719,584.218461914062,637.070388183594,
,13907769.61,4369,3.0011500120163,0.13400000333786,0,789.916843261719,-9.89299964904785,576.464008789063,-9.89299964904785,635.869702148437,-9.89299964904785,,,0.237266003630697,39.6489289830824,0.967116902286397,,25,789.916843261719,576.464008789063,635.869702148437,
,13907778.72,4369,3.00064992904663,0.13400000333786,0,789.136000976563,-9.86800003051758,567.586489257812,-9.86800003051758,633.464931640625,-9.86800003051758,,,0.219182304944322,15.8038812802591,1.62316730766991,,25,789.136000976563,567.586489257812,633.464931640625,
,13907788.39,4369,3.00055003166199,0.13400000333786,0,787.925717773438,-9.81900024414063,580.435385742187,-9.81900024414063,626.44833984375,-9.81900024414063,,,0.229388223088762,57.4126928886169,0.953681022559429,,25,787.925717773438,580.435385742187,626.44833984375,
,13907797.98,4369,3.00094997882843,0.13400000333786,0,787.459450683594,-9.79500007629395,574.05625,-9.79500007629395,624.769208984375,-9.79500007629395,,,0.29552656414086,54.646489379912,0.893481201364208,,25,787.459450683594,574.05625,624.769208984375,
,13907806.81,4369,2.99900007247925,0.13400000333786,0,786.946098632813,-9.77000045776367,574.15712890625,-9.77000045776367,623.194895019531,-9.77000045776367,,,0.206337618425706,43.2608587365975,0.717378762381353,,25,786.946098632813,574.15712890625,623.194895019531,
,13907816.00,4369,3.00174999237061,0.13400000333786,0,785.89912109375,-9.72200012207031,554.936354980469,-9.72200012207031,620.602856445312,-9.72200012207031,,,0.195512325764008,26.9867565667191,0.36118131761071,,25,785.89912109375,554.936354980469,620.602856445312,
,13907824.75,4369,2.99840009212494,0.13400000333786,0,785.260239257812,-9.69699954986572,547.069638671875,-9.69699954986572,618.959909667969,-9.69699954986572,,,0.217605222216618,0.385800637874867,0.672266057356923,,25,785.260239257812,547.069638671875,618.959909667969,
,13907833.75,4369,3.0011500120163,0.13400000333786,0,784.5300390625,-9.64799976348877,549.92287109375,-9.64799976348877,611.277099609375,-9.64799976348877,,,0.241032008214355,24.5902332021996,0.856550896299601,,25,784.5300390625,549.92287109375,611.277099609375,
,13907843.36,4369,3.00039994716644,0.13400000333786,0,781.563857421875,-9.62399959564209,543.450727539063,-9.62399959564209,609.413854980469,-9.62399959564209,,,11.0629652322622,0.316373892405559,0.578058947081322,,25,781.563857421875,543.450727539063,609.413854980469,
,13907853.02,4369,2.99975001811981,0.13400000333786,0,747.946352539062,-9.59899997711182,554.717783203125,-9.59899997711182,608.088598632812,-9.59899997711182,,,24.5556265795767,46.9172194512854,1.24450955596428,,25,747.946352539062,554.717783203125,608.088598632812,
,13907862.61,4369,2.99985003471375,0.13400000333786,0,727.079462890625,-9.55099964141846,545.116069335937,-9.55099964141846,605.571853027344,-9.55099964141846,,,0.336489752665495,36.5111907961128,0.35708342876242,,25,727.079462890625,545.116069335937,605.571853027344,
,13907871.05,4369,3.00015008449554,0.13400000333786,0,726.927888183594,-9.52600002288818,539.662346191406,-9.52600002288818,604.63119140625,-9.52600002288818,,,0.272392456616204,36.0446932484281,0.191934701789324,,25,726.927888183594,539.662346191406,604.63119140625,
,13907880.97,4369,2.99950003623962,0.13400000333786,0,726.527023925781,-9.5019998550415,532.474841308594,-9.5019998550415,603.290666503906,-9.5019998550415,,,0.174170394527328,26.2208867463217,0.505892751982154,,25,726.527023925781,532.474841308594,603.290666503906,
,13907890.39,4369,2.99965000152588,0.13400000333786,0,726.217053222656,-9.45300006866455,535.147907714844,-9.45300006866455,601.309763183594,-9.45300006866455,,,0.183369796380689,34.4544390620047,0.427744662937349,,25,726.217053222656,535.147907714844,601.309763183594,
,13907899.50,4369,3.00150001049042,0.13400000333786,0,726.221618652344,-9.42800045013428,529.660622558594,-9.42800045013428,600.431857910156,-9.42800045013428,,,0.143876166668105,26.5941689082059,0.457878521371875,,25,726.221618652344,529.660622558594,600.431857910156,
,13907908.84,4369,2.99995005130768,0.13400000333786,0,725.744731445312,-9.4040002822876,527.446746826172,-9.4040002822876,599.000571289062,-9.4040002822876,,,0.171686784686531,27.1855144152445,0.475830811851801,,25,725.744731445312,527.446746826172,599.000571289062,
,13907918.31,4369,3.00045001506805,0.13400000333786,0,725.217351074219,-9.35499954223633,516.807186279297,-9.35499954223633,595.794787597656,-9.35499954223633,,,0.419415701289118,16.3780151164562,1.32896278659832,,25,725.217351074219,516.807186279297,595.794787597656,
,13907927.84,4369,3.00069999694824,0.13400000333786,0,725.112827148438,-9.33100032806396,513.334444580078,-9.33100032806396,594.028718261719,-9.33100032806396,,,0.300074014855904,32.1027962556099,1.01083819539778,,25,725.112827148438,513.334444580078,594.028718261719,
,13907937.56,4369,3.00040006637573,0.13400000333786,0,724.825888671875,-9.30599975585938,529.329887695313,-9.30599975585938,592.597504882812,-9.30599975585938,,,0.356922558321658,52.9098517329815,0.748704089177299,,25,724.825888671875,529.329887695313,592.597504882812,
,13907946.83,4369,2.99974989891052,0.13400000333786,0,724.169438476563,-9.25699996948242,507.82470703125,-9.25699996948242,589.91787109375,-9.25699996948242,,,0.165680556648328,44.4148600066615,0.43253116130427,,25,724.169438476563,507.82470703125,589.91787109375,
,13907956.11,4369,2.99944996833801,0.13400000333786,0,724.205952148438,-9.23299980163574,499.201175537109,-9.23299980163574,588.880549316406,-9.23299980163574,,,0.20842805657976,32.7781686518757,0.534786806279651,,25,724.205952148438,499.201175537109,588.880549316406,
,13907965.75,4369,3.00019991397858,0.13400000333786,0,723.886916503906,-9.20899963378906,500.915458984375,-9.20899963378906,587.393139648437,-9.20899963378906,,,0.202454642137105,45.0006533414958,0.609478007988216,,25,723.886916503906,500.915458984375,587.393139648437,
,13907974.88,4369,2.99979996681213,0.13400000333786,0,723.368681640625,-9.15999984741211,493.005593261719,-9.15999984741211,584.859670410156,-9.15999984741211,,,0.188543557177526,32.7182074811936,0.936224031091744,,25,723.368681640625,493.005593261719,584.859670410156,
,13907984.84,4369,3.00010001659393,0.13400000333786,0,723.160124511719,-9.13500022888184,497.321638183594,-9.13500022888184,583.280002441406,-9.13500022888184,,,0.187260207277424,44.9735681173558,0.463053444616261,,25,723.160124511719,497.321638183594,583.280002441406,
,13907993.70,4369,2.99960005283356,0.13400000333786,0,722.900009765625,-9.11100006103516,495.272905273438,-9.11100006103516,581.807041015625,-9.11100006103516,,,0.192806922220513,45.0179740812729,0.526822009816179,,25,722.900009765625,495.272905273438,581.807041015625,
,13908002.64,4369,2.99919998645782,0.13400000333786,0,722.485993652344,-9.0620002746582,487.147092285156,-9.0620002746582,578.979748535156,-9.0620002746582,,,0.318819220006559,36.3320925031472,0.46651343744566,,25,722.485993652344,487.147092285156,578.979748535156,
,13908011.47,4369,3.00174999237061,0.13400000333786,0,722.244978027344,-9.03800010681152,478.854586181641,-9.03800010681152,577.546794433594,-9.03800010681152,,,0.288068034132995,17.0081976409585,0.541992151737212,,25,722.244978027344,478.854586181641,577.546794433594,
,13908021.56,4369,3.0003000497818,0.13400000333786,0,721.862590332031,-9.01299953460693,480.890252685547,-9.01299953460693,575.963024902344,-9.01299953460693,,,0.180952620587633,23.9136577945446,0.367125476842171,,25,721.862590332031,480.890252685547,575.963024902344,
,13908031.81,4369,2.99994993209839,0.13400000333786,0,721.183171386719,-8.96399974822998,474.607545166016,-8.96399974822998,572.515295410156,-8.96399974822998,,,0.107682846607063,17.6438876049899,0.412748075045881,,25,721.183171386719,474.607545166016,572.515295410156,
,13908040.70,4369,3.0006000995636,0.13400000333786,0,721.087216796875,-8.9399995803833,480.242026367188,-8.9399995803833,570.952133789062,-8.9399995803833,,,0.266312849168522,28.1410935206481,0.608425859180424,,25,721.087216796875,480.242026367188,570.952133789062,
,13908049.84,4369,2.99849998950958,0.13400000333786,0,720.641857910156,-8.89099979400635,427.607099609375,-8.89099979400635,566.69634765625,-8.89099979400635,,,0.186427515983753,0.179555318655999,1.21999939250592,,25,720.641857910156,427.607099609375,566.69634765625,
,13908060.88,4369,3.00069999694824,0.13400000333786,0,720.469716796875,-8.86699962615967,426.819254150391,-8.86699962615967,562.903776855469,-8.86699962615967,,,0.14468958838621,0.170332267372396,1.17881273489924,,25,720.469716796875,426.819254150391,562.903776855469,
,13908071.91,4369,3.0008499622345,0.13400000333786,0,720.322670898438,-8.84200000762939,425.917586669922,-8.84200000762939,559.779973144531,-8.84200000762939,,,0.172038113344974,0.210471998799544,1.39120061607106,,25,720.322670898438,425.917586669922,559.779973144531,
,13908083.00,4369,3.00020003318787,0.13400000333786,0,719.91408203125,-8.79300022125244,434.757073974609,-8.79300022125244,554.05138671875,-8.79300022125244,,,0.174547937077789,15.8873231187469,0.644791232040492,,25,719.91408203125,434.757073974609,554.05138671875,
,13908092.50,4369,3.00080001354218,0.13400000333786,0,719.562941894531,-8.76900005340576,432.936995849609,-8.76900005340576,551.916723632812,-8.76900005340576,,,0.246381600521827,16.6095740578071,0.637388002888301,,25,719.562941894531,432.936995849609,551.916723632812,
,13908102.27,4369,3.00075006484985,0.13400000333786,0,719.327778320313,-8.74499988555908,432.8438671875,-8.74499988555908,549.980100097656,-8.74499988555908,,,0.125641548316126,17.2785562601748,0.738467589039513,,25,719.327778320313,432.8438671875,549.980100097656,
,13908112.08,4369,2.9996999502182,0.13400000333786,0,718.872800292969,-8.69600009918213,427.780059814453,-8.69600009918213,546.061765136719,-8.69600009918213,,,0.184575648300054,16.5651439702758,0.577557903033443,,25,718.872800292969,427.780059814453,546.061765136719,
,13908121.55,4369,3.00015008449554,0.13400000333786,0,718.607644042969,-8.67099952697754,426.819562988281,-8.67099952697754,544.316875,-8.67099952697754,,,0.24927327126681,16.5094152179419,0.794450133042479,,25,718.607644042969,426.819562988281,544.316875,
,13908130.31,4369,3.00135004520416,0.13400000333786,0,718.357736816406,-8.64700031280518,417.395228271484,-8.64700031280518,542.330651855469,-8.64700031280518,,,0.20458139010037,33.4315201010614,0.9501543863528,,25,718.357736816406,417.395228271484,542.330651855469,
,13908140.22,4369,3.00169992446899,0.13400000333786,0,716.915231933594,-8.59799957275391,394.719750976563,-8.59799957275391,529.395146484375,-8.59799957275391,,,0.790995200284951,62.7840041538272,4.3799882913703,,25,716.915231933594,394.719750976563,529.395146484375,
,13908149.45,4369,3.0003000497818,0.13400000333786,0,712.358459472656,-8.57400035858154,428.451545410156,-8.57400035858154,521.068151855469,-8.57400035858154,,,1.63239184979261,41.0262348421153,1.27318208041183,,25,712.358459472656,428.451545410156,521.068151855469,
,13908159.48,4369,3.00034999847412,0.13400000333786,0,707.219111328125,-8.54899978637695,437.951945800781,-8.54899978637695,518.070654296875,-8.54899978637695,,,4.95075165587245,6.23031735944221,2.95515559198975,,25,707.219111328125,437.951945800781,518.070654296875,
,13908168.33,4369,2.99954998493195,0.13400000333786,0,703.50537109375,-8.5,436.06724609375,-8.5,512.379731445312,-8.5,,,0.237847723693203,0.343630364258647,1.02952470660776,,25,703.50537109375,436.06724609375,512.379731445312,
,13908177.56,4369,3,0.13400000333786,0,703.376936035156,-8.47599983215332,434.751629638672,-8.47599983215332,510.442819824219,-8.47599983215332,,,0.310980474427735,0.290554620410004,0.783833166659922,,25,703.376936035156,434.751629638672,510.442819824219,
,13908186.39,4369,3.00064992904663,0.13400000333786,0,702.731691894531,-8.45100021362305,432.124259033203,-8.45100021362305,508.727255859375,-8.45100021362305,,,0.241261586236637,6.93533974880679,0.73279504238114,,25,702.731691894531,432.124259033203,508.727255859375,
,13908194.59,4369,2.99975001811981,0.13400000333786,0,695.987341308594,-8.40299987792969,422.288431396484,-8.40299987792969,505.224827880859,-8.40299987792969,,,2.37745794059931,14.6749547054859,0.760746125948962,,25,695.987341308594,422.288431396484,505.224827880859,
,13908204.11,4369,2.9991500377655,0.13400000333786,0,689.031013183594,-8.37800025939941,421.521317138672,-8.37800025939941,503.960623779297,-8.37800025939941,,,1.63554216894957,14.0597421895634,0.646031091203212,,25,689.031013183594,421.521317138672,503.960623779297,
,13908212.59,4369,3.00045001506805,0.13400000333786,0,685.103586425781,-8.35400009155273,417.02662109375,-8.35400009155273,502.264559326172,-8.35400009155273,,,1.1490988806424,16.5496610733225,0.896542347050915,,25,685.103586425781,417.02662109375,502.264559326172,
,13908222.56,4369,2.99804997444153,0.13400000333786,0,683.569157714844,-8.30500030517578,403.550346679687,-8.30500030517578,498.880283203125,-8.30500030517578,,,0.202303314541306,19.9922897497088,0.635331599910156,,25,683.569157714844,403.550346679687,498.880283203125,
,13908231.30,4369,2.99925005435944,0.13400000333786,0,683.283205566406,-8.27999973297119,391.842464599609,-8.27999973297119,497.180831298828,-8.27999973297119,,,0.169789319773934,19.2272984354268,0.730122933870655,,25,683.283205566406,391.842464599609,497.180831298828,
,13908240.44,4369,3.00144994258881,0.13400000333786,0,682.8851171875,-8.25599956512451,378.691196289062,-8.25599956512451,495.313814697266,-8.25599956512451,,,0.16171618866447,20.8425498247336,0.729469515898681,,25,682.8851171875,378.691196289062,495.313814697266,
,13908249.48,4369,2.99940001964569,0.13400000333786,0,682.132790527344,-8.20699977874756,363.639444580078,-8.20699977874756,491.339698486328,-8.20699977874756,,,0.211880132380392,14.3563705206434,0.75075008168035,,25,682.132790527344,363.639444580078,491.339698486328,
,13908259.02,4369,3.00080001354218,0.13400000333786,0,679.155856933594,-8.18299961090088,359.601713867188,-8.18299961090088,487.795087890625,-8.18299961090088,,,1.94283327475161,10.3772255739525,1.0759727350895,,25,679.155856933594,359.601713867188,487.795087890625,
,13908268.59,4369,2.99889993667603,0.13400000333786,0,673.541193847656,-8.15799999237061,356.266051025391,-8.15799999237061,485.537092285156,-8.15799999237061,,,3.06860152270756,0.628214861443831,1.11713184566835,,25,673.541193847656,356.266051025391,485.537092285156,
,13908278.20,4369,3.00055003166199,0.13400000333786,0,662.028176269531,-8.10900020599365,357.827487792969,-8.10900020599365,481.611401367188,-8.10900020599365,,,1.05940225357216,14.4354946025402,1.14012361568482,,25,662.028176269531,357.827487792969,481.611401367188,
,13908286.59,4369,3.00049996376038,0.13400000333786,0,660.626823730469,-8.08500003814697,235.492744750977,-8.08500003814697,479.291654052734,-8.08500003814697,,,0.368841662252802,0.356506022529653,1.01757893965845,,25,660.626823730469,235.492744750977,479.291654052734,
,13908297.48,4369,2.9988499879837,0.13400000333786,0,659.54556640625,-8.03600025177002,232.022161254883,-8.03600025177002,474.921949462891,-8.03600025177002,,,0.250544323795957,0.328949864768344,1.0687948118046,,25,659.54556640625,232.022161254883,474.921949462891,
,13908308.45,4369,2.99989998340607,0.13400000333786,0,592.122053222656,-8.01200008392334,230.432747802734,-8.01200008392334,472.266545410156,-8.01200008392334,,,118.90126836505,0.340405318055697,1.17983273113654,,25,592.122053222656,230.432747802734,472.266545410156,
,13908319.67,4369,3.00020003318787,0.13400000333786,0,647.129392089844,-7.98699998855591,222.132688598633,-7.98699998855591,470.250472412109,-7.98699998855591,,,54.4266140082567,33.4978457029158,0.933975854714613,,25,647.129392089844,222.132688598633,470.250472412109,
,13908330.69,4369,3.00095009803772,0.13400000333786,0,435.562501220703,-7.93800020217896,172.092680206299,-7.93800020217896,465.945560302734,-7.93800020217896,,,110.322600589903,77.0078457620196,0.720215265346662,,25,435.562501220703,172.092680206299,465.945560302734,
,13908343.36,4369,3.00120007991791,0.13400000333786,0,632.681457519531,-7.91400003433228,163.420132141113,-7.91400003433228,464.073997802734,-7.91400003433228,,,74.4482179255597,78.7619986827497,0.605482577398672,,25,632.681457519531,163.420132141113,464.073997802734,
,13908354.56,4369,3.00104999542236,0.13400000333786,0,609.574068603516,-7.8899998664856,108.972722625732,-7.8899998664856,462.157918701172,-7.8899998664856,,,100.079264877846,75.4120122639093,0.864319187412339,,25,609.574068603516,108.972722625732,462.157918701172,
,13908366.11,4369,2.99940001964569,0.13400000333786,0,564.523405761719,-7.84100008010864,109.217814483643,-7.84100008010864,458.006010742188,-7.84100008010864,,,126.456094437607,72.9754633765728,0.980685903327087,,25,564.523405761719,109.217814483643,458.006010742188,
,13908377.59,4369,3.00044989585876,0.13400000333786,0,552.162574462891,-7.81599998474121,100.634757843018,-7.81599998474121,456.083706054688,-7.81599998474121,,,129.043829037822,67.5920268085843,0.814061632541738,,25,552.162574462891,100.634757843018,456.083706054688,
,13908389.44,4369,2.99919998645782,0.13400000333786,0,380.049090576172,-7.79199981689453,67.8646937561035,-7.79199981689453,454.230522460937,-7.79199981689453,,,0.179061655597834,42.2138740433611,1.60014612341392,,25,380.049090576172,67.8646937561035,454.230522460937,
,13908402.25,4369,2.99994993209839,0.13400000333786,0,635.215087890625,-7.74300003051758,100.083127441406,-7.74300003051758,447.097366943359,-7.74300003051758,,,0.601103199853564,80.995413791131,3.29051950591562,,25,635.215087890625,100.083127441406,447.097366943359,
,13908412.70,4369,2.99959993362427,0.13400000333786,0,593.640140380859,-7.7189998626709,153.283860778809,-7.7189998626709,437.274149169922,-7.7189998626709,,,93.2119922070494,95.216324806477,4.04309630653112,,25,593.640140380859,153.283860778809,437.274149169922,
,13908422.95,4369,3.00160002708435,0.13400000333786,0,379.875104980469,-7.69399976730347,219.359951019287,-7.69399976730347,431.683715820313,-7.69399976730347,,,0.112803702364933,61.088425980555,4.90314847648606,,25,379.875104980469,219.359951019287,431.683715820313,
,13908434.52,4369,3.00034999847412,0.13400000333786,0,410.102174072266,-7.64499998092651,204.964879455566,-7.64499998092651,423.128856201172,-7.64499998092651,,,82.313646451938,55.9706331399675,2.97850961390948,,25,410.102174072266,204.964879455566,423.128856201172,
,13908446.11,4369,3.0003000497818,0.13400000333786,0,379.7266796875,-7.62099981307983,166.453249206543,-7.62099981307983,418.380788574219,-7.62099981307983,,,0.101993989028657,78.0662546536029,2.59982588051697,,25,379.7266796875,166.453249206543,418.380788574219,
,13908457.38,4369,3.00154995918274,0.13400000333786,0,582.730476074219,-7.59600019454956,195.409385223389,-7.59600019454956,415.709506835937,-7.59600019454956,,,101.568593368045,62.5036303766761,5.62994204209162,,25,582.730476074219,195.409385223389,415.709506835937,
,13908466.59,4369,2.9988499879837,0.13400000333786,0,570.852211914063,-7.5479998588562,163.584801483154,-7.5479998588562,409.398479003906,-7.5479998588562,,,107.511611401029,76.6379649670496,1.69994587477466,,25,570.852211914063,163.584801483154,409.398479003906,
,13908477.23,4369,3.00144994258881,0.13400000333786,0,379.510061035156,-7.52299976348877,160.503866729736,-7.52299976348877,406.429580078125,-7.52299976348877,,,0.109312387888496,75.0861403695745,1.25250938359555,,25,379.510061035156,160.503866729736,406.429580078125,
,13908488.69,4369,2.99855005741119,0.13400000333786,0,379.325306396484,-7.49900007247925,180.512166748047,-7.49900007247925,404.256052246094,-7.49900007247925,,,0.161835979965319,65.0291558895573,1.35663184894152,,25,379.325306396484,180.512166748047,404.256052246094,
,13908499.95,4369,2.99840009212494,0.13400000333786,0,379.1909375,-7.44999980926514,153.599531860352,-7.44999980926514,398.917856445313,-7.44999980926514,,,0.158057214069623,71.4187701605131,1.40301100347399,,25,379.1909375,153.599531860352,398.917856445313,
,13908511.27,4369,2.99899995326996,0.13400000333786,0,379.212349853516,-7.42600011825562,168.886533813477,-7.42600011825562,396.410389404297,-7.42600011825562,,,0.0873003839785833,60.3754668789402,1.26788819884868,,25,379.212349853516,168.886533813477,396.410389404297,
,13908522.44,4369,3.00010001659393,0.13400000333786,0,379.130510253906,-7.40100002288818,198.072890625,-7.40100002288818,393.830430908203,-7.40100002288818,,,0.101554797240368,12.766148974318,1.38258967750704,,25,379.130510253906,198.072890625,393.830430908203,
,13908533.70,4369,2.99985003471375,0.13400000333786,0,379.074503173828,-7.35200023651123,117.66610244751,-7.35200023651123,389.493173828125,-7.35200023651123,,,0.121110368461229,77.6188388260119,1.00490570786611,,25,379.074503173828,117.66610244751,389.493173828125,
,13908544.66,4369,3.00195002555847,0.13400000333786,0,379.03283203125,-7.32800006866455,92.9585330200195,-7.32800006866455,387.721901855469,-7.32800006866455,,,0.152564058636181,71.1376697898974,0.903512792297701,,25,379.03283203125,92.9585330200195,387.721901855469,
,13908555.81,4369,2.99890005588531,0.13400000333786,0,379.129459228516,-7.30299997329712,66.4442587280274,-7.30299997329712,385.683818359375,-7.30299997329712,,,0.105842274525331,49.8288455256073,1.03677301315887,,25,379.129459228516,66.4442587280274,385.683818359375,
,13908567.17,4369,3.00059998035431,0.13400000333786,0,378.933937988281,-7.25500011444092,47.3274919128418,-7.25500011444092,380.993322753906,-7.25500011444092,,,0.0805748156652557,0.189327352596635,1.16801438862405,,25,378.933937988281,47.3274919128418,380.993322753906,
,13908578.06,4369,3.00045001506805,0.13400000333786,0,546.913885498047,-7.23000001907349,48.0045422363281,-7.23000001907349,379.484412841797,-7.23000001907349,,,104.69282141351,3.62918556540757,1.36078295364869,,25,546.913885498047,48.0045422363281,379.484412841797,
,13908587.41,4369,2.99979996681213,0.13400000333786,0,378.848336181641,-7.18100023269653,52.6723782348633,-7.18100023269653,375.2561328125,-7.18100023269653,,,0.119314845478753,32.1059482633958,1.15804692758205,,25,378.848336181641,52.6723782348633,375.2561328125,
,13908598.66,4369,3.00020003318787,0.13400000333786,0,378.850499267578,-7.15700006484985,45.6018760681152,-7.15700006484985,372.872138671875,-7.15700006484985,,,0.168587459471657,0.280636946849319,1.02341538402066,,25,378.850499267578,45.6018760681152,372.872138671875,
,13908609.63,4369,2.9993999004364,0.13400000333786,0,378.730534667969,-7.13199996948242,58.0363356018066,-7.13199996948242,369.690892333984,-7.13199996948242,,,0.127550788412648,44.0645571991083,1.00071588193652,,25,378.730534667969,58.0363356018066,369.690892333984,
,13908620.70,4369,2.99899995326996,0.13400000333786,0,378.613522949219,-7.08400011062622,44.2369227600098,-7.08400011062622,361.133469238281,-7.08400011062622,,,0.135496170443352,0.29204295275888,1.10926896237493,,25,378.613522949219,44.2369227600098,361.133469238281,
,13908631.36,4369,2.99965000152588,0.13400000333786,0,378.578532714844,-7.05900001525879,63.1772814941406,-7.05900001525879,359.060855712891,-7.05900001525879,,,0.137259755745934,52.2939806207256,1.75783353198569,,25,378.578532714844,63.1772814941406,359.060855712891,
,13908642.59,4369,3.00059998035431,0.13400000333786,0,378.527260742187,-7.03499984741211,56.2738543701172,-7.03499984741211,356.721960449219,-7.03499984741211,,,0.148706265091454,43.400064392571,1.03512783707399,,25,378.527260742187,56.2738543701172,356.721960449219,
,13908653.67,4369,3.00104999542236,0.13400000333786,0,378.489708251953,-6.98600006103516,55.3387878417969,-6.98600006103516,352.948952636719,-6.98600006103516,,,0.131947156343494,43.3064843931821,0.996836921426405,,25,378.489708251953,55.3387878417969,352.948952636719,
,13908664.11,4369,2.99849998950958,0.13400000333786,0,378.443067626953,-6.96099996566772,54.8768035888672,-6.96099996566772,351.037701416016,-6.96099996566772,,,0.10225540902497,43.2292016419297,0.980308440086908,,25,378.443067626953,54.8768035888672,351.037701416016,
,13908675.34,4369,2.99970006942749,0.13400000333786,0,378.399525146484,-6.93699979782104,54.4036402893066,-6.93699979782104,348.783848876953,-6.93699979782104,,,0.141697087828902,43.1347927669175,0.899545313700872,,25,378.399525146484,54.4036402893066,348.783848876953,
,13908686.28,4369,3,0.13400000333786,0,378.348404541016,-6.88800001144409,66.5462898254395,-6.88800001144409,343.588685302734,-6.88800001144409,,,0.137738293211281,58.0777680507411,1.67143129075457,,25,378.348404541016,66.5462898254395,343.588685302734,
,13908696.97,4369,2.99870002269745,0.13400000333786,0,503.601079101563,-6.86399984359741,41.932972869873,-6.86399984359741,341.090969238281,-6.86399984359741,,,102.337153165262,6.67966609807686,1.364027692006,,25,503.601079101563,41.932972869873,341.090969238281,
,13908707.05,4369,2.99909996986389,0.13400000333786,0,452.599675292969,-6.83900022506714,52.9906364440918,-6.83900022506714,338.641982421875,-6.83900022506714,,,99.2462899497514,42.8988086184342,1.12017697088981,,25,452.599675292969,52.9906364440918,338.641982421875,
,13908715.94,4369,2.99920010566711,0.13400000333786,0,458.125521240234,-6.78999996185303,52.1342822265625,-6.78999996185303,334.712109375,-6.78999996185303,,,97.875809314168,42.8147011747389,1.01983161728853,,25,458.125521240234,52.1342822265625,334.712109375,
,13908725.11,4369,2.99930000305176,0.13400000333786,0,433.034934082031,-6.76599979400635,57.9247196960449,-6.76599979400635,333.014733886719,-6.76599979400635,,,88.0984476095221,51.2635100371137,1.0835829172827,,25,433.034934082031,57.9247196960449,333.014733886719,
,13908734.63,4369,2.99995005130768,0.13400000333786,0,460.86021484375,-6.74200010299683,51.3615591430664,-6.74200010299683,330.964285888672,-6.74200010299683,,,93.4210479727739,42.716021115555,0.978772240274311,,25,460.86021484375,51.3615591430664,330.964285888672,
,13908743.61,4369,3.00009989738464,0.13400000333786,0,554.016970214844,-6.69299983978271,50.5473905944824,-6.69299983978271,327.001866455078,-6.69299983978271,,,0.409667178969935,42.7338329665271,1.14202479462751,,25,554.016970214844,50.5473905944824,327.001866455078,
,13908752.70,4369,3.00050008296967,0.13400000333786,0,553.123996582031,-6.66800022125244,50.2201788330078,-6.66800022125244,325.088275146484,-6.66800022125244,,,0.290215646909182,42.6150026811924,1.10534448919653,,25,553.123996582031,50.2201788330078,325.088275146484,
,13908762.17,4369,3.00020003318787,0.13400000333786,0,552.437502441406,-6.64400005340576,49.836753692627,-6.64400005340576,322.789797363281,-6.64400005340576,,,0.243874858206711,42.6652913955479,1.07612266109287,,25,552.437502441406,49.836753692627,322.789797363281,
,13908771.48,4369,3.00064992904663,0.13400000333786,0,551.386879882813,-6.59499979019165,36.7240362548828,-6.59499979019165,318.820267333984,-6.59499979019165,,,0.201689656226635,0.300735956250786,0.872425334438878,,25,551.386879882813,36.7240362548828,318.820267333984,
,13908780.59,4369,3.00014996528625,0.13400000333786,0,550.67330078125,-6.57100009918213,55.1541474914551,-6.57100009918213,316.728005371094,-6.57100009918213,,,0.226452320614384,50.9979284536218,1.17516493821176,,25,550.67330078125,55.1541474914551,316.728005371094,
,13908788.95,4369,2.99839997291565,0.13400000333786,0,550.009348144531,-6.5460000038147,48.6322627258301,-6.5460000038147,314.710056152344,-6.5460000038147,,,0.157347835060802,42.4979666213751,1.00318009053875,,25,550.009348144531,48.6322627258301,314.710056152344,
,13908798.38,4369,2.99979996681213,0.13400000333786,0,548.6771484375,-6.49700021743774,66.8613520812988,-6.49700021743774,310.204600830078,-6.49700021743774,,,0.157340512868926,62.5838378535211,1.10601210838609,,25,548.6771484375,66.8613520812988,310.204600830078,
,13908807.59,4369,3.00110006332397,0.13400000333786,0,541.133184814453,-6.47300004959106,72.9052055358887,-6.47300004959106,308.048862304687,-6.47300004959106,,,33.3888952673629,66.6303869514652,1.10436176776207,,25,541.133184814453,72.9052055358887,308.048862304687,
,13908816.41,4369,3.00075006484985,0.13400000333786,0,505.995302734375,-6.42399978637695,60.2541540527344,-6.42399978637695,304.207537841797,-6.42399978637695,,,72.1508398857011,57.0158328006951,1.99155343824454,,25,505.995302734375,60.2541540527344,304.207537841797,
,13908825.48,4369,2.99919998645782,0.13400000333786,0,471.511444091797,-6.40000009536743,59.345320892334,-6.40000009536743,301.163918457031,-6.40000009536743,,,83.4105861585112,57.112434258426,1.38955465035348,,25,471.511444091797,59.345320892334,301.163918457031,
,13908834.19,4369,3.00069999694824,0.13400000333786,0,444.419239501953,-6.375,46.6877444458008,-6.375,299.017016601562,-6.375,,,81.9653794223298,42.2652216865491,1.30156986313374,,25,444.419239501953,46.6877444458008,299.017016601562,
,13908843.00,4369,3.00020003318787,0.13400000333786,0,390.620451660156,-6.32600021362305,33.7747998046875,-6.32600021362305,277.435323486328,-6.32600021362305,,,44.6304888832045,0.213034953259239,5.05978981646222,,25,390.620451660156,33.7747998046875,277.435323486328,
,13908851.53,4369,3.00080001354218,0.13400000333786,0,397.026379394531,-6.30200004577637,52.162585144043,-6.30200004577637,264.765562744141,-6.30200004577637,,,53.2393168021897,50.4008942507543,3.13642247491123,,25,397.026379394531,52.162585144043,264.765562744141,
,13908860.00,4369,2.99875009059906,0.13400000333786,0,390.266916503906,-6.27699995040894,45.6799967956543,-6.27699995040894,259.779533691406,-6.27699995040894,,,43.9695415968717,42.0368569824767,2.4264027580618,,25,390.266916503906,45.6799967956543,259.779533691406,
,13908868.44,4369,2.99909996986389,0.13400000333786,0,377.212652587891,-6.22900009155273,45.3005361938477,-6.22900009155273,252.315549316406,-6.22900009155273,,,0.156435227779707,41.9313585061626,2.09818644543968,,25,377.212652587891,45.3005361938477,252.315549316406,
,13908878.02,4369,3.00055003166199,0.13400000333786,0,377.993341064453,-6.2039999961853,33.3161053466797,-6.2039999961853,249.277156982422,-6.2039999961853,,,4.06686650609285,2.5940716694826,3.56339801242127,,25,377.993341064453,33.3161053466797,249.277156982422,
,13908886.92,4369,2.99825000762939,0.13400000333786,0,377.182120361328,-6.17999982833862,44.7609843444824,-6.17999982833862,246.519238891602,-6.17999982833862,,,0.118537742750658,41.7729183557106,1.35240815837262,,25,377.182120361328,44.7609843444824,246.519238891602,
,13908896.11,4369,3.00055003166199,0.13400000333786,0,377.053215332031,-6.13100004196167,68.9603806304932,-6.13100004196167,241.866834106445,-6.13100004196167,,,0.0935589315095385,65.4918330362194,1.58298486041101,,25,377.053215332031,68.9603806304932,241.866834106445,
,13908905.72,4369,3.00065004825592,0.13400000333786,0,376.941491699219,-6.10599994659424,38.0705819702148,-6.10599994659424,238.914929199219,-6.10599994659424,,,0.0900159866431668,29.9406082892742,1.28019640497095,,25,376.941491699219,38.0705819702148,238.914929199219,
,13908914.64,4369,3.00109994411469,0.13400000333786,0,376.859552001953,-6.08199977874756,50.0807302093506,-6.08199977874756,236.74668762207,-6.08199977874756,,,0.113333986037056,49.5547148052137,1.57052750059772,,25,376.859552001953,50.0807302093506,236.74668762207,
,13908923.53,4369,2.99930000305176,0.13400000333786,0,376.669515380859,-6.03299999237061,49.6413365936279,-6.03299999237061,232.052276000977,-6.03299999237061,,,0.0948935539512537,49.2749204214334,1.64270737158842,,25,376.669515380859,49.6413365936279,232.052276000977,
,13908933.36,4369,3,0.13400000333786,0,376.756619873047,-6.00899982452393,37.2971532440186,-6.00899982452393,230.025415039062,-6.00899982452393,,,0.130228406866313,29.6196659569739,2.0293565983248,,25,376.756619873047,37.2971532440186,230.025415039062,
,13908941.63,4369,3.00104999542236,0.13400000333786,0,376.688591308594,-5.98400020599365,31.1468905639648,-5.98400020599365,227.070164794922,-5.98400020599365,,,0.168512515332743,0.215387035335712,1.67485923361778,,25,376.688591308594,31.1468905639648,227.070164794922,
,13908951.41,4369,2.99905002117157,0.13400000333786,0,376.424748535156,-5.93599987030029,30.7744398498535,-5.93599987030029,221.755433349609,-5.93599987030029,,,0.15995466952669,0.158831418615165,1.41709350268295,,25,376.424748535156,30.7744398498535,221.755433349609,
,13908959.56,4369,2.99914991855621,0.13400000333786,0,376.389051513672,-5.91099977493286,30.6773215484619,-5.91099977493286,220.364016723633,-5.91099977493286,,,0.117483235884103,0.197339203568783,1.68657086961482,,25,376.389051513672,30.6773215484619,220.364016723633,
,13908967.84,4369,3.00185000896454,0.13400000333786,0,376.300474853516,-5.88700008392334,30.4938335418701,-5.88700008392334,217.973723754883,-5.88700008392334,,,0.120945502657395,0.198949087886739,1.36335205515427,,25,376.300474853516,30.4938335418701,217.973723754883,
,13908976.73,4369,2.99880003929138,0.13400000333786,0,376.128519287109,-5.83799982070923,30.1510758209229,-5.83799982070923,213.877361450195,-5.83799982070923,,,0.126796124423994,0.134605667037704,1.10245967570195,,25,376.128519287109,30.1510758209229,213.877361450195,
,13908985.59,4369,3.00034999847412,0.13400000333786,0,375.981662597656,-5.81300020217896,30.053818359375,-5.81300020217896,211.654247436523,-5.81300020217896,,,0.111838356954605,0.175107542795662,1.68321143572019,,25,375.981662597656,30.053818359375,211.654247436523,
,13908994.80,4369,3.00010001659393,0.13400000333786,0,376.038937988281,-5.78900003433228,30.0504489898682,-5.78900003433228,209.199755859375,-5.78900003433228,,,0.133462021933409,0.403180292678949,2.26805432964634,,25,376.038937988281,30.0504489898682,209.199755859375,
,13909003.14,4369,3.00045001506805,0.13400000333786,0,375.815349121094,-5.73999977111816,29.6658781433105,-5.73999977111816,203.316708984375,-5.73999977111816,,,0.156800885190796,0.174532413464753,2.2134536405164,,25,375.815349121094,29.6658781433105,203.316708984375,
,13909011.86,4369,3.00199997425079,0.13400000333786,0,375.66650390625,-5.71600008010864,29.6290560150146,-5.71600008010864,200.704378051758,-5.71600008010864,,,0.0857894459289349,0.223568864308954,2.5687141150429,,25,375.66650390625,29.6290560150146,200.704378051758,
,13909020.52,4369,2.99924993515015,0.13400000333786,0,375.442768554688,-5.69099998474121,29.5196351623535,-5.69099998474121,198.83571472168,-5.69099998474121,,,0.126238312936251,0.201612220808816,2.29473306008025,,25,375.442768554688,29.5196351623535,198.83571472168,
,13909029.69,4369,2.99984991550446,0.13400000333786,0,375.354313964844,-5.64200019836426,29.2009199523926,-5.64200019836426,192.841162109375,-5.64200019836426,,,0.177851218845181,0.144114457787063,3.26718903384035,,25,375.354313964844,29.2009199523926,192.841162109375,
,13909038.36,4369,3.0006000995636,0.13400000333786,0,375.307895507812,-5.61800003051758,29.0394514465332,-5.61800003051758,183.657276000977,-5.61800003051758,,,0.191045234917253,0.136232754786839,5.94510561957539,,25,375.307895507812,29.0394514465332,183.657276000977,
,13909046.86,4369,3.0003000497818,0.13400000333786,0,374.803325195312,-5.56899976730347,28.8966287994385,-5.56899976730347,157.899633178711,-5.56899976730347,,,0.104053488433957,0.146568397589486,4.81217466436544,,25,374.803325195312,28.8966287994385,157.899633178711,
,13909055.73,4369,3.00045001506805,0.13400000333786,0,374.729025878906,-5.54500007629395,28.9886290740967,-5.54500007629395,150.410618286133,-5.54500007629395,,,0.121885934463949,0.99245053312565,3.35336229241982,,25,374.729025878906,28.9886290740967,150.410618286133,
,13909064.34,4369,3.00114989280701,0.13400000333786,0,374.415606689453,-5.51999998092651,28.6202019500732,-5.51999998092651,144.742380371094,-5.51999998092651,,,0.137364447813289,0.108254889170821,2.22387844247994,,25,374.415606689453,28.6202019500732,144.742380371094,
,13909072.81,4369,2.99819993972778,0.13400000333786,0,374.114478759766,-5.47100019454956,28.4757147979736,-5.47100019454956,138.342180175781,-5.47100019454956,,,0.096335033807241,0.100008323158096,1.71755514468693,,25,374.114478759766,28.4757147979736,138.342180175781,
,13909081.39,4369,2.99940001964569,0.13400000333786,0,373.982691650391,-5.44700002670288,28.3794478607178,-5.44700002670288,135.827025756836,-5.44700002670288,,,0.111867642662911,0.138282010341449,2.22283002066523,,25,373.982691650391,28.3794478607178,135.827025756836,
,13909089.95,4369,3.00040006637573,0.13400000333786,0,373.599660644531,-5.4229998588562,28.3045545196533,-5.4229998588562,133.833178710937,-5.4229998588562,,,0.208666547309171,0.154164375351006,1.87723449381,,25,373.599660644531,28.3045545196533,133.833178710937,
,13909098.77,4369,3.00004994869232,0.13400000333786,0,373.229256591797,-5.37400007247925,28.106362991333,-5.37400007247925,129.906776428223,-5.37400007247925,,,0.17721803777426,0.142358662660034,1.88723282404594,,25,373.229256591797,28.106362991333,129.906776428223,
,13909107.47,4369,3.00049996376038,0.13400000333786,0,373.244565429688,-5.34899997711182,28.0022387695313,-5.34899997711182,128.201647338867,-5.34899997711182,,,0.190910352084846,0.140687745618145,1.80401039031477,,25,373.244565429688,28.0022387695313,128.201647338867,
,13909116.09,4369,2.99979996681213,0.13400000333786,0,374.821014404297,-5.32499980926514,32.0718354034424,-5.32499980926514,130.701651916504,-5.32499980926514,,,5.64506530065967,11.2157653516776,13.0294975826442,,25,374.821014404297,32.0718354034424,130.701651916504,
,13909125.45,4369,2.99989998340607,0.13400000333786,0,372.511917724609,-5.27600002288818,27.8165277099609,-5.27600002288818,124.142848510742,-5.27600002288818,,,0.184219881463181,0.145201903883869,1.92520291074052,,25,372.511917724609,27.8165277099609,124.142848510742,
,13909134.59,4369,3.00010001659393,0.13400000333786,0,372.371059570313,-5.2519998550415,27.7439253997803,-5.2519998550415,122.922610168457,-5.2519998550415,,,0.221586113731268,0.119823309463037,1.54013012342009,,25,372.371059570313,27.7439253997803,122.922610168457,
,13909143.22,4369,3.00010001659393,0.13400000333786,0,372.122978515625,-5.22700023651123,27.6364319610596,-5.22700023651123,121.45281463623,-5.22700023651123,,,0.108618252018503,0.15060209825482,1.7285383388723,,25,372.122978515625,27.6364319610596,121.45281463623,
,13909152.53,4369,2.99910008907318,0.13400000333786,0,372.262664794922,-5.17799997329712,27.5203948974609,-5.17799997329712,119.755064697266,-5.17799997329712,,,0.170881353103365,0.148654800011675,1.77331210422772,,25,372.262664794922,27.5203948974609,119.755064697266,
,13909161.70,4369,2.9993999004364,0.13400000333786,0,371.912683105469,-5.15399980545044,27.4691246795654,-5.15399980545044,118.739270935059,-5.15399980545044,,,0.108258351243162,0.155817352513063,1.80785484024587,,25,371.912683105469,27.4691246795654,118.739270935059,
,13909170.58,4369,3.00040006637573,0.13400000333786,0,371.934859619141,-5.12900018692017,27.4261510467529,-5.12900018692017,117.173771057129,-5.12900018692017,,,0.190599236142136,0.19976511020661,1.63731503604574,,25,371.934859619141,27.4261510467529,117.173771057129,
,13909179.08,4369,2.99995005130768,0.13400000333786,0,373.617526855469,-5.08099985122681,28.7964176177979,-5.08099985122681,119.090335388184,-5.08099985122681,,,6.49705927082872,5.44311735793845,9.66472754732237,,25,373.617526855469,28.7964176177979,119.090335388184,
,13909187.88,4369,3.00064992904663,0.13400000333786,0,371.486368408203,-5.05600023269653,27.1442174530029,-5.05600023269653,114.96583984375,-5.05600023269653,,,0.192491133869553,0.099881243113508,1.7607595102621,,25,371.486368408203,27.1442174530029,114.96583984375,
,13909196.03,4369,3,0.13400000333786,0,371.222025146484,-5.03200006484985,27.0458333587647,-5.03200006484985,114.023853759766,-5.03200006484985,,,0.140002269143576,0.11362639523495,1.59448840695189,,25,371.222025146484,27.0458333587647,114.023853759766,
,13909204.69,4369,3.00230002403259,0.13400000333786,0,370.730241699219,-5,27.0867004394531,-5,112.458813171387,-5,,,0.148956305764293,0.138496639371688,1.82856130863135,,25,370.730241699219,27.0867004394531,112.458813171387,