File: icepp/data/250308/250308_3D_mh_photolitho_IV2.dat
[Header]
TITLE, IV scan 0.1 to 1.0
FILEOPENTIME,13891252.22,3/8/2025,5:52 PM
BYAPP, Resistivity, 2.1, 1.0
INFO, APPNAME, PPMS MultiVu Application, 1.5.11
INFO, , Sample1 Name
INFO, 1, Sample1 Cross Section
INFO, 1, Sample1 Length
INFO, Ohm, Sample1 Units
INFO, , Sample2 Name
INFO, 1, Sample2 Cross Section
INFO, 1, Sample2 Length
INFO, Ohm, Sample2 Units
INFO, , Sample3 Name
INFO, 1, Sample3 Cross Section
INFO, 1, Sample3 Length
INFO, Ohm, Sample3 Units
INFO, , Sample4 Name
INFO, 1, Sample4 Cross Section
INFO, 1, Sample4 Length
INFO, Ohm, Sample4 Units
FIELDGROUP, Resistivity,2,3,4,5,6,7,8,9,10,11,12,13,14,15,16,17,18,19,20,21,22,23,24,25,26,27,28,29,30,31,32,33,34,35,36,37,38,39,40,41
STARTUPGROUP, Resistivity
STARTUPAXIS, X, 2, LINEAR, AUTO
STARTUPAXIS, Y1, 7, LINEAR, AUTO
STARTUPAXIS, Y2, 9, LINEAR, AUTO
STARTUPAXIS, Y3, 11, LINEAR, AUTO
PLOT_APPEARANCE, ALL, HORZ_GRID_ON, VERT_GRID_ON, MARKERS_AND_LINES, ALL_LINES
DATATYPE, TIME, 2
DATATYPE, COMMENT, 1
[Data]
Comment,Time Stamp (sec),Status (code),Temperature (K),Magnetic Field (Oe),Sample Position (deg),Bridge 1 Resistivity (Ohm),Bridge 1 Excitation (uA),Bridge 2 Resistivity (Ohm),Bridge 2 Excitation (uA),Bridge 3 Resistivity (Ohm),Bridge 3 Excitation (uA),Bridge 4 Resistivity (Ohm),Bridge 4 Excitation (uA),Bridge 1 Std. Dev. (Ohm),Bridge 2 Std. Dev. (Ohm),Bridge 3 Std. Dev. (Ohm),Bridge 4 Std. Dev. (Ohm),Number of Readings,Bridge 1 Resistance (Ohms),Bridge 2 Resistance (Ohms),Bridge 3 Resistance (Ohms),Bridge 4 Resistance (Ohms),Signal 1 Vin (V),Signal 2 Vin (V),Digital Inputs (code),Drive 1 Iout (mA),Drive 1 Ipower (watts),Drive 2 Iout (mA),Drive 2 Ipower (watts),Pressure (),Map 20 (),Map 21 (),Map 22 (),Map 23 (),Map 24 (),Map 25 (),Map 26 (),Map 27 (),Map 28 (),Map 29 ()
,13891460.69,4369,2.99989998340607,0.13400000333786,0,299.544006347656,0.100000001490116,23.2033309173584,0.100000001490116,30.048868637085,0.100000001490116,,,0.715528833026265,0.446283119159693,1.97623383407389,,25,299.544006347656,23.2033309173584,30.048868637085,
,13891469.06,4369,2.99994993209839,0.13400000333786,0,300.321925048828,0.200000002980232,22.9715860748291,0.200000002980232,30.7572216033936,0.200000002980232,,,1.00451779425588,0.202041212872647,1.79932270234978,,25,300.321925048828,22.9715860748291,30.7572216033936,
,13891477.23,4369,3.00055003166199,0.13400000333786,0,300.395811767578,0.300000011920929,22.48626953125,0.300000011920929,31.4606623077393,0.300000011920929,,,1.31049255458363,0.158169796461422,1.77677418032349,,25,300.395811767578,22.48626953125,31.4606623077393,
,13891485.47,4369,2.9988499879837,0.13400000333786,0,301.911676025391,0.400999993085861,22.8790245819092,0.400999993085861,31.2777786254883,0.400999993085861,,,2.254725387995,0.193410750330158,2.14711124548766,,25,301.911676025391,22.8790245819092,31.2777786254883,
,13891494.33,4369,2.99979996681213,0.13400000333786,0,301.788714599609,0.500999987125397,22.8938542175293,0.500999987125397,31.7316619110107,0.500999987125397,,,0.694200996510529,0.139492546680299,2.10863360010316,,25,301.788714599609,22.8938542175293,31.7316619110107,
,13891502.33,4369,3.00034999847412,0.13400000333786,0,302.663725585938,0.601000010967255,22.6701100921631,0.601000010967255,32.1508322143555,0.601000010967255,,,1.81912200491572,0.107615978608662,2.33256688814118,,25,302.663725585938,22.6701100921631,32.1508322143555,
,13891509.95,4369,3.00010001659393,0.13400000333786,0,302.910434570312,0.700999975204468,22.7383104705811,0.700999975204468,31.53296043396,0.700999975204468,,,0.571315520783948,0.0990397206913719,1.53538210641831,,25,302.910434570312,22.7383104705811,31.53296043396,
,13891518.64,4369,2.99925005435944,0.13400000333786,0,302.885588378906,0.800999999046326,22.8936720275879,0.800999999046326,32.5535005187988,0.800999999046326,,,0.57689762424399,0.080140369975573,1.69551198910495,,25,302.885588378906,22.8936720275879,32.5535005187988,
,13891526.78,4369,2.99919998645782,0.13400000333786,0,304.247059326172,0.898999989032745,22.8349172973633,0.898999989032745,32.546150894165,0.898999989032745,,,0.535726438993435,0.0551487448158891,1.2231510186671,,25,304.247059326172,22.8349172973633,32.546150894165,
,13891535.80,4369,2.99954998493195,0.13400000333786,0,305.57138671875,0.999000012874603,22.9097930908203,0.999000012874603,33.9936985778809,0.999000012874603,,,0.985953605374679,0.17137196754832,2.23897341545172,,25,305.57138671875,22.9097930908203,33.9936985778809,