File: icepp/data/250308/250308_3D_mh_photolitho_IV_minus_fineUp1.dat
[Header]
TITLE, IV scan -5 to -10 (0.033 scan)
FILEOPENTIME,13903206.92,3/8/2025,9:11 PM
BYAPP, Resistivity, 2.1, 1.0
INFO, APPNAME, PPMS MultiVu Application, 1.5.11
INFO, , Sample1 Name
INFO, 1, Sample1 Cross Section
INFO, 1, Sample1 Length
INFO, Ohm, Sample1 Units
INFO, , Sample2 Name
INFO, 1, Sample2 Cross Section
INFO, 1, Sample2 Length
INFO, Ohm, Sample2 Units
INFO, , Sample3 Name
INFO, 1, Sample3 Cross Section
INFO, 1, Sample3 Length
INFO, Ohm, Sample3 Units
INFO, , Sample4 Name
INFO, 1, Sample4 Cross Section
INFO, 1, Sample4 Length
INFO, Ohm, Sample4 Units
FIELDGROUP, Resistivity,2,3,4,5,6,7,8,9,10,11,12,13,14,15,16,17,18,19,20,21,22,23,24,25,26,27,28,29,30,31,32,33,34,35,36,37,38,39,40,41
STARTUPGROUP, Resistivity
STARTUPAXIS, X, 2, LINEAR, AUTO
STARTUPAXIS, Y1, 7, LINEAR, AUTO
STARTUPAXIS, Y2, 9, LINEAR, AUTO
STARTUPAXIS, Y3, 11, LINEAR, AUTO
PLOT_APPEARANCE, ALL, HORZ_GRID_ON, VERT_GRID_ON, MARKERS_AND_LINES, ALL_LINES
DATATYPE, TIME, 2
DATATYPE, COMMENT, 1
[Data]
Comment,Time Stamp (sec),Status (code),Temperature (K),Magnetic Field (Oe),Sample Position (deg),Bridge 1 Resistivity (Ohm),Bridge 1 Excitation (uA),Bridge 2 Resistivity (Ohm),Bridge 2 Excitation (uA),Bridge 3 Resistivity (Ohm),Bridge 3 Excitation (uA),Bridge 4 Resistivity (Ohm),Bridge 4 Excitation (uA),Bridge 1 Std. Dev. (Ohm),Bridge 2 Std. Dev. (Ohm),Bridge 3 Std. Dev. (Ohm),Bridge 4 Std. Dev. (Ohm),Number of Readings,Bridge 1 Resistance (Ohms),Bridge 2 Resistance (Ohms),Bridge 3 Resistance (Ohms),Bridge 4 Resistance (Ohms),Signal 1 Vin (V),Signal 2 Vin (V),Digital Inputs (code),Drive 1 Iout (mA),Drive 1 Ipower (watts),Drive 2 Iout (mA),Drive 2 Ipower (watts),Pressure (),Map 20 (),Map 21 (),Map 22 (),Map 23 (),Map 24 (),Map 25 (),Map 26 (),Map 27 (),Map 28 (),Map 29 ()
,13906276.13,4369,2.99829995632172,0.13400000333786,0,370.418065185547,-5,27.191575088501,-5,112.701108703613,-5,,,0.140727988398701,0.0767641635923261,1.69281599701172,,25,370.418065185547,27.191575088501,112.701108703613,
,13906285.16,4369,3.00065004825592,0.13400000333786,0,371.238074951172,-5.03200006484985,27.1802238464355,-5.03200006484985,114.392590332031,-5.03200006484985,,,0.186942707648838,0.125674576251384,1.65496918350658,,25,371.238074951172,27.1802238464355,114.392590332031,
,13906294.00,4369,3.00010001659393,0.13400000333786,0,371.344936523438,-5.05600023269653,27.2244493865967,-5.05600023269653,114.846943359375,-5.05600023269653,,,0.09248943920421,0.115891202234952,1.71733999091528,,25,371.344936523438,27.2244493865967,114.846943359375,
,13906302.31,4369,3.00049996376038,0.13400000333786,0,371.653636474609,-5.08099985122681,27.2920233154297,-5.08099985122681,116.236230773926,-5.08099985122681,,,0.146291983544073,0.120566199086591,1.8279041679966,,25,371.653636474609,27.2920233154297,116.236230773926,
,13906310.72,4369,3.00080001354218,0.13400000333786,0,372.020662841797,-5.12900018692017,27.4160287475586,-5.12900018692017,117.27652557373,-5.12900018692017,,,0.144368279566965,0.133837056766286,1.42789514210881,,25,372.020662841797,27.4160287475586,117.27652557373,
,13906319.22,4369,2.99895000457764,0.13400000333786,0,372.107513427734,-5.15399980545044,27.5126261901855,-5.15399980545044,118.81326385498,-5.15399980545044,,,0.123365717507814,0.134600362928597,1.79349047598439,,25,372.107513427734,27.5126261901855,118.81326385498,
,13906328.30,4369,2.99995005130768,0.13400000333786,0,372.140949707031,-5.17799997329712,27.5575505065918,-5.17799997329712,119.598236694336,-5.17799997329712,,,0.147800828305806,0.140149785819471,1.60434465150238,,25,372.140949707031,27.5575505065918,119.598236694336,
,13906336.64,4369,2.99975001811981,0.13400000333786,0,372.632689208984,-5.22700023651123,27.7244025421143,-5.22700023651123,122.626597900391,-5.22700023651123,,,0.197944819901864,0.101017983027267,1.55195006738837,,25,372.632689208984,27.7244025421143,122.626597900391,
,13906344.36,4369,2.99855005741119,0.13400000333786,0,372.701042480469,-5.2519998550415,27.8008848571777,-5.2519998550415,123.428900146484,-5.2519998550415,,,0.159916722889954,0.111667269914757,1.75321434238794,,25,372.701042480469,27.8008848571777,123.428900146484,
,13906353.41,4369,3.00094997882843,0.13400000333786,0,373.085250244141,-5.27600002288818,27.8553700256348,-5.27600002288818,124.304961242676,-5.27600002288818,,,0.190794435963484,0.124499907155496,2.11086474484036,,25,373.085250244141,27.8553700256348,124.304961242676,
,13906362.67,4369,3.00069999694824,0.13400000333786,0,373.325753173828,-5.32499980926514,28.0435607910156,-5.32499980926514,127.400825805664,-5.32499980926514,,,0.132407780621782,0.131841306752464,1.75504254249444,,25,373.325753173828,28.0435607910156,127.400825805664,
,13906371.19,4369,2.9985499382019,0.13400000333786,0,373.534283447266,-5.34899997711182,28.1235742950439,-5.34899997711182,128.440563354492,-5.34899997711182,,,0.11403868470293,0.11572840054535,2.22152719353981,,25,373.534283447266,28.1235742950439,128.440563354492,
,13906380.00,4369,2.99949991703033,0.13400000333786,0,373.677248535156,-5.37400007247925,28.1946060180664,-5.37400007247925,130.35547668457,-5.37400007247925,,,0.144886439232843,0.133765219233383,1.54615218867234,,25,373.677248535156,28.1946060180664,130.35547668457,
,13906388.11,4369,2.99870002269745,0.13400000333786,0,373.993751220703,-5.4229998588562,28.4178073883057,-5.4229998588562,133.919055786133,-5.4229998588562,,,0.147091283006051,0.127565444520596,1.78553823409791,,25,373.993751220703,28.4178073883057,133.919055786133,
,13906397.20,4369,3.00109994411469,0.13400000333786,0,374.082978515625,-5.44700002670288,28.4905968475342,-5.44700002670288,136.151016235352,-5.44700002670288,,,0.105588488194725,0.136744696968764,2.09151286152974,,25,374.082978515625,28.4905968475342,136.151016235352,
,13906406.09,4369,2.99954998493195,0.13400000333786,0,374.377908935547,-5.47100019454956,28.5701565551758,-5.47100019454956,139.154260253906,-5.47100019454956,,,0.119884650645764,0.123198232010543,1.84510339885464,,25,374.377908935547,28.5701565551758,139.154260253906,
,13906414.41,4369,3.0011500120163,0.13400000333786,0,374.709987792969,-5.51999998092651,28.7934669494629,-5.51999998092651,145.136319580078,-5.51999998092651,,,0.194443534158575,0.131864101653473,2.51266435050581,,25,374.709987792969,28.7934669494629,145.136319580078,
,13906422.80,4369,3.00090003013611,0.13400000333786,0,374.7825,-5.54500007629395,28.8742350769043,-5.54500007629395,150.393965454102,-5.54500007629395,,,0.18058286175913,0.123714569680894,2.80504985470187,,25,374.7825,28.8742350769043,150.393965454102,
,13906430.80,4369,3.00034999847412,0.13400000333786,0,374.9830078125,-5.56899976730347,28.9319647216797,-5.56899976730347,155.771931152344,-5.56899976730347,,,0.110733402683142,0.127651080489534,3.73167385007626,,25,374.9830078125,28.9319647216797,155.771931152344,
,13906438.59,4369,3.00014996528625,0.13400000333786,0,375.251130371094,-5.61800003051758,29.1838134002686,-5.61800003051758,182.49229675293,-5.61800003051758,,,0.121298114375298,0.128265088985251,4.14876620102675,,25,375.251130371094,29.1838134002686,182.49229675293,
,13906447.22,4369,2.99965000152588,0.13400000333786,0,375.437901611328,-5.64200019836426,29.3766313171387,-5.64200019836426,192.687570800781,-5.64200019836426,,,0.155936130143225,0.180387425225075,4.82261402537005,,25,375.437901611328,29.3766313171387,192.687570800781,
,13906455.88,4369,3.00015008449554,0.13400000333786,0,375.689302978516,-5.69099998474121,29.6432772827148,-5.69099998474121,199.168934326172,-5.69099998474121,,,0.155100469134086,0.201981282139799,2.14448075116324,,25,375.689302978516,29.6432772827148,199.168934326172,
,13906465.22,4369,2.99984991550446,0.13400000333786,0,375.899301757813,-5.71600008010864,29.6927500915527,-5.71600008010864,200.787940063477,-5.71600008010864,,,0.140194061120225,0.16978036445684,2.41357802318107,,25,375.899301757813,29.6927500915527,200.787940063477,
,13906474.25,4369,3.00045001506805,0.13400000333786,0,375.931876220703,-5.73999977111816,29.7514547729492,-5.73999977111816,203.223338012695,-5.73999977111816,,,0.115372899183873,0.154898781439355,2.487976650626,,25,375.931876220703,29.7514547729492,203.223338012695,
,13906483.42,4369,3.00059998035431,0.13400000333786,0,376.065587158203,-5.78900003433228,29.987495880127,-5.78900003433228,208.539429931641,-5.78900003433228,,,0.108017188981465,0.157805923006184,1.2959488490736,,25,376.065587158203,29.987495880127,208.539429931641,
,13906492.00,4369,3.00020003318787,0.13400000333786,0,376.118120117188,-5.81300020217896,30.1533068084717,-5.81300020217896,211.579014282227,-5.81300020217896,,,0.0971848508232388,0.166617691560619,1.5885699188654,,25,376.118120117188,30.1533068084717,211.579014282227,
,13906501.27,4369,2.99985003471375,0.13400000333786,0,376.285474853516,-5.83799982070923,30.272723236084,-5.83799982070923,213.881034545898,-5.83799982070923,,,0.127568460668269,0.172778665987352,1.62725282790714,,25,376.285474853516,30.272723236084,213.881034545898,
,13906510.13,4369,2.99914991855621,0.13400000333786,0,376.533333740234,-5.88700008392334,30.532606048584,-5.88700008392334,217.901513671875,-5.88700008392334,,,0.109564310817258,0.158979197191319,1.60118324694555,,25,376.533333740234,30.532606048584,217.901513671875,
,13906519.64,4369,2.99970006942749,0.13400000333786,0,376.573717041016,-5.91099977493286,30.733138885498,-5.91099977493286,219.669569702148,-5.91099977493286,,,0.0853643782959578,0.198629402308382,1.45081993449775,,25,376.573717041016,30.733138885498,219.669569702148,
,13906528.41,4369,2.99965000152588,0.13400000333786,0,376.678848876953,-5.93599987030029,30.9165210723877,-5.93599987030029,222.635557250977,-5.93599987030029,,,0.123466855889949,0.143563811984701,1.82638116749992,,25,376.678848876953,30.9165210723877,222.635557250977,
,13906537.36,4369,2.99935007095337,0.13400000333786,0,377.104997558594,-5.98400020599365,31.4611951446533,-5.98400020599365,227.712035522461,-5.98400020599365,,,1.19602625878389,1.39361392602025,4.68068859255287,,25,377.104997558594,31.4611951446533,227.712035522461,
,13906545.78,4369,2.99994993209839,0.13400000333786,0,376.8066796875,-6.00899982452393,37.3754737091064,-6.00899982452393,229.334999389648,-6.00899982452393,,,0.0857248262085986,29.6304988045809,1.58241964641197,,25,376.8066796875,37.3754737091064,229.334999389648,
,13906554.44,4369,3.00045001506805,0.13400000333786,0,376.967702636719,-6.03299999237061,55.7819940185547,-6.03299999237061,232.473540039063,-6.03299999237061,,,0.134482759580617,55.6100836912893,1.64463238113341,,25,376.967702636719,55.7819940185547,232.473540039063,
,13906564.16,4369,3.00050008296967,0.13400000333786,0,377.071416015625,-6.08199977874756,50.12072265625,-6.08199977874756,236.522568359375,-6.08199977874756,,,0.088879770721637,49.5963645122819,1.68357181996561,,25,377.071416015625,50.12072265625,236.522568359375,
,13906572.63,4369,2.99950003623962,0.13400000333786,0,377.1111328125,-6.10599994659424,32.0369728851318,-6.10599994659424,238.71345703125,-6.10599994659424,,,0.111072898274874,0.205455472712503,1.45635915161995,,25,377.1111328125,32.0369728851318,238.71345703125,
,13906581.98,4369,2.99940001964569,0.13400000333786,0,377.128884277344,-6.13100004196167,44.4556880187988,-6.13100004196167,241.409956054688,-6.13100004196167,,,0.0989431615791271,41.5671748887362,1.65679785107772,,25,377.128884277344,44.4556880187988,241.409956054688,
,13906591.63,4369,3.00074994564056,0.13400000333786,0,377.262082519531,-6.17999982833862,44.925421295166,-6.17999982833862,246.05986328125,-6.17999982833862,,,0.131571112990613,41.7413087379727,1.7251360779981,,25,377.262082519531,44.925421295166,246.05986328125,
,13906601.16,4369,2.99909996986389,0.13400000333786,0,377.232066650391,-6.2039999961853,45.1108387756348,-6.2039999961853,248.953844604492,-6.2039999961853,,,0.143817269166096,41.7685378400279,1.44771546405064,,25,377.232066650391,45.1108387756348,248.953844604492,
,13906610.23,4369,2.99979996681213,0.13400000333786,0,377.287702636719,-6.22900009155273,33.0325860595703,-6.22900009155273,252.401516113281,-6.22900009155273,,,0.134528744479157,0.236585545290353,1.49439474460793,,25,377.287702636719,33.0325860595703,252.401516113281,
,13906619.08,4369,3.00135004520416,0.13400000333786,0,390.538132324219,-6.27699995040894,39.513895111084,-6.27699995040894,259.377690429688,-6.27699995040894,,,44.0436798598814,30.3966462862782,2.70619122094079,,25,390.538132324219,39.513895111084,259.377690429688,
,13906627.53,4369,2.99925005435944,0.13400000333786,0,403.722614746094,-6.30200004577637,39.7444696044922,-6.30200004577637,265.824815673828,-6.30200004577637,,,60.1241580273207,30.3903973259701,2.89988322961703,,25,403.722614746094,39.7444696044922,265.824815673828,
,13906636.25,4369,3.00034999847412,0.13400000333786,0,403.936533203125,-6.32600021362305,52.3647138977051,-6.32600021362305,276.038099365234,-6.32600021362305,,,60.6469714231657,50.4997797977495,7.62022849724685,,25,403.936533203125,52.3647138977051,276.038099365234,
,13906645.38,4369,2.99970006942749,0.13400000333786,0,444.614188232422,-6.375,52.858317565918,-6.375,298.963825683594,-6.375,,,82.0913000031117,50.5925285008111,1.17238662663763,,25,444.614188232422,52.858317565918,298.963825683594,
,13906654.36,4369,3.0003000497818,0.13400000333786,0,485.479145507813,-6.40000009536743,47.0200695800781,-6.40000009536743,301.637119140625,-6.40000009536743,,,80.9074480747528,42.2669244005571,0.976871212250071,,25,485.479145507813,47.0200695800781,301.637119140625,
,13906663.23,4369,3.00134992599487,0.13400000333786,0,540.231776123047,-6.42399978637695,41.0182685852051,-6.42399978637695,303.457551269531,-6.42399978637695,,,33.1661853596062,30.5871573154731,1.17420384662282,,25,540.231776123047,41.0182685852051,303.457551269531,
,13906672.95,4369,3.00034999847412,0.13400000333786,0,541.601578369141,-6.47300004959106,35.2381887817383,-6.47300004959106,307.825494384766,-6.47300004959106,,,33.487795220332,0.157885785968324,1.07597553358068,,25,541.601578369141,35.2381887817383,307.825494384766,
,13906682.58,4369,2.99920010566711,0.13400000333786,0,549.25453125,-6.49700021743774,60.6417190551758,-6.49700021743774,310.48078125,-6.49700021743774,,,0.152425093017746,57.3831290379031,1.20251978664217,,25,549.25453125,60.6417190551758,310.48078125,
,13906691.56,4369,3.00059998035431,0.13400000333786,0,550.605539550781,-6.5460000038147,55.0297123718262,-6.5460000038147,314.660633544922,-6.5460000038147,,,0.215489253345594,50.9061277992138,0.963118355994106,,25,550.605539550781,55.0297123718262,314.660633544922,
,13906701.31,4369,3.00049996376038,0.13400000333786,0,551.2896484375,-6.57100009918213,42.7592349243164,-6.57100009918213,316.876112060547,-6.57100009918213,,,0.278241407561545,30.7503775242014,0.904283510168845,,25,551.2896484375,42.7592349243164,316.876112060547,
,13906709.98,4369,2.99900007247925,0.13400000333786,0,551.759592285156,-6.59499979019165,42.9534637451172,-6.59499979019165,318.532338867187,-6.59499979019165,,,0.295512374816238,30.7639835374634,0.958178227703128,,25,551.759592285156,42.9534637451172,318.532338867187,
,13906719.38,4369,3.00020003318787,0.13400000333786,0,552.996323242187,-6.64400005340576,75.4447918701172,-6.64400005340576,323.243278808594,-6.64400005340576,,,0.719731100243105,66.9424847837072,1.86850900897106,,25,552.996323242187,75.4447918701172,323.243278808594,
,13906728.33,4369,3.00059998035431,0.13400000333786,0,553.674672851562,-6.66800022125244,62.9079951477051,-6.66800022125244,324.549044189453,-6.66800022125244,,,0.490368998480565,57.6182281704753,0.970134537416339,,25,553.674672851562,62.9079951477051,324.549044189453,
,13906736.63,4369,3.00034999847412,0.13400000333786,0,555.451318359375,-6.69299983978271,57.0074873352051,-6.69299983978271,327.170740966797,-6.69299983978271,,,1.31326702276316,51.0849584582816,0.977776190825474,,25,555.451318359375,57.0074873352051,327.170740966797,
,13906745.83,4369,2.9994500875473,0.13400000333786,0,455.081674804688,-6.74200010299683,57.7711093139648,-6.74200010299683,331.618590087891,-6.74200010299683,,,93.998010213875,51.2369132492019,1.0164329192207,,25,455.081674804688,57.7711093139648,331.618590087891,
,13906755.42,4369,3.00045001506805,0.13400000333786,0,449.471265869141,-6.76599979400635,45.4815765380859,-6.76599979400635,333.121071777344,-6.76599979400635,,,94.8428999334821,30.8975403302573,1.00560310483622,,25,449.471265869141,45.4815765380859,333.121071777344,
,13906764.17,4369,2.99944996833801,0.13400000333786,0,474.85693359375,-6.78999996185303,53.4717590332031,-6.78999996185303,336.689688720703,-6.78999996185303,,,100.448602575418,42.7084196422776,5.75784929710961,,25,474.85693359375,53.4717590332031,336.689688720703,
,13906773.16,4369,3.0011500120163,0.13400000333786,0,452.963765869141,-6.83900022506714,46.9560040283203,-6.83900022506714,338.560521240234,-6.83900022506714,,,99.3293351938856,30.9869675191985,1.12509888703558,,25,452.963765869141,46.9560040283203,338.560521240234,
,13906782.25,4369,3.00050008296967,0.13400000333786,0,378.5201953125,-6.86399984359741,53.376039276123,-6.86399984359741,340.818553466797,-6.86399984359741,,,0.121600251910297,42.9510133602538,1.19021134146224,,25,378.5201953125,53.376039276123,340.818553466797,
,13906793.34,4369,2.99934995174408,0.13400000333786,0,378.560788574219,-6.88800001144409,47.6133436584473,-6.88800001144409,343.916849365234,-6.88800001144409,,,0.119281036880748,31.0424714194778,1.5115751563418,,25,378.560788574219,47.6133436584473,343.916849365234,
,13906803.86,4369,2.99940001964569,0.13400000333786,0,378.591539306641,-6.93699979782104,61.2452931213379,-6.93699979782104,349.300222167969,-6.93699979782104,,,0.138597688823742,51.6790798534655,1.14900993057954,,25,378.591539306641,61.2452931213379,349.300222167969,
,13906814.47,4369,2.99965000152588,0.13400000333786,0,378.68166015625,-6.96099996566772,55.0543013000488,-6.96099996566772,350.877534179687,-6.96099996566772,,,0.15549605926589,43.2446230858267,0.979509784536198,,25,378.68166015625,55.0543013000488,350.877534179687,
,13906825.78,4369,3.00125002861023,0.13400000333786,0,378.708869628906,-6.98600006103516,68.3314562988281,-6.98600006103516,353.09208984375,-6.98600006103516,,,0.156266064022982,58.5318582015324,1.02552684326882,,25,378.708869628906,68.3314562988281,353.09208984375,
,13906836.64,4369,3.00004994869232,0.13400000333786,0,506.937399902344,-7.03499984741211,63.0701301574707,-7.03499984741211,357.45724609375,-7.03499984741211,,,104.618712107918,52.0899352944896,1.48950893728117,,25,506.937399902344,63.0701301574707,357.45724609375,
,13906846.41,4369,3.0008499622345,0.13400000333786,0,378.792553710938,-7.05900001525879,69.8233842468262,-7.05900001525879,358.850272216797,-7.05900001525879,,,0.181818780114562,58.967972377646,1.0443503085918,,25,378.792553710938,69.8233842468262,358.850272216797,
,13906857.38,4369,3.00164997577667,0.13400000333786,0,378.862287597656,-7.08400011062622,63.9248045349121,-7.08400011062622,361.648546142578,-7.08400011062622,,,0.182513995772951,52.4274381658173,1.31222675873959,,25,378.862287597656,63.9248045349121,361.648546142578,
,13906868.02,4369,2.99940001964569,0.13400000333786,0,378.971204833984,-7.13199996948242,58.3864047241211,-7.13199996948242,369.992447509766,-7.13199996948242,,,0.131317032289384,44.0315962896413,1.25895722494043,,25,378.971204833984,58.3864047241211,369.992447509766,
,13906879.14,4369,3.00040006637573,0.13400000333786,0,379.025028076172,-7.15700006484985,52.2816424560547,-7.15700006484985,372.849874267578,-7.15700006484985,,,0.108786641732614,31.9780503817408,0.871861736177916,,25,379.025028076172,52.2816424560547,372.849874267578,
,13906889.88,4369,3.00015008449554,0.13400000333786,0,378.961500244141,-7.18100023269653,46.2242524719238,-7.18100023269653,374.965379638672,-7.18100023269653,,,0.0913629961058987,0.316163856454372,0.903056749027751,,25,378.961500244141,46.2242524719238,374.965379638672,
,13906901.22,4369,3.00125002861023,0.13400000333786,0,379.098865966797,-7.23000001907349,66.8040579223633,-7.23000001907349,378.968917236328,-7.23000001907349,,,0.135531697734166,53.4958664536998,0.893767433606978,,25,379.098865966797,66.8040579223633,378.968917236328,
,13906912.38,4369,3.00050008296967,0.13400000333786,0,379.117906494141,-7.25500011444092,67.8454273986816,-7.25500011444092,381.331431884766,-7.25500011444092,,,0.158404173505356,55.3830259425,0.853487100376197,,25,379.117906494141,67.8454273986816,381.331431884766,
,13906923.31,4369,2.9996999502182,0.13400000333786,0,379.197918701172,-7.30299997329712,118.124502258301,-7.30299997329712,385.309114990234,-7.30299997329712,,,0.133712385909053,74.7624920158558,0.883892159827314,,25,379.197918701172,118.124502258301,385.309114990234,
,13906934.06,4369,2.99835002422333,0.13400000333786,0,379.296092529297,-7.32800006866455,118.762312011719,-7.32800006866455,387.510173339844,-7.32800006866455,,,0.122481904053563,78.558373967083,1.00256071155053,,25,379.296092529297,118.762312011719,387.510173339844,
,13906945.22,4369,2.99994993209839,0.13400000333786,0,388.812342529297,-7.35200023651123,127.088036346436,-7.35200023651123,389.626390380859,-7.35200023651123,,,46.3642032205301,77.5871360508876,0.956803788309615,,25,388.812342529297,127.088036346436,389.626390380859,
,13906956.31,4369,3.00019991397858,0.13400000333786,0,503.547802734375,-7.40100002288818,184.754313812256,-7.40100002288818,394.251188964844,-7.40100002288818,,,119.337351008776,50.7666208582363,3.29073913164701,,25,503.547802734375,184.754313812256,394.251188964844,
,13906966.36,4369,2.9991500377655,0.13400000333786,0,379.395338134766,-7.42600011825562,184.7948487854,-7.42600011825562,395.958050537109,-7.42600011825562,,,0.111548690214572,50.8411825537642,0.998790797474731,,25,379.395338134766,184.7948487854,395.958050537109,
,13906977.88,4369,2.99924993515015,0.13400000333786,0,379.519831542969,-7.44999980926514,192.851220550537,-7.44999980926514,398.874927978516,-7.44999980926514,,,0.113501773449059,43.4502987065493,1.58957468365411,,25,379.519831542969,192.851220550537,398.874927978516,
,13906988.83,4369,2.99925005435944,0.13400000333786,0,379.574675292969,-7.49900007247925,146.479013366699,-7.49900007247925,404.260476074219,-7.49900007247925,,,0.138973814868405,77.9701854229032,1.39702831692095,,25,379.574675292969,146.479013366699,404.260476074219,
,13907000.08,4369,2.9988499879837,0.13400000333786,0,590.730804443359,-7.52299976348877,181.339737548828,-7.52299976348877,406.921314697266,-7.52299976348877,,,92.1094667578368,65.1444079162451,1.2675456554131,,25,590.730804443359,181.339737548828,406.921314697266,
,13907009.69,4369,3.00069999694824,0.13400000333786,0,379.791640625,-7.5479998588562,191.254121246338,-7.5479998588562,409.270776367188,-7.5479998588562,,,0.142038529017934,60.6797567164293,1.45936836663011,,25,379.791640625,191.254121246338,409.270776367188,
,13907020.48,4369,2.99995005130768,0.13400000333786,0,633.027333984375,-7.59600019454956,171.392463378906,-7.59600019454956,415.77498046875,-7.59600019454956,,,1.13506702664105,74.2315029416091,4.99214520962582,,25,633.027333984375,171.392463378906,415.77498046875,
,13907030.02,4369,3.00080001354218,0.13400000333786,0,582.551187744141,-7.62099981307983,196.054903259277,-7.62099981307983,418.830167236328,-7.62099981307983,,,101.245495430964,62.3026894119026,2.59793418864174,,25,582.551187744141,196.054903259277,418.830167236328,
,13907040.14,4369,2.99989998340607,0.13400000333786,0,380.001638183594,-7.64499998092651,163.653590240479,-7.64499998092651,423.399132080078,-7.64499998092651,,,0.146470212053042,82.7543749303638,4.30906593313331,,25,380.001638183594,163.653590240479,423.399132080078,
,13907052.00,4369,2.99930000305176,0.13400000333786,0,379.986248779297,-7.69399976730347,174.086621551514,-7.69399976730347,432.692276611328,-7.69399976730347,,,0.0930496295766245,89.9800745970444,4.05214373782287,,25,379.986248779297,174.086621551514,432.692276611328,
,13907063.33,4369,3.00059998035431,0.13400000333786,0,634.583557128906,-7.7189998626709,131.569569244385,-7.7189998626709,437.266424560547,-7.7189998626709,,,0.232615087044855,94.4471729899265,5.28771069124909,,25,634.583557128906,131.569569244385,437.266424560547,
,13907072.84,4369,3.00029993057251,0.13400000333786,0,635.721291503906,-7.74300003051758,92.6276103210449,-7.74300003051758,447.774678955078,-7.74300003051758,,,0.767823572263834,75.8288806518665,2.18069083603872,,25,635.721291503906,92.6276103210449,447.774678955078,
,13907082.33,4369,2.99890005588531,0.13400000333786,0,506.834080810547,-7.79199981689453,99.2562008666992,-7.79199981689453,453.939227294922,-7.79199981689453,,,131.774878059752,70.1730161730008,0.725207683194034,,25,506.834080810547,99.2562008666992,453.939227294922,
,13907094.16,4369,2.99980008602142,0.13400000333786,0,638.702751464844,-7.81599998474121,93.6222280883789,-7.81599998474121,455.864951171875,-7.81599998474121,,,52.7787649380331,67.2606609285966,0.9149779761325,,25,638.702751464844,93.6222280883789,455.864951171875,
,13907105.31,4369,2.99955010414124,0.13400000333786,0,651.913325195313,-7.84100008010864,132.33775604248,-7.84100008010864,458.180627441406,-7.84100008010864,,,0.438904065744905,79.2199507200643,0.665670519303058,,25,651.913325195313,132.33775604248,458.180627441406,
,13907116.22,4369,2.9991500377655,0.13400000333786,0,511.575447998047,-7.8899998664856,128.119033660889,-7.8899998664856,462.051575927734,-7.8899998664856,,,136.568340919323,80.5620616038158,0.734317125651789,,25,511.575447998047,128.119033660889,462.051575927734,
,13907128.17,4369,2.99860000610352,0.13400000333786,0,611.139741210937,-7.91400003433228,156.166876373291,-7.91400003433228,463.840474853516,-7.91400003433228,,,100.742744171164,80.8712636126566,0.900292038433448,,25,611.139741210937,156.166876373291,463.840474853516,
,13907138.84,4369,3.00080001354218,0.13400000333786,0,612.434819335938,-7.93800020217896,326.749911499023,-7.93800020217896,466.34552734375,-7.93800020217896,,,101.234383265386,45.0158225587995,1.5629737251079,,25,612.434819335938,326.749911499023,466.34552734375,
,13907148.69,4369,2.9996999502182,0.13400000333786,0,524.986875,-7.98699998855591,222.225774383545,-7.98699998855591,470.200844726562,-7.98699998855591,,,138.831739029269,33.469024111077,0.885129048809729,,25,524.986875,222.225774383545,470.200844726562,
,13907160.27,4369,2.99954998493195,0.13400000333786,0,536.471199951172,-8.01200008392334,230.549273681641,-8.01200008392334,472.398840332031,-8.01200008392334,,,138.197725960445,0.210408269452111,0.68451363991152,,25,536.471199951172,230.549273681641,472.398840332031,
,13907171.53,4369,2.99995005130768,0.13400000333786,0,615.124957275391,-8.03600025177002,225.374037628174,-8.03600025177002,475.128392333984,-8.03600025177002,,,102.305401861963,34.0608964459956,1.0093973333544,,25,615.124957275391,225.374037628174,475.128392333984,
,13907183.39,4369,2.99975001811981,0.13400000333786,0,627.435441894531,-8.08500003814697,235.74448425293,-8.08500003814697,479.6676171875,-8.08500003814697,,,91.0394042851981,0.298229375745091,0.464487122544612,,25,627.435441894531,235.74448425293,479.6676171875,
,13907194.48,4369,2.99954998493195,0.13400000333786,0,662.897292480469,-8.10900020599365,355.557103271484,-8.10900020599365,481.302360839844,-8.10900020599365,,,2.68329663806172,10.6030573527454,0.983877453940836,,25,662.897292480469,355.557103271484,481.302360839844,
,13907203.47,4369,3.00015008449554,0.13400000333786,0,675.320075683594,-8.15799999237061,356.124779052734,-8.15799999237061,485.582889404297,-8.15799999237061,,,2.53851015529593,0.318262111484744,1.22308498907929,,25,675.320075683594,356.124779052734,485.582889404297,
,13907213.11,4369,3.00144994258881,0.13400000333786,0,681.203581542969,-8.18299961090088,360.215103759766,-8.18299961090088,488.976691894531,-8.18299961090088,,,1.08042447571091,10.3096285231791,1.7501096714548,,25,681.203581542969,360.215103759766,488.976691894531,
,13907222.11,4369,3.00034999847412,0.13400000333786,0,682.388706054688,-8.20699977874756,359.112325439453,-8.20699977874756,491.336848144531,-8.20699977874756,,,0.338482487225504,0.494606841050954,1.26452239821045,,25,682.388706054688,359.112325439453,491.336848144531,
,13907231.77,4369,3.00024998188019,0.13400000333786,0,683.054296875,-8.25599956512451,373.317332763672,-8.25599956512451,495.46599609375,-8.25599956512451,,,0.226205919527022,15.9196287438502,0.825427477176286,,25,683.054296875,373.317332763672,495.46599609375,
,13907241.33,4369,3.00169992446899,0.13400000333786,0,683.419130859375,-8.27999973297119,392.576647949219,-8.27999973297119,497.226197509766,-8.27999973297119,,,0.207143566416729,19.1093890324019,0.7816666431807,,25,683.419130859375,392.576647949219,497.226197509766,
,13907251.20,4369,3.00039994716644,0.13400000333786,0,683.704802246094,-8.30500030517578,401.225416259766,-8.30500030517578,498.965856933594,-8.30500030517578,,,0.288092246228986,17.5939461737753,0.657438603480602,,25,683.704802246094,401.225416259766,498.965856933594,
,13907260.31,4369,2.99985003471375,0.13400000333786,0,686.835844726563,-8.35400009155273,413.601918945312,-8.35400009155273,503.113293457031,-8.35400009155273,,,3.84867647480983,41.5911187169805,2.96375975257979,,25,686.835844726563,413.601918945312,503.113293457031,
,13907269.13,4369,2.99944996833801,0.13400000333786,0,689.801345214844,-8.37800025939941,423.132263183594,-8.37800025939941,503.942982177734,-8.37800025939941,,,2.07585721672568,12.9643464372895,0.771755486491167,,25,689.801345214844,423.132263183594,503.942982177734,
,13907278.08,4369,3.00014996528625,0.13400000333786,0,697.493264160156,-8.40299987792969,425.202404785156,-8.40299987792969,505.403997802734,-8.40299987792969,,,2.69245653295621,12.7499162152889,0.650429847745659,,25,697.493264160156,425.202404785156,505.403997802734,
,13907287.53,4369,3.00005006790161,0.13400000333786,0,702.915603027344,-8.45100021362305,434.816127929688,-8.45100021362305,508.825078125,-8.45100021362305,,,0.388531524825635,5.67600028238269,0.611648483533308,,25,702.915603027344,434.816127929688,508.825078125,
,13907296.50,4369,3.00144994258881,0.13400000333786,0,703.440375976562,-8.47599983215332,435.008850097656,-8.47599983215332,510.653907470703,-8.47599983215332,,,0.282978033357704,0.286192424920732,0.637503342112604,,25,703.440375976562,435.008850097656,510.653907470703,
,13907304.80,4369,2.99960005283356,0.13400000333786,0,703.868811035156,-8.5,436.110455322266,-8.5,512.640490722656,-8.5,,,0.248930356567114,0.315964435398495,0.848750732371402,,25,703.868811035156,436.110455322266,512.640490722656,
,13907314.44,4369,3.00110006332397,0.13400000333786,0,708.057766113281,-8.54899978637695,445.162114257813,-8.54899978637695,518.891262207031,-8.54899978637695,,,2.72112065264889,24.0323821512869,3.2237087506947,,25,708.057766113281,445.162114257813,518.891262207031,
,13907322.78,4369,3.00024998188019,0.13400000333786,0,713.61931640625,-8.57400035858154,413.952644042969,-8.57400035858154,521.796916503906,-8.57400035858154,,,2.14140332775091,66.6353969939857,1.845730315871,,25,713.61931640625,413.952644042969,521.796916503906,
,13907331.63,4369,2.9993999004364,0.13400000333786,0,716.911137695313,-8.59799957275391,367.924108886719,-8.59799957275391,529.692302246094,-8.59799957275391,,,0.832273842441431,83.9911132145667,2.75463998702267,,25,716.911137695313,367.924108886719,529.692302246094,
,13907341.14,4369,3.00010001659393,0.13400000333786,0,718.5887890625,-8.64700031280518,393.201932373047,-8.64700031280518,542.259267578125,-8.64700031280518,,,0.197462700639969,61.6443329233436,0.819916062197565,,25,718.5887890625,393.201932373047,542.259267578125,
,13907349.73,4369,2.99979996681213,0.13400000333786,0,718.789833984375,-8.67099952697754,422.117955322266,-8.67099952697754,544.324731445313,-8.67099952697754,,,0.147229741881165,30.1109748809016,0.740929254149516,,25,718.789833984375,422.117955322266,544.324731445313,
,13907359.52,4369,3,0.13400000333786,0,719.075603027344,-8.69600009918213,427.798980712891,-8.69600009918213,546.222116699219,-8.69600009918213,,,0.30787668948,16.5715650082513,0.611890798789178,,25,719.075603027344,427.798980712891,546.222116699219,
,13907368.70,4369,3,0.13400000333786,0,719.54947265625,-8.74499988555908,428.769211425781,-8.74499988555908,550.05734375,-8.74499988555908,,,0.230189623783652,15.7832864822223,0.874971541745272,,25,719.54947265625,428.769211425781,550.05734375,
,13907378.42,4369,2.99900007247925,0.13400000333786,0,720.046865234375,-8.76900005340576,433.455314941406,-8.76900005340576,552.906127929688,-8.76900005340576,,,1.4934239961384,16.3343539251256,3.15560318150056,,25,720.046865234375,433.455314941406,552.906127929688,
,13907388.33,4369,3.00004994869232,0.13400000333786,0,719.877431640625,-8.79300022125244,432.065465087891,-8.79300022125244,554.22638671875,-8.79300022125244,,,0.226716298305368,14.952606972106,0.873109096298292,,25,719.877431640625,432.065465087891,554.22638671875,
,13907397.53,4369,3.00049996376038,0.13400000333786,0,720.329248046875,-8.84200000762939,425.932827148438,-8.84200000762939,559.568586425781,-8.84200000762939,,,0.159186074393511,0.271359928481492,1.29150388828973,,25,720.329248046875,425.932827148438,559.568586425781,
,13907408.06,4369,3.00010001659393,0.13400000333786,0,720.607492675781,-8.86699962615967,426.904276123047,-8.86699962615967,563.343071289063,-8.86699962615967,,,0.197909386465898,0.189669929364163,1.19242004463618,,25,720.607492675781,426.904276123047,563.343071289063,
,13907419.02,4369,2.99829995632172,0.13400000333786,0,720.582780761719,-8.89099979400635,427.547669677734,-8.89099979400635,566.184431152344,-8.89099979400635,,,0.139705198971706,0.185104299835677,1.13802906958507,,25,720.582780761719,427.547669677734,566.184431152344,
,13907429.69,4369,2.99895000457764,0.13400000333786,0,721.027993164063,-8.9399995803833,473.366684570312,-8.9399995803833,570.651826171875,-8.9399995803833,,,0.189028195178209,17.8675681965775,0.539118493010243,,25,721.027993164063,473.366684570312,570.651826171875,
,13907439.66,4369,2.99880003929138,0.13400000333786,0,733.258774414062,-8.96399974822998,479.40091796875,-8.96399974822998,574.170280761719,-8.96399974822998,,,40.5723398315844,28.7969639256267,4.88154783216583,,25,733.258774414062,479.40091796875,574.170280761719,
,13907448.38,4369,3.00039994716644,0.13400000333786,0,721.655234375,-9.01299953460693,484.384301757813,-9.01299953460693,575.848110351562,-9.01299953460693,,,0.125999393168617,28.6308486429197,0.576214163903279,,25,721.655234375,484.384301757813,575.848110351562,
,13907457.63,4369,2.99935007095337,0.13400000333786,0,722.030131835937,-9.03800010681152,478.781949462891,-9.03800010681152,577.464833984375,-9.03800010681152,,,0.217532568349331,17.0226688298583,0.58992747531083,,25,722.030131835937,478.781949462891,577.464833984375,
,13907467.17,4369,3,0.13400000333786,0,722.412023925781,-9.0620002746582,483.726849365234,-9.0620002746582,579.021176757813,-9.0620002746582,,,0.182019859586128,32.98710920911,0.581710074813792,,25,722.412023925781,483.726849365234,579.021176757813,
,13907476.48,4369,3.00024998188019,0.13400000333786,0,722.840053710937,-9.11100006103516,495.420115966797,-9.11100006103516,581.928569335937,-9.11100006103516,,,0.168533248866812,45.0718345539493,0.482295595926484,,25,722.840053710937,495.420115966797,581.928569335937,
,13907486.39,4369,2.99920010566711,0.13400000333786,0,723.048937988281,-9.13500022888184,510.433670654297,-9.13500022888184,583.088708496094,-9.13500022888184,,,0.190533788818626,60.8119629899042,0.520478257653949,,25,723.048937988281,510.433670654297,583.088708496094,
,13907495.39,4369,2.99975001811981,0.13400000333786,0,723.251396484375,-9.15999984741211,495.433234863281,-9.15999984741211,584.497895507812,-9.15999984741211,,,0.287321078536661,32.8571157767922,0.526579809395151,,25,723.251396484375,495.433234863281,584.497895507812,
,13907503.95,4369,2.99944996833801,0.13400000333786,0,723.689948730469,-9.20899963378906,487.628045654297,-9.20899963378906,587.387885742187,-9.20899963378906,,,0.259940171330368,0.252450216631185,0.55507880939177,,25,723.689948730469,487.628045654297,587.387885742187,
,13907513.00,4369,2.99889993667603,0.13400000333786,0,723.990090332031,-9.23299980163574,498.106798095703,-9.23299980163574,588.598779296875,-9.23299980163574,,,0.177146256094574,32.7415500898123,0.56358361002131,,25,723.990090332031,498.106798095703,588.598779296875,
,13907522.06,4369,3.00055003166199,0.13400000333786,0,724.440883789062,-9.25699996948242,494.963148193359,-9.25699996948242,590.017189941406,-9.25699996948242,,,0.216047773956667,10.2346432358678,0.488414232265135,,25,724.440883789062,494.963148193359,590.017189941406,
,13907531.75,4369,2.99950003623962,0.13400000333786,0,724.694064941406,-9.30599975585938,508.453658447266,-9.30599975585938,592.943356933594,-9.30599975585938,,,0.15418192272412,12.7088394040495,0.956206030131546,,25,724.694064941406,508.453658447266,592.943356933594,
,13907541.27,4369,3.00009989738464,0.13400000333786,0,725.094855957031,-9.33100032806396,515.528994140625,-9.33100032806396,593.976882324219,-9.33100032806396,,,0.195760831360365,31.6119603174166,0.919552905897539,,25,725.094855957031,515.528994140625,593.976882324219,
,13907550.41,4369,3.00049996376038,0.13400000333786,0,725.324133300781,-9.35499954223633,521.803006591797,-9.35499954223633,595.827604980469,-9.35499954223633,,,0.207060211052101,29.4687712104314,1.06161705581851,,25,725.324133300781,521.803006591797,595.827604980469,
,13907560.33,4369,2.99974989891052,0.13400000333786,0,738.344187011719,-9.4040002822876,548.625590820312,-9.4040002822876,599.79142578125,-9.4040002822876,,,42.0646295520344,53.8390392489238,2.95619932338477,,25,738.344187011719,548.625590820312,599.79142578125,
,13907569.50,4369,2.99950003623962,0.13400000333786,0,725.932666015625,-9.42800045013428,534.863347167969,-9.42800045013428,600.103698730469,-9.42800045013428,,,0.135897375750554,36.8964240809448,0.480256513254337,,25,725.932666015625,534.863347167969,600.103698730469,
,13907578.63,4369,2.99989998340607,0.13400000333786,0,726.177856445313,-9.45300006866455,541.356091308594,-9.45300006866455,601.372338867188,-9.45300006866455,,,0.237050310860697,43.942325258007,0.416387072236399,,25,726.177856445313,541.356091308594,601.372338867188,
,13907587.63,4369,3.00009989738464,0.13400000333786,0,726.429206542969,-9.5019998550415,537.972302246094,-9.5019998550415,603.480612792969,-9.5019998550415,,,0.205145939332176,36.3542362419704,0.273165496111791,,25,726.429206542969,537.972302246094,603.480612792969,
,13907596.67,4369,3.00045001506805,0.13400000333786,0,726.62103515625,-9.52600002288818,537.066691894531,-9.52600002288818,604.686403808594,-9.52600002288818,,,0.147468380787553,28.2649281151309,0.434227132575199,,25,726.62103515625,537.066691894531,604.686403808594,
,13907606.42,4369,2.99965000152588,0.13400000333786,0,726.949321289062,-9.55099964141846,534.935559082031,-9.55099964141846,605.865085449219,-9.55099964141846,,,0.280249267293553,0.542422614180021,0.428729524988822,,25,726.949321289062,534.935559082031,605.865085449219,
,13907615.83,4369,2.99995005130768,0.13400000333786,0,751.895825195312,-9.59899997711182,562.585615234375,-9.59899997711182,609.347768554687,-9.59899997711182,,,48.231019836233,57.9333997924367,4.59482591403292,,25,751.895825195312,562.585615234375,609.347768554687,
,13907625.39,4369,3.00139999389648,0.13400000333786,0,779.37283203125,-9.62399959564209,551.797346191406,-9.62399959564209,609.802458496094,-9.62399959564209,,,15.2669803471448,40.7441313328838,0.631016928785207,,25,779.37283203125,551.797346191406,609.802458496094,
,13907634.31,4369,3.00024998188019,0.13400000333786,0,784.335270996094,-9.64799976348877,558.17181640625,-9.64799976348877,611.287917480469,-9.64799976348877,,,0.18411690946929,46.5310975670059,1.34085311030351,,25,784.335270996094,558.17181640625,611.287917480469,
,13907643.63,4369,3.00080001354218,0.13400000333786,0,785.355678710937,-9.69699954986572,552.935229492188,-9.69699954986572,619.334719238281,-9.69699954986572,,,0.291356900502207,27.0824863110803,0.598332624152944,,25,785.355678710937,552.935229492188,619.334719238281,
,13907653.25,4369,3.00059998035431,0.13400000333786,0,785.852038574219,-9.72200012207031,562.82908203125,-9.72200012207031,620.498752441406,-9.72200012207031,,,0.205378682281577,46.1561604638604,0.494494210832806,,25,785.852038574219,562.82908203125,620.498752441406,
,13907663.41,4369,2.99920010566711,0.13400000333786,0,786.917683105469,-9.77000045776367,572.719367675781,-9.77000045776367,622.95134765625,-9.77000045776367,,,0.149376137835242,49.5587047789069,0.551643350584181,,25,786.917683105469,572.719367675781,622.95134765625,
,13907672.81,4369,3.0011500120163,0.13400000333786,0,787.311945800781,-9.79500007629395,570.299887695312,-9.79500007629395,624.175463867188,-9.79500007629395,,,0.191675496431142,44.7512077528955,0.458626162977322,,25,787.311945800781,570.299887695312,624.175463867188,
,13907682.47,4369,2.99924993515015,0.13400000333786,0,787.827604980469,-9.81900024414063,578.088894042969,-9.81900024414063,626.172172851563,-9.81900024414063,,,0.246595090576923,54.7861376982394,0.876918101826024,,25,787.827604980469,578.088894042969,626.172172851563,
,13907691.34,4369,3.00069999694824,0.13400000333786,0,789.154216308594,-9.86800003051758,579.649006347656,-9.86800003051758,633.918842773438,-9.86800003051758,,,0.255663378552862,48.6971685697629,0.991885801183278,,25,789.154216308594,579.649006347656,633.918842773438,
,13907700.58,4369,2.99910008907318,0.13400000333786,0,789.980666503906,-9.89299964904785,588.706010742187,-9.89299964904785,635.954470214844,-9.89299964904785,,,0.223818924350276,54.407290189087,0.665843793275452,,25,789.980666503906,588.706010742187,635.954470214844,
,13907710.14,4369,2.99800002574921,0.13400000333786,0,790.72146484375,-9.91699981689453,576.058032226563,-9.91699981689453,636.771352539062,-9.91699981689453,,,0.489034585486508,12.2667651818126,1.28575030775746,,25,790.72146484375,576.058032226563,636.771352539062,
,13907719.02,4369,2.99950003623962,0.13400000333786,0,792.693293457031,-9.96599960327148,603.70837890625,-9.96599960327148,639.250412597656,-9.96599960327148,,,0.316715389321742,25.5218646296449,0.438802303416502,,25,792.693293457031,603.70837890625,639.250412597656,
,13907728.73,4369,2.9991500377655,0.13400000333786,0,794.503898925781,-9.98999977111816,615.336640625,-9.98999977111816,640.491657714844,-9.98999977111816,,,0.334200810551315,48.2584330808549,0.421264734657829,,25,794.503898925781,615.336640625,640.491657714844,