File: icepp/data/250308/250308-ch1Nb50Al100-ch2Nb100Al20-ch3Nb100Al100_coarseUp1.dat
[Header]
TITLE, 5K to 300K
FILEOPENTIME,13834313.45,3/8/2025,2:03 AM
BYAPP, Resistivity, 2.1, 1.0
INFO, APPNAME, PPMS MultiVu Application, 1.5.11
INFO, , Sample1 Name
INFO, 1, Sample1 Cross Section
INFO, 1, Sample1 Length
INFO, Ohm, Sample1 Units
INFO, , Sample2 Name
INFO, 1, Sample2 Cross Section
INFO, 1, Sample2 Length
INFO, Ohm, Sample2 Units
INFO, , Sample3 Name
INFO, 1, Sample3 Cross Section
INFO, 1, Sample3 Length
INFO, Ohm, Sample3 Units
INFO, , Sample4 Name
INFO, 1, Sample4 Cross Section
INFO, 1, Sample4 Length
INFO, Ohm, Sample4 Units
FIELDGROUP, Resistivity,2,3,4,5,6,7,8,9,10,11,12,13,14,15,16,17,18,19,20,21,22,23,24,25,26,27,28,29,30,31,32,33,34,35,36,37,38,39,40,41
STARTUPGROUP, Resistivity
STARTUPAXIS, X, 2, LINEAR, AUTO
STARTUPAXIS, Y1, 7, LINEAR, AUTO
STARTUPAXIS, Y2, 9, LINEAR, AUTO
STARTUPAXIS, Y3, 11, LINEAR, AUTO
PLOT_APPEARANCE, ALL, HORZ_GRID_ON, VERT_GRID_ON, MARKERS_AND_LINES, ALL_LINES
DATATYPE, TIME, 2
DATATYPE, COMMENT, 1
[Data]
Comment,Time Stamp (sec),Status (code),Temperature (K),Magnetic Field (Oe),Sample Position (deg),Bridge 1 Resistivity (Ohm),Bridge 1 Excitation (uA),Bridge 2 Resistivity (Ohm),Bridge 2 Excitation (uA),Bridge 3 Resistivity (Ohm),Bridge 3 Excitation (uA),Bridge 4 Resistivity (Ohm),Bridge 4 Excitation (uA),Bridge 1 Std. Dev. (Ohm),Bridge 2 Std. Dev. (Ohm),Bridge 3 Std. Dev. (Ohm),Bridge 4 Std. Dev. (Ohm),Number of Readings,Bridge 1 Resistance (Ohms),Bridge 2 Resistance (Ohms),Bridge 3 Resistance (Ohms),Bridge 4 Resistance (Ohms),Signal 1 Vin (V),Signal 2 Vin (V),Digital Inputs (code),Drive 1 Iout (mA),Drive 1 Ipower (watts),Drive 2 Iout (mA),Drive 2 Ipower (watts),Pressure (),Map 20 (),Map 21 (),Map 22 (),Map 23 (),Map 24 (),Map 25 (),Map 26 (),Map 27 (),Map 28 (),Map 29 ()
,13841105.13,4370,5.08995008468628,0.13400000333786,0,0.000931946827331558,9.98999977111816,9.1666912776418e-005,9.98999977111816,-0.00132153125130571,9.98999977111816,,,0.00485546220484986,0.0035817928806883,0.00483003799256555,,25,0.000931946827331558,9.1666912776418e-005,-0.00132153125130571,
,13841227.03,4370,7.12395000457764,0.13400000333786,0,9.93001251481473e-005,9.98999977111816,-0.00111521669663489,9.98999977111816,-0.000366646546754055,9.98999977111816,,,0.00257458386625753,0.00356548885736218,0.00318713751812046,,25,9.93001251481473e-005,-0.00111521669663489,-0.000366646546754055,
,13841346.59,4370,9.09964990615845,0.13400000333786,0,8.26283878326416,9.98999977111816,80.6663772583008,9.98999977111816,10.3314797083102,9.98999977111816,,,0.00299665774750755,0.00853766922251582,3.61621330148739,,25,8.26283878326416,80.6663772583008,10.3314797083102,
,13841466.20,4370,11.099949836731,0.13400000333786,0,8.26730476379394,9.98999977111816,80.7805792236328,9.98999977111816,11.801976852417,9.98999977111816,,,0.00272110341905458,0.00393483595995461,0.00338147809554718,,25,8.26730476379394,80.7805792236328,11.801976852417,
,13841586.59,4370,13.1040000915527,0.13400000333786,0,8.27600791931152,9.98999977111816,80.9256838989258,9.98999977111816,11.8157693099976,9.98999977111816,,,0.00312583804984136,0.00393298479320703,0.00279010987587641,,25,8.27600791931152,80.9256838989258,11.8157693099976,
,13841707.59,4370,15.1169500350952,0.13400000333786,0,8.28283538818359,9.98999977111816,81.0701400756836,9.98999977111816,11.8272669219971,9.98999977111816,,,0.00269676235759311,0.00527148954120631,0.00316471990267099,,25,8.28283538818359,81.0701400756836,11.8272669219971,
,13841827.00,4370,17.1084003448486,0.13400000333786,0,8.29486312866211,9.98999977111816,81.2857247924805,9.98999977111816,11.8469820022583,9.98999977111816,,,0.00326943127381945,0.00709953075208232,0.00330467591670251,,25,8.29486312866211,81.2857247924805,11.8469820022583,
,13841946.80,4370,19.1104497909546,0.13400000333786,0,8.30575798034668,9.98999977111816,81.5244534301758,9.98999977111816,11.867357673645,9.98999977111816,,,0.00362735608603788,0.00785630569469533,0.00347103015909762,,25,8.30575798034668,81.5244534301758,11.867357673645,
,13842066.58,4370,21.1066007614136,0.13400000333786,0,8.32682952880859,9.98999977111816,81.8719415283203,9.98999977111816,11.9013924789429,9.98999977111816,,,0.00640783200952742,0.0092140254234435,0.00318367566585861,,25,8.32682952880859,81.8719415283203,11.9013924789429,
,13842186.47,4370,23.1047496795654,0.13400000333786,0,8.34484539031982,9.98999977111816,82.2016223144531,9.98999977111816,11.9306661224365,9.98999977111816,,,0.00268006510353143,0.00988655144423987,0.0033751670383609,,25,8.34484539031982,82.2016223144531,11.9306661224365,
,13842306.86,4370,25.100549697876,0.13400000333786,0,8.37394329071045,9.98999977111816,82.6560217285156,9.98999977111816,11.9776934432983,9.98999977111816,,,0.00374068297048036,0.0102107232909273,0.00430548877108464,,25,8.37394329071045,82.6560217285156,11.9776934432983,
,13842427.38,4370,27.1102504730225,0.13400000333786,0,8.41018939971924,9.98999977111816,83.1940188598633,9.98999977111816,12.034646987915,9.98999977111816,,,0.00488400491150466,0.0121020072077353,0.0028607553118455,,25,8.41018939971924,83.1940188598633,12.034646987915,
,13842546.86,4370,29.1107997894287,0.13400000333786,0,8.45410545349121,9.98999977111816,83.8083114624023,9.98999977111816,12.1027476501465,9.98999977111816,,,0.00343517941920836,0.0149109489339278,0.0030782769299677,,25,8.45410545349121,83.8083114624023,12.1027476501465,
,13842666.27,4370,31.0938005447388,0.13400000333786,0,8.49857765197754,9.98999977111816,84.4272955322266,9.98999977111816,12.1717597579956,9.98999977111816,,,0.00221113312664661,0.0135450265461747,0.00285916597978513,,25,8.49857765197754,84.4272955322266,12.1717597579956,
,13842787.20,4370,33.1117496490479,0.13400000333786,0,8.55588848114014,9.98999977111816,85.1641040039062,9.98999977111816,12.2618161773682,9.98999977111816,,,0.00302227742504283,0.0164508868231282,0.00257609446027903,,25,8.55588848114014,85.1641040039062,12.2618161773682,
,13842906.55,4370,35.1030006408691,0.13400000333786,0,8.62245460510254,9.98999977111816,85.9527398681641,9.98999977111816,12.3603883743286,9.98999977111816,,,0.00262606500296524,0.0186860703722277,0.00326559597474817,,25,8.62245460510254,85.9527398681641,12.3603883743286,
,13843027.22,4370,37.1144504547119,0.13400000333786,0,8.69628414154053,9.98999977111816,86.8054614257812,9.98999977111816,12.4710046005249,9.98999977111816,,,0.00336496660898993,0.0188168589542654,0.00357572693144756,,25,8.69628414154053,86.8054614257812,12.4710046005249,
,13843146.47,4370,39.0947513580322,0.13400000333786,0,8.78124694824219,9.98999977111816,87.7353161621094,9.98999977111816,12.5958703994751,9.98999977111816,,,0.00279048570268294,0.0209751672458734,0.003387251611257,,25,8.78124694824219,87.7353161621094,12.5958703994751,
,13843267.52,4370,41.1190490722656,0.13400000333786,0,8.87326049804688,9.98999977111816,88.7062615966797,9.98999977111816,12.7327565383911,9.98999977111816,,,0.00349087700094904,0.0215029502419783,0.00386931988901354,,25,8.87326049804688,88.7062615966797,12.7327565383911,
,13843387.00,4370,43.1077995300293,0.13400000333786,0,8.97564422607422,9.98999977111816,89.7446499633789,9.98999977111816,12.8831087875366,9.98999977111816,,,0.00279903569253946,0.0225349135246442,0.00472324621711319,,25,8.97564422607422,89.7446499633789,12.8831087875366,
,13843506.39,4370,45.0995006561279,0.13400000333786,0,9.08803283691406,9.98999977111816,90.8455987548828,9.98999977111816,13.0491830825806,9.98999977111816,,,0.00321364726906189,0.0232420161547977,0.00407887367421435,,25,9.08803283691406,90.8455987548828,13.0491830825806,
,13843626.52,4370,47.1005001068115,0.13400000333786,0,9.20906486511231,9.98999977111816,91.965390625,9.98999977111816,13.223267288208,9.98999977111816,,,0.00356732038224288,0.0248708164194416,0.00434195339929601,,25,9.20906486511231,91.965390625,13.223267288208,
,13843746.17,4370,49.094898223877,0.13400000333786,0,9.3353010559082,9.98999977111816,93.0925750732422,9.98999977111816,13.4044807815552,9.98999977111816,,,0.0039411513814781,0.0259476108643251,0.00492738812790491,,25,9.3353010559082,93.0925750732422,13.4044807815552,
,13843866.64,4370,51.0958995819092,0.13400000333786,0,9.47616695404053,9.98999977111816,94.3348391723633,9.98999977111816,13.6080351638794,9.98999977111816,,,0.00358010870964421,0.0268670116890169,0.00417662371523132,,25,9.47616695404053,94.3348391723633,13.6080351638794,
,13843987.03,4370,53.1049499511719,0.13400000333786,0,9.62186824798584,9.98999977111816,95.5595779418945,9.98999977111816,13.817346534729,9.98999977111816,,,0.00366704686020436,0.026875708414608,0.00438187775044679,,25,9.62186824798584,95.5595779418945,13.817346534729,
,13844106.22,4370,55.0957489013672,0.13400000333786,0,9.77719501495361,9.98999977111816,96.8238717651367,9.98999977111816,14.0382829284668,9.98999977111816,,,0.00434025652481524,0.0290513049553396,0.00537210678261727,,25,9.77719501495361,96.8238717651367,14.0382829284668,
,13844226.59,4370,57.101900100708,0.13400000333786,0,9.94061828613281,9.98999977111816,98.1359243774414,9.98999977111816,14.2739723968506,9.98999977111816,,,0.00407501139214589,0.0288831895899894,0.00533211648193528,,25,9.94061828613281,98.1359243774414,14.2739723968506,
,13844347.23,4370,59.1054000854492,0.13400000333786,0,10.1102045440674,9.98999977111816,99.439460144043,9.98999977111816,14.514481010437,9.98999977111816,,,0.00444460869243684,0.0292246640455356,0.00601229181814165,,25,10.1102045440674,99.439460144043,14.514481010437,
,13844466.98,4370,61.10959815979,0.13400000333786,0,10.2949319076538,9.98999977111816,100.809143066406,9.98999977111816,14.7728940963745,9.98999977111816,,,0.00460349652966227,0.0301486223229629,0.00612479930662486,,25,10.2949319076538,100.809143066406,14.7728940963745,
,13844586.66,4370,63.1009502410889,0.13400000333786,0,10.4788182830811,9.98999977111816,102.156656494141,9.98999977111816,15.034534034729,9.98999977111816,,,0.00494554085280278,0.0296283164814148,0.00622511052026079,,25,10.4788182830811,102.156656494141,15.034534034729,
,13844707.56,4370,65.1147994995117,0.13400000333786,0,10.6777473449707,9.98999977111816,103.576787414551,9.98999977111816,15.3145473098755,9.98999977111816,,,0.00446451426965078,0.030606759031514,0.00682891960009945,,25,10.6777473449707,103.576787414551,15.3145473098755,
,13844826.56,4370,67.0971984863281,0.13400000333786,0,10.8732236862183,9.98999977111816,104.936055603027,9.98999977111816,15.5911321258545,9.98999977111816,,,0.00523262301976791,0.0309277108962755,0.00663425319961654,,25,10.8732236862183,104.936055603027,15.5911321258545,
,13844947.39,4370,69.1127471923828,0.13400000333786,0,11.0836123275757,9.98999977111816,106.363673706055,9.98999977111816,15.8858650588989,9.98999977111816,,,0.00590169661421677,0.0309265589393757,0.00706606243157742,,25,11.0836123275757,106.363673706055,15.8858650588989,
,13845067.41,4370,71.1078987121582,0.13400000333786,0,11.2977090072632,9.98999977111816,107.781481628418,9.98999977111816,16.1862990570068,9.98999977111816,,,0.00476913668931559,0.0311151153528852,0.00705392976877449,,25,11.2977090072632,107.781481628418,16.1862990570068,
,13845186.86,4370,73.1040496826172,0.13400000333786,0,11.5160497283936,9.98999977111816,109.209462585449,9.98999977111816,16.4939221191406,9.98999977111816,,,0.0049165351338681,0.0313528815472845,0.00767514841335219,,25,11.5160497283936,109.209462585449,16.4939221191406,
,13845306.56,4370,75.099250793457,0.13400000333786,0,11.742331199646,9.98999977111816,110.65749420166,9.98999977111816,16.8115718078613,9.98999977111816,,,0.00592328572526739,0.0317221459537828,0.00757870977614888,,25,11.742331199646,110.65749420166,16.8115718078613,
,13845427.28,4370,77.1075477600098,0.13400000333786,0,11.9702345657349,9.98999977111816,112.082026062012,9.98999977111816,17.130470123291,9.98999977111816,,,0.00503828758291257,0.0308723370165422,0.00701605760294475,,25,11.9702345657349,112.082026062012,17.130470123291,
,13845546.47,4370,79.0952491760254,0.13400000333786,0,12.207474937439,9.98999977111816,113.540581970215,9.98999977111816,17.4618183135986,9.98999977111816,,,0.00530886847366695,0.0320003239938729,0.00773083334543956,,25,12.207474937439,113.540581970215,17.4618183135986,
,13845667.52,4370,81.116397857666,0.13400000333786,0,12.4443891906738,9.98999977111816,114.960277099609,9.98999977111816,17.7926502990723,9.98999977111816,,,0.00578074393833009,0.03109609887843,0.00807450844911153,,25,12.4443891906738,114.960277099609,17.7926502990723,
,13845787.61,4370,83.1134490966797,0.13400000333786,0,12.6895497512817,9.98999977111816,116.426889648437,9.98999977111816,18.135686416626,9.98999977111816,,,0.00599615676698139,0.0324795358193879,0.00757610236940012,,25,12.6895497512817,116.426889648437,18.135686416626,
,13845906.47,4370,85.0929489135742,0.13400000333786,0,12.9336151123047,9.98999977111816,117.845017089844,9.98999977111816,18.4752745819092,9.98999977111816,,,0.00577988459467869,0.0308446063403954,0.00781016980355226,,25,12.9336151123047,117.845017089844,18.4752745819092,
,13846027.50,4370,87.1059494018555,0.13400000333786,0,13.1912254714966,9.98999977111816,119.335101623535,9.98999977111816,18.8344821166992,9.98999977111816,,,0.00525624803851291,0.0312410646032883,0.00834276001842471,,25,13.1912254714966,119.335101623535,18.8344821166992,
,13846147.75,4370,89.113899230957,0.13400000333786,0,13.4459592056274,9.98999977111816,120.763874511719,9.98999977111816,19.1885346221924,9.98999977111816,,,0.00626943116719198,0.031178794061444,0.00755076754290404,,25,13.4459592056274,120.763874511719,19.1885346221924,
,13846267.73,4370,91.1133003234863,0.13400000333786,0,13.7052214813232,9.98999977111816,122.213733215332,9.98999977111816,19.550344619751,9.98999977111816,,,0.00590427945252865,0.0313894926727013,0.00844266156365768,,25,13.7052214813232,122.213733215332,19.550344619751,
,13846387.19,4370,93.1034507751465,0.13400000333786,0,13.9703759002686,9.98999977111816,123.67862121582,9.98999977111816,19.9194393920898,9.98999977111816,,,0.00587078468056745,0.0318265365566323,0.00806651486940929,,25,13.9703759002686,123.67862121582,19.9194393920898,
,13846507.73,4370,95.112247467041,0.13400000333786,0,14.2323901367188,9.98999977111816,125.101726989746,9.98999977111816,20.2851369476318,9.98999977111816,,,0.00605217963145238,0.0313100656943511,0.00867736855032717,,25,14.2323901367188,125.101726989746,20.2851369476318,
,13846627.42,4370,97.1087989807129,0.13400000333786,0,14.5041003036499,9.98999977111816,126.562137145996,9.98999977111816,20.6596416473389,9.98999977111816,,,0.00635243002411753,0.0311150119662171,0.0085708376240703,,25,14.5041003036499,126.562137145996,20.6596416473389,
,13846747.70,4370,99.1096496582031,0.13400000333786,0,14.7730952072144,9.98999977111816,127.997487487793,9.98999977111816,21.0348593139648,9.98999977111816,,,0.00645808376202592,0.0307753184639226,0.00868259380125495,,25,14.7730952072144,127.997487487793,21.0348593139648,
,13846866.75,4370,101.096347808838,0.13400000333786,0,15.0451525115967,9.98999977111816,129.435200195312,9.98999977111816,21.4129620361328,9.98999977111816,,,0.00588239723936753,0.030188152606928,0.00851161620164932,,25,15.0451525115967,129.435200195312,21.4129620361328,
,13846986.72,4370,103.094200134277,0.13400000333786,0,15.3173166275024,9.98999977111816,130.854002685547,9.98999977111816,21.7887386322021,9.98999977111816,,,0.00733736584374259,0.0307139218580649,0.00785052078241112,,25,15.3173166275024,130.854002685547,21.7887386322021,
,13847106.89,4370,105.098148345947,0.13400000333786,0,15.5933451843262,9.98999977111816,132.276441040039,9.98999977111816,22.1716412353516,9.98999977111816,,,0.0073044624123071,0.0301897290795509,0.00926718344018994,,25,15.5933451843262,132.276441040039,22.1716412353516,
,13847227.33,4370,107.107048034668,0.13400000333786,0,15.8700384902954,9.98999977111816,133.695718994141,9.98999977111816,22.5547159576416,9.98999977111816,,,0.0061876788555676,0.030590227497416,0.00847840758344173,,25,15.8700384902954,133.695718994141,22.5547159576416,
,13847347.55,4370,109.109451293945,0.13400000333786,0,16.1461575317383,9.98999977111816,135.101950073242,9.98999977111816,22.9402626800537,9.98999977111816,,,0.00653800450626454,0.0300880161868264,0.00838568721571234,,25,16.1461575317383,135.101950073242,22.9402626800537,
,13847467.11,4370,111.104202270508,0.13400000333786,0,16.4233382415771,9.98999977111816,136.486638793945,9.98999977111816,23.3227046203613,9.98999977111816,,,0.00627422403430369,0.0297356475231898,0.00770189597232667,,25,16.4233382415771,136.486638793945,23.3227046203613,
,13847587.67,4370,113.112552642822,0.13400000333786,0,16.7076778411865,9.98999977111816,137.906500244141,9.98999977111816,23.7147947692871,9.98999977111816,,,0.00709821999141676,0.0442310122676824,0.0111474314075758,,25,16.7076778411865,137.906500244141,23.7147947692871,
,13847707.67,4370,115.111198425293,0.13400000333786,0,16.9862006378174,9.98999977111816,139.280879516602,9.98999977111816,24.0998877716064,9.98999977111816,,,0.00654352966866727,0.0244669654736247,0.00769750782270692,,25,16.9862006378174,139.280879516602,24.0998877716064,
,13847826.84,4370,117.099552154541,0.13400000333786,0,17.2668834686279,9.98999977111816,140.667430419922,9.98999977111816,24.488821182251,9.98999977111816,,,0.00588480593463299,0.0241551811851897,0.00733494876013439,,25,17.2668834686279,140.667430419922,24.488821182251,
,13847947.55,4370,119.114101409912,0.13400000333786,0,17.5523448944092,9.98999977111816,142.060216064453,9.98999977111816,24.8830796813965,9.98999977111816,,,0.00802256853114347,0.0348757447847334,0.00952201665873328,,25,17.5523448944092,142.060216064453,24.8830796813965,
,13848066.64,4370,121.099197387695,0.13400000333786,0,17.83459815979,9.98999977111816,143.434836425781,9.98999977111816,25.2726629638672,9.98999977111816,,,0.00609715606785476,0.0288584756426834,0.00922060906717088,,25,17.83459815979,143.434836425781,25.2726629638672,
,13848186.88,4370,123.096500396729,0.13400000333786,0,18.119934387207,9.98999977111816,144.823708496094,9.98999977111816,25.6680821228027,9.98999977111816,,,0.00726565686714737,0.039199508455568,0.0100432102997932,,25,18.119934387207,144.823708496094,25.6680821228027,
,13848307.67,4370,125.114196777344,0.13400000333786,0,18.4097280883789,9.98999977111816,146.216228027344,9.98999977111816,26.0676011657715,9.98999977111816,,,0.00594768617372059,0.0315376868864466,0.00890603252768252,,25,18.4097280883789,146.216228027344,26.0676011657715,
,13848426.73,4370,127.095550537109,0.13400000333786,0,18.6907437133789,9.98999977111816,147.558818359375,9.98999977111816,26.4573825073242,9.98999977111816,,,0.00729969962577056,0.0361410632773628,0.00994038150392368,,25,18.6907437133789,147.558818359375,26.4573825073242,
,13848547.30,4370,129.108200073242,0.13400000333786,0,18.9864995574951,9.98999977111816,148.985328979492,9.98999977111816,26.8667944335938,9.98999977111816,,,0.00616987322356466,0.0255753423039458,0.00757171471220962,,25,18.9864995574951,148.985328979492,26.8667944335938,
,13848666.58,4370,131.095054626465,0.13400000333786,0,19.2645247650146,9.98999977111816,150.271823730469,9.98999977111816,27.2493115997314,9.98999977111816,,,0.00711000001544637,0.0295739994654388,0.008363509175409,,25,19.2645247650146,150.271823730469,27.2493115997314,
,13848786.94,4370,133.104347229004,0.13400000333786,0,19.5601829528809,9.98999977111816,151.696249389648,9.98999977111816,27.6597547912598,9.98999977111816,,,0.0068336911051498,0.0285513323773854,0.00899331059441809,,25,19.5601829528809,151.696249389648,27.6597547912598,
,13848907.28,4370,135.111953735352,0.13400000333786,0,19.8508261871338,9.98999977111816,153.059836425781,9.98999977111816,28.058424911499,9.98999977111816,,,0.00531702328439776,0.0289642927857291,0.00892077856255184,,25,19.8508261871338,153.059836425781,28.058424911499,
,13849026.22,4370,137.096153259277,0.13400000333786,0,20.1354653167725,9.98999977111816,154.394478759766,9.98999977111816,28.4522399139404,9.98999977111816,,,0.00707335602358856,0.0288059375587055,0.0088101469553296,,25,20.1354653167725,154.394478759766,28.4522399139404,
,13849146.52,4370,139.101852416992,0.13400000333786,0,20.4293475341797,9.98999977111816,155.783416748047,9.98999977111816,28.8568011474609,9.98999977111816,,,0.00629323337024076,0.0288903198660819,0.00926952769661594,,25,20.4293475341797,155.783416748047,28.8568011474609,
,13849266.17,4370,141.102195739746,0.13400000333786,0,20.7150873565674,9.98999977111816,157.100777587891,9.98999977111816,29.2498584747314,9.98999977111816,,,0.00680001472621717,0.0303716591719335,0.00929776426607769,,25,20.7150873565674,157.100777587891,29.2498584747314,
,13849386.39,4370,143.105201721191,0.13400000333786,0,21.0071301269531,9.98999977111816,158.469915771484,9.98999977111816,29.6535708618164,9.98999977111816,,,0.00653300625999387,0.0282113692482516,0.00917601215249878,,25,21.0071301269531,158.469915771484,29.6535708618164,
,13849506.73,4370,145.118148803711,0.13400000333786,0,21.2953037261963,9.98999977111816,159.812269287109,9.98999977111816,30.0515799713135,9.98999977111816,,,0.00578127818039163,0.0291112816495358,0.00938431206747619,,25,21.2953037261963,159.812269287109,30.0515799713135,
,13849626.09,4370,147.103996276855,0.13400000333786,0,21.5844378662109,9.98999977111816,161.153994140625,9.98999977111816,30.4485199737549,9.98999977111816,,,0.00674086300431834,0.028949769090813,0.00878532729033191,,25,21.5844378662109,161.153994140625,30.4485199737549,
,13849746.08,4370,149.111953735352,0.13400000333786,0,21.873497543335,9.98999977111816,162.495501098633,9.98999977111816,30.8474298858643,9.98999977111816,,,0.00609084931477129,0.0303452853143719,0.00876498201273894,,25,21.873497543335,162.495501098633,30.8474298858643,
,13849865.61,4370,151.106796264648,0.13400000333786,0,22.1589507293701,9.98999977111816,163.82025390625,9.98999977111816,31.2429947662354,9.98999977111816,,,0.00666688548619033,0.0296194817897635,0.00872234464751626,,25,22.1589507293701,163.82025390625,31.2429947662354,
,13849985.81,4370,153.105995178223,0.13400000333786,0,22.4550691223145,9.98999977111816,165.194925537109,9.98999977111816,31.6499482727051,9.98999977111816,,,0.00710492478502682,0.0295108734859463,0.00865413578515386,,25,22.4550691223145,165.194925537109,31.6499482727051,
,13850105.72,4370,155.109451293945,0.13400000333786,0,22.7416551208496,9.98999977111816,166.503051757813,9.98999977111816,32.0425224304199,9.98999977111816,,,0.0072815104460119,0.0290191700310843,0.00912416373081098,,25,22.7416551208496,166.503051757813,32.0425224304199,
,13850225.45,4370,157.107650756836,0.13400000333786,0,23.0254756164551,9.98999977111816,167.800316162109,9.98999977111816,32.4335932922363,9.98999977111816,,,0.00689107995220525,0.0306759884512502,0.00983797423325633,,25,23.0254756164551,167.800316162109,32.4335932922363,
,13850345.42,4370,159.108695983887,0.13400000333786,0,23.3181572723389,9.98999977111816,169.15306640625,9.98999977111816,32.8357916259766,9.98999977111816,,,0.00743317510386019,0.0283864009752523,0.00908108555835335,,25,23.3181572723389,169.15306640625,32.8357916259766,
,13850465.08,4370,161.11205291748,0.13400000333786,0,23.6049574279785,9.98999977111816,170.461408691406,9.98999977111816,33.2287074279785,9.98999977111816,,,0.00661115483582957,0.0294751421613799,0.00935107992469318,,25,23.6049574279785,170.461408691406,33.2287074279785,
,13850584.89,4370,163.109504699707,0.13400000333786,0,23.89197265625,9.98999977111816,171.790648193359,9.98999977111816,33.6262409973145,9.98999977111816,,,0.00558672607686391,0.0293089695145442,0.00839425157183625,,25,23.89197265625,171.790648193359,33.6262409973145,
,13850704.59,4370,165.104698181152,0.13400000333786,0,24.1807531738281,9.98999977111816,173.114564819336,9.98999977111816,34.0229473876953,9.98999977111816,,,0.00609077342631697,0.0286110016400728,0.00948487691618625,,25,24.1807531738281,173.114564819336,34.0229473876953,
,13850824.50,4370,167.104644775391,0.13400000333786,0,24.4768882751465,9.98999977111816,174.491104736328,9.98999977111816,34.4299731445313,9.98999977111816,,,0.00671968259869706,0.0290192735821207,0.00942088919634735,,25,24.4768882751465,174.491104736328,34.4299731445313,
,13850945.36,4370,169.118698120117,0.13400000333786,0,24.7674475097656,9.98999977111816,175.826343994141,9.98999977111816,34.8299374389648,9.98999977111816,,,0.00719341820854977,0.0285209098194744,0.00831931391796514,,25,24.7674475097656,175.826343994141,34.8299374389648,
,13851064.69,4370,171.109397888184,0.13400000333786,0,25.0519524383545,9.98999977111816,177.128107299805,9.98999977111816,35.221326751709,9.98999977111816,,,0.00676849190393792,0.0292734461598481,0.00916717544176705,,25,25.0519524383545,177.128107299805,35.221326751709,
,13851184.22,4370,173.102249145508,0.13400000333786,0,25.3388932037354,9.98999977111816,178.445090332031,9.98999977111816,35.6165254211426,9.98999977111816,,,0.00677559858486794,0.0289598680475672,0.00894414751215741,,25,25.3388932037354,178.445090332031,35.6165254211426,
,13851304.41,4370,175.110153198242,0.13400000333786,0,25.6337034606934,9.98999977111816,179.812896118164,9.98999977111816,36.0213885498047,9.98999977111816,,,0.00673819466445142,0.0286937867389502,0.0084178464031226,,25,25.6337034606934,179.812896118164,36.0213885498047,
,13851424.08,4370,177.1064453125,0.13400000333786,0,25.9181589508057,9.98999977111816,181.109215087891,9.98999977111816,36.4109928894043,9.98999977111816,,,0.00649947742891532,0.028345850311103,0.00881369936454966,,25,25.9181589508057,181.109215087891,36.4109928894043,
,13851544.52,4370,179.114448547363,0.13400000333786,0,26.207738571167,9.98999977111816,182.442494506836,9.98999977111816,36.8098139953613,9.98999977111816,,,0.00615343398895716,0.0290640892200674,0.00825904049974324,,25,26.207738571167,182.442494506836,36.8098139953613,
,13851664.61,4370,181.116004943848,0.13400000333786,0,26.4939184570312,9.98999977111816,183.748358764648,9.98999977111816,37.2016220092773,9.98999977111816,,,0.00637274392927501,0.0291042528503017,0.00861054758388315,,25,26.4939184570312,183.748358764648,37.2016220092773,
,13851784.34,4370,183.118698120117,0.13400000333786,0,26.7817168426514,9.98999977111816,185.068558959961,9.98999977111816,37.5965068054199,9.98999977111816,,,0.0074564140142813,0.0286447955813018,0.00928439405045155,,25,26.7817168426514,185.068558959961,37.5965068054199,
,13851904.39,4370,185.121101379395,0.13400000333786,0,27.0735803222656,9.98999977111816,186.422199707031,9.98999977111816,37.9981713867188,9.98999977111816,,,0.00660112759918414,0.0293581280036029,0.00948433178393804,,25,27.0735803222656,186.422199707031,37.9981713867188,
,13852023.03,4370,187.102897644043,0.13400000333786,0,27.3530612945557,9.98999977111816,187.695079345703,9.98999977111816,38.3819450378418,9.98999977111816,,,0.00672385792518362,0.0290709796883161,0.00907974555486137,,25,27.3530612945557,187.695079345703,38.3819450378418,
,13852143.02,4370,189.105598449707,0.13400000333786,0,27.6477812194824,9.98999977111816,189.064837036133,9.98999977111816,38.7861964416504,9.98999977111816,,,0.00565651136396082,0.0281954672096161,0.0089176370282775,,25,27.6477812194824,189.064837036133,38.7861964416504,
,13852263.58,4370,191.115844726563,0.13400000333786,0,27.9302239990234,9.98999977111816,190.407253417969,9.98999977111816,39.1737989807129,9.98999977111816,,,0.00695084144263535,0.0280684967279126,0.00927967706910104,,25,27.9302239990234,190.407253417969,39.1737989807129,
,13852383.34,4370,193.111450195313,0.13400000333786,0,28.2135915374756,9.98999977111816,191.724919433594,9.98999977111816,39.5628926086426,9.98999977111816,,,0.00704831394807017,0.0281829946287636,0.00867109664293544,,25,28.2135915374756,191.724919433594,39.5628926086426,
,13852503.08,4370,195.11164855957,0.13400000333786,0,28.4973954772949,9.98999977111816,193.038511352539,9.98999977111816,39.9526707458496,9.98999977111816,,,0.00664122215875614,0.0268611365536277,0.00899314638918524,,25,28.4973954772949,193.038511352539,39.9526707458496,
,13852622.39,4370,197.105751037598,0.13400000333786,0,28.7866223144531,9.98999977111816,194.352903442383,9.98999977111816,40.3481568908691,9.98999977111816,,,0.0062231128579007,0.0313963426259358,0.00858551195924766,,25,28.7866223144531,194.352903442383,40.3481568908691,
,13852742.31,4370,199.106399536133,0.13400000333786,0,29.0672040557861,9.98999977111816,195.660374755859,9.98999977111816,40.7340196228027,9.98999977111816,,,0.00651914632674308,0.0290945158628129,0.00894040308152255,,25,29.0672040557861,195.660374755859,40.7340196228027,
,13852862.56,4370,201.10880279541,0.13400000333786,0,29.357237701416,9.98999977111816,196.974111328125,9.98999977111816,41.1299340820312,9.98999977111816,,,0.00667898278041777,0.0294196561078513,0.0079157755842876,,25,29.357237701416,196.974111328125,41.1299340820312,
,13852982.03,4370,203.10139465332,0.13400000333786,0,29.6423110961914,9.98999977111816,198.278555908203,9.98999977111816,41.5219216918945,9.98999977111816,,,0.00702302838381675,0.0325419152169296,0.00903917506925597,,25,29.6423110961914,198.278555908203,41.5219216918945,
,13853102.14,4370,205.109703063965,0.13400000333786,0,29.9261934661865,9.98999977111816,199.590639648438,9.98999977111816,41.9105804443359,9.98999977111816,,,0.00587196104484494,0.0286320164695135,0.00917091420652722,,25,29.9261934661865,199.590639648438,41.9105804443359,
,13853221.84,4370,207.104354858398,0.13400000333786,0,30.2112435913086,9.98999977111816,200.902995605469,9.98999977111816,42.3020748901367,9.98999977111816,,,0.00704031302805711,0.0273656817009315,0.00900825545640668,,25,30.2112435913086,200.902995605469,42.3020748901367,
,13853341.83,4370,209.102905273438,0.13400000333786,0,30.4928499603271,9.98999977111816,202.201343994141,9.98999977111816,42.6866932678223,9.98999977111816,,,0.00683331555695629,0.0289648392129327,0.00865518977742048,,25,30.4928499603271,202.201343994141,42.6866932678223,
,13853461.89,4370,211.109794616699,0.13400000333786,0,30.7782015991211,9.98999977111816,203.509608154297,9.98999977111816,43.0774243164063,9.98999977111816,,,0.006416817454449,0.0279586168353133,0.00778933582624945,,25,30.7782015991211,203.509608154297,43.0774243164063,
,13853581.13,4370,213.102149963379,0.13400000333786,0,31.0576683807373,9.98999977111816,204.797738037109,9.98999977111816,43.462261505127,9.98999977111816,,,0.00678275376027299,0.0275571809647922,0.00931115726006916,,25,31.0576683807373,204.797738037109,43.462261505127,
,13853702.06,4370,215.118545532227,0.13400000333786,0,31.3480072021484,9.98999977111816,206.102349243164,9.98999977111816,43.8581755065918,9.98999977111816,,,0.00659518035527858,0.0273725880976282,0.0082622890667776,,25,31.3480072021484,206.102349243164,43.8581755065918,
,13853821.63,4370,217.109405517578,0.13400000333786,0,31.6311965179443,9.98999977111816,207.401243286133,9.98999977111816,44.2463261413574,9.98999977111816,,,0.00644136472797197,0.0286106521575225,0.00891244767917971,,25,31.6311965179443,207.401243286133,44.2463261413574,
,13853940.73,4370,219.103248596191,0.13400000333786,0,31.9139936065674,9.98999977111816,208.674204711914,9.98999977111816,44.6342169189453,9.98999977111816,,,0.00669712999937184,0.0281774345536713,0.00851385926545413,,25,31.9139936065674,208.674204711914,44.6342169189453,
,13854061.42,4370,221.110702514648,0.13400000333786,0,32.2007257080078,9.98999977111816,209.960872802734,9.98999977111816,45.0255740356445,9.98999977111816,,,0.00646571896484725,0.0272080506004076,0.00838569634651362,,25,32.2007257080078,209.960872802734,45.0255740356445,
,13854180.17,4370,223.091400146484,0.13400000333786,0,32.4818629455566,9.98999977111816,211.233881835938,9.98999977111816,45.4102221679687,9.98999977111816,,,0.00718848647372796,0.0285654573437239,0.00853894519085417,,25,32.4818629455566,211.233881835938,45.4102221679687,
,13854300.70,4370,225.101249694824,0.13400000333786,0,32.7568856811523,9.98999977111816,212.513397216797,9.98999977111816,45.7869166564941,9.98999977111816,,,0.00671725001644708,0.0284145897594591,0.00882109875724913,,25,32.7568856811523,212.513397216797,45.7869166564941,
,13854421.25,4370,227.115852355957,0.13400000333786,0,33.0423011779785,9.98999977111816,213.785501098633,9.98999977111816,46.1779331970215,9.98999977111816,,,0.00619116317109396,0.0272166989029235,0.00785387390965801,,25,33.0423011779785,213.785501098633,46.1779331970215,
,13854540.31,4370,229.099700927734,0.13400000333786,0,33.3287316894531,9.98999977111816,215.051522216797,9.98999977111816,46.5707350158691,9.98999977111816,,,0.00683244819108541,0.0282896733975809,0.00920650119928973,,25,33.3287316894531,215.051522216797,46.5707350158691,
,13854660.23,4370,231.104652404785,0.13400000333786,0,33.6076719665527,9.98999977111816,216.313433837891,9.98999977111816,46.9532600402832,9.98999977111816,,,0.00555767212993717,0.0276159087783595,0.00809067509650327,,25,33.6076719665527,216.313433837891,46.9532600402832,
,13854779.97,4370,233.10270690918,0.13400000333786,0,33.885446472168,9.98999977111816,217.571447753906,9.98999977111816,47.332921295166,9.98999977111816,,,0.00776137395686395,0.0266937856170897,0.00931818684467269,,25,33.885446472168,217.571447753906,47.332921295166,
,13854900.78,4370,235.121452331543,0.13400000333786,0,34.1688958740234,9.98999977111816,218.828731079102,9.98999977111816,47.7201582336426,9.98999977111816,,,0.00560727183331993,0.0289724469257837,0.00814994004031169,,25,34.1688958740234,218.828731079102,47.7201582336426,
,13855020.28,4370,237.112098693848,0.13400000333786,0,34.4486381530762,9.98999977111816,220.077990112305,9.98999977111816,48.1012658691406,9.98999977111816,,,0.00798553020145733,0.0277747265699587,0.010225832192535,,25,34.4486381530762,220.077990112305,48.1012658691406,
,13855139.67,4370,239.107597351074,0.13400000333786,0,34.7295062255859,9.98999977111816,221.326759033203,9.98999977111816,48.4840992736816,9.98999977111816,,,0.00909932640448641,0.0287417949681529,0.0131335359155818,,25,34.7295062255859,221.326759033203,48.4840992736816,
,13855259.05,4370,241.09684753418,0.13400000333786,0,35.0031069946289,9.98999977111816,222.557091064453,9.98999977111816,48.8597370910645,9.98999977111816,,,0.00812926741488073,0.0284650111691393,0.0107872388286169,,25,35.0031069946289,222.557091064453,48.8597370910645,
,13855379.45,4370,243.108406066895,0.13400000333786,0,35.2869374084473,9.98999977111816,223.797631835937,9.98999977111816,49.2468687438965,9.98999977111816,,,0.00423960929187107,0.0289126776110761,0.00522886560810076,,25,35.2869374084473,223.797631835937,49.2468687438965,
,13855499.56,4370,245.116645812988,0.13400000333786,0,35.5698303222656,9.98999977111816,225.025578613281,9.98999977111816,49.6330702209473,9.98999977111816,,,0.00575447092397663,0.028465920233601,0.00689720091716326,,25,35.5698303222656,225.025578613281,49.6330702209473,
,13855619.36,4370,247.114051818848,0.13400000333786,0,35.8442472839355,9.98999977111816,226.247656860352,9.98999977111816,50.0118280029297,9.98999977111816,,,0.00760891209373568,0.02663449686384,0.0105817115524489,,25,35.8442472839355,226.247656860352,50.0118280029297,
,13855738.59,4370,249.101951599121,0.13400000333786,0,36.1226458740234,9.98999977111816,227.455155639648,9.98999977111816,50.3912977600098,9.98999977111816,,,0.00664565076847122,0.0278430107173052,0.00817095710132488,,25,36.1226458740234,227.455155639648,50.3912977600098,
,13855858.92,4370,251.105400085449,0.13400000333786,0,36.3908058166504,9.98999977111816,228.674443969727,9.98999977111816,50.7561695861816,9.98999977111816,,,0.00625679291075613,0.0252654448325508,0.00881516768927265,,25,36.3908058166504,228.674443969727,50.7561695861816,
,13855979.47,4370,253.115898132324,0.13400000333786,0,36.6820611572266,9.98999977111816,229.900325317383,9.98999977111816,51.1541273498535,9.98999977111816,,,0.00681276456979,0.0263015803669995,0.00823358693552091,,25,36.6820611572266,229.900325317383,51.1541273498535,
,13856098.16,4370,255.098152160645,0.13400000333786,0,36.9577069091797,9.98999977111816,231.080509033203,9.98999977111816,51.5301364135742,9.98999977111816,,,0.00704281078253211,0.0273286304544877,0.00781601029748624,,25,36.9577069091797,231.080509033203,51.5301364135742,
,13856218.78,4370,257.102996826172,0.13400000333786,0,37.2373422241211,9.98999977111816,232.284186401367,9.98999977111816,51.9105461120605,9.98999977111816,,,0.00609754381989798,0.027169207096544,0.00823885200316446,,25,37.2373422241211,232.284186401367,51.9105461120605,
,13856338.75,4370,259.102401733398,0.13400000333786,0,37.5162689208984,9.98999977111816,233.474373168945,9.98999977111816,52.2936851501465,9.98999977111816,,,0.00660013060036093,0.0263062289584255,0.00836828856478738,,25,37.5162689208984,233.474373168945,52.2936851501465,
,13856459.09,4370,261.112152099609,0.13400000333786,0,37.7862269592285,9.98999977111816,234.669388427734,9.98999977111816,52.6603843688965,9.98999977111816,,,0.0058305421213636,0.0249969830720585,0.00792330107245726,,25,37.7862269592285,234.669388427734,52.6603843688965,
,13856579.08,4370,263.109100341797,0.13400000333786,0,38.068677520752,9.98999977111816,235.842725219727,9.98999977111816,53.047131652832,9.98999977111816,,,0.0056760238169996,0.0258393823680861,0.00851769091745501,,25,38.068677520752,235.842725219727,53.047131652832,
,13856699.63,4370,265.114151000977,0.13400000333786,0,38.3495909118652,9.98999977111816,237.028707275391,9.98999977111816,53.4275952148437,9.98999977111816,,,0.00607734598213684,0.0253257722735385,0.00755671721025063,,25,38.3495909118652,237.028707275391,53.4275952148437,
,13856819.58,4370,267.109451293945,0.13400000333786,0,38.6218435668945,9.98999977111816,238.182901611328,9.98999977111816,53.8008212280273,9.98999977111816,,,0.00595974683256041,0.0249742011427937,0.00837693796236512,,25,38.6218435668945,238.182901611328,53.8008212280273,
,13856939.95,4370,269.113800048828,0.13400000333786,0,38.8950204467773,9.98999977111816,239.348428955078,9.98999977111816,54.1768571472168,9.98999977111816,,,0.0101859785042941,0.0246919015737931,0.00763762652818823,,25,38.8950204467773,239.348428955078,54.1768571472168,
,13857060.33,4370,271.112197875977,0.13400000333786,0,39.169076385498,9.98999977111816,240.509360351562,9.98999977111816,54.5489860534668,9.98999977111816,,,0.00612476748710587,0.0256064762684983,0.00872469210276742,,25,39.169076385498,240.509360351562,54.5489860534668,
,13857179.55,4370,273.101089477539,0.13400000333786,0,39.4527198791504,9.98999977111816,241.656901855469,9.98999977111816,54.9367721557617,9.98999977111816,,,0.00896559674784692,0.0247928270184738,0.00845567699932064,,25,39.4527198791504,241.656901855469,54.9367721557617,
,13857299.25,4370,275.089004516602,0.13400000333786,0,39.7241041564941,9.98999977111816,242.802840576172,9.98999977111816,55.3048735046387,9.98999977111816,,,0.00680169484827725,0.0246318197089338,0.00852005661025759,,25,39.7241041564941,242.802840576172,55.3048735046387,
,13857419.67,4370,277.098358154297,0.13400000333786,0,40.0019088745117,9.98999977111816,243.94974609375,9.98999977111816,55.6815835571289,9.98999977111816,,,0.0059934073087202,0.0250197406219548,0.00761075816297375,,25,40.0019088745117,243.94974609375,55.6815835571289,
,13857539.81,4370,279.102600097656,0.13400000333786,0,40.2721762084961,9.98999977111816,245.091066894531,9.98999977111816,56.0502305603027,9.98999977111816,,,0.00637040573528773,0.0252083444575814,0.00815527539316699,,25,40.2721762084961,245.091066894531,56.0502305603027,
,13857661.03,4370,281.113555908203,0.13400000333786,0,40.5531443786621,9.98999977111816,246.237418823242,9.98999977111816,56.4323237609863,9.98999977111816,,,0.00576770005904015,0.0246249912991008,0.00836292989480034,,25,40.5531443786621,246.237418823242,56.4323237609863,
,13857780.28,4370,283.105895996094,0.13400000333786,0,40.8310121154785,9.98999977111816,247.367069702148,9.98999977111816,56.8130755615234,9.98999977111816,,,0.00671989626728465,0.0256338704043703,0.00865330066416238,,25,40.8310121154785,247.367069702148,56.8130755615234,
,13857900.22,4370,285.099044799805,0.13400000333786,0,41.1073519897461,9.98999977111816,248.492072143555,9.98999977111816,57.1864964294434,9.98999977111816,,,0.0075523545427776,0.0274392460374962,0.00931779876206622,,25,41.1073519897461,248.492072143555,57.1864964294434,
,13858020.92,4370,287.106948852539,0.13400000333786,0,41.3767846679687,9.98999977111816,249.627894897461,9.98999977111816,57.5555828857422,9.98999977111816,,,0.00601852637059211,0.024684069629189,0.00797035331107318,,25,41.3767846679687,249.627894897461,57.5555828857422,
,13858140.89,4370,289.105850219727,0.13400000333786,0,41.6517640686035,9.98999977111816,250.752885131836,9.98999977111816,57.9284051513672,9.98999977111816,,,0.00617576718205194,0.0263041732844643,0.00834417224604773,,25,41.6517640686035,250.752885131836,57.9284051513672,
,13858261.22,4370,291.106948852539,0.13400000333786,0,41.9271788024902,9.98999977111816,251.868884887695,9.98999977111816,58.305880279541,9.98999977111816,,,0.0086419000213733,0.0259554110007721,0.00958867586190826,,25,41.9271788024902,251.868884887695,58.305880279541,
,13858381.06,4370,293.098648071289,0.13400000333786,0,42.1974766540527,9.98999977111816,253.001951293945,9.98999977111816,58.6705879211426,9.98999977111816,,,0.0048687778111973,0.0224633335437074,0.0079470173186353,,25,42.1974766540527,253.001951293945,58.6705879211426,
,13858501.14,4370,295.103851318359,0.13400000333786,0,42.4766177368164,9.98999977111816,254.105635375977,9.98999977111816,59.0508447265625,9.98999977111816,,,0.0061780274288095,0.0240415175078961,0.00792008011617184,,25,42.4766177368164,254.105635375977,59.0508447265625,
,13858621.56,4370,297.109298706055,0.13400000333786,0,42.7462254333496,9.98999977111816,255.220271606445,9.98999977111816,59.4196438598633,9.98999977111816,,,0.00669695823950233,0.0246713508535615,0.00842247019751823,,25,42.7462254333496,255.220271606445,59.4196438598633,
,13858740.92,4370,299.092712402344,0.13400000333786,0,43.0272749328613,9.98999977111816,256.318992919922,9.98999977111816,59.8009992980957,9.98999977111816,,,0.00640793535833627,0.0235344284437749,0.00831899593145679,,25,43.0272749328613,256.318992919922,59.8009992980957,
,13858802.30,4370,300.081848144531,0.13400000333786,0,43.158921661377,9.98999977111816,256.876918945313,9.98999977111816,59.9798942565918,9.98999977111816,,,0.00537997454854204,0.0220382935269568,0.00795409726718653,,25,43.158921661377,256.876918945313,59.9798942565918,