File: icepp/data/250308/250308_3D_mh_photolitho_IV_plus_fineUp1.dat
[Header]
TITLE, IV scan 5 to 10 (0.033 scan)
FILEOPENTIME,13902975.17,3/8/2025,9:07 PM
BYAPP, Resistivity, 2.1, 1.0
INFO, APPNAME, PPMS MultiVu Application, 1.5.11
INFO, , Sample1 Name
INFO, 1, Sample1 Cross Section
INFO, 1, Sample1 Length
INFO, Ohm, Sample1 Units
INFO, , Sample2 Name
INFO, 1, Sample2 Cross Section
INFO, 1, Sample2 Length
INFO, Ohm, Sample2 Units
INFO, , Sample3 Name
INFO, 1, Sample3 Cross Section
INFO, 1, Sample3 Length
INFO, Ohm, Sample3 Units
INFO, , Sample4 Name
INFO, 1, Sample4 Cross Section
INFO, 1, Sample4 Length
INFO, Ohm, Sample4 Units
FIELDGROUP, Resistivity,2,3,4,5,6,7,8,9,10,11,12,13,14,15,16,17,18,19,20,21,22,23,24,25,26,27,28,29,30,31,32,33,34,35,36,37,38,39,40,41
STARTUPGROUP, Resistivity
STARTUPAXIS, X, 2, LINEAR, AUTO
STARTUPAXIS, Y1, 7, LINEAR, AUTO
STARTUPAXIS, Y2, 9, LINEAR, AUTO
STARTUPAXIS, Y3, 11, LINEAR, AUTO
PLOT_APPEARANCE, ALL, HORZ_GRID_ON, VERT_GRID_ON, MARKERS_AND_LINES, ALL_LINES
DATATYPE, TIME, 2
DATATYPE, COMMENT, 1
[Data]
Comment,Time Stamp (sec),Status (code),Temperature (K),Magnetic Field (Oe),Sample Position (deg),Bridge 1 Resistivity (Ohm),Bridge 1 Excitation (uA),Bridge 2 Resistivity (Ohm),Bridge 2 Excitation (uA),Bridge 3 Resistivity (Ohm),Bridge 3 Excitation (uA),Bridge 4 Resistivity (Ohm),Bridge 4 Excitation (uA),Bridge 1 Std. Dev. (Ohm),Bridge 2 Std. Dev. (Ohm),Bridge 3 Std. Dev. (Ohm),Bridge 4 Std. Dev. (Ohm),Number of Readings,Bridge 1 Resistance (Ohms),Bridge 2 Resistance (Ohms),Bridge 3 Resistance (Ohms),Bridge 4 Resistance (Ohms),Signal 1 Vin (V),Signal 2 Vin (V),Digital Inputs (code),Drive 1 Iout (mA),Drive 1 Ipower (watts),Drive 2 Iout (mA),Drive 2 Ipower (watts),Pressure (),Map 20 (),Map 21 (),Map 22 (),Map 23 (),Map 24 (),Map 25 (),Map 26 (),Map 27 (),Map 28 (),Map 29 ()
,13903374.78,4369,3.00069999694824,0.13400000333786,0,370.256793212891,5,27.0787870025635,5,112.64984161377,5,,,0.148591624162104,0.185926275581507,1.75516392641226,,25,370.256793212891,27.0787870025635,112.64984161377,
,13903382.94,4369,3.00110006332397,0.13400000333786,0,370.255239257812,5.03200006484985,26.9179116821289,5.03200006484985,112.79805847168,5.03200006484985,,,0.218203549866424,0.069926492847829,1.81679448846828,,25,370.255239257812,26.9179116821289,112.79805847168,
,13903390.70,4369,3.00014996528625,0.13400000333786,0,370.424086914063,5.05600023269653,26.9815039825439,5.05600023269653,113.791821594238,5.05600023269653,,,0.19134622760669,0.0941740822177067,2.06379742129301,,25,370.424086914063,26.9815039825439,113.791821594238,
,13903399.19,4369,3.00025010108948,0.13400000333786,0,370.742860107422,5.08099985122681,27.0942881011963,5.08099985122681,115.643980102539,5.08099985122681,,,0.277837391740444,0.10769078643852,2.73588639352872,,25,370.742860107422,27.0942881011963,115.643980102539,
,13903408.09,4369,3.00024998188019,0.13400000333786,0,371.160076904297,5.12900018692017,27.2429451751709,5.12900018692017,116.897445983887,5.12900018692017,,,0.258556106818943,0.0937136952461152,1.74182828168857,,25,371.160076904297,27.2429451751709,116.897445983887,
,13903416.34,4369,2.99940001964569,0.13400000333786,0,373.312416992187,5.15399980545044,30.6694230651855,5.15399980545044,121.342878723145,5.15399980545044,,,6.560250266484,9.13969316306607,8.69130795078455,,25,373.312416992187,30.6694230651855,121.342878723145,
,13903424.67,4369,3.00059998035431,0.13400000333786,0,371.538129882812,5.17799997329712,27.4166931152344,5.17799997329712,118.400699768066,5.17799997329712,,,0.25749898706246,0.125428628204185,1.79890141276002,,25,371.538129882812,27.4166931152344,118.400699768066,
,13903433.50,4369,2.99889993667603,0.13400000333786,0,371.797916259766,5.22700023651123,27.5901159667969,5.22700023651123,120.72205078125,5.22700023651123,,,0.195752191118218,0.106058781161669,1.69140235917716,,25,371.797916259766,27.5901159667969,120.72205078125,
,13903441.45,4369,3.00010001659393,0.13400000333786,0,371.882860107422,5.2519998550415,27.6072774505615,5.2519998550415,121.493156433105,5.2519998550415,,,0.118484445855596,0.0899140024669584,1.85047327211617,,25,371.882860107422,27.6072774505615,121.493156433105,
,13903449.72,4369,3.00094997882843,0.13400000333786,0,372.12923828125,5.27600002288818,27.7131750488281,5.27600002288818,122.408379516602,5.27600002288818,,,0.161221757546745,0.136507857717675,1.77310623051726,,25,372.12923828125,27.7131750488281,122.408379516602,
,13903458.38,4369,2.99795007705688,0.13400000333786,0,372.423056640625,5.32499980926514,28.0146208190918,5.32499980926514,125.76051940918,5.32499980926514,,,0.146053157633646,0.408069043052365,3.07519415193462,,25,372.423056640625,28.0146208190918,125.76051940918,
,13903466.55,4369,3.00129997730255,0.13400000333786,0,372.738676757813,5.34899997711182,28.4315450286865,5.34899997711182,127.348843994141,5.34899997711182,,,0.167582053782296,1.28159052788941,3.28102347684673,,25,372.738676757813,28.4315450286865,127.348843994141,
,13903475.23,4369,3.00090003013611,0.13400000333786,0,372.994119873047,5.37400007247925,29.250481338501,5.37400007247925,129.964806518555,5.37400007247925,,,0.544933380123852,2.84472487398124,6.1904951638965,,25,372.994119873047,29.250481338501,129.964806518555,
,13903483.44,4369,3.00080001354218,0.13400000333786,0,373.325395507813,5.4229998588562,28.1094438171387,5.4229998588562,131.216523132324,5.4229998588562,,,0.121311171250291,0.107029960091193,2.03353130170378,,25,373.325395507813,28.1094438171387,131.216523132324,
,13903491.59,4369,3.00019991397858,0.13400000333786,0,373.3961328125,5.44700002670288,28.2106969451904,5.44700002670288,131.975122680664,5.44700002670288,,,0.200261187255127,0.138195672477122,2.19991083155732,,25,373.3961328125,28.2106969451904,131.975122680664,
,13903499.70,4369,3.00065004825592,0.13400000333786,0,373.57423828125,5.47100019454956,28.3802825164795,5.47100019454956,133.438399047852,5.47100019454956,,,0.229181318872712,0.134612016845534,1.5970002173104,,25,373.57423828125,28.3802825164795,133.438399047852,
,13903509.34,4369,2.99975001811981,0.13400000333786,0,374.001165771484,5.51999998092651,28.6415672302246,5.51999998092651,138.189353027344,5.51999998092651,,,0.201262165106109,0.167667767564695,2.15605398924253,,25,374.001165771484,28.6415672302246,138.189353027344,
,13903517.75,4369,2.99994993209839,0.13400000333786,0,374.033581542969,5.54500007629395,28.6434944915771,5.54500007629395,139.069156494141,5.54500007629395,,,0.107500570634555,0.129376685449645,2.67227265489955,,25,374.033581542969,28.6434944915771,139.069156494141,
,13903526.55,4369,3.00029993057251,0.13400000333786,0,374.220823974609,5.56899976730347,28.7804747772217,5.56899976730347,141.344757080078,5.56899976730347,,,0.227036453315411,0.147959535842249,2.13077154251726,,25,374.220823974609,28.7804747772217,141.344757080078,
,13903535.22,4369,2.99849998950958,0.13400000333786,0,374.825777587891,5.61800003051758,29.0531671142578,5.61800003051758,148.089825439453,5.61800003051758,,,1.4405801298592,0.232453822052765,4.8747252275635,,25,374.825777587891,29.0531671142578,148.089825439453,
,13903543.14,4369,3.00004994869232,0.13400000333786,0,374.608581542969,5.64200019836426,29.0118752288818,5.64200019836426,147.83608215332,5.64200019836426,,,0.206731170485047,0.106161453054328,3.91485948582749,,25,374.608581542969,29.0118752288818,147.83608215332,
,13903551.56,4369,3.00055003166199,0.13400000333786,0,374.890240478516,5.69099998474121,29.2509122467041,5.69099998474121,153.444339599609,5.69099998474121,,,0.235586066493667,0.140531978017203,3.75665679855901,,25,374.890240478516,29.2509122467041,153.444339599609,
,13903560.06,4369,2.99934995174408,0.13400000333786,0,374.981802978516,5.71600008010864,29.3984310913086,5.71600008010864,154.815814819336,5.71600008010864,,,0.142910882975482,0.161286527311674,3.66458892331059,,25,374.981802978516,29.3984310913086,154.815814819336,
,13903568.55,4369,2.99985003471375,0.13400000333786,0,375.120534667969,5.73999977111816,29.4865811157227,5.73999977111816,157.659460449219,5.73999977111816,,,0.15712892661708,0.136306419071984,2.90135435696935,,25,375.120534667969,29.4865811157227,157.659460449219,
,13903577.42,4369,3.00075006484985,0.13400000333786,0,375.346490478516,5.78900003433228,29.8101898193359,5.78900003433228,162.190270996094,5.78900003433228,,,0.107686716720311,0.22269150485285,3.72121847348371,,25,375.346490478516,29.8101898193359,162.190270996094,
,13903586.48,4369,2.99965000152588,0.13400000333786,0,375.445679931641,5.81300020217896,29.8178490447998,5.81300020217896,166.373303833008,5.81300020217896,,,0.118957452984435,0.098418175498966,3.93636678310537,,25,375.445679931641,29.8178490447998,166.373303833008,
,13903594.53,4369,2.99909996986389,0.13400000333786,0,375.545202636719,5.83799982070923,30.0545046234131,5.83799982070923,168.42663269043,5.83799982070923,,,0.13636796581424,0.142845413315228,3.55581497744244,,25,375.545202636719,30.0545046234131,168.42663269043,
,13903602.80,4369,2.99974989891052,0.13400000333786,0,375.756257324219,5.88700008392334,30.2222593688965,5.88700008392334,179.628490600586,5.88700008392334,,,0.208990408490557,0.135603493276605,5.63134758742693,,25,375.756257324219,30.2222593688965,179.628490600586,
,13903611.34,4369,3.00139999389648,0.13400000333786,0,375.824287109375,5.91099977493286,30.3042747497559,5.91099977493286,185.301325073242,5.91099977493286,,,0.19654438782195,0.14651497477891,5.19841050314939,,25,375.824287109375,30.3042747497559,185.301325073242,
,13903619.91,4369,2.99989998340607,0.13400000333786,0,375.861597900391,5.93599987030029,30.5255827331543,5.93599987030029,195.647356567383,5.93599987030029,,,0.199970714038556,0.153429807294528,5.26292330176084,,25,375.861597900391,30.5255827331543,195.647356567383,
,13903628.73,4369,3.00059998035431,0.13400000333786,0,376.082016601562,5.98400020599365,30.8077996063232,5.98400020599365,211.976146240234,5.98400020599365,,,0.134111153213357,0.134684200634214,3.35799837969537,,25,376.082016601562,30.8077996063232,211.976146240234,
,13903637.36,4369,2.99895000457764,0.13400000333786,0,376.221744384766,6.00899982452393,30.9694761657715,6.00899982452393,217.452701416016,6.00899982452393,,,0.146607792738536,0.155622478034607,3.28584801832515,,25,376.221744384766,30.9694761657715,217.452701416016,
,13903646.59,4369,2.99979996681213,0.13400000333786,0,376.387081298828,6.03299999237061,31.1597428894043,6.03299999237061,221.793980102539,6.03299999237061,,,0.24960166997334,0.14414245317309,2.27220187662009,,25,376.387081298828,31.1597428894043,221.793980102539,
,13903655.39,4369,2.99960005283356,0.13400000333786,0,378.795015869141,6.08199977874756,33.7671932983398,6.08199977874756,231.851737060547,6.08199977874756,,,7.29921696669602,7.15641336149024,4.29930345074631,,25,378.795015869141,33.7671932983398,231.851737060547,
,13903664.03,4369,2.99955010414124,0.13400000333786,0,376.413999023438,6.10599994659424,55.8968165588379,6.10599994659424,232.25548034668,6.10599994659424,,,0.178986428967005,55.8247126835576,1.78354799385702,,25,376.413999023438,55.8968165588379,232.25548034668,
,13903672.30,4369,2.99900007247925,0.13400000333786,0,376.518032226563,6.13100004196167,43.9964142608643,6.13100004196167,235.316049804688,6.13100004196167,,,0.199751017402714,41.4116072502195,1.66593117194995,,25,376.518032226563,43.9964142608643,235.316049804688,
,13903680.98,4369,3.00094997882843,0.13400000333786,0,376.516043701172,6.17999982833862,38.3349877929687,6.17999982833862,240.578071899414,6.17999982833862,,,0.129436061712597,30.0177113694268,1.5831909699835,,25,376.516043701172,38.3349877929687,240.578071899414,
,13903689.77,4369,2.99985003471375,0.13400000333786,0,376.567709960938,6.2039999961853,44.6797575378418,6.2039999961853,242.741486206055,6.2039999961853,,,0.168824983254762,41.6500218435567,1.3446389070956,,25,376.567709960938,44.6797575378418,242.741486206055,
,13903698.42,4369,3.00069999694824,0.13400000333786,0,376.684477539063,6.22900009155273,38.7267469787598,6.22900009155273,244.500212402344,6.22900009155273,,,0.159054338578038,30.1383283485101,1.47205016004234,,25,376.684477539063,38.7267469787598,244.500212402344,
,13903707.36,4369,3.0011500120163,0.13400000333786,0,376.713181152344,6.27699995040894,45.2697911071777,6.27699995040894,249.503535766602,6.27699995040894,,,0.193770580378786,41.8799089528639,1.31521655536395,,25,376.713181152344,45.2697911071777,249.503535766602,
,13903716.31,4369,3.00040006637573,0.13400000333786,0,377.371030273438,6.30200004577637,46.116187286377,6.30200004577637,252.595863037109,6.30200004577637,,,2.81232126494526,41.7897077621783,1.90654584510799,,25,377.371030273438,46.116187286377,252.595863037109,
,13903725.02,4369,2.99919998645782,0.13400000333786,0,376.758312988281,6.32600021362305,70.5002485656738,6.32600021362305,255.024501342773,6.32600021362305,,,0.106076892258011,66.1070641213354,1.92317858722533,,25,376.758312988281,70.5002485656738,255.024501342773,
,13903733.56,4369,2.99965000152588,0.13400000333786,0,383.246284179688,6.375,46.3092813110352,6.375,263.089864501953,6.375,,,31.8185550660654,42.0404665585702,4.41625150391233,,25,383.246284179688,46.3092813110352,263.089864501953,
,13903742.97,4369,3.00079989433289,0.13400000333786,0,376.866547851562,6.40000009536743,46.4793922424316,6.40000009536743,265.538979492187,6.40000009536743,,,0.169273263160371,42.1112513101966,2.75556471132348,,25,376.866547851562,46.4793922424316,265.538979492187,
,13903752.33,4369,2.9994500875473,0.13400000333786,0,376.807601318359,6.42399978637695,46.8583743286133,6.42399978637695,269.56654296875,6.42399978637695,,,0.0750006949341636,42.1545894708732,3.563803928692,,25,376.807601318359,46.8583743286133,269.56654296875,
,13903760.36,4369,3.00024998188019,0.13400000333786,0,383.814222412109,6.47300004959106,47.2634837341309,6.47300004959106,279.890927734375,6.47300004959106,,,33.0968667040161,42.2552993387092,5.21532332341903,,25,383.814222412109,47.2634837341309,279.890927734375,
,13903770.17,4369,3.00020003318787,0.13400000333786,0,376.993140869141,6.49700021743774,41.342804107666,6.49700021743774,286.596588134766,6.49700021743774,,,0.132550236238587,30.5636885149194,5.32850428898697,,25,376.993140869141,41.342804107666,286.596588134766,
,13903778.47,4369,2.99904990196228,0.13400000333786,0,418.760101318359,6.5460000038147,52.2334727478027,6.5460000038147,304.808812255859,6.5460000038147,,,73.960905665594,42.6143778605253,7.87506615721442,,25,418.760101318359,52.2334727478027,304.808812255859,
,13903787.97,4369,3.00069999694824,0.13400000333786,0,404.825667724609,6.57100009918213,42.2834797668457,6.57100009918213,307.3916796875,6.57100009918213,,,62.9233619890763,30.6238702338631,2.62938272059355,,25,404.825667724609,42.2834797668457,307.3916796875,
,13903797.28,4369,3.00014996528625,0.13400000333786,0,425.464606933594,6.59499979019165,42.586490020752,6.59499979019165,312.004489746094,6.59499979019165,,,77.3746644454448,30.6486218684413,1.76955556853619,,25,425.464606933594,42.586490020752,312.004489746094,
,13903805.97,4369,2.99954998493195,0.13400000333786,0,460.573248291016,6.64400005340576,55.5113218688965,6.64400005340576,317.737099609375,6.64400005340576,,,86.6492426533924,50.9536277768161,1.17810937635152,,25,460.573248291016,55.5113218688965,317.737099609375,
,13903815.11,4369,2.99909996986389,0.13400000333786,0,481.664643554687,6.66800022125244,43.4751356506348,6.66800022125244,320.597102050781,6.66800022125244,,,85.2271302771968,30.7590602974845,1.43553316127421,,25,481.664643554687,43.4751356506348,320.597102050781,
,13903823.73,4369,3.00195002555847,0.13400000333786,0,489.068845214844,6.69299983978271,50.0506185913086,6.69299983978271,322.631372070313,6.69299983978271,,,83.7273333421562,42.5403378710656,0.979177982206894,,25,489.068845214844,50.0506185913086,322.631372070313,
,13903833.22,4369,3.00065004825592,0.13400000333786,0,511.390185546875,6.74200010299683,44.3021058654785,6.74200010299683,326.941584472656,6.74200010299683,,,75.209693890291,30.8310115542478,0.929496923627105,,25,511.390185546875,44.3021058654785,326.941584472656,
,13903842.69,4369,3.00039994716644,0.13400000333786,0,548.278179931641,6.76599979400635,57.3238362121582,6.76599979400635,329.404868164063,6.76599979400635,,,34.8660922302171,51.1492039704597,1.0947987855873,,25,548.278179931641,57.3238362121582,329.404868164063,
,13903851.17,4369,2.99944996833801,0.13400000333786,0,536.0763671875,6.78999996185303,63.9224633789063,6.78999996185303,331.156086425781,6.78999996185303,,,58.5229235985406,57.8109056633311,0.840175201600609,,25,536.0763671875,63.9224633789063,331.156086425781,
,13903860.58,4369,2.99924993515015,0.13400000333786,0,437.682333984375,6.83900022506714,52.1019532775879,6.83900022506714,335.270289306641,6.83900022506714,,,87.4674966975653,42.756250046459,0.857393957550959,,25,437.682333984375,52.1019532775879,335.270289306641,
,13903870.56,4369,2.99965000152588,0.13400000333786,0,431.157121582031,6.86399984359741,46.1554302978516,6.86399984359741,337.258006591797,6.86399984359741,,,85.6685082847698,30.9182185636241,0.67404667640762,,25,431.157121582031,46.1554302978516,337.258006591797,
,13903879.94,4369,2.99955010414124,0.13400000333786,0,441.580853271484,6.88800001144409,65.643923034668,6.88800001144409,339.132397460938,6.88800001144409,,,92.9780521180813,57.9584478815152,1.01850205033104,,25,441.580853271484,65.643923034668,339.132397460938,
,13903889.58,4369,2.99979996681213,0.13400000333786,0,377.850500488281,6.93699979782104,53.712190246582,6.93699979782104,344.143511962891,6.93699979782104,,,0.0714514152097765,43.0019578723327,1.37207084596147,,25,377.850500488281,53.712190246582,344.143511962891,
,13903901.39,4369,3.00139999389648,0.13400000333786,0,377.974561767578,6.96099996566772,54.221388092041,6.96099996566772,347.816185302734,6.96099996566772,,,0.188876967225608,43.0684213050546,1.18584057656932,,25,377.974561767578,54.221388092041,347.816185302734,
,13903912.05,4369,2.99960005283356,0.13400000333786,0,377.885241699219,6.98600006103516,60.9609117126465,6.98600006103516,349.995710449219,6.98600006103516,,,0.108852359537108,51.6116712758555,0.534351374434991,,25,377.885241699219,60.9609117126465,349.995710449219,
,13903922.78,4369,2.99979996681213,0.13400000333786,0,378.059963378906,7.03499984741211,49.1641645812988,7.03499984741211,354.027796630859,7.03499984741211,,,0.144539229250877,31.3401689409976,0.741547654138377,,25,378.059963378906,49.1641645812988,354.027796630859,
,13903933.56,4369,2.99940001964569,0.13400000333786,0,377.993687744141,7.05900001525879,55.9197024536133,7.05900001525879,356.006506347656,7.05900001525879,,,0.126268750541985,43.4275606670113,0.671495650243433,,25,377.993687744141,55.9197024536133,356.006506347656,
,13903943.81,4369,3.00034999847412,0.13400000333786,0,378.095052490234,7.08400011062622,56.4243350219727,7.08400011062622,358.477116699219,7.08400011062622,,,0.153929149028816,43.6170182976532,0.794215070854119,,25,378.095052490234,56.4243350219727,358.477116699219,
,13903954.70,4369,2.99949991703033,0.13400000333786,0,447.068720703125,7.13199996948242,60.5382373046875,7.13199996948242,366.509300537109,7.13199996948242,,,100.362970203426,44.2025144767286,1.84375417580103,,25,447.068720703125,60.5382373046875,366.509300537109,
,13903966.09,4369,3.00045001506805,0.13400000333786,0,378.162576904297,7.15700006484985,70.7905760192871,7.15700006484985,369.681412353516,7.15700006484985,,,0.174105216769062,59.4315409591676,1.13673316573231,,25,378.162576904297,70.7905760192871,369.681412353516,
,13903977.41,4369,3.00065004825592,0.13400000333786,0,378.189688720703,7.18100023269653,58.3036059570313,7.18100023269653,371.881055908203,7.18100023269653,,,0.099215963754665,44.1913332795691,0.921303949908415,,25,378.189688720703,58.3036059570313,371.881055908203,
,13903988.20,4369,2.99924993515015,0.13400000333786,0,378.374548339844,7.23000001907349,52.808920135498,7.23000001907349,376.2058203125,7.23000001907349,,,0.125611021055841,32.1286932629757,0.948254589221065,,25,378.374548339844,52.808920135498,376.2058203125,
,13903999.14,4369,3.00014996528625,0.13400000333786,0,378.285477294922,7.25500011444092,66.396399230957,7.25500011444092,378.329801025391,7.25500011444092,,,0.0930755783586847,53.3538025056556,0.866390890933353,,25,378.285477294922,66.396399230957,378.329801025391,
,13904009.86,4369,2.99979996681213,0.13400000333786,0,378.437884521484,7.30299997329712,74.0152351379395,7.30299997329712,382.471318359375,7.30299997329712,,,0.119394452632296,60.6322753977396,0.972897409565545,,25,378.437884521484,74.0152351379395,382.471318359375,
,13904020.63,4369,3.00014996528625,0.13400000333786,0,611.543041992187,7.32800006866455,61.4021867370605,7.32800006866455,384.901088867188,7.32800006866455,,,0.570858196092895,44.9383927841422,1.80562882105493,,25,611.543041992187,61.4021867370605,384.901088867188,
,13904029.75,4369,2.9996999502182,0.13400000333786,0,378.556215820313,7.35200023651123,48.3192579650879,7.35200023651123,386.744731445312,7.35200023651123,,,0.146304216860484,0.228869690221154,1.1085819120364,,25,378.556215820313,48.3192579650879,386.744731445312,
,13904040.05,4369,3.00109994411469,0.13400000333786,0,378.668836669922,7.40100002288818,68.094821472168,7.40100002288818,390.825987548828,7.40100002288818,,,0.0744720214967516,47.9057099202789,1.02738989784558,,25,378.668836669922,68.094821472168,390.825987548828,
,13904051.25,4369,2.99994993209839,0.13400000333786,0,378.69470703125,7.42600011825562,57.3138261413574,7.42600011825562,392.823393554688,7.42600011825562,,,0.0841917218478527,32.8545663066415,1.31821257527826,,25,378.69470703125,57.3138261413574,392.823393554688,
,13904062.09,4369,3.00094997882843,0.13400000333786,0,378.782830810547,7.44999980926514,115.859228515625,7.44999980926514,395.384771728516,7.44999980926514,,,0.163605546531244,75.3104293098532,1.32811883945123,,25,378.782830810547,115.859228515625,395.384771728516,
,13904073.53,4369,3.00014996528625,0.13400000333786,0,415.356800537109,7.49900007247925,180.458372344971,7.49900007247925,400.504509277344,7.49900007247925,,,84.7462793426344,39.3852183039563,1.50448883504954,,25,415.356800537109,180.458372344971,400.504509277344,
,13904084.45,4369,2.99955010414124,0.13400000333786,0,378.826850585938,7.52299976348877,180.134181976318,7.52299976348877,402.690863037109,7.52299976348877,,,0.128248220153903,38.5434490384272,1.15895441664535,,25,378.826850585938,180.134181976318,402.690863037109,
,13904094.95,4369,2.99965000152588,0.13400000333786,0,378.989970703125,7.5479998588562,169.080533905029,7.5479998588562,405.017556152344,7.5479998588562,,,0.158910505549526,51.3108571330266,1.20479475088408,,25,378.989970703125,169.080533905029,405.017556152344,
,13904106.06,4369,2.99934995174408,0.13400000333786,0,379.068272705078,7.59600019454956,160.344047241211,7.59600019454956,410.832197265625,7.59600019454956,,,0.15200919622068,60.6997427065255,1.56473478360669,,25,379.068272705078,160.344047241211,410.832197265625,
,13904116.95,4369,3.00010001659393,0.13400000333786,0,550.211309814453,7.62099981307983,150.161312255859,7.62099981307983,414.669233398437,7.62099981307983,,,117.367571802754,66.9118631123867,1.37802662964004,,25,550.211309814453,150.161312255859,414.669233398437,
,13904126.64,4369,2.99959993362427,0.13400000333786,0,379.255291748047,7.64499998092651,180.392816314697,7.64499998092651,416.98314453125,7.64499998092651,,,0.233531369750821,47.0654910207646,1.17644115676177,,25,379.255291748047,180.392816314697,416.98314453125,
,13904138.11,4369,3.00094997882843,0.13400000333786,0,561.694422607422,7.69399976730347,192.99954498291,7.69399976730347,422.837176513672,7.69399976730347,,,113.699573951791,41.8749010402626,6.85655805833444,,25,561.694422607422,192.99954498291,422.837176513672,
,13904147.73,4369,2.99930000305176,0.13400000333786,0,379.319735107422,7.7189998626709,193.882906494141,7.7189998626709,423.232487792969,7.7189998626709,,,0.109170982193134,41.2784378864322,1.87864978138992,,25,379.319735107422,193.882906494141,423.232487792969,
,13904159.25,4369,2.99940001964569,0.13400000333786,0,379.423399658203,7.74300003051758,164.867007293701,7.74300003051758,425.678139648437,7.74300003051758,,,0.205178692687865,68.8757164844761,1.93327250395692,,25,379.423399658203,164.867007293701,425.678139648437,
,13904170.67,4369,3.00150001049042,0.13400000333786,0,379.521651611328,7.79199981689453,167.246613464355,7.79199981689453,430.605810546875,7.79199981689453,,,0.246307785367993,69.964992065988,3.99834258894919,,25,379.521651611328,167.246613464355,430.605810546875,
,13904181.89,4369,2.99875009059906,0.13400000333786,0,552.622873535156,7.81599998474121,186.989810180664,7.81599998474121,436.174621582031,7.81599998474121,,,118.737277423958,57.35917532023,6.61104715711596,,25,552.622873535156,186.989810180664,436.174621582031,
,13904192.05,4369,2.99895000457764,0.13400000333786,0,390.261767578125,7.84100008010864,203.832076263428,7.84100008010864,439.030965576172,7.84100008010864,,,52.0338758853743,63.230060899588,7.31291474610231,,25,390.261767578125,203.832076263428,439.030965576172,
,13904203.73,4369,2.99899995326996,0.13400000333786,0,379.582386474609,7.8899998664856,197.262274017334,7.8899998664856,453.541428222656,7.8899998664856,,,0.223318920424126,52.1106432852695,5.8002320309497,,25,379.582386474609,197.262274017334,453.541428222656,
,13904214.30,4369,3.00059998035431,0.13400000333786,0,379.570938720703,7.91400003433228,212.143091583252,7.91400003433228,458.088395996094,7.91400003433228,,,0.17234455863373,31.7768438276277,6.01881861446999,,25,379.570938720703,212.143091583252,458.088395996094,
,13904225.41,4369,3.00020003318787,0.13400000333786,0,379.681877441406,7.93800020217896,208.339027099609,7.93800020217896,462.467457275391,7.93800020217896,,,0.245169780047872,44.6872413718256,1.1794441380969,,25,379.681877441406,208.339027099609,462.467457275391,
,13904237.19,4369,3.00069999694824,0.13400000333786,0,379.83962890625,7.98699998855591,213.477481079102,7.98699998855591,466.353009033203,7.98699998855591,,,0.181581209239631,45.9472101864512,1.18474276247363,,25,379.83962890625,213.477481079102,466.353009033203,
,13904248.84,4369,3.00059998035431,0.13400000333786,0,601.130187988281,8.01200008392334,221.914867858887,8.01200008392334,468.471895751953,8.01200008392334,,,110.603887355497,33.485234062362,0.764559036173135,,25,601.130187988281,221.914867858887,468.471895751953,
,13904258.56,4369,2.99979996681213,0.13400000333786,0,602.296789550781,8.03600025177002,230.397474975586,8.03600025177002,471.014362792969,8.03600025177002,,,111.107699846459,0.295459827533261,0.928156464154699,,25,602.296789550781,230.397474975586,471.014362792969,
,13904269.09,4369,2.99975001811981,0.13400000333786,0,513.706158447266,8.08500003814697,233.338795166016,8.08500003814697,476.373953857422,8.08500003814697,,,139.288357145542,0.31131409838552,0.983387809259634,,25,513.706158447266,233.338795166016,476.373953857422,
,13904278.61,4369,2.99880003929138,0.13400000333786,0,502.820476074219,8.10900020599365,262.554758911133,8.10900020599365,478.261081542969,8.10900020599365,,,138.600444544372,49.4450725395806,0.741556609363815,,25,502.820476074219,262.554758911133,478.261081542969,
,13904289.05,4369,3.0008499622345,0.13400000333786,0,649.098933105469,8.15799999237061,265.965594482422,8.15799999237061,482.829709472656,8.15799999237061,,,54.8853982411269,49.2455189918629,1.49055461952859,,25,649.098933105469,265.965594482422,482.829709472656,
,13904297.30,4369,2.99889993667603,0.13400000333786,0,560.128052978516,8.18299961090088,277.322346801758,8.18299961090088,486.721605224609,8.18299961090088,,,134.884075339473,53.5063569263141,0.960061932166943,,25,560.128052978516,277.322346801758,486.721605224609,
,13904307.06,4369,3.00014996528625,0.13400000333786,0,540.325704345703,8.20699977874756,287.905703125,8.20699977874756,488.446634521484,8.20699977874756,,,142.037727564482,56.2473539034563,0.741477207388066,,25,540.325704345703,287.905703125,488.446634521484,
,13904317.14,4369,3.00005006790161,0.13400000333786,0,669.720932617187,8.25599956512451,324.32778503418,8.25599956512451,493.465264892578,8.25599956512451,,,59.3044588588651,69.9737392464294,5.1219718116301,,25,669.720932617187,324.32778503418,493.465264892578,
,13904326.00,4369,2.9996999502182,0.13400000333786,0,669.203114013672,8.27999973297119,316.78671875,8.27999973297119,491.894772949219,8.27999973297119,,,58.8792065580177,71.479792282898,5.62008061510506,,25,669.203114013672,316.78671875,491.894772949219,
,13904335.23,4369,2.99980008602142,0.13400000333786,0,681.452429199219,8.30500030517578,353.312694091797,8.30500030517578,495.115672607422,8.30500030517578,,,0.308837360920659,62.806475896703,2.64725722339052,,25,681.452429199219,353.312694091797,495.115672607422,
,13904344.34,4369,2.99890005588531,0.13400000333786,0,681.95365234375,8.35400009155273,374.55151550293,8.35400009155273,498.785759277344,8.35400009155273,,,0.286147325557798,65.2743338766211,0.848827510017951,,25,681.95365234375,374.55151550293,498.785759277344,
,13904353.36,4369,2.99940001964569,0.13400000333786,0,670.358854980469,8.37800025939941,363.893167114258,8.37800025939941,500.704362792969,8.37800025939941,,,59.1367531949626,79.6019262945521,0.797270001697039,,25,670.358854980469,363.893167114258,500.704362792969,
,13904362.78,4369,3.00014996528625,0.13400000333786,0,682.674602050781,8.40299987792969,391.992711181641,8.40299987792969,502.255832519531,8.40299987792969,,,0.367826395718661,71.0646525526526,0.632773100402215,,25,682.674602050781,391.992711181641,502.255832519531,
,13904372.52,4369,2.99925005435944,0.13400000333786,0,683.812543945313,8.45100021362305,402.063099365234,8.45100021362305,506.512690429688,8.45100021362305,,,0.689594517371449,65.7819998410039,1.67059503922583,,25,683.812543945313,402.063099365234,506.512690429688,
,13904381.19,4369,3.00090003013611,0.13400000333786,0,684.43333984375,8.47599983215332,417.736101074219,8.47599983215332,507.695579833984,8.47599983215332,,,0.725957789197912,48.7691292612881,1.5764853307675,,25,684.43333984375,417.736101074219,507.695579833984,
,13904390.69,4369,3.0003000497818,0.13400000333786,0,690.172451171875,8.5,412.215766601563,8.5,508.976925048828,8.5,,,2.65648232303706,58.3333006388058,1.23251019984944,,25,690.172451171875,412.215766601563,508.976925048828,
,13904399.08,4369,3.00024998188019,0.13400000333786,0,701.866713867188,8.54899978637695,431.548214111328,8.54899978637695,512.022612304688,8.54899978637695,,,0.547718108604911,35.5047453373803,0.893693599299943,,25,701.866713867188,431.548214111328,512.022612304688,
,13904408.39,4369,2.99855005741119,0.13400000333786,0,702.274040527344,8.57400035858154,343.222589111328,8.57400035858154,513.334729003906,8.57400035858154,,,0.52056898038122,88.5399522705982,1.12865941265806,,25,702.274040527344,343.222589111328,513.334729003906,
,13904417.70,4369,2.99975001811981,0.13400000333786,0,702.376850585938,8.59799957275391,337.212944335937,8.59799957275391,515.601545410156,8.59799957275391,,,0.358238696290046,88.0673517214709,1.37821031016169,,25,702.376850585938,337.212944335937,515.601545410156,
,13904426.34,4369,3.00010001659393,0.13400000333786,0,704.014809570313,8.64700031280518,393.734940185547,8.64700031280518,520.410822753906,8.64700031280518,,,0.878301279125738,67.7005264368131,0.842486998830491,,25,704.014809570313,393.734940185547,520.410822753906,
,13904436.05,4369,2.99954998493195,0.13400000333786,0,706.170014648437,8.67099952697754,426.261278076172,8.67099952697754,526.505485839844,8.67099952697754,,,3.02709476004605,16.7311713353676,10.1487030597033,,25,706.170014648437,426.261278076172,526.505485839844,
,13904445.48,4369,3.00020003318787,0.13400000333786,0,711.351647949219,8.69600009918213,425.668708496094,8.69600009918213,525.225075683594,8.69600009918213,,,2.04931820181606,16.4690872078383,1.2073279401665,,25,711.351647949219,425.668708496094,525.225075683594,
,13904455.27,4369,2.99930000305176,0.13400000333786,0,716.998166503906,8.74499988555908,429.018721923828,8.74499988555908,529.684348144531,8.74499988555908,,,0.285953161306291,17.0553928007145,1.71042651338138,,25,716.998166503906,429.018721923828,529.684348144531,
,13904464.80,4369,2.99994993209839,0.13400000333786,0,717.524111328125,8.76900005340576,428.987670898438,8.76900005340576,533.132983398438,8.76900005340576,,,0.301439690490518,16.4659776175717,1.47357191328667,,25,717.524111328125,428.987670898438,533.132983398438,
,13904474.45,4369,3.00049996376038,0.13400000333786,0,718.01009765625,8.79300022125244,424.649820556641,8.79300022125244,535.57421875,8.79300022125244,,,0.396010388684874,12.7483990192107,1.57568136587937,,25,718.01009765625,424.649820556641,535.57421875,
,13904483.72,4369,3.00190007686615,0.13400000333786,0,718.365158691406,8.84200000762939,422.88142578125,8.84200000762939,540.795583496094,8.84200000762939,,,0.354825718578569,0.392511981587721,1.69550574283267,,25,718.365158691406,422.88142578125,540.795583496094,
,13904494.80,4369,3.00014996528625,0.13400000333786,0,718.625107421875,8.86699962615967,457.920048828125,8.86699962615967,543.554558105469,8.86699962615967,,,0.623941858174132,53.8051025883608,2.20514230051651,,25,718.625107421875,457.920048828125,543.554558105469,
,13904505.00,4369,3.00150001049042,0.13400000333786,0,719.030583496094,8.89099979400635,425.730524902344,8.89099979400635,545.649228515625,8.89099979400635,,,0.430699748187513,0.266439247521786,1.84431024963744,,25,719.030583496094,425.730524902344,545.649228515625,
,13904516.25,4369,2.9994500875473,0.13400000333786,0,719.4880859375,8.9399995803833,471.712241210938,8.9399995803833,554.709230957031,8.9399995803833,,,0.475380428543974,17.8818212673679,3.46286017289343,,25,719.4880859375,471.712241210938,554.709230957031,
,13904526.09,4369,3.00045001506805,0.13400000333786,0,719.684479980469,8.96399974822998,469.0583203125,8.96399974822998,562.043537597656,8.96399974822998,,,0.501249238508187,0.264231890009973,3.14537453619823,,25,719.684479980469,469.0583203125,562.043537597656,
,13904535.48,4369,2.99989998340607,0.13400000333786,0,720.140766601563,9.01299953460693,478.398784179687,9.01299953460693,570.807785644531,9.01299953460693,,,0.466518829921322,24.1614313941141,0.80450408128235,,25,720.140766601563,478.398784179687,570.807785644531,
,13904544.81,4369,2.9996999502182,0.13400000333786,0,720.139135742187,9.03800010681152,475.840640869141,9.03800010681152,573.017202148437,9.03800010681152,,,0.371828377279453,17.2820877427862,0.475948672796798,,25,720.139135742187,475.840640869141,573.017202148437,
,13904553.92,4369,3.00014996528625,0.13400000333786,0,720.358420410156,9.0620002746582,491.566057128906,9.0620002746582,575.053000488281,9.0620002746582,,,0.351228424709569,34.7394989185417,0.901128999084011,,25,720.358420410156,491.566057128906,575.053000488281,
,13904563.25,4369,3.00005006790161,0.13400000333786,0,720.956535644531,9.11100006103516,487.8566796875,9.11100006103516,578.345366210938,9.11100006103516,,,0.441475239688256,27.2423912369596,0.579286516030076,,25,720.956535644531,487.8566796875,578.345366210938,
,13904572.94,4369,2.99900007247925,0.13400000333786,0,721.113930664063,9.13500022888184,493.080593261719,9.13500022888184,579.909970703125,9.13500022888184,,,0.412071656104367,30.0741607823528,0.577772060911217,,25,721.113930664063,493.080593261719,579.909970703125,
,13904583.14,4369,3.00020003318787,0.13400000333786,0,721.342905273438,9.15999984741211,485.824029541016,9.15999984741211,581.55630859375,9.15999984741211,,,0.337447138799335,15.6088839589812,0.601077418218103,,25,721.342905273438,485.824029541016,581.55630859375,
,13904592.75,4369,2.99895000457764,0.13400000333786,0,722.026298828125,9.20899963378906,496.919805908203,9.20899963378906,584.279521484375,9.20899963378906,,,0.41081839025268,35.2454861040912,0.510369782717022,,25,722.026298828125,496.919805908203,584.279521484375,
,13904601.22,4369,2.99965000152588,0.13400000333786,0,722.195861816406,9.23299980163574,517.434031982422,9.23299980163574,585.556643066406,9.23299980163574,,,0.378680681972789,55.4609285911714,0.362401300093814,,25,722.195861816406,517.434031982422,585.556643066406,
,13904610.33,4369,2.99985003471375,0.13400000333786,0,722.577556152344,9.25699996948242,493.487436523438,9.25699996948242,586.972065429688,9.25699996948242,,,0.455054862861438,16.2982936710418,0.703983149982856,,25,722.577556152344,493.487436523438,586.972065429688,
,13904620.05,4369,3.00025010108948,0.13400000333786,0,722.862719726563,9.30599975585938,501.470635986328,9.30599975585938,590.098764648438,9.30599975585938,,,0.328506639118993,33.0266223411411,1.37398458632978,,25,722.862719726563,501.470635986328,590.098764648438,
,13904630.00,4369,2.99924993515015,0.13400000333786,0,723.192077636719,9.33100032806396,519.094465332031,9.33100032806396,591.930063476563,9.33100032806396,,,0.350024462158627,51.7308660228494,1.10428377711368,,25,723.192077636719,519.094465332031,591.930063476563,
,13904640.06,4369,3.00064992904663,0.13400000333786,0,723.357468261719,9.35499954223633,505.927094726562,9.35499954223633,593.086252441406,9.35499954223633,,,0.412232580852667,32.8167879248156,1.00242016496767,,25,723.357468261719,505.927094726562,593.086252441406,
,13904649.78,4369,3.00034999847412,0.13400000333786,0,724.0099609375,9.4040002822876,519.017868652344,9.4040002822876,596.341494140625,9.4040002822876,,,0.382016581905133,16.8448917084947,0.722639523655723,,25,724.0099609375,519.017868652344,596.341494140625,
,13904659.44,4369,3.00144994258881,0.13400000333786,0,723.930595703125,9.42800045013428,523.4818359375,9.42800045013428,597.271979980469,9.42800045013428,,,0.367198503233018,8.65272982346653,0.572415026408612,,25,723.930595703125,523.4818359375,597.271979980469,
,13904669.14,4369,3.00080001354218,0.13400000333786,0,724.346384277344,9.45300006866455,522.754445800781,9.45300006866455,598.503891601562,9.45300006866455,,,0.362132346673033,0.207626056677954,0.431803105471705,,25,724.346384277344,522.754445800781,598.503891601562,
,13904678.27,4369,3.00059998035431,0.13400000333786,0,725.353483886719,9.5019998550415,546.431174316406,9.5019998550415,600.737319335938,9.5019998550415,,,1.72540787163045,49.2555715516365,0.716705629544825,,25,725.353483886719,546.431174316406,600.737319335938,
,13904687.56,4369,3.00010001659393,0.13400000333786,0,725.103876953125,9.52600002288818,531.908959960938,9.52600002288818,601.737009277344,9.52600002288818,,,0.413529391094302,26.3836542056582,0.509228885382843,,25,725.103876953125,531.908959960938,601.737009277344,
,13904697.02,4369,2.99930000305176,0.13400000333786,0,725.526813964844,9.55099964141846,531.630051269531,9.55099964141846,603.120346679687,9.55099964141846,,,0.391721265113453,1.27712712418242,0.503551676124427,,25,725.526813964844,531.630051269531,603.120346679687,
,13904706.09,4369,3.0008499622345,0.13400000333786,0,725.834919433594,9.59899997711182,543.273195800781,9.59899997711182,605.15392578125,9.59899997711182,,,0.423427594966835,25.3295882515976,0.494803608855585,,25,725.834919433594,543.273195800781,605.15392578125,
,13904715.23,4369,3,0.13400000333786,0,725.970739746094,9.62399959564209,541.700517578125,9.62399959564209,606.12634765625,9.62399959564209,,,0.44999827240883,5.44335559136021,0.6227226518464,,25,725.970739746094,541.700517578125,606.12634765625,
,13904724.95,4369,3.00034999847412,0.13400000333786,0,726.1132421875,9.64799976348877,542.49779296875,9.64799976348877,607.357668457031,9.64799976348877,,,0.585326704516357,0.412368634177157,0.642334722239753,,25,726.1132421875,542.49779296875,607.357668457031,
,13904733.88,4369,2.9988499879837,0.13400000333786,0,768.179013671875,9.69699954986572,545.370651855469,9.69699954986572,613.419389648437,9.69699954986572,,,21.1724527886992,0.502092314378915,1.48846985106209,,25,768.179013671875,545.370651855469,613.419389648437,
,13904743.09,4369,2.99965000152588,0.13400000333786,0,784.078605957031,9.72200012207031,553.200632324219,9.72200012207031,616.682114257812,9.72200012207031,,,0.577187475003322,23.8721000035911,0.63815113835526,,25,784.078605957031,553.200632324219,616.682114257812,
,13904753.03,4369,3.00010001659393,0.13400000333786,0,785.470771484375,9.77000045776367,558.364396972656,9.77000045776367,619.55818359375,9.77000045776367,,,0.626253902659509,23.0652928581275,0.434681071206834,,25,785.470771484375,558.364396972656,619.55818359375,
,13904762.98,4369,3.00045001506805,0.13400000333786,0,785.961142578125,9.79500007629395,561.41830078125,9.79500007629395,620.820200195313,9.79500007629395,,,0.485542261818341,22.5977404751883,0.488245695965475,,25,785.961142578125,561.41830078125,620.820200195313,
,13904772.66,4369,2.99985003471375,0.13400000333786,0,786.398713378906,9.81900024414063,562.463374023438,9.81900024414063,621.888369140625,9.81900024414063,,,0.420148205199562,22.492775810368,0.420622868728233,,25,786.398713378906,562.463374023438,621.888369140625,
,13904782.39,4369,3.00064992904663,0.13400000333786,0,787.429821777344,9.86800003051758,559.603024902344,9.86800003051758,624.467736816406,9.86800003051758,,,0.500155276722424,0.274469753147182,1.01772322965537,,25,787.429821777344,559.603024902344,624.467736816406,
,13904791.78,4369,3.00015008449554,0.13400000333786,0,788.192258300781,9.89299964904785,565.702937011719,9.89299964904785,626.573422851563,9.89299964904785,,,0.617622402677888,23.645647605791,0.805170505191492,,25,788.192258300781,565.702937011719,626.573422851563,
,13904800.92,4369,3.00050008296967,0.13400000333786,0,793.25369140625,9.91699981689453,587.174521484375,9.91699981689453,627.432900390625,9.91699981689453,,,22.8861047836431,46.4016915601193,0.759186564090613,,25,793.25369140625,587.174521484375,627.432900390625,
,13904809.91,4369,3.00040006637573,0.13400000333786,0,790.525920410156,9.96599960327148,594.291354980469,9.96599960327148,631.551994628906,9.96599960327148,,,0.573058715452093,15.5057102310548,0.781724835689114,,25,790.525920410156,594.291354980469,631.551994628906,
,13904819.23,4369,3.00159990787506,0.13400000333786,0,792.06314453125,9.98999977111816,614.175737304687,9.98999977111816,633.100659179687,9.98999977111816,,,0.780409132422178,35.5937491850551,0.7066265746205,,25,792.06314453125,614.175737304687,633.100659179687,