File: icepp/data/250309/250309_3D_mh_photolitho_IV_minus_fineDown1.dat
[Header]
TITLE, IV scan -55 to -35 (0.1 scan)
FILEOPENTIME,13956151.55,3/9/2025,11:54 AM
BYAPP, Resistivity, 2.1, 1.0
INFO, APPNAME, PPMS MultiVu Application, 1.5.11
INFO, , Sample1 Name
INFO, 1, Sample1 Cross Section
INFO, 1, Sample1 Length
INFO, Ohm, Sample1 Units
INFO, , Sample2 Name
INFO, 1, Sample2 Cross Section
INFO, 1, Sample2 Length
INFO, Ohm, Sample2 Units
INFO, , Sample3 Name
INFO, 1, Sample3 Cross Section
INFO, 1, Sample3 Length
INFO, Ohm, Sample3 Units
INFO, , Sample4 Name
INFO, 1, Sample4 Cross Section
INFO, 1, Sample4 Length
INFO, Ohm, Sample4 Units
FIELDGROUP, Resistivity,2,3,4,5,6,7,8,9,10,11,12,13,14,15,16,17,18,19,20,21,22,23,24,25,26,27,28,29,30,31,32,33,34,35,36,37,38,39,40,41
STARTUPGROUP, Resistivity
STARTUPAXIS, X, 2, LINEAR, AUTO
STARTUPAXIS, Y1, 7, LINEAR, AUTO
STARTUPAXIS, Y2, 9, LINEAR, AUTO
STARTUPAXIS, Y3, 11, LINEAR, AUTO
PLOT_APPEARANCE, ALL, HORZ_GRID_ON, VERT_GRID_ON, MARKERS_AND_LINES, ALL_LINES
DATATYPE, TIME, 2
DATATYPE, COMMENT, 1
[Data]
Comment,Time Stamp (sec),Status (code),Temperature (K),Magnetic Field (Oe),Sample Position (deg),Bridge 1 Resistivity (Ohm),Bridge 1 Excitation (uA),Bridge 2 Resistivity (Ohm),Bridge 2 Excitation (uA),Bridge 3 Resistivity (Ohm),Bridge 3 Excitation (uA),Bridge 4 Resistivity (Ohm),Bridge 4 Excitation (uA),Bridge 1 Std. Dev. (Ohm),Bridge 2 Std. Dev. (Ohm),Bridge 3 Std. Dev. (Ohm),Bridge 4 Std. Dev. (Ohm),Number of Readings,Bridge 1 Resistance (Ohms),Bridge 2 Resistance (Ohms),Bridge 3 Resistance (Ohms),Bridge 4 Resistance (Ohms),Signal 1 Vin (V),Signal 2 Vin (V),Digital Inputs (code),Drive 1 Iout (mA),Drive 1 Ipower (watts),Drive 2 Iout (mA),Drive 2 Ipower (watts),Pressure (),Map 20 (),Map 21 (),Map 22 (),Map 23 (),Map 24 (),Map 25 (),Map 26 (),Map 27 (),Map 28 (),Map 29 ()
,13961635.52,4369,3.00080001354218,0.13400000333786,0,17.1190983581543,-54.9580001831055,-0.000571997762017418,-54.9580001831055,450.006948242187,-54.9580001831055,,,0.00628953874763519,0.000759991289430997,0.069816598317985,,25,17.1190983581543,-0.000571997762017418,450.006948242187,
,13961653.73,4369,2.99880003929138,0.13400000333786,0,17.0146715545654,-54.7140007019043,0.000700117499800399,-54.7140007019043,450.119088134766,-54.7140007019043,,,0.00493831093035401,0.000716174728315316,0.0556870319529446,,25,17.0146715545654,0.000700117499800399,450.119088134766,
,13961671.39,4369,3,0.13400000333786,0,16.9017806243896,-54.4700012207031,-0.000448243662540335,-54.4700012207031,450.455875244141,-54.4700012207031,,,0.00354583021095835,0.000745436767852545,0.0412451493174041,,25,16.9017806243896,-0.000448243662540335,450.455875244141,
,13961690.39,4369,2.99890005588531,0.13400000333786,0,16.7784968566895,-54.226001739502,-7.31701363110915e-005,-54.226001739502,450.357841796875,-54.226001739502,,,0.00739552727278709,0.0008150311163013,0.0494580895173427,,25,16.7784968566895,-7.31701363110915e-005,450.357841796875,
,13961707.56,4369,2.99985003471375,0.13400000333786,0,16.6116603088379,-53.9809989929199,0.000472111534909345,-53.9809989929199,450.532794189453,-53.9809989929199,,,0.013109858029336,0.000793510473904761,0.105130267832936,,25,16.6116603088379,0.000472111534909345,450.532794189453,
,13961724.30,4369,3.00045001506805,0.13400000333786,0,16.6144564819336,-53.9809989929199,-0.000562576010124758,-53.9809989929199,450.453621826172,-53.9809989929199,,,0.00970656075855478,0.00076603242280813,0.0515125594312768,,25,16.6144564819336,-0.000562576010124758,450.453621826172,
,13961742.75,4369,2.99985003471375,0.13400000333786,0,16.4101956939697,-53.7369995117188,-0.000610548319527879,-53.7369995117188,450.664105224609,-53.7369995117188,,,0.164771242848343,0.000640678965432646,0.182869652372742,,25,16.4101956939697,-0.000610548319527879,450.664105224609,
,13961760.55,4369,2.99979996681213,0.13400000333786,0,16.0368100357056,-53.4930000305176,-0.00131798543530749,-53.4930000305176,450.643638916016,-53.4930000305176,,,0.0262771727192628,0.000813948345727089,0.0685011179694347,,25,16.0368100357056,-0.00131798543530749,450.643638916016,
,13961778.00,4369,2.99919998645782,0.13400000333786,0,15.7689968109131,-53.2490005493164,0.000616151737049222,-53.2490005493164,450.744592285156,-53.2490005493164,,,0.0290561093594799,0.000980471398301626,0.057606620850097,,25,15.7689968109131,0.000616151737049222,450.744592285156,
,13961796.42,4369,2.99879992008209,0.13400000333786,0,15.6152685928345,-53.0040016174316,-0.00158930107252672,-53.0040016174316,450.866186523437,-53.0040016174316,,,0.0134145357844845,0.000845299579559783,0.0632881961997813,,25,15.6152685928345,-0.00158930107252672,450.866186523437,
,13961813.53,4369,3.00065004825592,0.13400000333786,0,15.4926636505127,-52.7599983215332,0.000833089303632733,-52.7599983215332,450.851328125,-52.7599983215332,,,0.00717025069277873,0.000861540249266876,0.0560207013345709,,25,15.4926636505127,0.000833089303632733,450.851328125,
,13961831.45,4369,3.00089991092682,0.13400000333786,0,15.4946709823608,-52.7599983215332,-0.00145501359656919,-52.7599983215332,450.914533691406,-52.7599983215332,,,0.00843406049607015,0.000787508156304522,0.0908178191650291,,25,15.4946709823608,-0.00145501359656919,450.914533691406,
,13961850.16,4369,2.99940001964569,0.13400000333786,0,15.4136096191406,-52.515998840332,0.000865907812258229,-52.515998840332,450.859827880859,-52.515998840332,,,0.00588172057075972,0.000757978175501011,0.0684684921362734,,25,15.4136096191406,0.000865907812258229,450.859827880859,
,13961868.34,4369,3.00024998188019,0.13400000333786,0,15.3329369354248,-52.2719993591309,0.000572145845217165,-52.2719993591309,451.122293701172,-52.2719993591309,,,0.00930065529907431,0.00082762857870682,0.0433887265684988,,25,15.3329369354248,0.000572145845217165,451.122293701172,
,13961885.77,4369,2.99980008602142,0.13400000333786,0,15.2568768692017,-52.0270004272461,-0.00158393183664884,-52.0270004272461,451.310625,-52.0270004272461,,,0.00548716328477854,0.000693193263246787,0.0639895564763283,,25,15.2568768692017,-0.00158393183664884,451.310625,
,13961904.25,4369,2.99965000152588,0.13400000333786,0,15.1820252609253,-51.7830009460449,-0.000940150183159858,-51.7830009460449,451.335240478516,-51.7830009460449,,,0.00350061431346164,0.00111473526082645,0.0945365934361712,,25,15.1820252609253,-0.000940150183159858,451.335240478516,
,13961921.88,4369,3.0003000497818,0.13400000333786,0,15.184627571106,-51.7830009460449,-0.00201881780172698,-51.7830009460449,451.353518066406,-51.7830009460449,,,0.0346487362611252,0.000901904301858933,0.0708085084677531,,25,15.184627571106,-0.00201881780172698,451.353518066406,
,13961940.23,4369,2.99989998340607,0.13400000333786,0,15.1049789810181,-51.5390014648438,0.000204291622503661,-51.5390014648438,451.554162597656,-51.5390014648438,,,0.00478943595118825,0.000778367104706326,0.0769262969247522,,25,15.1049789810181,0.000204291622503661,451.554162597656,
,13961958.11,4369,2.99989998340607,0.13400000333786,0,15.0380195617676,-51.2949981689453,0.000389714235207066,-51.2949981689453,451.719710693359,-51.2949981689453,,,0.00663635890056566,0.000879308410674649,0.0581514550702988,,25,15.0380195617676,0.000389714235207066,451.719710693359,
,13961975.58,4369,3.00014996528625,0.13400000333786,0,14.9518994522095,-51.0499992370605,-0.000741302600945346,-51.0499992370605,451.854290771484,-51.0499992370605,,,0.00499846314914538,0.000922501779051532,0.0579523244211362,,25,14.9518994522095,-0.000741302600945346,451.854290771484,
,13961993.56,4369,3.00100004673004,0.13400000333786,0,14.8768284606934,-50.8059997558594,-0.0014357049606042,-50.8059997558594,451.888178710938,-50.8059997558594,,,0.00525049281012812,0.00102039970551207,0.057930943453515,,25,14.8768284606934,-0.0014357049606042,451.888178710938,
,13962010.22,4369,3.00034999847412,0.13400000333786,0,14.8015176773071,-50.5620002746582,0.00105643630609848,-50.5620002746582,451.977663574219,-50.5620002746582,,,0.00453898486605014,0.00083046860886719,0.059762816863768,,25,14.8015176773071,0.00105643630609848,451.977663574219,
,13962027.28,4369,2.99994993209839,0.13400000333786,0,14.8069660186768,-50.5620002746582,-0.00131903618574142,-50.5620002746582,451.980081787109,-50.5620002746582,,,0.00505787071761149,0.000628129665083932,0.0858036246122767,,25,14.8069660186768,-0.00131903618574142,451.980081787109,
,13962045.53,4369,3.00065004825592,0.13400000333786,0,14.7215420150757,-50.318000793457,0.000846220598323271,-50.318000793457,452.007294921875,-50.318000793457,,,0.00404838849062073,0.000983447070985378,0.0571596743389288,,25,14.7215420150757,0.000846220598323271,452.007294921875,
,13962063.72,4369,2.9991500377655,0.13400000333786,0,14.6388850021362,-50.0730018615723,-0.000496807359158993,-50.0730018615723,452.024567871094,-50.0730018615723,,,0.00692195528811416,0.000884447232303634,0.0496411897716591,,25,14.6388850021362,-0.000496807359158993,452.024567871094,
,13962081.20,4369,2.9988499879837,0.13400000333786,0,14.5333945083618,-50,-0.00045484205998946,-50,452.846678466797,-50,,,0.00475974202109476,0.000818389898823194,0.0799445680928617,,25,14.5333945083618,-0.00045484205998946,452.846678466797,
,13962099.13,4369,3.0011500120163,0.13400000333786,0,14.4646957015991,-49.7799987792969,-0.000527384892629925,-49.7799987792969,452.982100830078,-49.7799987792969,,,0.0439016304871564,0.000551198507838099,0.0443296369201322,,25,14.4646957015991,-0.000527384892629925,452.982100830078,
,13962116.53,4369,3.00065004825592,0.13400000333786,0,14.3806270599365,-49.5849990844727,-0.00177604043623433,-49.5849990844727,453.102883300781,-49.5849990844727,,,0.00626690690636801,0.000845464056469088,0.117511254612805,,25,14.3806270599365,-0.00177604043623433,453.102883300781,
,13962134.33,4369,3,0.13400000333786,0,14.3005244827271,-49.3889999389648,-0.00132253868709086,-49.3889999389648,453.120524902344,-49.3889999389648,,,0.00603387770829304,0.000810605121556623,0.0466442659963072,,25,14.3005244827271,-0.00132253868709086,453.120524902344,
,13962152.27,4369,3.00040006637573,0.13400000333786,0,14.2203468704224,-49.1940002441406,0.00120384262874722,-49.1940002441406,453.272667236328,-49.1940002441406,,,0.00545486632291732,0.00100253772982061,0.0997917544195612,,25,14.2203468704224,0.00120384262874722,453.272667236328,
,13962170.83,4369,3.00014996528625,0.13400000333786,0,14.1250024032593,-48.9990005493164,0.00032704291457776,-48.9990005493164,453.296730957031,-48.9990005493164,,,0.00606461035841817,0.000869607969462598,0.0569366806041615,,25,14.1250024032593,0.00032704291457776,453.296730957031,
,13962188.09,4369,2.99970006942749,0.13400000333786,0,14.020347442627,-48.7789993286133,0.000722676693403628,-48.7789993286133,453.390462646484,-48.7789993286133,,,0.00846383189143105,0.000990120156113073,0.0516657215254857,,25,14.020347442627,0.000722676693403628,453.390462646484,
,13962205.63,4369,2.99979996681213,0.13400000333786,0,13.9321586227417,-48.5830001831055,0.0016713659837842,-48.5830001831055,453.392357177734,-48.5830001831055,,,0.00987764153816485,0.000765535625609223,0.0598453877214203,,25,13.9321586227417,0.0016713659837842,453.392357177734,
,13962222.05,4369,3.00010001659393,0.13400000333786,0,13.8387357330322,-48.3880004882813,0.000498318596801255,-48.3880004882813,453.598630371094,-48.3880004882813,,,0.0422619265055636,0.000897819417579895,0.0490987934936031,,25,13.8387357330322,0.000498318596801255,453.598630371094,
,13962240.30,4369,2.99979996681213,0.13400000333786,0,13.7259535598755,-48.1920013427734,0.000772744895366486,-48.1920013427734,453.633752441406,-48.1920013427734,,,0.0111392757248688,0.00111572381679564,0.0606838405675936,,25,13.7259535598755,0.000772744895366486,453.633752441406,
,13962257.64,4369,2.99905002117157,0.13400000333786,0,13.5918648529053,-47.9970016479492,-0.00227390183834359,-47.9970016479492,453.739711914063,-47.9970016479492,,,0.00499298069958752,0.00102165797219174,0.043943577308306,,25,13.5918648529053,-0.00227390183834359,453.739711914063,
,13962275.05,4369,2.99989998340607,0.13400000333786,0,13.4506472396851,-47.7770004272461,0.000268311696709134,-47.7770004272461,453.888619384766,-47.7770004272461,,,0.0145536822442052,0.00137848306697582,0.0549508951138472,,25,13.4506472396851,0.000268311696709134,453.888619384766,
,13962292.70,4369,2.99980008602142,0.13400000333786,0,13.2934897994995,-47.5820007324219,7.37735151778907e-005,-47.5820007324219,453.942121582031,-47.5820007324219,,,0.0126099073676215,0.000981036664230963,0.0514254622688571,,25,13.2934897994995,7.37735151778907e-005,453.942121582031,
,13962309.91,4369,3.00150001049042,0.13400000333786,0,13.0544306945801,-47.3860015869141,-8.69505788432434e-005,-47.3860015869141,454.073806152344,-47.3860015869141,,,0.025262794877902,0.000909987142676255,0.0528569956545998,,25,13.0544306945801,-8.69505788432434e-005,454.073806152344,
,13962327.81,4369,2.99950003623962,0.13400000333786,0,9.99252040863037,-47.1910018920898,-9.37874187366106e-005,-47.1910018920898,454.109781494141,-47.1910018920898,,,0.184503548383037,0.000995141410435905,0.055525707907352,,25,9.99252040863037,-9.37874187366106e-005,454.109781494141,
,13962345.86,4369,3.00024998188019,0.13400000333786,0,9.52776588439941,-46.9959983825684,0.000844385413220152,-46.9959983825684,454.207673339844,-46.9959983825684,,,0.02446926132042,0.00114176469271517,0.0696085104239066,,25,9.52776588439941,0.000844385413220152,454.207673339844,
,13962362.81,4369,3.00064992904663,0.13400000333786,0,9.38117431640625,-46.7999992370605,0.000414125907118432,-46.7999992370605,454.339404296875,-46.7999992370605,,,0.0281474297501035,0.00114476169773897,0.0588565978211224,,25,9.38117431640625,0.000414125907118432,454.339404296875,
,13962380.91,4369,3.00020003318787,0.13400000333786,0,9.24422668457031,-46.5800018310547,-0.000602910490706563,-46.5800018310547,454.400377197266,-46.5800018310547,,,0.0316806119123341,0.000929932908338267,0.0476143495703276,,25,9.24422668457031,-0.000602910490706563,454.400377197266,
,13962398.48,4369,2.99890005588531,0.13400000333786,0,9.15712169647217,-46.3849983215332,0.000664684056828264,-46.3849983215332,454.584604492188,-46.3849983215332,,,0.0428073577923862,0.00111001128651515,0.0876806754973501,,25,9.15712169647217,0.000664684056828264,454.584604492188,
,13962415.13,4369,3.0014500617981,0.13400000333786,0,9.03717407226562,-46.189998626709,0.00011895864008693,-46.189998626709,454.58673828125,-46.189998626709,,,0.0164930490733728,0.00121210911612862,0.0801376918620446,,25,9.03717407226562,0.00011895864008693,454.58673828125,
,13962434.08,4369,3.00039994716644,0.13400000333786,0,8.95670742034912,-45.9939994812012,0.000428036372177303,-45.9939994812012,454.757420654297,-45.9939994812012,,,0.0180363086028566,0.000842917866423972,0.0618311567527093,,25,8.95670742034912,0.000428036372177303,454.757420654297,
,13962451.58,4369,3.00080001354218,0.13400000333786,0,8.87724426269531,-45.798999786377,0.000286608157912269,-45.798999786377,454.854615478516,-45.798999786377,,,0.0118041997787715,0.0012740763314089,0.0494169111665218,,25,8.87724426269531,0.000286608157912269,454.854615478516,
,13962470.63,4369,3.0003000497818,0.13400000333786,0,8.78607627868652,-45.5789985656738,0.000904143955849577,-45.5789985656738,454.976774902344,-45.5789985656738,,,0.00850185050004834,0.0011607420199485,0.0611594115512244,,25,8.78607627868652,0.000904143955849577,454.976774902344,
,13962487.83,4369,3.00150001049042,0.13400000333786,0,8.71244995117187,-45.382999420166,0.00241782261116896,-45.382999420166,455.015286865234,-45.382999420166,,,0.0089969139427117,0.00107904176270925,0.0467735551925532,,25,8.71244995117187,0.00241782261116896,455.015286865234,
,13962505.23,4369,3.00065004825592,0.13400000333786,0,8.63502380371094,-45.1879997253418,5.06622053217143e-005,-45.1879997253418,455.058084716797,-45.1879997253418,,,0.0103413914438526,0.00113711275216929,0.0474257944556696,,25,8.63502380371094,5.06622053217143e-005,455.058084716797,
,13962522.56,4369,3.00010001659393,0.13400000333786,0,8.67073631286621,-44.9930000305176,-0.000586885840748437,-44.9930000305176,455.240267333984,-44.9930000305176,,,0.423858958975456,0.00108023424731109,0.0486694305200817,,25,8.67073631286621,-0.000586885840748437,455.240267333984,
,13962539.22,4369,3.00095009803772,0.13400000333786,0,8.48715930938721,-44.7970008850098,-0.00122652871592436,-44.7970008850098,455.3219140625,-44.7970008850098,,,0.00744092849944848,0.000977406304457871,0.0506039930697693,,25,8.48715930938721,-0.00122652871592436,455.3219140625,
,13962556.81,4369,2.99950003623962,0.13400000333786,0,8.4019185256958,-44.5769996643066,0.000910744422290009,-44.5769996643066,455.438549804688,-44.5769996643066,,,0.00752965278878484,0.000819538684768916,0.0510246385742508,,25,8.4019185256958,0.000910744422290009,455.438549804688,
,13962573.84,4369,3.00005006790161,0.13400000333786,0,8.32813270568848,-44.3819999694824,0.000161641860322561,-44.3819999694824,455.573864746094,-44.3819999694824,,,0.00678766202967535,0.000943215871223307,0.0627220470682991,,25,8.32813270568848,0.000161641860322561,455.573864746094,
,13962591.78,4369,2.99985003471375,0.13400000333786,0,8.24855178833008,-44.1870002746582,0.000103617992717773,-44.1870002746582,455.675789794922,-44.1870002746582,,,0.00757195585906923,0.001153841156184,0.0535453935586218,,25,8.24855178833008,0.000103617992717773,455.675789794922,
,13962608.81,4369,2.99954998493195,0.13400000333786,0,8.16617279052734,-43.9910011291504,-0.0014398223880562,-43.9910011291504,455.747111816406,-43.9910011291504,,,0.00840060822694336,0.00112983799100951,0.053786019386,,25,8.16617279052734,-0.0014398223880562,455.747111816406,
,13962626.86,4369,2.99995005130768,0.13400000333786,0,8.08363265991211,-43.7960014343262,-0.000250918080564588,-43.7960014343262,455.869561767578,-43.7960014343262,,,0.00552427549535624,0.00119263505417433,0.0443889867576762,,25,8.08363265991211,-0.000250918080564588,455.869561767578,
,13962644.84,4369,2.99970006942749,0.13400000333786,0,7.9980039024353,-43.5999984741211,0.00111301657307195,-43.5999984741211,455.937579345703,-43.5999984741211,,,0.0104248029748996,0.00085573233636317,0.0570901717507874,,25,7.9980039024353,0.00111301657307195,455.937579345703,
,13962662.50,4369,2.9996999502182,0.13400000333786,0,7.91430856704712,-43.3810005187988,-0.0011188564467011,-43.3810005187988,456.229636230469,-43.3810005187988,,,0.0177420306414869,0.000948511842898291,0.114656168748695,,25,7.91430856704712,-0.0011188564467011,456.229636230469,
,13962679.95,4369,3,0.13400000333786,0,7.81074850082397,-43.185001373291,0.00373894517309964,-43.185001373291,456.200272216797,-43.185001373291,,,0.00693612903125184,0.0010044572704653,0.0485743475346877,,25,7.81074850082397,0.00373894517309964,456.200272216797,
,13962696.81,4369,3.00015008449554,0.13400000333786,0,7.71562421798706,-42.9900016784668,0.000330182411998976,-42.9900016784668,456.331787109375,-42.9900016784668,,,0.00676196671227206,0.00110789077736546,0.114778583193218,,25,7.71562421798706,0.000330182411998976,456.331787109375,
,13962714.20,4369,3.00134992599487,0.13400000333786,0,7.62177015304565,-42.7939987182617,0.000855981115018949,-42.7939987182617,456.327946777344,-42.7939987182617,,,0.00877309625424185,0.000847017717984052,0.0827347082683719,,25,7.62177015304565,0.000855981115018949,456.327946777344,
,13962731.34,4369,3.00199997425079,0.13400000333786,0,7.50564613342285,-42.5989990234375,-0.00149046528153121,-42.5989990234375,456.386613769531,-42.5989990234375,,,0.0466437861208815,0.00125805465300586,0.068956136630537,,25,7.50564613342285,-0.00149046528153121,456.386613769531,
,13962749.03,4369,2.99979996681213,0.13400000333786,0,7.30663780212402,-42.3790016174316,-0.000136863549705595,-42.3790016174316,456.482766113281,-42.3790016174316,,,0.232903956766363,0.0011517246379283,0.0750622415624012,,25,7.30663780212402,-0.000136863549705595,456.482766113281,
,13962766.81,4369,3.00024998188019,0.13400000333786,0,7.1186060333252,-42.1839981079102,-0.000155573735828511,-42.1839981079102,456.664847412109,-42.1839981079102,,,0.353707301200434,0.00107616925769652,0.0479740723378671,,25,7.1186060333252,-0.000155573735828511,456.664847412109,
,13962785.08,4369,2.99960005283356,0.13400000333786,0,6.0874195766449,-41.9879989624023,-0.00165007662319113,-41.9879989624023,456.783321533203,-41.9879989624023,,,1.04915484850905,0.00111630377692074,0.0535994068047992,,25,6.0874195766449,-0.00165007662319113,456.783321533203,
,13962801.88,4369,2.99960005283356,0.13400000333786,0,3.34202580213547,-41.7929992675781,0.000964075390947983,-41.7929992675781,456.862592773437,-41.7929992675781,,,1.79943977734525,0.00111875107146227,0.0617625343766394,,25,3.34202580213547,0.000964075390947983,456.862592773437,
,13962819.31,4369,2.99940001964569,0.13400000333786,0,1.38407978460193,-41.5970001220703,0.000245801656856202,-41.5970001220703,456.878781738281,-41.5970001220703,,,1.383110555671,0.000838885562052526,0.0878591802428211,,25,1.38407978460193,0.000245801656856202,456.878781738281,
,13962836.66,4369,2.99985003471375,0.13400000333786,0,0.154413723126054,-41.3779983520508,-0.00269613618089352,-41.3779983520508,457.143846435547,-41.3779983520508,,,0.181186193387777,0.00139187680106346,0.044862186645221,,25,0.154413723126054,-0.00269613618089352,457.143846435547,
,13962853.80,4369,2.99899995326996,0.13400000333786,0,0.0946262354962528,-41.181999206543,-0.000144535433501005,-41.181999206543,457.209604492188,-41.181999206543,,,0.0480350111385719,0.00103506624738173,0.0686191828577509,,25,0.0946262354962528,-0.000144535433501005,457.209604492188,
,13962870.94,4369,2.99944996833801,0.13400000333786,0,0.0617988556437194,-40.9869995117188,0.000476664884481579,-40.9869995117188,457.29974609375,-40.9869995117188,,,0.0523304279132052,0.00103009985418222,0.0598968796718552,,25,0.0617988556437194,0.000476664884481579,457.29974609375,
,13962888.39,4369,3.00164997577667,0.13400000333786,0,0.0629446309804916,-40.7910003662109,-0.00123464862932451,-40.7910003662109,457.2908984375,-40.7910003662109,,,0.0445630105093029,0.00111332950556748,0.0600046566444342,,25,0.0629446309804916,-0.00123464862932451,457.2908984375,
,13962905.27,4369,2.99919998645782,0.13400000333786,0,0.0413276502446388,-40.5960006713867,0.000548879877896979,-40.5960006713867,457.432093505859,-40.5960006713867,,,0.0390999930082497,0.000974082436078992,0.0519044287900603,,25,0.0413276502446388,0.000548879877896979,457.432093505859,
,13962922.84,4369,2.9988499879837,0.13400000333786,0,0.03086367617012,-40.4010009765625,-0.00125041324528866,-40.4010009765625,457.573334960937,-40.4010009765625,,,0.0350141278129874,0.00084483397428867,0.0445283731071903,,25,0.03086367617012,-0.00125041324528866,457.573334960937,
,13962940.02,4369,2.99925005435944,0.13400000333786,0,0.0538121789321303,-40.1809997558594,-0.00057735949754715,-40.1809997558594,457.724761962891,-40.1809997558594,,,0.161484759528458,0.00110739350073289,0.0563418479273645,,25,0.0538121789321303,-0.00057735949754715,457.724761962891,
,13962957.89,4369,2.99985003471375,0.13400000333786,0,0.011138308084337,-39.9850006103516,0.00151539014885202,-39.9850006103516,457.827791748047,-39.9850006103516,,,0.0145912374239975,0.00113981298968578,0.0460588550926606,,25,0.011138308084337,0.00151539014885202,457.827791748047,
,13962976.23,4369,3.00119996070862,0.13400000333786,0,0.00309582354675513,-39.7900009155273,0.000667500972049311,-39.7900009155273,457.8854296875,-39.7900009155273,,,0.00882410292361045,0.000986839099122203,0.0542215844028942,,25,0.00309582354675513,0.000667500972049311,457.8854296875,
,13962994.48,4369,3.0005499124527,0.13400000333786,0,0.00196963648806559,-39.5950012207031,-0.00153793528210372,-39.5950012207031,457.998901367188,-39.5950012207031,,,0.00454673470320686,0.00135633694865134,0.0936802549382974,,25,0.00196963648806559,-0.00153793528210372,457.998901367188,
,13963011.81,4369,3.00020003318787,0.13400000333786,0,0.00142547249619383,-39.398998260498,0.00116207000479335,-39.398998260498,458.110390625,-39.398998260498,,,0.00526958260592387,0.000973414290070331,0.0536019769765005,,25,0.00142547249619383,0.00116207000479335,458.110390625,
,13963030.39,4369,2.99970006942749,0.13400000333786,0,-0.000112975099764299,-39.1790008544922,-0.00160112977668177,-39.1790008544922,458.261462402344,-39.1790008544922,,,0.00114200296726196,0.00106334578713737,0.0910929237148514,,25,-0.000112975099764299,-0.00160112977668177,458.261462402344,
,13963048.78,4369,3.00114989280701,0.13400000333786,0,-5.08905883179978e-005,-38.984001159668,-0.000661577560240403,-38.984001159668,458.301866455078,-38.984001159668,,,0.000949303043598056,0.000860904875028269,0.0589026489464623,,25,-5.08905883179978e-005,-0.000661577560240403,458.301866455078,
,13963066.78,4369,2.9991500377655,0.13400000333786,0,-0.000720047256909311,-38.7879981994629,-0.00101121392974164,-38.7879981994629,458.511577148437,-38.7879981994629,,,0.00141257911583152,0.00164870324474462,0.0474356336480727,,25,-0.000720047256909311,-0.00101121392974164,458.511577148437,
,13963085.84,4369,2.99879992008209,0.13400000333786,0,-0.00193768733937759,-38.5929985046387,-0.000284721404314041,-38.5929985046387,458.513605957031,-38.5929985046387,,,0.0010132228905721,0.00119006371227045,0.0411850786549272,,25,-0.00193768733937759,-0.000284721404314041,458.513605957031,
,13963103.02,4369,3.00209999084473,0.13400000333786,0,-0.00226552338222973,-38.3979988098145,-0.00170907903811894,-38.3979988098145,458.669827880859,-38.3979988098145,,,0.00139819035022263,0.00112699429099599,0.0500771395925554,,25,-0.00226552338222973,-0.00170907903811894,458.669827880859,
,13963120.98,4369,2.99994993209839,0.13400000333786,0,0.0293635565211298,-38.1780014038086,0.00221875753428321,-38.1780014038086,458.784904785156,-38.1780014038086,,,0.134861204195738,0.00111794451620071,0.0524666483695256,,25,0.0293635565211298,0.00221875753428321,458.784904785156,
,13963139.27,4369,3.00025010108948,0.13400000333786,0,0.000888138749287464,-37.9819984436035,0.00141459202452097,-37.9819984436035,458.959189453125,-37.9819984436035,,,0.000821964843803931,0.00131207602836858,0.0410320995373422,,25,0.000888138749287464,0.00141459202452097,458.959189453125,
,13963156.67,4369,3.00080001354218,0.13400000333786,0,-0.003711819187738,-37.7869987487793,-0.00242338573327288,-37.7869987487793,459.052567138672,-37.7869987487793,,,0.00135208615987909,0.00142542108582596,0.0409161597730583,,25,-0.003711819187738,-0.00242338573327288,459.052567138672,
,13963174.33,4369,2.99919998645782,0.13400000333786,0,0.000958161576418206,-37.5919990539551,-0.000381640616978984,-37.5919990539551,459.078409423828,-37.5919990539551,,,0.00107803691911289,0.00115737965509662,0.0497882426685009,,25,0.000958161576418206,-0.000381640616978984,459.078409423828,
,13963192.94,4369,3.00080001354218,0.13400000333786,0,0.000118373387376778,-37.3959999084473,-0.00108168789185584,-37.3959999084473,459.177019042969,-37.3959999084473,,,0.000823318580003161,0.0010557695882448,0.0803090881130146,,25,0.000118373387376778,-0.00108168789185584,459.177019042969,
,13963209.89,4369,2.99940001964569,0.13400000333786,0,-0.00122266451217001,-37.201000213623,0.000578509045590181,-37.201000213623,459.339149169922,-37.201000213623,,,0.00095691756529114,0.00114178657961775,0.0832505561621914,,25,-0.00122266451217001,0.000578509045590181,459.339149169922,
,13963227.91,4369,3.00039994716644,0.13400000333786,0,-0.00250519742490724,-36.9809989929199,-0.000647967041586526,-36.9809989929199,459.418524169922,-36.9809989929199,,,0.00104716539537646,0.00134988394224636,0.0761708168191646,,25,-0.00250519742490724,-0.000647967041586526,459.418524169922,
,13963245.02,4369,2.99865007400513,0.13400000333786,0,0.0184591462922981,-36.7859992980957,0.000825661895796657,-36.7859992980957,459.564343261719,-36.7859992980957,,,0.0886179683749594,0.00107013444109321,0.0674585706080788,,25,0.0184591462922981,0.000825661895796657,459.564343261719,
,13963263.88,4369,2.99950003623962,0.13400000333786,0,0.000375414536392782,-36.5900001525879,0.000863453422789462,-36.5900001525879,459.709879150391,-36.5900001525879,,,0.00112469765336701,0.00118698910087091,0.0811220273179059,,25,0.000375414536392782,0.000863453422789462,459.709879150391,
,13963280.94,4369,2.99820005893707,0.13400000333786,0,0.000570347122848034,-36.3950004577637,0.000171942880260758,-36.3950004577637,459.8258984375,-36.3950004577637,,,0.000932612129971266,0.00105005810354384,0.0386837121308428,,25,0.000570347122848034,0.000171942880260758,459.8258984375,
,13963299.92,4369,3.00125002861023,0.13400000333786,0,0.156002221184317,-36.1990013122559,0.00118921486660838,-36.1990013122559,459.905428466797,-36.1990013122559,,,0.519396151244666,0.00115046538814205,0.0468425001663149,,25,0.156002221184317,0.00118921486660838,459.905428466797,
,13963317.70,4369,3.00019991397858,0.13400000333786,0,0.000309664816886652,-35.9790000915527,-0.00146348439273424,-35.9790000915527,460.092712402344,-35.9790000915527,,,0.00118431140882323,0.00104726323411892,0.0573594110091339,,25,0.000309664816886652,-0.00146348439273424,460.092712402344,
,13963336.22,4369,3.00020003318787,0.13400000333786,0,-0.0018638771714177,-35.7840003967285,0.000157811100361869,-35.7840003967285,460.143747558594,-35.7840003967285,,,0.00114331887374864,0.00162303965457609,0.0551142740070998,,25,-0.0018638771714177,0.000157811100361869,460.143747558594,
,13963355.28,4369,3.00034999847412,0.13400000333786,0,0.000227292240597308,-35.5890007019043,-0.000733339082798921,-35.5890007019043,460.236309814453,-35.5890007019043,,,0.00169446434679083,0.00154615728485606,0.0843332111623949,,25,0.000227292240597308,-0.000733339082798921,460.236309814453,
,13963372.73,4369,2.99995005130768,0.13400000333786,0,0.000543413806008175,-35.3930015563965,-0.000414029554231092,-35.3930015563965,460.365280761719,-35.3930015563965,,,0.00124231332630254,0.00109645453069692,0.0570535572990924,,25,0.000543413806008175,-0.000414029554231092,460.365280761719,
,13963390.84,4369,3.00010001659393,0.13400000333786,0,0.00105790284695104,-35.1980018615723,0.00191636499017477,-35.1980018615723,460.409141845703,-35.1980018615723,,,0.00130404884537933,0.00141249630683137,0.0393166177686382,,25,0.00105790284695104,0.00191636499017477,460.409141845703,
,13963407.31,4369,3.00065004825592,0.13400000333786,0,-0.00127842920366675,-34.9780006408691,-0.000383965095388703,-34.9780006408691,460.570538330078,-34.9780006408691,,,0.00121918003531617,0.00120685976419571,0.0677845125208604,,25,-0.00127842920366675,-0.000383965095388703,460.570538330078,