File: icepp/data/250309/250309_3D_mh_photolitho_IV_plus_fineUp1.dat
[Header]
TITLE, IV scan 35 to 55 (0.1 scan)
FILEOPENTIME,13955921.88,3/9/2025,11:50 AM
BYAPP, Resistivity, 2.1, 1.0
INFO, APPNAME, PPMS MultiVu Application, 1.5.11
INFO, , Sample1 Name
INFO, 1, Sample1 Cross Section
INFO, 1, Sample1 Length
INFO, Ohm, Sample1 Units
INFO, , Sample2 Name
INFO, 1, Sample2 Cross Section
INFO, 1, Sample2 Length
INFO, Ohm, Sample2 Units
INFO, , Sample3 Name
INFO, 1, Sample3 Cross Section
INFO, 1, Sample3 Length
INFO, Ohm, Sample3 Units
INFO, , Sample4 Name
INFO, 1, Sample4 Cross Section
INFO, 1, Sample4 Length
INFO, Ohm, Sample4 Units
FIELDGROUP, Resistivity,2,3,4,5,6,7,8,9,10,11,12,13,14,15,16,17,18,19,20,21,22,23,24,25,26,27,28,29,30,31,32,33,34,35,36,37,38,39,40,41
STARTUPGROUP, Resistivity
STARTUPAXIS, X, 2, LINEAR, AUTO
STARTUPAXIS, Y1, 7, LINEAR, AUTO
STARTUPAXIS, Y2, 9, LINEAR, AUTO
STARTUPAXIS, Y3, 11, LINEAR, AUTO
PLOT_APPEARANCE, ALL, HORZ_GRID_ON, VERT_GRID_ON, MARKERS_AND_LINES, ALL_LINES
DATATYPE, TIME, 2
DATATYPE, COMMENT, 1
[Data]
Comment,Time Stamp (sec),Status (code),Temperature (K),Magnetic Field (Oe),Sample Position (deg),Bridge 1 Resistivity (Ohm),Bridge 1 Excitation (uA),Bridge 2 Resistivity (Ohm),Bridge 2 Excitation (uA),Bridge 3 Resistivity (Ohm),Bridge 3 Excitation (uA),Bridge 4 Resistivity (Ohm),Bridge 4 Excitation (uA),Bridge 1 Std. Dev. (Ohm),Bridge 2 Std. Dev. (Ohm),Bridge 3 Std. Dev. (Ohm),Bridge 4 Std. Dev. (Ohm),Number of Readings,Bridge 1 Resistance (Ohms),Bridge 2 Resistance (Ohms),Bridge 3 Resistance (Ohms),Bridge 4 Resistance (Ohms),Signal 1 Vin (V),Signal 2 Vin (V),Digital Inputs (code),Drive 1 Iout (mA),Drive 1 Ipower (watts),Drive 2 Iout (mA),Drive 2 Ipower (watts),Pressure (),Map 20 (),Map 21 (),Map 22 (),Map 23 (),Map 24 (),Map 25 (),Map 26 (),Map 27 (),Map 28 (),Map 29 ()
,13956342.66,4369,2.99975001811981,0.13400000333786,0,0.0393358914589044,34.9780006408691,-0.000510515703936107,34.9780006408691,462.096613769531,34.9780006408691,,,0.138752565286877,0.00131652716483197,0.0581480146465196,,25,0.0393358914589044,-0.000510515703936107,462.096613769531,
,13956359.88,4369,3.00029993057251,0.13400000333786,0,-0.000320860269712284,35.1980018615723,0.000476954447512981,35.1980018615723,461.860435791016,35.1980018615723,,,0.00141284108249512,0.0013521629338523,0.0445409992331316,,25,-0.000320860269712284,0.000476954447512981,461.860435791016,
,13956378.33,4369,2.99989998340607,0.13400000333786,0,0.0035447268281132,35.3930015563965,0.0044373769685626,35.3930015563965,461.806524658203,35.3930015563965,,,0.00134317515178774,0.00120501370276752,0.0370188989663526,,25,0.0035447268281132,0.0044373769685626,461.806524658203,
,13956396.25,4369,2.99930000305176,0.13400000333786,0,-0.000849038385786116,35.5890007019043,-0.000583177881198935,35.5890007019043,461.701827392578,35.5890007019043,,,0.00141243671631892,0.00103318529122684,0.0526695664514034,,25,-0.000849038385786116,-0.000583177881198935,461.701827392578,
,13956414.72,4369,3.00164997577667,0.13400000333786,0,-0.000814590041991323,35.7840003967285,0.000234567808220163,35.7840003967285,461.518549804688,35.7840003967285,,,0.00110635345433952,0.00111988354515893,0.0656221227887925,,25,-0.000814590041991323,0.000234567808220163,461.518549804688,
,13956432.33,4369,3.00034999847412,0.13400000333786,0,0.00325327384984121,35.9790000915527,4.66571145807393e-005,35.9790000915527,461.387396240234,35.9790000915527,,,0.00123214117117082,0.00137084318119284,0.0445124615934293,,25,0.00325327384984121,4.66571145807393e-005,461.387396240234,
,13956450.08,4369,3.00099992752075,0.13400000333786,0,-0.00199438169598579,36.1990013122559,-0.00167393133277074,36.1990013122559,461.311484375,36.1990013122559,,,0.00115469210568593,0.000883605725107896,0.0448576186444416,,25,-0.00199438169598579,-0.00167393133277074,461.311484375,
,13956467.63,4369,2.99965000152588,0.13400000333786,0,0.00382080793380737,36.3950004577637,-4.19408082962036e-006,36.3950004577637,461.240406494141,36.3950004577637,,,0.0160749366690614,0.00143044597463968,0.0498003060737076,,25,0.00382080793380737,-4.19408082962036e-006,461.240406494141,
,13956485.69,4369,2.99870002269745,0.13400000333786,0,0.00184392353752628,36.5900001525879,5.42330386815593e-005,36.5900001525879,461.128037109375,36.5900001525879,,,0.00114542324641192,0.00113604041286915,0.0527494977861571,,25,0.00184392353752628,5.42330386815593e-005,461.128037109375,
,13956504.20,4369,2.99880003929138,0.13400000333786,0,0.00199965779756894,36.7859992980957,0.00168021039455198,36.7859992980957,460.998758544922,36.7859992980957,,,0.00130782430435197,0.00110622493409614,0.0584972901393106,,25,0.00199965779756894,0.00168021039455198,460.998758544922,
,13956520.92,4369,2.9996999502182,0.13400000333786,0,0.0738363133696839,36.9809989929199,0.001060641266522,36.9809989929199,460.929342041016,36.9809989929199,,,0.265602526584874,0.00125467857413676,0.068587676142355,,25,0.0738363133696839,0.001060641266522,460.929342041016,
,13956537.52,4369,2.9991500377655,0.13400000333786,0,-0.000131275330204517,37.201000213623,0.000853289600345306,37.201000213623,460.760385742188,37.201000213623,,,0.00107271650565503,0.00143837678169123,0.0466999022155806,,25,-0.000131275330204517,0.000853289600345306,460.760385742188,
,13956554.81,4369,2.99995005130768,0.13400000333786,0,-0.000367262645740993,37.3959999084473,0.00155882590217516,37.3959999084473,460.623841552734,37.3959999084473,,,0.001073075650114,0.00122370548306662,0.0490045210353895,,25,-0.000367262645740993,0.00155882590217516,460.623841552734,
,13956572.52,4369,3.00010001659393,0.13400000333786,0,0.000495197674026713,37.5919990539551,0.000657557565718889,37.5919990539551,460.560184326172,37.5919990539551,,,0.000913644140517222,0.00106741596603731,0.0571309653750635,,25,0.000495197674026713,0.000657557565718889,460.560184326172,
,13956590.89,4369,3.00024998188019,0.13400000333786,0,0.000516975881764665,37.7869987487793,-0.000880474565783516,37.7869987487793,460.489599609375,37.7869987487793,,,0.00137746334158121,0.00149042667077593,0.0490832995469268,,25,0.000516975881764665,-0.000880474565783516,460.489599609375,
,13956608.33,4369,2.99919998645782,0.13400000333786,0,0.00145859272684902,37.9819984436035,0.00160324653901625,37.9819984436035,460.317897949219,37.9819984436035,,,0.00104438200752728,0.00112310318209329,0.0393812980297047,,25,0.00145859272684902,0.00160324653901625,460.317897949219,
,13956625.22,4369,3.00164997577667,0.13400000333786,0,0.0020584870793391,38.1780014038086,0.00037172679323703,38.1780014038086,460.204287109375,38.1780014038086,,,0.0012080786196664,0.00107309025171502,0.0481897927837062,,25,0.0020584870793391,0.00037172679323703,460.204287109375,
,13956642.61,4369,3.00010001659393,0.13400000333786,0,0.0425960695330286,38.3979988098145,0.000882449329947121,38.3979988098145,460.096333007813,38.3979988098145,,,0.159386648537654,0.00107850685596259,0.0576548067124015,,25,0.0425960695330286,0.000882449329947121,460.096333007813,
,13956660.11,4369,3.00119996070862,0.13400000333786,0,0.00222627534007188,38.5929985046387,-0.00196133673249278,38.5929985046387,460.027211914062,38.5929985046387,,,0.00350331588344411,0.00105391021967377,0.0467492141317922,,25,0.00222627534007188,-0.00196133673249278,460.027211914062,
,13956677.42,4369,2.99940001964569,0.13400000333786,0,0.00692908085620729,38.7879981994629,-0.00087744750053389,38.7879981994629,459.944201660156,38.7879981994629,,,0.0110595680199504,0.000928182238255044,0.0453295437615385,,25,0.00692908085620729,-0.00087744750053389,459.944201660156,
,13956694.67,4369,2.99965000152588,0.13400000333786,0,0.0055787456582766,38.984001159668,-0.00040715056413319,38.984001159668,459.792692871094,38.984001159668,,,0.00801185009305407,0.00131067044315633,0.0479074955307171,,25,0.0055787456582766,-0.00040715056413319,459.792692871094,
,13956712.39,4369,2.99919998645782,0.13400000333786,0,0.00793783716275357,39.1790008544922,5.84237140719779e-005,39.1790008544922,459.641345214844,39.1790008544922,,,0.0151430102952912,0.00142177745064884,0.0438801610313329,,25,0.00793783716275357,5.84237140719779e-005,459.641345214844,
,13956729.78,4369,2.9996999502182,0.13400000333786,0,0.0173692430983647,39.398998260498,-0.00116595495666843,39.398998260498,459.5742578125,39.398998260498,,,0.0213770670881745,0.00122967268920275,0.0506113124964127,,25,0.0173692430983647,-0.00116595495666843,459.5742578125,
,13956746.53,4369,2.9996999502182,0.13400000333786,0,0.0273478903993964,39.5950012207031,-0.000967487031593919,39.5950012207031,459.427906494141,39.5950012207031,,,0.0338013058639472,0.00153492592856854,0.044354651286417,,25,0.0273478903993964,-0.000967487031593919,459.427906494141,
,13956763.45,4369,2.99974989891052,0.13400000333786,0,0.124862624621601,39.7900009155273,0.00157650959677994,39.7900009155273,459.359650878906,39.7900009155273,,,0.272021195413543,0.000958978116656653,0.0897634833774909,,25,0.124862624621601,0.00157650959677994,459.359650878906,
,13956781.31,4369,3.00010001659393,0.13400000333786,0,0.0375915567280026,39.9850006103516,0.00268347502453253,39.9850006103516,459.240739746094,39.9850006103516,,,0.0348683509691225,0.00106173787349209,0.0534562093341759,,25,0.0375915567280026,0.00268347502453253,459.240739746094,
,13956798.95,4369,2.99924993515015,0.13400000333786,0,0.0570736705884337,40.1809997558594,0.0013179320198833,40.1809997558594,459.086644287109,40.1809997558594,,,0.0454225600514933,0.00104888777512762,0.0553689217330661,,25,0.0570736705884337,0.0013179320198833,459.086644287109,
,13956815.73,4369,3.00085008144379,0.13400000333786,0,0.0508395739062689,40.4010009765625,-0.000687531845760532,40.4010009765625,459.008181152344,40.4010009765625,,,0.0447049549826229,0.00117031495664635,0.0526798601745055,,25,0.0508395739062689,-0.000687531845760532,459.008181152344,
,13956834.14,4369,2.99889993667603,0.13400000333786,0,0.0898588596656918,40.5960006713867,0.000127827345859259,40.5960006713867,458.944727783203,40.5960006713867,,,0.0489243121152435,0.00113938431683681,0.0493988413936372,,25,0.0898588596656918,0.000127827345859259,458.944727783203,
,13956852.11,4369,2.9996999502182,0.13400000333786,0,0.140076314508915,40.7910003662109,0.000950278701493517,40.7910003662109,458.814930419922,40.7910003662109,,,0.0791090414059479,0.0010457727073792,0.0434746760004473,,25,0.140076314508915,0.000950278701493517,458.814930419922,
,13956869.38,4369,3.00005006790161,0.13400000333786,0,1.86078750103712,40.9869995117188,0.000707569101068657,40.9869995117188,458.672495117188,40.9869995117188,,,1.18708297725616,0.00102529741571357,0.0327873866872297,,25,1.86078750103712,0.000707569101068657,458.672495117188,
,13956886.83,4369,2.99979996681213,0.13400000333786,0,5.83677569389343,41.181999206543,0.000922692029271275,41.181999206543,458.5882421875,41.181999206543,,,0.816129032254353,0.00138464188706174,0.0414890704566575,,25,5.83677569389343,0.000922692029271275,458.5882421875,
,13956903.67,4369,2.9991500377655,0.13400000333786,0,6.37580505371094,41.3779983520508,0.000468403489794582,41.3779983520508,458.443345947266,41.3779983520508,,,0.358398722968872,0.00121708910118203,0.0366150374172979,,25,6.37580505371094,0.000468403489794582,458.443345947266,
,13956920.20,4369,2.99919998645782,0.13400000333786,0,6.7249462890625,41.5970001220703,0.000854908647015691,41.5970001220703,458.374739990234,41.5970001220703,,,0.0286867766943232,0.00114266338500526,0.0528968718106475,,25,6.7249462890625,0.000854908647015691,458.374739990234,
,13956937.38,4369,3.00129997730255,0.13400000333786,0,6.90369939804077,41.7929992675781,-0.000905770601239055,41.7929992675781,458.256545410156,41.7929992675781,,,0.0232426889056974,0.00087766241225876,0.0598023962013929,,25,6.90369939804077,-0.000905770601239055,458.256545410156,
,13956954.31,4369,2.99960005283356,0.13400000333786,0,7.04646814346313,41.9879989624023,0.00205000535876025,41.9879989624023,458.152075195312,41.9879989624023,,,0.0246220855337274,0.000911260136301147,0.0521730810775314,,25,7.04646814346313,0.00205000535876025,458.152075195312,
,13956971.25,4369,2.99954998493195,0.13400000333786,0,7.18837856292725,42.1839981079102,0.000463073868304491,42.1839981079102,458.052932128906,42.1839981079102,,,0.0176691874576149,0.0010281455291121,0.0502267976269697,,25,7.18837856292725,0.000463073868304491,458.052932128906,
,13956988.14,4369,2.9991500377655,0.13400000333786,0,7.31492919921875,42.3790016174316,-0.00276916286675259,42.3790016174316,457.950174560547,42.3790016174316,,,0.0133613723019831,0.00105087292678027,0.037417841824136,,25,7.31492919921875,-0.00276916286675259,457.950174560547,
,13957005.45,4369,3.00029993057251,0.13400000333786,0,7.44560894012451,42.5989990234375,-0.00211383345071226,42.5989990234375,457.841539306641,42.5989990234375,,,0.0127126452993277,0.000809103067308208,0.0451034344316569,,25,7.44560894012451,-0.00211383345071226,457.841539306641,
,13957021.22,4369,3.00014996528625,0.13400000333786,0,7.55961881637573,42.7939987182617,0.00140143169352086,42.7939987182617,457.693679199219,42.7939987182617,,,0.00851667016190219,0.000802354320847418,0.0410654593326293,,25,7.55961881637573,0.00140143169352086,457.693679199219,
,13957038.25,4369,3.00080001354218,0.13400000333786,0,7.66767255783081,42.9900016784668,-0.000291119516186882,42.9900016784668,457.607202148438,42.9900016784668,,,0.0128772748991496,0.000778028809877325,0.0501964415894515,,25,7.66767255783081,-0.000291119516186882,457.607202148438,
,13957056.23,4369,2.99955010414124,0.13400000333786,0,7.76953611373901,43.185001373291,-0.000675036868196912,43.185001373291,457.494293212891,43.185001373291,,,0.0137213587426351,0.00106170358867578,0.044494925211481,,25,7.76953611373901,-0.000675036868196912,457.494293212891,
,13957073.56,4369,3.00034999847412,0.13400000333786,0,7.86260147094727,43.3810005187988,-0.000179440029605757,43.3810005187988,457.438371582031,43.3810005187988,,,0.00945492138007765,0.00109226775961235,0.0444418292352171,,25,7.86260147094727,-0.000179440029605757,457.438371582031,
,13957090.38,4369,2.99925005435944,0.13400000333786,0,7.96094434738159,43.5999984741211,-0.00144906596979126,43.5999984741211,457.298527832031,43.5999984741211,,,0.0067228127460173,0.000770464503449946,0.0351164778275965,,25,7.96094434738159,-0.00144906596979126,457.298527832031,
,13957108.06,4369,2.99880003929138,0.13400000333786,0,8.05080963134766,43.7960014343262,-0.00145678217755631,43.7960014343262,457.231151123047,43.7960014343262,,,0.0105522946783249,0.00096850107532234,0.0443867538707654,,25,8.05080963134766,-0.00145678217755631,457.231151123047,
,13957124.70,4369,3.00019991397858,0.13400000333786,0,8.25902462005615,43.9910011291504,0.00245282770367339,43.9910011291504,457.092602539063,43.9910011291504,,,0.553537000161237,0.000991201399483672,0.0593984709346136,,25,8.25902462005615,0.00245282770367339,457.092602539063,
,13957141.30,4369,3.00139999389648,0.13400000333786,0,8.21211483001709,44.1870002746582,0.00290142909623683,44.1870002746582,457.026044921875,44.1870002746582,,,0.0088339293267733,0.000810790178553148,0.0455791800812772,,25,8.21211483001709,0.00290142909623683,457.026044921875,
,13957158.34,4369,2.99965000152588,0.13400000333786,0,8.29058753967285,44.3819999694824,-0.00053642574173864,44.3819999694824,456.9070703125,44.3819999694824,,,0.00742623305723116,0.000868986584467825,0.0378651454635444,,25,8.29058753967285,-0.00053642574173864,456.9070703125,
,13957176.13,4369,2.99970006942749,0.13400000333786,0,8.36519874572754,44.5769996643066,0.000393724390305579,44.5769996643066,456.743642578125,44.5769996643066,,,0.00492250887441654,0.000975000645035094,0.0438186904142537,,25,8.36519874572754,0.000393724390305579,456.743642578125,
,13957192.89,4369,3.00029993057251,0.13400000333786,0,8.45375019073486,44.7970008850098,-0.000119245848618448,44.7970008850098,456.637415771484,44.7970008850098,,,0.00480052866078893,0.00120937362085161,0.0452081132924892,,25,8.45375019073486,-0.000119245848618448,456.637415771484,
,13957210.48,4369,2.99979996681213,0.13400000333786,0,8.52399551391601,44.9930000305176,9.49796359054744e-005,44.9930000305176,456.632203369141,44.9930000305176,,,0.0056014176788764,0.0012077411863458,0.0589752086229795,,25,8.52399551391601,9.49796359054744e-005,456.632203369141,
,13957228.34,4369,2.99940001964569,0.13400000333786,0,8.60141796112061,45.1879997253418,1.01341464323923e-005,45.1879997253418,456.539886474609,45.1879997253418,,,0.00487166013316501,0.000979145192069288,0.0435009483975735,,25,8.60141796112061,1.01341464323923e-005,456.539886474609,
,13957245.95,4369,3.00090003013611,0.13400000333786,0,8.67773769378662,45.382999420166,-0.000174866327433847,45.382999420166,456.374686279297,45.382999420166,,,0.00853287441472145,0.000853691225465353,0.0426135950580491,,25,8.67773769378662,-0.000174866327433847,456.374686279297,
,13957263.36,4369,2.99940001964569,0.13400000333786,0,8.751090965271,45.5789985656738,0.000934246887918562,45.5789985656738,456.269749755859,45.5789985656738,,,0.00685074010523315,0.00100391896729613,0.0525106542811648,,25,8.751090965271,0.000934246887918562,456.269749755859,
,13957280.31,4369,2.99890005588531,0.13400000333786,0,8.83618301391602,45.798999786377,-0.00074973126873374,45.798999786377,456.166888427734,45.798999786377,,,0.0119169437953466,0.000718923934491623,0.0404677207406942,,25,8.83618301391602,-0.00074973126873374,456.166888427734,
,13957297.36,4369,2.99899995326996,0.13400000333786,0,8.91382434844971,45.9939994812012,3.31822130829096e-005,45.9939994812012,456.124594726563,45.9939994812012,,,0.0137736485535459,0.000991032262941205,0.0421754071748901,,25,8.91382434844971,3.31822130829096e-005,456.124594726563,
,13957314.25,4369,2.99949991703033,0.13400000333786,0,8.99478912353516,46.189998626709,0.00146050518145785,46.189998626709,455.967043457031,46.189998626709,,,0.0160917591910651,0.000938016826197929,0.124325899118865,,25,8.99478912353516,0.00146050518145785,455.967043457031,
,13957331.45,4369,3.0008499622345,0.13400000333786,0,9.08194087982178,46.3849983215332,0.00046390921343118,46.3849983215332,455.906235351562,46.3849983215332,,,0.0197382734907636,0.00119940697705876,0.0362070551635634,,25,9.08194087982178,0.00046390921343118,455.906235351562,
,13957348.77,4369,3.00044989585876,0.13400000333786,0,9.18169910430908,46.5800018310547,-0.000891123995534144,46.5800018310547,455.899871826172,46.5800018310547,,,0.0257201550587937,0.00105814381290526,0.0424828364271484,,25,9.18169910430908,-0.000891123995534144,455.899871826172,
,13957367.53,4369,3.00004994869232,0.13400000333786,0,9.30871383666992,46.7999992370605,0.00112510685896268,46.7999992370605,455.721643066406,46.7999992370605,,,0.0245850674827335,0.00075677630737201,0.0445202853560562,,25,9.30871383666992,0.00112510685896268,455.721643066406,
,13957385.05,4369,3.00014996528625,0.13400000333786,0,9.44181285858154,46.9959983825684,-0.00321192538365722,46.9959983825684,455.608532714844,46.9959983825684,,,0.0222552158426312,0.000908784989524026,0.0372834651276503,,25,9.44181285858154,-0.00321192538365722,455.608532714844,
,13957401.19,4369,2.99870002269745,0.13400000333786,0,9.59958824157715,47.1910018920898,0.00161715461057611,47.1910018920898,455.563955078125,47.1910018920898,,,0.0184130634492684,0.000845572397931408,0.0416052013443376,,25,9.59958824157715,0.00161715461057611,455.563955078125,
,13957418.30,4369,3.00004994869232,0.13400000333786,0,10.5120909118652,47.3860015869141,0.00169741965160938,47.3860015869141,455.472449951172,47.3860015869141,,,0.257624340042834,0.000961947356862243,0.0344383394314864,,25,10.5120909118652,0.00169741965160938,455.472449951172,
,13957435.38,4369,3.00034999847412,0.13400000333786,0,13.2310313415527,47.5820007324219,0.00117070185020566,47.5820007324219,455.379604492188,47.5820007324219,,,0.0159982022420979,0.00109357841327672,0.0586490032827573,,25,13.2310313415527,0.00117070185020566,455.379604492188,
,13957452.53,4369,2.99905002117157,0.13400000333786,0,13.4272677993774,47.7770004272461,0.000760274055064656,47.7770004272461,455.251678466797,47.7770004272461,,,0.0136955958737679,0.00113303647174232,0.0519054518128855,,25,13.4272677993774,0.000760274055064656,455.251678466797,
,13957469.88,4369,2.99910008907318,0.13400000333786,0,13.5732094573975,47.9970016479492,0.00126562157704029,47.9970016479492,455.0558203125,47.9970016479492,,,0.00790190451053703,0.000973117792840007,0.0421336806469755,,25,13.5732094573975,0.00126562157704029,455.0558203125,
,13957486.73,4369,3.00045001506805,0.13400000333786,0,13.6903050994873,48.1920013427734,0.000769520001194905,48.1920013427734,455.045541992188,48.1920013427734,,,0.00673512844204395,0.000748559451035781,0.0362233348176044,,25,13.6903050994873,0.000769520001194905,455.045541992188,
,13957505.39,4369,3.00090003013611,0.13400000333786,0,13.8069190216064,48.3880004882813,-0.000839047213084996,48.3880004882813,454.904074707031,48.3880004882813,,,0.0066495566221555,0.000815217505412112,0.0494948801256216,,25,13.8069190216064,-0.000839047213084996,454.904074707031,
,13957522.61,4369,3,0.13400000333786,0,13.9100124740601,48.5830001831055,0.00410589890554547,48.5830001831055,454.796977539062,48.5830001831055,,,0.00583276153760448,0.000919790568892845,0.0472523389075691,,25,13.9100124740601,0.00410589890554547,454.796977539062,
,13957539.06,4369,2.99965000152588,0.13400000333786,0,14.0180160522461,48.7789993286133,0.000741502581804525,48.7789993286133,454.706989746094,48.7789993286133,,,0.0516001737784,0.000719982453361382,0.0361347000653597,,25,14.0180160522461,0.000741502581804525,454.706989746094,
,13957556.17,4369,2.99909996986389,0.13400000333786,0,14.112282409668,48.9990005493164,0.00108395606803242,48.9990005493164,454.608646240234,48.9990005493164,,,0.00562120590236378,0.00111241249967675,0.035748806878553,,25,14.112282409668,0.00108395606803242,454.608646240234,
,13957573.64,4369,2.99919998645782,0.13400000333786,0,14.200563621521,49.1940002441406,-0.000490194132435136,49.1940002441406,454.573359375,49.1940002441406,,,0.00500222269123885,0.00101122284552542,0.0352327446748047,,25,14.200563621521,-0.000490194132435136,454.573359375,
,13957590.97,4369,2.99979996681213,0.13400000333786,0,14.276781539917,49.3889999389648,0.000386237589991651,49.3889999389648,454.476937255859,49.3889999389648,,,0.00510752289141326,0.000956372945618829,0.0412770536985086,,25,14.276781539917,0.000386237589991651,454.476937255859,
,13957607.39,4369,2.99985003471375,0.13400000333786,0,14.3640997695923,49.5849990844727,-0.000264687640010379,49.5849990844727,454.38587890625,49.5849990844727,,,0.00551428331776938,0.000823288728317398,0.0430731916299314,,25,14.3640997695923,-0.000264687640010379,454.38587890625,
,13957625.22,4369,3.00160002708435,0.13400000333786,0,14.441097869873,49.7799987792969,-2.75925520691089e-005,49.7799987792969,454.381431884766,49.7799987792969,,,0.00495079153843301,0.000928620300961499,0.0389095291418041,,25,14.441097869873,-2.75925520691089e-005,454.381431884766,
,13957643.22,4369,3.00020003318787,0.13400000333786,0,14.5233501052856,50,-0.000341860761400312,50,454.247878417969,50,,,0.0035232446153483,0.000979155317003275,0.0660742122176266,,25,14.5233501052856,-0.000341860761400312,454.247878417969,
,13957660.75,4369,2.99984991550446,0.13400000333786,0,14.4775532913208,50.0730018615723,0.000283419936313294,50.0730018615723,454.527142333984,50.0730018615723,,,0.0582199746750048,0.000804431478109453,0.0416563327492742,,25,14.4775532913208,0.000283419936313294,454.527142333984,
,13957678.89,4369,3.00015008449554,0.13400000333786,0,14.5566351699829,50.318000793457,-0.00105830538930604,50.318000793457,454.534790039063,50.318000793457,,,0.00442560017206754,0.000792052865011328,0.0467949039517985,,25,14.5566351699829,-0.00105830538930604,454.534790039063,
,13957697.28,4369,2.99940001964569,0.13400000333786,0,14.6398636245728,50.5620002746582,-0.0012583361857105,50.5620002746582,454.258469238281,50.5620002746582,,,0.00551789269361856,0.000880733974781586,0.0418841165516547,,25,14.6398636245728,-0.0012583361857105,454.258469238281,
,13957713.89,4369,2.99994993209839,0.13400000333786,0,14.6432585144043,50.5620002746582,-0.000624641700414941,50.5620002746582,454.047806396484,50.5620002746582,,,0.00318029853767245,0.000780361386437001,0.0670675549120072,,25,14.6432585144043,-0.000624641700414941,454.047806396484,
,13957730.58,4369,3.00014996528625,0.13400000333786,0,14.7241760253906,50.8059997558594,-0.00149558531586081,50.8059997558594,454.119411621094,50.8059997558594,,,0.00635615629212054,0.00104118252095054,0.062065817812076,,25,14.7241760253906,-0.00149558531586081,454.119411621094,
,13957747.47,4369,2.99919998645782,0.13400000333786,0,14.7981729507446,51.0499992370605,0.00118959112674929,51.0499992370605,454.037821044922,51.0499992370605,,,0.00398924901532783,0.000812778097274907,0.0353539668070418,,25,14.7981729507446,0.00118959112674929,454.037821044922,
,13957765.45,4369,3.00055003166199,0.13400000333786,0,14.8774800491333,51.2949981689453,-0.000743687957874499,51.2949981689453,453.604085693359,51.2949981689453,,,0.0058596981818485,0.000817921533501824,0.0356941579867673,,25,14.8774800491333,-0.000743687957874499,453.604085693359,
,13957782.13,4369,2.9996999502182,0.13400000333786,0,14.9618454360962,51.5390014648438,-0.000828941921936348,51.5390014648438,453.825186767578,51.5390014648438,,,0.0635578550780431,0.000856758614144467,0.0462877073295819,,25,14.9618454360962,-0.000828941921936348,453.825186767578,
,13957799.63,4369,3.00045001506805,0.13400000333786,0,15.020584564209,51.7830009460449,-0.00103134172037244,51.7830009460449,453.670880126953,51.7830009460449,,,0.00399953412534488,0.000808328317466507,0.0413526482033942,,25,15.020584564209,-0.00103134172037244,453.670880126953,
,13957818.14,4369,2.99899995326996,0.13400000333786,0,15.0199127578735,51.7830009460449,0.00212751065846533,51.7830009460449,453.672941894531,51.7830009460449,,,0.00438825371699333,0.000950352308957393,0.0371466029553542,,25,15.0199127578735,0.00212751065846533,453.672941894531,
,13957835.47,4369,3.00124990940094,0.13400000333786,0,15.0878777313232,52.0270004272461,0.00123176188149955,52.0270004272461,453.561094970703,52.0270004272461,,,0.00413750001630142,0.000612028363666543,0.0378205101069682,,25,15.0878777313232,0.00123176188149955,453.561094970703,
,13957852.47,4369,3.00194990634918,0.13400000333786,0,15.1586423492432,52.2719993591309,-0.00164344780845568,52.2719993591309,453.451092529297,52.2719993591309,,,0.0044872293585894,0.000573554822718269,0.0478683504268347,,25,15.1586423492432,-0.00164344780845568,453.451092529297,
,13957870.13,4369,2.99979996681213,0.13400000333786,0,15.2315990066528,52.515998840332,-0.000822285973117687,52.515998840332,453.272254638672,52.515998840332,,,0.0058219323136095,0.000677610308170102,0.028597610742595,,25,15.2315990066528,-0.000822285973117687,453.272254638672,
,13957888.50,4369,2.99965000152588,0.13400000333786,0,15.3127299499512,52.7599983215332,-0.000514809860032983,52.7599983215332,453.120703125,52.7599983215332,,,0.00507309830307763,0.000748714257965667,0.0378975883794286,,25,15.3127299499512,-0.000514809860032983,453.120703125,
,13957906.22,4369,2.9985499382019,0.13400000333786,0,15.3101183319092,52.7599983215332,0.000723047555075027,52.7599983215332,453.061398925781,52.7599983215332,,,0.00698489292909091,0.000718696178429416,0.0392329806018934,,25,15.3101183319092,0.000723047555075027,453.061398925781,
,13957923.63,4369,2.99979996681213,0.13400000333786,0,15.3940940475464,53.0040016174316,0.000570001535234042,53.0040016174316,453.081639404297,53.0040016174316,,,0.00664026696683867,0.000854211967127597,0.038741056151914,,25,15.3940940475464,0.000570001535234042,453.081639404297,
,13957941.20,4369,3.00005006790161,0.13400000333786,0,15.5109637832642,53.2490005493164,0.000320933004841208,53.2490005493164,453.004887695313,53.2490005493164,,,0.0112869873885523,0.000766780546826597,0.0363158169913291,,25,15.5109637832642,0.000320933004841208,453.004887695313,
,13957959.36,4369,3.00045001506805,0.13400000333786,0,15.7698324584961,53.4930000305176,-0.000119813434721436,53.4930000305176,452.848524169922,53.4930000305176,,,0.276102858402901,0.00082499789796329,0.28673422667743,,25,15.7698324584961,-0.000119813434721436,452.848524169922,
,13957977.14,4369,3,0.13400000333786,0,15.9461640548706,53.7369995117188,0.000349219778436236,53.7369995117188,452.513137207031,53.7369995117188,,,0.0148440439177461,0.000713172573947063,0.0437182837155113,,25,15.9461640548706,0.000349219778436236,452.513137207031,
,13957994.05,4369,3.00249993801117,0.13400000333786,0,16.2947441864014,53.9809989929199,0.000825400858884677,53.9809989929199,452.45607421875,53.9809989929199,,,0.0169449460610683,0.000916335475103771,0.0379006773724775,,25,16.2947441864014,0.000825400858884677,452.45607421875,
,13958010.55,4369,3.00004994869232,0.13400000333786,0,16.2938086700439,53.9809989929199,-0.00116177996736951,53.9809989929199,452.536643066406,53.9809989929199,,,0.014876281919133,0.00077026824546983,0.044589349672013,,25,16.2938086700439,-0.00116177996736951,452.536643066406,
,13958028.23,4369,3.00034999847412,0.13400000333786,0,16.5540791320801,54.226001739502,7.87941884482279e-005,54.226001739502,452.465006103516,54.226001739502,,,0.00954928945548549,0.000802461260627375,0.0717844592593053,,25,16.5540791320801,7.87941884482279e-005,452.465006103516,
,13958046.23,4369,2.99970006942749,0.13400000333786,0,16.6927526092529,54.4700012207031,0.00165556069870945,54.4700012207031,452.355073242187,54.4700012207031,,,0.00588477916367479,0.000953030662448866,0.0488800359991289,,25,16.6927526092529,0.00165556069870945,452.355073242187,
,13958063.27,4369,3.00020003318787,0.13400000333786,0,16.8155153656006,54.7140007019043,0.000315128611400723,54.7140007019043,452.300711669922,54.7140007019043,,,0.00673859869883774,0.00104459395526833,0.037351878604048,,25,16.8155153656006,0.000315128611400723,452.300711669922,
,13958080.20,4369,3.00065004825592,0.13400000333786,0,16.9830822753906,54.9580001831055,-0.00069131619122345,54.9580001831055,452.112384033203,54.9580001831055,,,0.237234197936918,0.000769280059207624,0.310035961040342,,25,16.9830822753906,-0.00069131619122345,452.112384033203,