File: icepp/data/250309/250309_3D_mh_photolitho_IV_minus_fineUp1.dat
[Header]
TITLE, IV scan -35 to -55 (0.1 scan)
FILEOPENTIME,13956082.78,3/9/2025,11:53 AM
BYAPP, Resistivity, 2.1, 1.0
INFO, APPNAME, PPMS MultiVu Application, 1.5.11
INFO, , Sample1 Name
INFO, 1, Sample1 Cross Section
INFO, 1, Sample1 Length
INFO, Ohm, Sample1 Units
INFO, , Sample2 Name
INFO, 1, Sample2 Cross Section
INFO, 1, Sample2 Length
INFO, Ohm, Sample2 Units
INFO, , Sample3 Name
INFO, 1, Sample3 Cross Section
INFO, 1, Sample3 Length
INFO, Ohm, Sample3 Units
INFO, , Sample4 Name
INFO, 1, Sample4 Cross Section
INFO, 1, Sample4 Length
INFO, Ohm, Sample4 Units
FIELDGROUP, Resistivity,2,3,4,5,6,7,8,9,10,11,12,13,14,15,16,17,18,19,20,21,22,23,24,25,26,27,28,29,30,31,32,33,34,35,36,37,38,39,40,41
STARTUPGROUP, Resistivity
STARTUPAXIS, X, 2, LINEAR, AUTO
STARTUPAXIS, Y1, 7, LINEAR, AUTO
STARTUPAXIS, Y2, 9, LINEAR, AUTO
STARTUPAXIS, Y3, 11, LINEAR, AUTO
PLOT_APPEARANCE, ALL, HORZ_GRID_ON, VERT_GRID_ON, MARKERS_AND_LINES, ALL_LINES
DATATYPE, TIME, 2
DATATYPE, COMMENT, 1
[Data]
Comment,Time Stamp (sec),Status (code),Temperature (K),Magnetic Field (Oe),Sample Position (deg),Bridge 1 Resistivity (Ohm),Bridge 1 Excitation (uA),Bridge 2 Resistivity (Ohm),Bridge 2 Excitation (uA),Bridge 3 Resistivity (Ohm),Bridge 3 Excitation (uA),Bridge 4 Resistivity (Ohm),Bridge 4 Excitation (uA),Bridge 1 Std. Dev. (Ohm),Bridge 2 Std. Dev. (Ohm),Bridge 3 Std. Dev. (Ohm),Bridge 4 Std. Dev. (Ohm),Number of Readings,Bridge 1 Resistance (Ohms),Bridge 2 Resistance (Ohms),Bridge 3 Resistance (Ohms),Bridge 4 Resistance (Ohms),Signal 1 Vin (V),Signal 2 Vin (V),Digital Inputs (code),Drive 1 Iout (mA),Drive 1 Ipower (watts),Drive 2 Iout (mA),Drive 2 Ipower (watts),Pressure (),Map 20 (),Map 21 (),Map 22 (),Map 23 (),Map 24 (),Map 25 (),Map 26 (),Map 27 (),Map 28 (),Map 29 ()
,13959848.59,4369,3.00080001354218,0.13400000333786,0,0.00188921070075594,-34.9780006408691,-0.00174959236348514,-34.9780006408691,460.318721923828,-34.9780006408691,,,0.00118677194669532,0.000989888902791095,0.0671864725224254,,25,0.00188921070075594,-0.00174959236348514,460.318721923828,
,13959865.83,4369,2.99954998493195,0.13400000333786,0,-0.00109281922806986,-35.1980018615723,0.000975731442158576,-35.1980018615723,460.152838134766,-35.1980018615723,,,0.00170674201689293,0.00126914564613431,0.051488458589688,,25,-0.00109281922806986,0.000975731442158576,460.152838134766,
,13959883.19,4369,2.99979996681213,0.13400000333786,0,0.0377564326243009,-35.3930015563965,-0.000457078812178224,-35.3930015563965,460.081020507813,-35.3930015563965,,,0.142279046209928,0.00114016391578388,0.117120622014056,,25,0.0377564326243009,-0.000457078812178224,460.081020507813,
,13959900.95,4369,3.00024998188019,0.13400000333786,0,0.00127377603610512,-35.5890007019043,-0.000561833873798605,-35.5890007019043,459.957581787109,-35.5890007019043,,,0.0012256240287345,0.00094318684443714,0.0607104900368561,,25,0.00127377603610512,-0.000561833873798605,459.957581787109,
,13959918.02,4369,2.99909996986389,0.13400000333786,0,-0.000712305337656289,-35.7840003967285,0.00198763042397331,-35.7840003967285,459.808013916016,-35.7840003967285,,,0.00111581458843368,0.00140070831578619,0.0562897535092403,,25,-0.000712305337656289,0.00198763042397331,459.808013916016,
,13959937.02,4369,2.99994993209839,0.13400000333786,0,0.00146778091439046,-35.9790000915527,0.000551478388952091,-35.9790000915527,459.740526123047,-35.9790000915527,,,0.00116279564720918,0.00130992215725167,0.0728789128058653,,25,0.00146778091439046,0.000551478388952091,459.740526123047,
,13959955.70,4369,3.00044989585876,0.13400000333786,0,-0.000990819170256145,-36.1990013122559,0.000223461350542493,-36.1990013122559,459.569830322266,-36.1990013122559,,,0.00141574426171579,0.00151501374834066,0.0544737180071737,,25,-0.000990819170256145,0.000223461350542493,459.569830322266,
,13959973.91,4369,3.0008499622345,0.13400000333786,0,0.000255842962651514,-36.3950004577637,0.00163991138309939,-36.3950004577637,459.478201904297,-36.3950004577637,,,0.00122927857624699,0.00110445511395386,0.0741477592677219,,25,0.000255842962651514,0.00163991138309939,459.478201904297,
,13959991.27,4369,2.99900007247925,0.13400000333786,0,0.00106369671353605,-36.5900001525879,0.00137654863181524,-36.5900001525879,459.435510253906,-36.5900001525879,,,0.00107326416905798,0.00112549434455788,0.098087024239523,,25,0.00106369671353605,0.00137654863181524,459.435510253906,
,13960009.69,4369,3.00050008296967,0.13400000333786,0,-0.000107875426765531,-36.7859992980957,0.000921090162009932,-36.7859992980957,459.272270507812,-36.7859992980957,,,0.00120232416111737,0.00158462392404129,0.0540341053648143,,25,-0.000107875426765531,0.000921090162009932,459.272270507812,
,13960028.52,4369,2.99940001964569,0.13400000333786,0,-0.00332239616196603,-36.9809989929199,-0.00115561605256516,-36.9809989929199,459.145708007813,-36.9809989929199,,,0.00125252196597723,0.00104451599110875,0.0601413714115744,,25,-0.00332239616196603,-0.00115561605256516,459.145708007813,
,13960046.59,4369,3.00049996376038,0.13400000333786,0,0.00263807042269036,-37.201000213623,0.00135390861949418,-37.201000213623,459.026094970703,-37.201000213623,,,0.00114969371191477,0.00142448874700651,0.0569855984331128,,25,0.00263807042269036,0.00135390861949418,459.026094970703,
,13960064.89,4369,3.00010001659393,0.13400000333786,0,0.0217281949910102,-37.3959999084473,0.000706176512758248,-37.3959999084473,458.977601318359,-37.3959999084473,,,0.101119948962299,0.00117879902391137,0.0928393844819925,,25,0.0217281949910102,0.000706176512758248,458.977601318359,
,13960082.95,4369,2.99899995326996,0.13400000333786,0,-0.000300446591572836,-37.5919990539551,0.00149817282101139,-37.5919990539551,458.854613037109,-37.5919990539551,,,0.00136948431241147,0.00128720830776732,0.0492824762893249,,25,-0.000300446591572836,0.00149817282101139,458.854613037109,
,13960100.70,4369,2.99955010414124,0.13400000333786,0,-0.000678606247820426,-37.7869987487793,-0.000428168217476923,-37.7869987487793,458.649183349609,-37.7869987487793,,,0.00113587596694084,0.000948716474295688,0.0851666432469529,,25,-0.000678606247820426,-0.000428168217476923,458.649183349609,
,13960118.33,4369,3.00075006484985,0.13400000333786,0,0.126752912136726,-37.9819984436035,2.4108964134939e-005,-37.9819984436035,458.614318847656,-37.9819984436035,,,0.542980837283338,0.00114227511535173,0.066211368023477,,25,0.126752912136726,2.4108964134939e-005,458.614318847656,
,13960136.59,4369,2.99920010566711,0.13400000333786,0,0.000271866768598556,-38.1780014038086,0.000587712007109076,-38.1780014038086,458.499982910156,-38.1780014038086,,,0.0011324128666095,0.000768165044248902,0.0544993805688286,,25,0.000271866768598556,0.000587712007109076,458.499982910156,
,13960154.06,4369,2.99930000305176,0.13400000333786,0,0.00035771063703578,-38.3979988098145,0.000333863261039369,-38.3979988098145,458.333936767578,-38.3979988098145,,,0.00116726347318479,0.00101444042438422,0.0583525386577793,,25,0.00035771063703578,0.000333863261039369,458.333936767578,
,13960171.77,4369,3.00064992904663,0.13400000333786,0,-0.000462642543716356,-38.5929985046387,0.00153818760911236,-38.5929985046387,458.295203857422,-38.5929985046387,,,0.00108568804262361,0.00114981187480833,0.0765333120934997,,25,-0.000462642543716356,0.00153818760911236,458.295203857422,
,13960188.95,4369,3.00110006332397,0.13400000333786,0,0.00250238535809331,-38.7879981994629,-0.000574446956743486,-38.7879981994629,458.170338134766,-38.7879981994629,,,0.00114680346176274,0.00097323117248667,0.0504797823995699,,25,0.00250238535809331,-0.000574446956743486,458.170338134766,
,13960206.83,4369,3.00019991397858,0.13400000333786,0,0.00257614883012138,-38.984001159668,-0.000657740109309088,-38.984001159668,458.037646484375,-38.984001159668,,,0.00140528261499954,0.00140386386681347,0.0548592827330527,,25,0.00257614883012138,-0.000657740109309088,458.037646484375,
,13960224.98,4369,2.99919998645782,0.13400000333786,0,0.00257921246578917,-39.1790008544922,0.00213116195867769,-39.1790008544922,458.079396972656,-39.1790008544922,,,0.00115153069180773,0.00122101293769504,0.100442562677551,,25,0.00257921246578917,0.00213116195867769,458.079396972656,
,13960243.00,4369,3.00055003166199,0.13400000333786,0,0.0468924786805292,-39.398998260498,0.000213059564703144,-39.398998260498,457.821020507812,-39.398998260498,,,0.15676883261445,0.00157140199258299,0.080634014163501,,25,0.0468924786805292,0.000213059564703144,457.821020507812,
,13960260.84,4369,3.0003000497818,0.13400000333786,0,0.00390527870622464,-39.5950012207031,0.00130304461054038,-39.5950012207031,457.792127685547,-39.5950012207031,,,0.00624804554739843,0.0010718874654694,0.119577075351812,,25,0.00390527870622464,0.00130304461054038,457.792127685547,
,13960279.50,4369,2.99990010261536,0.13400000333786,0,0.00795918696618173,-39.7900009155273,-0.000329874744638801,-39.7900009155273,457.658692626953,-39.7900009155273,,,0.0144900096276581,0.00129313232612643,0.0621758547652776,,25,0.00795918696618173,-0.000329874744638801,457.658692626953,
,13960297.64,4369,3.0005499124527,0.13400000333786,0,0.010562076640781,-39.9850006103516,0.000492413412139285,-39.9850006103516,457.465408935547,-39.9850006103516,,,0.0170215660095121,0.00101556496498602,0.0740250128151269,,25,0.010562076640781,0.000492413412139285,457.465408935547,
,13960315.78,4369,3.0008499622345,0.13400000333786,0,0.0166146749071777,-40.1809997558594,-0.000129149259300902,-40.1809997558594,457.421997070313,-40.1809997558594,,,0.0258026605955946,0.00137453510191836,0.0902091214679069,,25,0.0166146749071777,-0.000129149259300902,457.421997070313,
,13960334.33,4369,2.99940001964569,0.13400000333786,0,0.0279347804281861,-40.4010009765625,0.00260271330364048,-40.4010009765625,457.285961914063,-40.4010009765625,,,0.0284555905053248,0.00117804220053578,0.0670847604785242,,25,0.0279347804281861,0.00260271330364048,457.285961914063,
,13960351.27,4369,3,0.13400000333786,0,0.0449971354450099,-40.5960006713867,0.00119937214825768,-40.5960006713867,457.243665771484,-40.5960006713867,,,0.0406564780752629,0.0010803354610534,0.0338021902501056,,25,0.0449971354450099,0.00119937214825768,457.243665771484,
,13960369.91,4369,2.99980008602142,0.13400000333786,0,0.0629815464670537,-40.7910003662109,0.000336739701160695,-40.7910003662109,457.098143310547,-40.7910003662109,,,0.048719560877997,0.00108794919943006,0.0490284452454809,,25,0.0629815464670537,0.000336739701160695,457.098143310547,
,13960388.02,4369,3.00010001659393,0.13400000333786,0,0.066181628042832,-40.9869995117188,-0.000234607387683354,-40.9869995117188,457.010485839844,-40.9869995117188,,,0.0501356896608689,0.00121074016048301,0.0742334320735974,,25,0.066181628042832,-0.000234607387683354,457.010485839844,
,13960406.59,4369,2.99930000305176,0.13400000333786,0,0.0861014467291534,-41.181999206543,0.000674520611355547,-41.181999206543,456.927264404297,-41.181999206543,,,0.0579122671431418,0.00110270477737002,0.0499199420151953,,25,0.0861014467291534,0.000674520611355547,456.927264404297,
,13960424.92,4369,2.99965000152588,0.13400000333786,0,0.187805279642344,-41.3779983520508,0.00333430155180395,-41.3779983520508,456.734063720703,-41.3779983520508,,,0.186038628352767,0.00134958673829418,0.0511356188692103,,25,0.187805279642344,0.00333430155180395,456.734063720703,
,13960442.73,4369,3.0003000497818,0.13400000333786,0,0.476773079931736,-41.5970001220703,-0.000535733088909183,-41.5970001220703,456.589411621094,-41.5970001220703,,,0.272520741476995,0.000933962618047049,0.0747238713650804,,25,0.476773079931736,-0.000535733088909183,456.589411621094,
,13960459.80,4369,2.99959993362427,0.13400000333786,0,2.58437024354935,-41.7929992675781,0.000584293483698275,-41.7929992675781,456.556744384766,-41.7929992675781,,,1.28988347502526,0.00114989298589464,0.0609571022190187,,25,2.58437024354935,0.000584293483698275,456.556744384766,
,13960478.05,4369,3.00049996376038,0.13400000333786,0,6.07367722511292,-41.9879989624023,-0.00141029373800848,-41.9879989624023,456.390021972656,-41.9879989624023,,,1.15557017617765,0.00110311761208328,0.049332384788013,,25,6.07367722511292,-0.00141029373800848,456.390021972656,
,13960494.97,4369,2.99940001964569,0.13400000333786,0,7.13708518981934,-42.1839981079102,-0.00097320068103727,-42.1839981079102,456.308001708984,-42.1839981079102,,,0.271054389571074,0.000994177342183386,0.0995618618342308,,25,7.13708518981934,-0.00097320068103727,456.308001708984,
,13960512.42,4369,3.00004994869232,0.13400000333786,0,7.31256750106812,-42.3790016174316,-0.00105169797461713,-42.3790016174316,456.180355224609,-42.3790016174316,,,0.220413005271013,0.0012682197434269,0.0622268712116326,,25,7.31256750106812,-0.00105169797461713,456.180355224609,
,13960529.69,4369,2.99954998493195,0.13400000333786,0,7.45981624603272,-42.5989990234375,0.00149045852245763,-42.5989990234375,456.199860839844,-42.5989990234375,,,0.223885321378245,0.00130266410402185,0.0731442358761593,,25,7.45981624603272,0.00149045852245763,456.199860839844,
,13960547.23,4369,3.00005006790161,0.13400000333786,0,7.58868740081787,-42.7939987182617,0.00105559704417828,-42.7939987182617,455.957437744141,-42.7939987182617,,,0.105086037651109,0.00113158369371175,0.0537835635294103,,25,7.58868740081787,0.00105559704417828,455.957437744141,
,13960565.13,4369,2.9994500875473,0.13400000333786,0,7.71143379211426,-42.9900016784668,-0.00214775089174509,-42.9900016784668,455.862103271484,-42.9900016784668,,,0.00655870296778965,0.00085973093926075,0.0633596969866332,,25,7.71143379211426,-0.00214775089174509,455.862103271484,
,13960582.75,4369,3.00135004520416,0.13400000333786,0,7.80322505950928,-43.185001373291,-0.00120514926733449,-43.185001373291,455.775419921875,-43.185001373291,,,0.00580608757929242,0.0013549905674998,0.0650379773284262,,25,7.80322505950928,-0.00120514926733449,455.775419921875,
,13960600.33,4369,3.00085008144379,0.13400000333786,0,7.9167555809021,-43.3810005187988,-0.000358917951234616,-43.3810005187988,455.686824951172,-43.3810005187988,,,0.0913418042962556,0.00117575435527503,0.0656665829912858,,25,7.9167555809021,-0.000358917951234616,455.686824951172,
,13960618.09,4369,3.00034999847412,0.13400000333786,0,7.99575750350952,-43.5999984741211,-0.000136514590703882,-43.5999984741211,455.664989013672,-43.5999984741211,,,0.00920203609000381,0.00101271577872263,0.0648076335127847,,25,7.99575750350952,-0.000136514590703882,455.664989013672,
,13960635.72,4369,2.99975001811981,0.13400000333786,0,8.07167675018311,-43.7960014343262,-0.0020247163833119,-43.7960014343262,455.574343261719,-43.7960014343262,,,0.00488051917332099,0.000928013012938054,0.088866537741497,,25,8.07167675018311,-0.0020247163833119,455.574343261719,
,13960653.45,4369,2.99889993667603,0.13400000333786,0,8.16016212463379,-43.9910011291504,-0.00108937467884971,-43.9910011291504,455.401057128906,-43.9910011291504,,,0.00632328446068367,0.000830863158795491,0.0541489038422387,,25,8.16016212463379,-0.00108937467884971,455.401057128906,
,13960671.78,4369,2.99955010414124,0.13400000333786,0,8.23823608398438,-44.1870002746582,-0.00341965957079083,-44.1870002746582,455.261636962891,-44.1870002746582,,,0.00694528055472617,0.00116550515699524,0.042120202999373,,25,8.23823608398438,-0.00341965957079083,455.261636962891,
,13960687.97,4369,3.00069999694824,0.13400000333786,0,8.32369827270508,-44.3819999694824,-0.000653381177107804,-44.3819999694824,455.315378417969,-44.3819999694824,,,0.00888724522922213,0.000984135652042302,0.104746270235837,,25,8.32369827270508,-0.000653381177107804,455.315378417969,
,13960705.30,4369,2.99890005588531,0.13400000333786,0,8.3997412109375,-44.5769996643066,0.000499818114913069,-44.5769996643066,455.045065917969,-44.5769996643066,,,0.00865325637922375,0.00118012902922533,0.0528909386770971,,25,8.3997412109375,0.000499818114913069,455.045065917969,
,13960722.25,4369,3.00014996528625,0.13400000333786,0,8.57259895324707,-44.7970008850098,-0.0015091962274164,-44.7970008850098,455.032495117188,-44.7970008850098,,,0.376767088313188,0.00111529757542422,0.084006363289922,,25,8.57259895324707,-0.0015091962274164,455.032495117188,
,13960739.00,4369,3.00050008296967,0.13400000333786,0,8.55443744659424,-44.9930000305176,-0.00156391787459143,-44.9930000305176,454.953273925781,-44.9930000305176,,,0.00874434828232659,0.000851524386370924,0.0481638129613419,,25,8.55443744659424,-0.00156391787459143,454.953273925781,
,13960756.33,4369,2.9993999004364,0.13400000333786,0,8.6269803237915,-45.1879997253418,0.000118208295316435,-45.1879997253418,454.844306640625,-45.1879997253418,,,0.00508722195784023,0.00098957811519239,0.0528573510750918,,25,8.6269803237915,0.000118208295316435,454.844306640625,
,13960773.33,4369,3.00085008144379,0.13400000333786,0,8.70289943695068,-45.382999420166,0.000743225630722009,-45.382999420166,454.780592041016,-45.382999420166,,,0.00465125818571433,0.00119438541176207,0.0571530804981446,,25,8.70289943695068,0.000743225630722009,454.780592041016,
,13960790.91,4369,2.99919998645782,0.13400000333786,0,8.77644390106201,-45.5789985656738,-0.000860528204357252,-45.5789985656738,454.655988769531,-45.5789985656738,,,0.00895087760864865,0.000887321404814975,0.0497793233555357,,25,8.77644390106201,-0.000860528204357252,454.655988769531,
,13960808.33,4369,3.00045001506805,0.13400000333786,0,8.8716967010498,-45.798999786377,-0.000526545981119852,-45.798999786377,454.552877197266,-45.798999786377,,,0.0144367867562242,0.00104981760312335,0.0688226359301087,,25,8.8716967010498,-0.000526545981119852,454.552877197266,
,13960825.36,4369,3.00014996528625,0.13400000333786,0,8.94246845245361,-45.9939994812012,0.00113152752339374,-45.9939994812012,454.455416259766,-45.9939994812012,,,0.0114467082174369,0.000749325117502719,0.0456575017074509,,25,8.94246845245361,0.00113152752339374,454.455416259766,
,13960844.03,4369,2.99840009212494,0.13400000333786,0,9.09081314086914,-46.189998626709,0.000204886707942933,-46.189998626709,454.397642822266,-46.189998626709,,,0.160736409315647,0.0010705962809497,0.0763361871127175,,25,9.09081314086914,0.000204886707942933,454.397642822266,
,13960861.44,4369,2.99995005130768,0.13400000333786,0,9.13371505737305,-46.3849983215332,-0.000342198116413783,-46.3849983215332,454.262260742187,-46.3849983215332,,,0.0254471387424474,0.000831323971173287,0.0572512937752531,,25,9.13371505737305,-0.000342198116413783,454.262260742187,
,13960879.11,4369,3.00134992599487,0.13400000333786,0,9.23258010864258,-46.5800018310547,-0.00244760532863438,-46.5800018310547,454.178166503906,-46.5800018310547,,,0.0260594501886059,0.000933486143238974,0.066091432202804,,25,9.23258010864258,-0.00244760532863438,454.178166503906,
,13960897.09,4369,2.99909996986389,0.13400000333786,0,9.36697280883789,-46.7999992370605,-0.000140242156630848,-46.7999992370605,454.013033447266,-46.7999992370605,,,0.0226606378612054,0.000769908428266814,0.052835472154856,,25,9.36697280883789,-0.000140242156630848,454.013033447266,
,13960915.30,4369,3.00004994869232,0.13400000333786,0,9.5326180267334,-46.9959983825684,0.000883357051643543,-46.9959983825684,453.973400878906,-46.9959983825684,,,0.0324419264469464,0.00113929561980324,0.065479268897145,,25,9.5326180267334,0.000883357051643543,453.973400878906,
,13960932.97,4369,3.00059998035431,0.13400000333786,0,9.90718669891357,-47.1910018920898,0.000106732656713575,-47.1910018920898,453.842166748047,-47.1910018920898,,,0.082456240764905,0.000877068167740633,0.106524387924935,,25,9.90718669891357,0.000106732656713575,453.842166748047,
,13960949.88,4369,3.00045001506805,0.13400000333786,0,13.0360391235352,-47.3860015869141,-0.00114345992769813,-47.3860015869141,453.782030029297,-47.3860015869141,,,0.0193014972554728,0.00100084941542768,0.0473798340084763,,25,13.0360391235352,-0.00114345992769813,453.782030029297,
,13960967.17,4369,3.00094997882843,0.13400000333786,0,13.273738861084,-47.5820007324219,-0.00137292788247578,-47.5820007324219,453.666047363281,-47.5820007324219,,,0.0101930897221681,0.00099656038952651,0.0592737601652642,,25,13.273738861084,-0.00137292788247578,453.666047363281,
,13960983.94,4369,3.00049996376038,0.13400000333786,0,13.4364630889893,-47.7770004272461,0.00158771360293031,-47.7770004272461,453.595861816406,-47.7770004272461,,,0.00895927278029653,0.00068379257324393,0.0958649552828533,,25,13.4364630889893,0.00158771360293031,453.595861816406,
,13961001.13,4369,3.00020003318787,0.13400000333786,0,13.5844366836548,-47.9970016479492,0.000594667840050533,-47.9970016479492,453.469996337891,-47.9970016479492,,,0.00739650779061682,0.000829290073974822,0.0506080018485779,,25,13.5844366836548,0.000594667840050533,453.469996337891,
,13961019.08,4369,2.99905002117157,0.13400000333786,0,13.7493617630005,-48.1920013427734,-0.00125409210129874,-48.1920013427734,453.341514892578,-48.1920013427734,,,0.203363586406154,0.00102855505698178,0.120937792316919,,25,13.7493617630005,-0.00125409210129874,453.341514892578,
,13961037.06,4369,2.99930000305176,0.13400000333786,0,13.8120450210571,-48.3880004882813,-0.00114499757095473,-48.3880004882813,453.236143798828,-48.3880004882813,,,0.00678738559261979,0.000704651422337723,0.0607151832956088,,25,13.8120450210571,-0.00114499757095473,453.236143798828,
,13961055.41,4369,3.00055003166199,0.13400000333786,0,13.9148746109009,-48.5830001831055,-0.000216737453883979,-48.5830001831055,453.161319580078,-48.5830001831055,,,0.00552311522853241,0.000646140423225521,0.0465782905897067,,25,13.9148746109009,-0.000216737453883979,453.161319580078,
,13961073.09,4369,3.00005006790161,0.13400000333786,0,14.013865737915,-48.7789993286133,0.00109829501772765,-48.7789993286133,453.042507324219,-48.7789993286133,,,0.00384172276823234,0.00093936015999404,0.0459056427555483,,25,14.013865737915,0.00109829501772765,453.042507324219,
,13961090.25,4369,3.00069999694824,0.13400000333786,0,14.1207160568237,-48.9990005493164,0.00126783386804163,-48.9990005493164,452.962890625,-48.9990005493164,,,0.00582695852860853,0.00105993008854816,0.052704686289213,,25,14.1207160568237,0.00126783386804163,452.962890625,
,13961107.16,4369,2.99944996833801,0.13400000333786,0,14.2019590759277,-49.1940002441406,0.000319533402216621,-49.1940002441406,452.884567871094,-49.1940002441406,,,0.0052692705751475,0.000707534328973556,0.0480901556398037,,25,14.2019590759277,0.000319533402216621,452.884567871094,
,13961125.02,4369,3.00050008296967,0.13400000333786,0,14.2926068115234,-49.3889999389648,0.00138746729819104,-49.3889999389648,452.808037109375,-49.3889999389648,,,0.00444639317327187,0.00106160164735023,0.0801751295021414,,25,14.2926068115234,0.00138746729819104,452.808037109375,
,13961143.30,4369,3.00010001659393,0.13400000333786,0,14.3799161529541,-49.5849990844727,-0.000147746868897229,-49.5849990844727,452.64982421875,-49.5849990844727,,,0.0249868860724315,0.000736460748165026,0.0615777906662344,,25,14.3799161529541,-0.000147746868897229,452.64982421875,
,13961161.39,4369,2.99985003471375,0.13400000333786,0,14.4505784988403,-49.7799987792969,0.000156363181886263,-49.7799987792969,452.683326416016,-49.7799987792969,,,0.00404353439431734,0.000867039147409358,0.100567644154799,,25,14.4505784988403,0.000156363181886263,452.683326416016,
,13961178.00,4369,2.99994993209839,0.13400000333786,0,14.5286490249634,-50,-0.00110805009491742,-50,452.387498779297,-50,,,0.00430948541645709,0.000933410133072703,0.108166035123885,,25,14.5286490249634,-0.00110805009491742,452.387498779297,
,13961195.92,4369,3.00004994869232,0.13400000333786,0,14.6341931533813,-50.0730018615723,0.0009814792429097,-50.0730018615723,452.072255859375,-50.0730018615723,,,0.00356502218576314,0.000790832296252375,0.0748207805636978,,25,14.6341931533813,0.0009814792429097,452.072255859375,
,13961213.09,4369,2.99905002117157,0.13400000333786,0,14.7198988342285,-50.318000793457,0.000178933618008159,-50.318000793457,452.098519287109,-50.318000793457,,,0.00544017497656842,0.00079313833088408,0.104098449693146,,25,14.7198988342285,0.000178933618008159,452.098519287109,
,13961231.06,4369,3.00034999847412,0.13400000333786,0,14.7946681976318,-50.5620002746582,-0.0010534457815811,-50.5620002746582,451.857357177734,-50.5620002746582,,,0.00323551107424408,0.000942391057807148,0.0491277860425392,,25,14.7946681976318,-0.0010534457815811,451.857357177734,
,13961248.22,4369,3.00024998188019,0.13400000333786,0,14.7971432876587,-50.5620002746582,0.000386364070582204,-50.5620002746582,451.861127929687,-50.5620002746582,,,0.00378814211796935,0.000851433090201577,0.0422452940547717,,25,14.7971432876587,0.000386364070582204,451.861127929687,
,13961267.09,4369,2.99934995174408,0.13400000333786,0,14.8729510116577,-50.8059997558594,0.000807986742292997,-50.8059997558594,451.648800048828,-50.8059997558594,,,0.00282107374514992,0.000962880633947676,0.0462954055337362,,25,14.8729510116577,0.000807986742292997,451.648800048828,
,13961284.09,4369,2.99994993209839,0.13400000333786,0,14.9510653305054,-51.0499992370605,-0.000502232776489109,-51.0499992370605,451.851356201172,-51.0499992370605,,,0.0037373761546781,0.000819390453328297,0.0609479555439511,,25,14.9510653305054,-0.000502232776489109,451.851356201172,
,13961302.89,4369,3.0008499622345,0.13400000333786,0,15.0265352249146,-51.2949981689453,0.00100561572471634,-51.2949981689453,451.662419433594,-51.2949981689453,,,0.00366327696648351,0.000633276271425473,0.0676138433512203,,25,15.0265352249146,0.00100561572471634,451.662419433594,
,13961321.75,4369,2.99895000457764,0.13400000333786,0,15.1169332504272,-51.5390014648438,-0.00151304293249268,-51.5390014648438,451.432741699219,-51.5390014648438,,,0.0667371412390893,0.000785928774627916,0.0365634412744956,,25,15.1169332504272,-0.00151304293249268,451.432741699219,
,13961338.86,4369,3.00020003318787,0.13400000333786,0,15.1755110168457,-51.7830009460449,0.000244595141266473,-51.7830009460449,451.422364501953,-51.7830009460449,,,0.00421353787927467,0.00121016584244342,0.0432883485424916,,25,15.1755110168457,0.000244595141266473,451.422364501953,
,13961356.17,4369,3.00045001506805,0.13400000333786,0,15.1771817779541,-51.7830009460449,0.00142631387512665,-51.7830009460449,451.472038574219,-51.7830009460449,,,0.00446997525247593,0.000729292133163166,0.0920465188506109,,25,15.1771817779541,0.00142631387512665,451.472038574219,
,13961373.05,4369,2.99889993667603,0.13400000333786,0,15.2512381362915,-52.0270004272461,-0.00176289636467118,-52.0270004272461,451.241994628906,-52.0270004272461,,,0.00415943252931189,0.000729341420043238,0.0632208506111547,,25,15.2512381362915,-0.00176289636467118,451.241994628906,
,13961390.59,4369,2.99909996986389,0.13400000333786,0,15.3274230575562,-52.2719993591309,0.000467149936011992,-52.2719993591309,451.196918945313,-52.2719993591309,,,0.00444087060919832,0.000778522403290225,0.0509090777669975,,25,15.3274230575562,0.000467149936011992,451.196918945313,
,13961408.42,4369,2.99965000152588,0.13400000333786,0,15.4026131057739,-52.515998840332,-0.000726438001729548,-52.515998840332,450.97142578125,-52.515998840332,,,0.00523418769072914,0.000824435127415433,0.0565550101590876,,25,15.4026131057739,-0.000726438001729548,450.97142578125,
,13961425.27,4369,2.99880003929138,0.13400000333786,0,15.4896469497681,-52.7599983215332,-0.000537988239957485,-52.7599983215332,451.101209716797,-52.7599983215332,,,0.00738156194809709,0.000845771501214164,0.0662727879646054,,25,15.4896469497681,-0.000537988239957485,451.101209716797,
,13961444.19,4369,3.00014996528625,0.13400000333786,0,15.5065069198608,-52.7599983215332,0.00121191973332316,-52.7599983215332,450.965490722656,-52.7599983215332,,,0.0599256422294673,0.000653287758352723,0.0952901139215796,,25,15.5065069198608,0.00121191973332316,450.965490722656,
,13961462.67,4369,3.0003000497818,0.13400000333786,0,15.5929130554199,-53.0040016174316,0.000492328981636092,-53.0040016174316,450.727261962891,-53.0040016174316,,,0.0101276419901626,0.000823367010073711,0.115241244861937,,25,15.5929130554199,0.000492328981636092,450.727261962891,
,13961481.39,4369,2.99864995479584,0.13400000333786,0,15.7281773376465,-53.2490005493164,-0.000914216966484673,-53.2490005493164,450.602386474609,-53.2490005493164,,,0.0138012010784212,0.00095745404219005,0.0480497910808684,,25,15.7281773376465,-0.000914216966484673,450.602386474609,
,13961500.42,4369,3.0020500421524,0.13400000333786,0,16.0151767349243,-53.4930000305176,-0.00124943406379316,-53.4930000305176,450.717686767578,-53.4930000305176,,,0.0457202702759406,0.000616159279899743,0.058664616307676,,25,16.0151767349243,-0.00124943406379316,450.717686767578,
,13961518.33,4369,2.99905002117157,0.13400000333786,0,16.355915145874,-53.7369995117188,0.000905870373826474,-53.7369995117188,450.361165771484,-53.7369995117188,,,0.0118877918424113,0.00088948958011588,0.0534848374365714,,25,16.355915145874,0.000905870373826474,450.361165771484,
,13961536.42,4369,3.00045001506805,0.13400000333786,0,16.6099113464355,-53.9809989929199,0.000517360170488246,-53.9809989929199,450.355355224609,-53.9809989929199,,,0.00974812150595661,0.000917333427391478,0.0631617329081033,,25,16.6099113464355,0.000517360170488246,450.355355224609,
,13961553.33,4369,2.9991500377655,0.13400000333786,0,16.6144570159912,-53.9809989929199,-0.000995140905724838,-53.9809989929199,450.372315673828,-53.9809989929199,,,0.00918095783529452,0.000770332932194332,0.0899025280015849,,25,16.6144570159912,-0.000995140905724838,450.372315673828,
,13961570.83,4369,2.99944996833801,0.13400000333786,0,16.7825407409668,-54.226001739502,0.000416528900968842,-54.226001739502,450.177364501953,-54.226001739502,,,0.00662484741074778,0.000872214041681986,0.0441047649914418,,25,16.7825407409668,0.000416528900968842,450.177364501953,
,13961588.30,4369,2.99954998493195,0.13400000333786,0,16.906365814209,-54.4700012207031,-0.00112344991066493,-54.4700012207031,450.18833984375,-54.4700012207031,,,0.00746040856852679,0.000879387654033569,0.0548162615542479,,25,16.906365814209,-0.00112344991066493,450.18833984375,
,13961605.41,4369,2.99909996986389,0.13400000333786,0,17.0141330718994,-54.7140007019043,0.000680592299904674,-54.7140007019043,450.057154541016,-54.7140007019043,,,0.0072895891743962,0.000723685566049671,0.0581296238959553,,25,17.0141330718994,0.000680592299904674,450.057154541016,
,13961622.58,4369,2.99919998645782,0.13400000333786,0,17.1401985168457,-54.9580001831055,-0.000924637132848147,-54.9580001831055,450.021802978516,-54.9580001831055,,,0.106844583475254,0.000631267686952439,0.114210654220426,,25,17.1401985168457,-0.000924637132848147,450.021802978516,