File: icepp/data/250309/250309_3D_mh_photolitho_fineDown1.dat
[Header]
TITLE, 298K to 2K
FILEOPENTIME,13915428.92,3/9/2025,12:35 AM
BYAPP, Resistivity, 2.1, 1.0
INFO, APPNAME, PPMS MultiVu Application, 1.5.11
INFO, , Sample1 Name
INFO, 1, Sample1 Cross Section
INFO, 1, Sample1 Length
INFO, Ohm, Sample1 Units
INFO, , Sample2 Name
INFO, 1, Sample2 Cross Section
INFO, 1, Sample2 Length
INFO, Ohm, Sample2 Units
INFO, , Sample3 Name
INFO, 1, Sample3 Cross Section
INFO, 1, Sample3 Length
INFO, Ohm, Sample3 Units
INFO, , Sample4 Name
INFO, 1, Sample4 Cross Section
INFO, 1, Sample4 Length
INFO, Ohm, Sample4 Units
FIELDGROUP, Resistivity,2,3,4,5,6,7,8,9,10,11,12,13,14,15,16,17,18,19,20,21,22,23,24,25,26,27,28,29,30,31,32,33,34,35,36,37,38,39,40,41
STARTUPGROUP, Resistivity
STARTUPAXIS, X, 2, LINEAR, AUTO
STARTUPAXIS, Y1, 7, LINEAR, AUTO
STARTUPAXIS, Y2, 9, LINEAR, AUTO
STARTUPAXIS, Y3, 11, LINEAR, AUTO
PLOT_APPEARANCE, ALL, HORZ_GRID_ON, VERT_GRID_ON, MARKERS_AND_LINES, ALL_LINES
DATATYPE, TIME, 2
DATATYPE, COMMENT, 1
[Data]
Comment,Time Stamp (sec),Status (code),Temperature (K),Magnetic Field (Oe),Sample Position (deg),Bridge 1 Resistivity (Ohm),Bridge 1 Excitation (uA),Bridge 2 Resistivity (Ohm),Bridge 2 Excitation (uA),Bridge 3 Resistivity (Ohm),Bridge 3 Excitation (uA),Bridge 4 Resistivity (Ohm),Bridge 4 Excitation (uA),Bridge 1 Std. Dev. (Ohm),Bridge 2 Std. Dev. (Ohm),Bridge 3 Std. Dev. (Ohm),Bridge 4 Std. Dev. (Ohm),Number of Readings,Bridge 1 Resistance (Ohms),Bridge 2 Resistance (Ohms),Bridge 3 Resistance (Ohms),Bridge 4 Resistance (Ohms),Signal 1 Vin (V),Signal 2 Vin (V),Digital Inputs (code),Drive 1 Iout (mA),Drive 1 Ipower (watts),Drive 2 Iout (mA),Drive 2 Ipower (watts),Pressure (),Map 20 (),Map 21 (),Map 22 (),Map 23 (),Map 24 (),Map 25 (),Map 26 (),Map 27 (),Map 28 (),Map 29 ()
,13915910.77,4370,297.852493286133,0.13400000333786,0,2260.3819921875,0.00999999977648258,2043.49892089844,0.00999999977648258,2379.86081054688,0.00999999977648258,,,4.28654383000841,3.04091568325068,8.81215720633387,,25,2260.3819921875,2043.49892089844,2379.86081054688,
,13916037.30,4370,293.756286621094,0.13400000333786,0,2254.06858398438,0.00999999977648258,2039.87545410156,0.00999999977648258,2374.18221679687,0.00999999977648258,,,5.15796887031229,4.30657087110615,4.75583428507459,,25,2254.06858398438,2039.87545410156,2374.18221679687,
,13916155.63,4370,289.799606323242,0.13400000333786,0,2244.3288671875,0.00999999977648258,2034.54537109375,0.00999999977648258,2363.37638671875,0.00999999977648258,,,22.8619267172869,16.4243582179842,22.217964673088,,25,2244.3288671875,2034.54537109375,2363.37638671875,
,13916274.89,4370,285.805450439453,0.13400000333786,0,2249.23678710938,0.00999999977648258,2032.83476074219,0.00999999977648258,2366.22874023438,0.00999999977648258,,,11.4914550261753,13.3422265241718,10.620305923451,,25,2249.23678710938,2032.83476074219,2366.22874023438,
,13916395.22,4370,281.776245117188,0.13400000333786,0,2248.416640625,0.00999999977648258,2030.97400390625,0.00999999977648258,2363.73235351563,0.00999999977648258,,,3.76363544886946,3.04972177976672,3.95770466669747,,25,2248.416640625,2030.97400390625,2363.73235351563,
,13916514.81,4370,277.779663085938,0.13400000333786,0,2241.4841796875,0.00999999977648258,2024.70774414063,0.00999999977648258,2358.376484375,0.00999999977648258,,,6.00285896740871,9.28470999760611,6.10355775803329,,25,2241.4841796875,2024.70774414063,2358.376484375,
,13916634.89,4370,273.76741027832,0.13400000333786,0,2239.88208984375,0.00999999977648258,2025.44080566406,0.00999999977648258,2356.411015625,0.00999999977648258,,,3.34258126242208,3.18809988446122,3.70431694784401,,25,2239.88208984375,2025.44080566406,2356.411015625,
,13916754.28,4370,269.789505004883,0.13400000333786,0,2236.10903320312,0.00999999977648258,2018.25849121094,0.00999999977648258,2346.36530273437,0.00999999977648258,,,15.7865319795935,13.0521936602519,13.2553570192212,,25,2236.10903320312,2018.25849121094,2346.36530273437,
,13916874.56,4370,265.785507202148,0.13400000333786,0,2228.94237304688,0.00999999977648258,2012.46381347656,0.00999999977648258,2347.064609375,0.00999999977648258,,,5.21639770096762,4.77169025075954,4.98735262607043,,25,2228.94237304688,2012.46381347656,2347.064609375,
,13916995.19,4370,261.75080871582,0.13400000333786,0,2224.40594726562,0.00999999977648258,2010.8177734375,0.00999999977648258,2342.00262695312,0.00999999977648258,,,3.22878347694618,3.58832068713356,3.99901992800026,,25,2224.40594726562,2010.8177734375,2342.00262695312,
,13917115.00,4370,257.76383972168,0.13400000333786,0,2223.45166015625,0.00999999977648258,2008.40631835938,0.00999999977648258,2339.86499023438,0.00999999977648258,,,7.05383574962769,9.01329005218976,5.94705786287309,,25,2223.45166015625,2008.40631835938,2339.86499023438,
,13917234.48,4370,253.769203186035,0.13400000333786,0,2218.13509765625,0.00999999977648258,2004.64526855469,0.00999999977648258,2337.18456054688,0.00999999977648258,,,6.56581005685195,5.89838162176241,5.15135166075477,,25,2218.13509765625,2004.64526855469,2337.18456054688,
,13917354.20,4370,249.779899597168,0.13400000333786,0,2219.624140625,0.00999999977648258,2004.30609863281,0.00999999977648258,2331.95477539062,0.00999999977648258,,,10.8712897489515,8.43480358431134,8.03567888390812,,25,2219.624140625,2004.30609863281,2331.95477539062,
,13917474.78,4370,245.755393981934,0.13400000333786,0,2206.30768554687,0.00999999977648258,1983.92783691406,0.00999999977648258,2326.27827148438,0.00999999977648258,,,37.7128212037159,29.6300888359721,28.0357036223213,,25,2206.30768554687,1983.92783691406,2326.27827148438,
,13917594.31,4370,241.779998779297,0.13400000333786,0,2200.313671875,0.00999999977648258,1991.87254394531,0.00999999977648258,2321.72546875,0.00999999977648258,,,27.8992954381349,32.5460912599846,29.6276255938904,,25,2200.313671875,1991.87254394531,2321.72546875,
,13917715.06,4370,237.753646850586,0.13400000333786,0,2199.80908203125,0.00999999977648258,1991.62581054688,0.00999999977648258,2320.44232421875,0.00999999977648258,,,24.5152973727511,33.6140604966605,32.5270499293267,,25,2199.80908203125,1991.62581054688,2320.44232421875,
,13917834.47,4370,233.771102905273,0.13400000333786,0,2195.5508984375,0.00999999977648258,1982.13400390625,0.00999999977648258,2318.80900390625,0.00999999977648258,,,22.3121302767967,43.5379319544469,30.4377351867499,,25,2195.5508984375,1982.13400390625,2318.80900390625,
,13917955.02,4370,229.762451171875,0.13400000333786,0,2189.88374023438,0.00999999977648258,1983.86567382813,0.00999999977648258,2312.90799804688,0.00999999977648258,,,15.9904705118177,17.8102499644356,15.4206578476781,,25,2189.88374023438,1983.86567382813,2312.90799804688,
,13918073.91,4370,225.786506652832,0.13400000333786,0,2192.8425,0.00999999977648258,1975.51304199219,0.00999999977648258,2309.871953125,0.00999999977648258,,,6.26642766143209,7.15454025480081,8.01741780516885,,25,2192.8425,1975.51304199219,2309.871953125,
,13918193.73,4370,221.795356750488,0.13400000333786,0,2183.37615234375,0.00999999977648258,1972.8038671875,0.00999999977648258,2306.94881835937,0.00999999977648258,,,9.92992480782859,7.80157317119621,7.80036589700339,,25,2183.37615234375,1972.8038671875,2306.94881835937,
,13918314.30,4370,217.772804260254,0.13400000333786,0,2181.89095703125,0.00999999977648258,1968.87436523438,0.00999999977648258,2302.78682617188,0.00999999977648258,,,9.7379410282519,12.4471316284919,8.74998968008829,,25,2181.89095703125,1968.87436523438,2302.78682617188,
,13918434.28,4370,213.780052185059,0.13400000333786,0,2182.54412109375,0.00999999977648258,1963.71534667969,0.00999999977648258,2295.0742578125,0.00999999977648258,,,19.8800382237497,19.6986219281609,19.5875192330144,,25,2182.54412109375,1963.71534667969,2295.0742578125,
,13918554.09,4370,209.789451599121,0.13400000333786,0,2170.98663085938,0.00999999977648258,1963.95765625,0.00999999977648258,2296.1326953125,0.00999999977648258,,,11.7903253033879,11.9610267736428,12.5665654988169,,25,2170.98663085938,1963.95765625,2296.1326953125,
,13918674.33,4370,205.78150177002,0.13400000333786,0,2169.88389648437,0.00999999977648258,1957.28016113281,0.00999999977648258,2293.19078125,0.00999999977648258,,,26.0949290209259,25.2369237332324,20.4776609651507,,25,2169.88389648437,1957.28016113281,2293.19078125,
,13918794.31,4370,201.781753540039,0.13400000333786,0,2165.68491210938,0.00999999977648258,1959.02336425781,0.00999999977648258,2280.42883789062,0.00999999977648258,,,27.86590941453,23.075943784095,24.5388657537291,,25,2165.68491210938,1959.02336425781,2280.42883789062,
,13918914.23,4370,197.778701782227,0.13400000333786,0,2162.20340820313,0.00999999977648258,1944.76834960938,0.00999999977648258,2278.28743164063,0.00999999977648258,,,12.4119009978888,11.0473539443635,10.3852846293681,,25,2162.20340820313,1944.76834960938,2278.28743164063,
,13919034.13,4370,193.78295135498,0.13400000333786,0,2155.5767578125,0.00999999977648258,1947.60359863281,0.00999999977648258,2288.6814453125,0.00999999977648258,,,38.7355498889951,35.1707596839684,31.4940349705425,,25,2155.5767578125,1947.60359863281,2288.6814453125,
,13919154.70,4370,189.77335357666,0.13400000333786,0,2149.4117578125,0.00999999977648258,1939.60109863281,0.00999999977648258,2276.27177734375,0.00999999977648258,,,8.29336522668892,9.7227734856666,9.45683937535948,,25,2149.4117578125,1939.60109863281,2276.27177734375,
,13919274.47,4370,185.778854370117,0.13400000333786,0,2153.55168945313,0.00999999977648258,1933.138046875,0.00999999977648258,2266.71697265625,0.00999999977648258,,,27.2898382994112,20.9319304782505,34.7670824439635,,25,2153.55168945313,1933.138046875,2266.71697265625,
,13919394.77,4370,181.773750305176,0.13400000333786,0,2143.9081640625,0.00999999977648258,1925.65940917969,0.00999999977648258,2263.230078125,0.00999999977648258,,,30.0582215247522,42.9157062256543,23.8013114973436,,25,2143.9081640625,1925.65940917969,2263.230078125,
,13919514.00,4370,177.798805236816,0.13400000333786,0,2132.02983398437,0.00999999977648258,1920.01233398437,0.00999999977648258,2270.89701171875,0.00999999977648258,,,26.8353131715122,41.850139070362,35.2570287736942,,25,2132.02983398437,1920.01233398437,2270.89701171875,
,13919634.67,4370,173.781951904297,0.13400000333786,0,2131.75139648438,0.00999999977648258,1922.58034179688,0.00999999977648258,2257.784453125,0.00999999977648258,,,3.5725622158284,3.28694839665597,3.06418491059555,,25,2131.75139648438,1922.58034179688,2257.784453125,
,13919754.63,4370,169.784248352051,0.13400000333786,0,2127.30724609375,0.00999999977648258,1918.657734375,0.00999999977648258,2253.27030273438,0.00999999977648258,,,14.9657951675254,19.1102085772785,12.1501044311492,,25,2127.30724609375,1918.657734375,2253.27030273438,
,13919874.25,4370,165.780700683594,0.13400000333786,0,2123.90719726563,0.00999999977648258,1914.80599121094,0.00999999977648258,2242.16291015625,0.00999999977648258,,,22.3408001944109,22.2268539950752,23.5433136153205,,25,2123.90719726563,1914.80599121094,2242.16291015625,
,13919993.77,4370,161.80419921875,0.13400000333786,0,2116.52735351562,0.00999999977648258,1910.86911621094,0.00999999977648258,2245.62643554688,0.00999999977648258,,,19.8366171341338,12.3790635219784,17.1004723916056,,25,2116.52735351562,1910.86911621094,2245.62643554688,
,13920114.64,4370,157.772399902344,0.13400000333786,0,2107.8184765625,0.00999999977648258,1899.213671875,0.00999999977648258,2237.35715820313,0.00999999977648258,,,14.1574130692334,11.807722394716,17.455120481155,,25,2107.8184765625,1899.213671875,2237.35715820313,
,13920235.03,4370,153.759902954102,0.13400000333786,0,2109.87569335938,0.00999999977648258,1897.94331542969,0.00999999977648258,2246.42439453125,0.00999999977648258,,,22.0613199347215,20.0881399096774,28.6659404789781,,25,2109.87569335938,1897.94331542969,2246.42439453125,
,13920354.50,4370,149.775550842285,0.13400000333786,0,2095.79985839844,0.00999999977648258,1885.55432128906,0.00999999977648258,2222.77639648437,0.00999999977648258,,,27.8765959961024,35.3174901660491,32.4765790398044,,25,2095.79985839844,1885.55432128906,2222.77639648437,
,13920475.58,4370,145.741149902344,0.13400000333786,0,2096.98514648438,0.00999999977648258,1888.41514160156,0.00999999977648258,2223.7970703125,0.00999999977648258,,,14.0154967445706,16.406184934277,27.6709366567754,,25,2096.98514648438,1888.41514160156,2223.7970703125,
,13920595.06,4370,141.762145996094,0.13400000333786,0,2093.78005859375,0.00999999977648258,1881.17772460938,0.00999999977648258,2223.29591796875,0.00999999977648258,,,21.9368928537832,20.5921284077365,30.3522527435944,,25,2093.78005859375,1881.17772460938,2223.29591796875,
,13920715.20,4370,137.766998291016,0.13400000333786,0,2088.38975097656,0.00999999977648258,1870.91307617188,0.00999999977648258,2212.18099609375,0.00999999977648258,,,29.5489516119816,29.0778542181209,32.3844701010836,,25,2088.38975097656,1870.91307617188,2212.18099609375,
,13920835.36,4370,133.766593933105,0.13400000333786,0,2084.68077636719,0.00999999977648258,1881.14695800781,0.00999999977648258,2216.2787109375,0.00999999977648258,,,27.6404061159513,36.3449906286533,47.1923222616017,,25,2084.68077636719,1881.14695800781,2216.2787109375,
,13920955.13,4370,129.763801574707,0.13400000333786,0,2075.42603515625,0.00999999977648258,1866.36525390625,0.00999999977648258,2201.3384375,0.00999999977648258,,,13.7346659283087,21.9663943889006,26.8060546913454,,25,2075.42603515625,1866.36525390625,2201.3384375,
,13921073.44,4370,125.837051391602,0.13400000333786,0,2073.2472265625,0.00999999977648258,1862.84030273438,0.00999999977648258,2203.0457421875,0.00999999977648258,,,10.2389224890711,10.2443658519874,15.4168437659267,,25,2073.2472265625,1862.84030273438,2203.0457421875,
,13921194.75,4370,121.768600463867,0.13400000333786,0,2063.93474609375,0.00999999977648258,1855.97864257812,0.00999999977648258,2196.77342773438,0.00999999977648258,,,6.21053785674284,4.6884060118706,7.38741631671261,,25,2063.93474609375,1855.97864257812,2196.77342773438,
,13921314.36,4370,117.774349212646,0.13400000333786,0,2063.60366699219,0.00999999977648258,1855.31255859375,0.00999999977648258,2196.48530273438,0.00999999977648258,,,9.39298365063181,13.3259339551403,12.9354768010951,,25,2063.60366699219,1855.31255859375,2196.48530273438,
,13921435.31,4370,113.771549224854,0.13400000333786,0,2057.07080078125,0.00999999977648258,1864.17504882813,0.00999999977648258,2177.00287109375,0.00999999977648258,,,17.0192554603437,17.7560095671728,16.1835060399234,,25,2057.07080078125,1864.17504882813,2177.00287109375,
,13921554.94,4370,109.754150390625,0.13400000333786,0,2056.20109375,0.00999999977648258,1848.18481445313,0.00999999977648258,2194.21498046875,0.00999999977648258,,,28.5405785593971,38.6865331821834,43.9576156573846,,25,2056.20109375,1848.18481445313,2194.21498046875,
,13921674.77,4370,105.781349182129,0.13400000333786,0,2049.93418457031,0.00999999977648258,1830.087109375,0.00999999977648258,2172.58455078125,0.00999999977648258,,,43.8361281170348,44.7426688840359,51.1310420235781,,25,2049.93418457031,1830.087109375,2172.58455078125,
,13921794.64,4370,101.782649993896,0.13400000333786,0,2045.35983886719,0.00999999977648258,1837.161640625,0.00999999977648258,2188.00337890625,0.00999999977648258,,,39.8103627597421,42.8525915152236,65.8151849956394,,25,2045.35983886719,1837.161640625,2188.00337890625,
,13921915.25,4370,97.7591972351074,0.13400000333786,0,2036.02108886719,0.00999999977648258,1828.46752929688,0.00999999977648258,2187.78857421875,0.00999999977648258,,,49.5534136170721,44.1371588906742,67.9093630374998,,25,2036.02108886719,1828.46752929688,2187.78857421875,
,13922035.39,4370,93.7365531921387,0.13400000333786,0,2043.23306640625,0.00999999977648258,1825.09150878906,0.00999999977648258,2174.7687109375,0.00999999977648258,,,35.9984329645951,35.9124020274851,59.1654369816799,,25,2043.23306640625,1825.09150878906,2174.7687109375,
,13922154.30,4370,89.8226509094238,0.13400000333786,0,2026.6022265625,0.00999999977648258,1819.06178222656,0.00999999977648258,2163.69086914063,0.00999999977648258,,,12.8035492716619,14.1829033908244,29.8813431952661,,25,2026.6022265625,1819.06178222656,2163.69086914063,
,13922274.53,4370,85.7436485290527,0.13400000333786,0,2026.15031738281,0.00999999977648258,1818.80665527344,0.00999999977648258,2168.2883984375,0.00999999977648258,,,6.14310924181411,6.53001719778275,24.0048694015603,,25,2026.15031738281,1818.80665527344,2168.2883984375,
,13922395.02,4370,81.7891502380371,0.13400000333786,0,2029.57688964844,0.00999999977648258,1819.77104980469,0.00999999977648258,2168.07940429688,0.00999999977648258,,,27.3510636243993,29.8748566955944,51.5434682360389,,25,2029.57688964844,1819.77104980469,2168.07940429688,
,13922511.64,4370,77.8844985961914,0.13400000333786,0,2018.02580566406,0.00999999977648258,1808.49393066406,0.00999999977648258,2159.86208984375,0.00999999977648258,,,29.6180593277034,34.0090051793313,56.1041280796529,,25,2018.02580566406,1808.49393066406,2159.86208984375,
,13922633.59,4370,73.850700378418,0.13400000333786,0,2010.70331542969,0.00999999977648258,1806.52670898438,0.00999999977648258,2155.034609375,0.00999999977648258,,,28.9224063512789,32.5309216716183,52.4999820879142,,25,2010.70331542969,1806.52670898438,2155.034609375,
,13922751.88,4370,69.8391494750977,0.13400000333786,0,2009.69340820313,0.00999999977648258,1808.34440917969,0.00999999977648258,2152.50818359375,0.00999999977648258,,,10.9807584700222,14.3009357687934,18.2367261003535,,25,2009.69340820313,1808.34440917969,2152.50818359375,
,13922875.03,4370,65.7877502441406,0.13400000333786,0,2004.73131835938,0.00999999977648258,1796.37360351563,0.00999999977648258,2146.7391796875,0.00999999977648258,,,8.88308262652808,10.3585169968717,13.9741305957339,,25,2004.73131835938,1796.37360351563,2146.7391796875,
,13922993.92,4370,61.7947998046875,0.13400000333786,0,1994.31704589844,0.00999999977648258,1783.02684570313,0.00999999977648258,2141.07284179687,0.00999999977648258,,,15.2770334577328,24.5782166822404,33.2475846259491,,25,1994.31704589844,1783.02684570313,2141.07284179687,
,13923114.97,4370,57.7766513824463,0.13400000333786,0,1996.16166015625,0.00999999977648258,1787.79641601563,0.00999999977648258,2143.30966796875,0.00999999977648258,,,8.59866557128576,9.96455423694558,17.2987496340178,,25,1996.16166015625,1787.79641601563,2143.30966796875,
,13923234.09,4370,53.7924003601074,0.13400000333786,0,1988.88045898438,0.00999999977648258,1776.00708007813,0.00999999977648258,2130.5146484375,0.00999999977648258,,,8.06527609176007,7.10361250678109,8.64994905213168,,25,1988.88045898438,1776.00708007813,2130.5146484375,
,13923354.77,4370,49.7805004119873,0.13400000333786,0,1983.37668457031,0.00999999977648258,1773.43953613281,0.00999999977648258,2129.18166992187,0.00999999977648258,,,2.71643895676937,3.05718890450968,4.31797887345582,,25,1983.37668457031,1773.43953613281,2129.18166992187,
,13923474.47,4370,45.7805995941162,0.13400000333786,0,1980.69651367188,0.00999999977648258,1770.74693847656,0.00999999977648258,2125.4503125,0.00999999977648258,,,7.3960562199104,8.848147021639,6.1859363028905,,25,1980.69651367188,1770.74693847656,2125.4503125,
,13923595.34,4370,41.7761001586914,0.13400000333786,0,1974.70301269531,0.00999999977648258,1765.36539550781,0.00999999977648258,2118.35647460937,0.00999999977648258,,,3.81068114530998,3.86613953670922,4.78803416698165,,25,1974.70301269531,1765.36539550781,2118.35647460937,
,13923714.42,4370,37.7908515930176,0.13400000333786,0,1974.89302734375,0.00999999977648258,1763.380546875,0.00999999977648258,2120.99127929687,0.00999999977648258,,,7.89552609689845,7.11961831918835,11.9835012371039,,25,1974.89302734375,1763.380546875,2120.99127929687,
,13923836.00,4370,33.779899597168,0.13400000333786,0,1972.63138671875,0.00999999977648258,1762.517109375,0.00999999977648258,2120.5204296875,0.00999999977648258,,,3.83381801115296,5.29365465182185,5.54945122218976,,25,1972.63138671875,1762.517109375,2120.5204296875,
,13923955.36,4370,29.7714500427246,0.13400000333786,0,1971.69271484375,0.00999999977648258,1758.64152832031,0.00999999977648258,2120.9731640625,0.00999999977648258,,,5.66657268806206,5.89645875331819,6.96480618499899,,25,1971.69271484375,1758.64152832031,2120.9731640625,
,13924074.91,4370,25.7825498580933,0.13400000333786,0,1976.36299316406,0.00999999977648258,1760.48676269531,0.00999999977648258,2126.85079101563,0.00999999977648258,,,7.05910422609324,12.8103418052458,7.96837954974915,,25,1976.36299316406,1760.48676269531,2126.85079101563,
,13924194.56,4370,21.794750213623,0.13400000333786,0,1973.21366210938,0.00999999977648258,1762.18811523437,0.00999999977648258,2123.21557617188,0.00999999977648258,,,9.36097457073048,10.5694235344096,9.4355255218802,,25,1973.21366210938,1762.18811523437,2123.21557617188,
,13924314.34,4370,17.7898502349854,0.13400000333786,0,1976.2064453125,0.00999999977648258,1762.66879882813,0.00999999977648258,2129.10708007812,0.00999999977648258,,,5.7579794389888,5.48770742551662,5.63740365150964,,25,1976.2064453125,1762.66879882813,2129.10708007812,
,13924434.30,4370,13.8013000488281,0.13400000333786,0,1976.80217773437,0.00999999977648258,1759.01579101562,0.00999999977648258,2131.10595703125,0.00999999977648258,,,7.55097474430234,6.74604089165534,5.64866303180631,,25,1976.80217773437,1759.01579101562,2131.10595703125,
,13924556.03,4370,9.93879985809326,0.13400000333786,0,1985.78864746094,0.00999999977648258,1762.40672851563,0.00999999977648258,2150.51234375,0.00999999977648258,,,14.5056905111453,9.8378056517923,12.4168454246308,,25,1985.78864746094,1762.40672851563,2150.51234375,
,13925738.47,4370,9.11374998092651,0.13400000333786,0,1983.778203125,0.00999999977648258,1765.18192382813,0.00999999977648258,2143.33235351563,0.00999999977648258,,,4.13885896167844,5.10755879818546,9.02787317228148,,25,1983.778203125,1765.18192382813,2143.33235351563,
,13925834.72,4370,9.03634977340698,0.13400000333786,0,1983.92186523438,0.00999999977648258,1764.01597167969,0.00999999977648258,2143.2701171875,0.00999999977648258,,,5.21644401847632,6.77434810185913,10.3734765673981,,25,1983.92186523438,1764.01597167969,2143.2701171875,
,13925927.69,4370,8.95499992370605,0.13400000333786,0,1987.53044433594,0.00999999977648258,1769.46583007813,0.00999999977648258,2147.80868164062,0.00999999977648258,,,7.37086989091776,4.30247445751104,12.9299882792224,,25,1987.53044433594,1769.46583007813,2147.80868164062,
,13926021.61,4370,8.8779501914978,0.13400000333786,0,1979.59322753906,0.00999999977648258,1760.8361328125,0.00999999977648258,2142.94831054687,0.00999999977648258,,,6.06065273960799,5.84665400366576,16.5677538260491,,25,1979.59322753906,1760.8361328125,2142.94831054687,
,13926116.66,4370,8.79820013046265,0.13400000333786,0,1978.60560058594,0.00999999977648258,1771.16295898438,0.00999999977648258,2137.99904296875,0.00999999977648258,,,39.9398348959415,28.6423062437698,29.3208402316627,,25,1978.60560058594,1771.16295898438,2137.99904296875,
,13926218.00,4370,8.71304988861084,0.13400000333786,0,1983.26505371094,0.00999999977648258,1758.81283691406,0.00999999977648258,2141.80712890625,0.00999999977648258,,,29.2480187355282,29.5261787309179,35.9383307533155,,25,1983.26505371094,1758.81283691406,2141.80712890625,
,13926311.89,4370,8.63695001602173,0.13400000333786,0,1973.66345214844,0.00999999977648258,1763.56708007812,0.00999999977648258,2142.22279296875,0.00999999977648258,,,33.3116065769903,24.6834669314683,23.3546942421597,,25,1973.66345214844,1763.56708007812,2142.22279296875,
,13926409.64,4370,8.55430030822754,0.13400000333786,0,1981.56171386719,0.00999999977648258,1771.12784179687,0.00999999977648258,2149.32388671875,0.00999999977648258,,,17.1291286476088,22.5814997454056,22.4727520411219,,25,1981.56171386719,1771.12784179687,2149.32388671875,
,13926505.11,4370,8.4766001701355,0.13400000333786,0,1981.77876953125,0.00999999977648258,1760.95352050781,0.00999999977648258,2139.23188476563,0.00999999977648258,,,4.02272560646647,4.15843327666114,14.2149305073341,,25,1981.77876953125,1760.95352050781,2139.23188476563,
,13926599.69,4370,8.39665031433105,0.13400000333786,0,1985.51022460938,0.00999999977648258,1768.61737792969,0.00999999977648258,2141.03833984375,0.00999999977648258,,,5.80661417443134,6.5540442485715,8.0409126371854,,25,1985.51022460938,1768.61737792969,2141.03833984375,
,13926695.30,4370,8.31760025024414,0.13400000333786,0,1983.03016601562,0.00999999977648258,1762.27795410156,0.00999999977648258,2142.81231445313,0.00999999977648258,,,7.93534368546054,5.34010211989947,11.6471522123528,,25,1983.03016601562,1762.27795410156,2142.81231445313,
,13926793.28,4370,8.23495006561279,0.13400000333786,0,1982.02379882813,0.00999999977648258,1767.12374511719,0.00999999977648258,2146.14517578125,0.00999999977648258,,,18.1031541626334,10.2792508019673,19.1473855350166,,25,1982.02379882813,1767.12374511719,2146.14517578125,
,13926890.31,4370,8.15424966812134,0.13400000333786,0,1982.34457519531,0.00999999977648258,1765.94818847656,0.00999999977648258,2144.50271484375,0.00999999977648258,,,5.85313021750919,6.81401850827201,9.77560804884588,,25,1982.34457519531,1765.94818847656,2144.50271484375,
,13926985.95,4370,8.07490015029907,0.13400000333786,0,1979.90514160156,0.00999999977648258,1757.99470703125,0.00999999977648258,2138.81842773437,0.00999999977648258,,,25.5672535131269,21.8007442646084,17.4104418929605,,25,1979.90514160156,1757.99470703125,2138.81842773437,
,13927080.48,4370,7.99494981765747,0.13400000333786,0,1981.78009277344,0.00999999977648258,1765.60281738281,0.00999999977648258,2141.79999023437,0.00999999977648258,,,6.43024928693075,6.16203000596405,12.1790128817969,,25,1981.78009277344,1765.60281738281,2141.79999023437,
,13927180.98,4370,7.91459989547729,0.13400000333786,0,1985.60212890625,0.00999999977648258,1766.68274414062,0.00999999977648258,2148.81336914063,0.00999999977648258,,,18.9825946946519,19.5731576394953,16.4766717631193,,25,1985.60212890625,1766.68274414062,2148.81336914063,
,13927280.55,4370,7.83290004730225,0.13400000333786,0,1984.2542578125,0.00999999977648258,1766.49493652344,0.00999999977648258,2148.44899414063,0.00999999977648258,,,5.16926343480517,4.18061865618409,13.0157410889731,,25,1984.2542578125,1766.49493652344,2148.44899414063,
,13927368.42,4370,7.75629997253418,0.13400000333786,0,1979.91918945313,0.00999999977648258,1764.30214355469,0.00999999977648258,2144.70060546875,0.00999999977648258,,,4.14456288938418,6.03481581678351,11.2159456129802,,25,1979.91918945313,1764.30214355469,2144.70060546875,
,13927463.52,4370,7.67760014533997,0.13400000333786,0,1983.30716308594,0.00999999977648258,1772.50025878906,0.00999999977648258,2145.94983398437,0.00999999977648258,,,14.9509964538184,21.0223539747699,19.0458632283378,,25,1983.30716308594,1772.50025878906,2145.94983398437,
,13927561.33,4370,7.59465003013611,0.13400000333786,0,1979.54341796875,0.00999999977648258,1762.47580078125,0.00999999977648258,2147.706953125,0.00999999977648258,,,21.1970988492847,18.5104811612761,21.2038313858068,,25,1979.54341796875,1762.47580078125,2147.706953125,
,13927655.88,4370,7.51485013961792,0.13400000333786,0,1989.18384765625,0.00999999977648258,1761.14238769531,0.00999999977648258,2148.87317382812,0.00999999977648258,,,22.7352000995806,25.0147589914156,24.5417372288173,,25,1989.18384765625,1761.14238769531,2148.87317382812,
,13927753.36,4370,7.43605017662048,0.13400000333786,0,1979.82153320313,0.00999999977648258,1758.85740722656,0.00999999977648258,2144.05259765625,0.00999999977648258,,,6.00631699322824,4.85433834848386,17.5204137690949,,25,1979.82153320313,1758.85740722656,2144.05259765625,
,13927849.94,4370,7.35470008850098,0.13400000333786,0,1979.15612304688,0.00999999977648258,1768.24325683594,0.00999999977648258,2144.1985546875,0.00999999977648258,,,22.2937433748086,22.5865046460838,35.5767207821023,,25,1979.15612304688,1768.24325683594,2144.1985546875,
,13927945.41,4370,7.27279996871948,0.13400000333786,0,1985.69181640625,0.00999999977648258,1773.67538085938,0.00999999977648258,2155.47111328125,0.00999999977648258,,,11.1486739737617,18.2592623708021,14.8104434247135,,25,1985.69181640625,1773.67538085938,2155.47111328125,
,13928040.98,4370,7.19559979438782,0.13400000333786,0,1981.84431640625,0.00999999977648258,1763.94578613281,0.00999999977648258,2149.40041015625,0.00999999977648258,,,5.09550072846305,5.25004157731255,15.4392603743644,,25,1981.84431640625,1763.94578613281,2149.40041015625,
,13928135.31,4370,7.11605000495911,0.13400000333786,0,1984.85145019531,0.00999999977648258,1765.31785644531,0.00999999977648258,2144.09288085937,0.00999999977648258,,,4.21190536554731,4.23850693750042,15.6261406396925,,25,1984.85145019531,1765.31785644531,2144.09288085937,
,13928232.44,4370,7.03609991073608,0.13400000333786,0,1983.79512695313,0.00999999977648258,1766.85233398438,0.00999999977648258,2160.14643554688,0.00999999977648258,,,8.76715521683164,7.4218425939505,12.5296464083002,,25,1983.79512695313,1766.85233398438,2160.14643554688,
,13928329.47,4370,6.95429992675781,0.13400000333786,0,1972.80171875,0.00999999977648258,1752.19861328125,0.00999999977648258,2141.22358398438,0.00999999977648258,,,7.13694299937756,10.0529703923324,17.6469416145868,,25,1972.80171875,1752.19861328125,2141.22358398438,
,13928424.52,4370,6.87505006790161,0.13400000333786,0,1973.1683203125,0.00999999977648258,1752.27970703125,0.00999999977648258,2140.4709765625,0.00999999977648258,,,12.3497235985393,15.1669414616557,13.8320658330733,,25,1973.1683203125,1752.27970703125,2140.4709765625,
,13928519.72,4370,6.79844999313354,0.13400000333786,0,1969.32397460938,0.00999999977648258,1753.42164550781,0.00999999977648258,2134.60629882813,0.00999999977648258,,,11.4218321730855,19.2308126535211,19.9941015221488,,25,1969.32397460938,1753.42164550781,2134.60629882813,
,13928617.31,4370,6.71560001373291,0.13400000333786,0,1968.45647460937,0.00999999977648258,1745.17932617187,0.00999999977648258,2124.72189453125,0.00999999977648258,,,26.7359792600429,20.8028378304424,30.3944232770475,,25,1968.45647460937,1745.17932617187,2124.72189453125,
,13928711.02,4370,6.63599991798401,0.13400000333786,0,1970.52651367187,0.00999999977648258,1752.64508300781,0.00999999977648258,2132.59192382812,0.00999999977648258,,,17.3098746746459,16.6925173364435,18.5768812805864,,25,1970.52651367187,1752.64508300781,2132.59192382812,
,13928809.47,4370,6.55520009994507,0.13400000333786,0,1968.68479980469,0.00999999977648258,1750.16712402344,0.00999999977648258,2133.74811523437,0.00999999977648258,,,9.04111874765811,8.68304182999537,17.9617147220477,,25,1968.68479980469,1750.16712402344,2133.74811523437,
,13928906.02,4370,6.47435021400452,0.13400000333786,0,1970.58062011719,0.00999999977648258,1751.97414550781,0.00999999977648258,2137.08810546875,0.00999999977648258,,,4.82375116978063,3.74123238092131,11.0840123561052,,25,1970.58062011719,1751.97414550781,2137.08810546875,
,13929000.97,4370,6.39505004882813,0.13400000333786,0,1972.44057128906,0.00999999977648258,1750.98118652344,0.00999999977648258,2137.15305664063,0.00999999977648258,,,10.7390024489868,11.7274820014435,13.7688620129408,,25,1972.44057128906,1750.98118652344,2137.15305664063,
,13929098.36,4370,6.31299996376038,0.13400000333786,0,1966.85824707031,0.00999999977648258,1749.12614746094,0.00999999977648258,2128.85860351563,0.00999999977648258,,,24.6485802095332,27.4365311084162,33.2429619809008,,25,1966.85824707031,1749.12614746094,2128.85860351563,
,13929194.80,4370,6.23319983482361,0.13400000333786,0,1962.07831542969,0.00999999977648258,1746.77405761719,0.00999999977648258,2128.47913085937,0.00999999977648258,,,12.3424832924495,15.5906275587206,19.2083122115938,,25,1962.07831542969,1746.77405761719,2128.47913085937,
,13929290.03,4370,6.15474987030029,0.13400000333786,0,1947.5580078125,0.00999999977648258,1710.75262207031,0.00999999977648258,2117.8837109375,0.00999999977648258,,,24.0684673149824,24.9950950181952,25.8203922118646,,25,1947.5580078125,1710.75262207031,2117.8837109375,
,13929386.91,4370,6.07274985313416,0.13400000333786,0,1765.71481933594,0.00999999977648258,1514.63359375,0.00999999977648258,1961.15767089844,0.00999999977648258,,,19.0610122899298,11.3578808957,19.1595046922256,,25,1765.71481933594,1514.63359375,1961.15767089844,
,13929480.22,4370,5.99550008773804,0.13400000333786,0,1637.39686035156,0.00999999977648258,1402.71757324219,0.00999999977648258,1835.59931640625,0.00999999977648258,,,6.78080761215387,6.97592476890096,11.460636528753,,25,1637.39686035156,1402.71757324219,1835.59931640625,
,13929576.73,4370,5.91684985160828,0.13400000333786,0,1551.99352539063,0.00999999977648258,1335.58473632813,0.00999999977648258,1721.82094726562,0.00999999977648258,,,6.48693298583966,4.78055066292607,7.99512037951847,,25,1551.99352539063,1335.58473632813,1721.82094726562,
,13929673.98,4370,5.83325004577637,0.13400000333786,0,1525.97979980469,0.00999999977648258,1301.48909179688,0.00999999977648258,1674.78084472656,0.00999999977648258,,,7.13544867135604,8.14286416013572,11.6262697055321,,25,1525.97979980469,1301.48909179688,1674.78084472656,
,13929771.00,4370,5.75519990921021,0.13400000333786,0,1456.07032226563,0.00999999977648258,1205.64535644531,0.00999999977648258,1574.57655273437,0.00999999977648258,,,5.4942860699349,4.27751064546488,8.32247806376185,,25,1456.07032226563,1205.64535644531,1574.57655273437,
,13929864.22,4370,5.67659997940063,0.13400000333786,0,1358.88443359375,0.00999999977648258,1113.51294433594,0.00999999977648258,1442.39073242188,0.00999999977648258,,,24.2021057758666,23.202504332381,31.3830942345561,,25,1358.88443359375,1113.51294433594,1442.39073242188,
,13929962.56,4370,5.59464979171753,0.13400000333786,0,1210.66689941406,0.00999999977648258,813.869338378906,0.00999999977648258,1337.91255859375,0.00999999977648258,,,12.6274223154355,12.6368683017197,16.0614709601253,,25,1210.66689941406,813.869338378906,1337.91255859375,
,13930058.97,4370,5.51350021362305,0.13400000333786,0,862.993405761719,0.00999999977648258,684.904714355469,0.00999999977648258,984.429887695312,0.00999999977648258,,,12.6919541583693,9.40840579052537,13.3251335182973,,25,862.993405761719,684.904714355469,984.429887695312,
,13930152.78,4370,5.43630003929138,0.13400000333786,0,825.251362304688,0.00999999977648258,668.931728515625,0.00999999977648258,840.430048828125,0.00999999977648258,,,6.53193729933443,6.11292821395415,7.35434219446323,,25,825.251362304688,668.931728515625,840.430048828125,
,13930249.53,4370,5.35439991950989,0.13400000333786,0,797.562651367188,0.00999999977648258,618.08861328125,0.00999999977648258,814.887175292969,0.00999999977648258,,,15.1937755454269,8.97501280948833,12.4596294789914,,25,797.562651367188,618.08861328125,814.887175292969,
,13930344.80,4370,5.27555012702942,0.13400000333786,0,723.549621582031,0.00999999977648258,450.408779296875,0.00999999977648258,762.80361328125,0.00999999977648258,,,11.1380847840261,9.89894913141776,7.41326997586709,,25,723.549621582031,450.408779296875,762.80361328125,
,13930442.34,4370,5.19404983520508,0.13400000333786,0,493.716040039062,0.00999999977648258,176.1246875,0.00999999977648258,636.61548828125,0.00999999977648258,,,9.33062467741097,8.85890325018777,5.87931034662809,,25,493.716040039062,176.1246875,636.61548828125,
,13930537.53,4370,5.11614990234375,0.13400000333786,0,221.698094482422,0.00999999977648258,44.9685614013672,0.00999999977648258,540.016784667969,0.00999999977648258,,,5.99007701541438,2.95180759640614,5.49588782501525,,25,221.698094482422,44.9685614013672,540.016784667969,
,13930631.80,4370,5.03465008735657,0.13400000333786,0,70.8993179321289,0.00999999977648258,7.90353063583374,0.00999999977648258,517.735494384766,0.00999999977648258,,,4.68227092573684,3.16412692144678,4.28478668862843,,25,70.8993179321289,7.90353063583374,517.735494384766,
,13930727.33,4370,4.95774984359741,0.13400000333786,0,19.3979280471802,0.00999999977648258,1.20801468133926,0.00999999977648258,515.744836425781,0.00999999977648258,,,2.84784456740801,2.77061611802691,5.91362997968304,,25,19.3979280471802,1.20801468133926,515.744836425781,
,13930825.08,4370,4.87465000152588,0.13400000333786,0,9.43758642554283,0.00999999977648258,0.0546103024482727,0.00999999977648258,515.132667236328,0.00999999977648258,,,3.21831357594099,2.6197781342605,11.6908745200274,,25,9.43758642554283,0.0546103024482727,515.132667236328,
,13930921.95,4370,4.7957501411438,0.13400000333786,0,7.4431530714035,0.00999999977648258,0.254796698093414,0.00999999977648258,519.870261230469,0.00999999977648258,,,3.49122388752682,3.39935978818141,4.43855065920222,,25,7.4431530714035,0.254796698093414,519.870261230469,
,13931017.70,4370,4.71490001678467,0.13400000333786,0,5.65805878400803,0.00999999977648258,-0.108362262248993,0.00999999977648258,522.940850830078,0.00999999977648258,,,2.2740012374295,3.58064308805574,10.3253732798795,,25,5.65805878400803,-0.108362262248993,522.940850830078,
,13931109.84,4370,4.63819980621338,0.13400000333786,0,3.55069711208344,0.00999999977648258,0.643466925621033,0.00999999977648258,528.115788574219,0.00999999977648258,,,2.95705058400308,2.5972528752389,5.11486406131075,,25,3.55069711208344,0.643466925621033,528.115788574219,
,13931208.38,4370,4.55655002593994,0.13400000333786,0,3.65335609078407,0.00999999977648258,-0.100409374237061,0.00999999977648258,528.1609765625,0.00999999977648258,,,2.73673231813017,2.63069860418351,4.5463322984874,,25,3.65335609078407,-0.100409374237061,528.1609765625,
,13931305.03,4370,4.47565007209778,0.13400000333786,0,2.33655145764351,0.00999999977648258,-0.905378986597061,0.00999999977648258,534.949138183594,0.00999999977648258,,,3.10452792544898,1.98613565442593,5.27003390389671,,25,2.33655145764351,-0.905378986597061,534.949138183594,
,13931400.91,4370,4.39644980430603,0.13400000333786,0,2.025159907341,0.00999999977648258,-0.193240478038788,0.00999999977648258,539.23361328125,0.00999999977648258,,,2.27014024349272,3.06613594226152,5.00522229494146,,25,2.025159907341,-0.193240478038788,539.23361328125,
,13931498.56,4370,4.31404995918274,0.13400000333786,0,-0.67335502743721,0.00999999977648258,-0.0232191550731659,0.00999999977648258,542.809272460937,0.00999999977648258,,,2.18097909601583,2.95800850109221,6.46896223651967,,25,-0.67335502743721,-0.0232191550731659,542.809272460937,
,13931592.45,4370,4.23690009117126,0.13400000333786,0,1.26488309621811,0.00999999977648258,0.308508063554764,0.00999999977648258,548.49650390625,0.00999999977648258,,,2.88329223965494,3.35701933274348,6.74075920036528,,25,1.26488309621811,0.308508063554764,548.49650390625,
,13931691.69,4370,4.15310001373291,0.13400000333786,0,-0.926900326013565,0.00999999977648258,0.131310912370682,0.00999999977648258,554.888898925781,0.00999999977648258,,,3.26386156006229,3.39675574642461,11.2651408126797,,25,-0.926900326013565,0.131310912370682,554.888898925781,
,13931785.52,4370,4.07480001449585,0.13400000333786,0,-0.162416140437126,0.00999999977648258,-0.711537351608276,0.00999999977648258,558.634152832031,0.00999999977648258,,,2.55733412421316,2.82941304856341,6.11997565705978,,25,-0.162416140437126,-0.711537351608276,558.634152832031,
,13931880.33,4370,3.99705004692078,0.13400000333786,0,-0.0694872760772705,0.00999999977648258,0.193020308017731,0.00999999977648258,561.465407714844,0.00999999977648258,,,2.57745739707413,3.18337369438417,7.26918816851457,,25,-0.0694872760772705,0.193020308017731,561.465407714844,
,13931977.89,4370,3.91444993019104,0.13400000333786,0,-0.658483666181564,0.00999999977648258,0.852374492883682,0.00999999977648258,572.251311035156,0.00999999977648258,,,3.70490045102642,3.3157325508693,8.83777416956032,,25,-0.658483666181564,0.852374492883682,572.251311035156,
,13932073.00,4370,3.83314990997314,0.13400000333786,0,0.465044179558754,0.00999999977648258,0.57355448782444,0.00999999977648258,575.964943847656,0.00999999977648258,,,2.55891707998957,2.61607730221845,8.3191511586388,,25,0.465044179558754,0.57355448782444,575.964943847656,
,13932170.48,4370,3.7529000043869,0.13400000333786,0,-0.533292073607445,0.00999999977648258,0.0309154856204987,0.00999999977648258,580.917390136719,0.00999999977648258,,,3.10565996906424,3.33985608068068,8.73091609052989,,25,-0.533292073607445,0.0309154856204987,580.917390136719,
,13932264.91,4370,3.67645001411438,0.13400000333786,0,-0.147097257375717,0.00999999977648258,1.23097167253494,0.00999999977648258,586.755434570312,0.00999999977648258,,,2.9010562662852,2.96370492282607,8.60823004336648,,25,-0.147097257375717,1.23097167253494,586.755434570312,
,13932361.06,4370,3.59615004062653,0.13400000333786,0,-0.139384963512421,0.00999999977648258,0.665950360298157,0.00999999977648258,592.331870117187,0.00999999977648258,,,1.96321484366426,2.38804667866389,6.36284514771642,,25,-0.139384963512421,0.665950360298157,592.331870117187,
,13932457.00,4370,3.51484990119934,0.13400000333786,0,-0.39455483853817,0.00999999977648258,-0.0855020868778229,0.00999999977648258,599.021345214844,0.00999999977648258,,,2.86914449205611,2.83390540940859,8.0677154291685,,25,-0.39455483853817,-0.0855020868778229,599.021345214844,
,13932551.45,4370,3.4383499622345,0.13400000333786,0,0.603201568126678,0.00999999977648258,-0.108266998529434,0.00999999977648258,607.277045898437,0.00999999977648258,,,2.08393430857279,2.81396324027514,5.65749938147489,,25,0.603201568126678,-0.108266998529434,607.277045898437,
,13932650.38,4370,3.35430002212524,0.13400000333786,0,0.595882984399795,0.00999999977648258,0.0619098877906799,0.00999999977648258,612.149812011719,0.00999999977648258,,,3.66791789279119,3.10405483302421,6.42033879718088,,25,0.595882984399795,0.0619098877906799,612.149812011719,
,13932744.47,4370,3.27749991416931,0.13400000333786,0,0.511404895782471,0.00999999977648258,0.457164994478226,0.00999999977648258,620.427145996094,0.00999999977648258,,,2.25566940121366,3.20132744171632,6.58581565927658,,25,0.511404895782471,0.457164994478226,620.427145996094,
,13932842.20,4370,3.19200003147125,0.13400000333786,0,-0.0927877044677734,0.00999999977648258,0.610852270126343,0.00999999977648258,627.584987792969,0.00999999977648258,,,2.44646585123519,2.58696241969839,9.79336403157747,,25,-0.0927877044677734,0.610852270126343,627.584987792969,
,13932938.31,4370,3.11294996738434,0.13400000333786,0,-0.248325955867767,0.00999999977648258,0.341850824356079,0.00999999977648258,635.19287109375,0.00999999977648258,,,2.99812546842329,3.49622404738799,12.521298223067,,25,-0.248325955867767,0.341850824356079,635.19287109375,
,13933031.55,4370,3.03694999217987,0.13400000333786,0,-0.116174346804619,0.00999999977648258,-0.882925265431404,0.00999999977648258,645.371865234375,0.00999999977648258,,,3.04722520087549,2.64015620424523,11.646226302501,,25,-0.116174346804619,-0.882925265431404,645.371865234375,
,13933127.53,4370,2.95764994621277,0.13400000333786,0,0.433940298557282,0.00999999977648258,-0.53467642724514,0.00999999977648258,649.183498535156,0.00999999977648258,,,2.98574375706087,2.61592814229517,7.55009076059411,,25,0.433940298557282,-0.53467642724514,649.183498535156,
,13933223.47,4370,2.87870001792908,0.13400000333786,0,-0.783218950033188,0.00999999977648258,-1.78813934326172e-008,0.00999999977648258,660.641303710937,0.00999999977648258,,,3.13055242429154,2.56431400290174,12.4304917499038,,25,-0.783218950033188,-1.78813934326172e-008,660.641303710937,
,13933320.31,4370,2.79664993286133,0.13400000333786,0,0.78868766605854,0.00999999977648258,0.788687694072723,0.00999999977648258,669.966982421875,0.00999999977648258,,,2.62720734045892,2.67345217530108,14.0587127851223,,25,0.78868766605854,0.788687694072723,669.966982421875,
,13933416.63,4370,2.71714997291565,0.13400000333786,0,-0.426195516586304,0.00999999977648258,-0.154980204105377,0.00999999977648258,671.831359863281,0.00999999977648258,,,2.26119764204378,2.46571968597406,17.7699566539086,,25,-0.426195516586304,-0.154980204105377,671.831359863281,
,13933511.78,4370,2.63719999790192,0.13400000333786,0,-0.247701987624168,0.00999999977648258,-0.0387034183740616,0.00999999977648258,682.852434082031,0.00999999977648258,,,2.02187573000762,2.84726836738189,15.4767216547816,,25,-0.247701987624168,-0.0387034183740616,682.852434082031,
,13933607.97,4370,2.55699992179871,0.13400000333786,0,0.100716673135757,0.00999999977648258,-0.3799013453722,0.00999999977648258,686.691145019531,0.00999999977648258,,,2.4770835508474,2.46548565871728,8.58674601272468,,25,0.100716673135757,-0.3799013453722,686.691145019531,
,13933704.75,4370,2.47554993629456,0.13400000333786,0,0.927670617103577,0.00999999977648258,-0.123689426183701,0.00999999977648258,688.772238769531,0.00999999977648258,,,2.33714496881314,2.70674384776479,7.07028694633119,,25,0.927670617103577,-0.123689426183701,688.772238769531,
,13933802.64,4370,2.39335000514984,0.13400000333786,0,0.286494117379189,0.00999999977648258,0.193577116131783,0.00999999977648258,702.770078125,0.00999999977648258,,,2.99644365021181,2.93114359356663,8.00952195711702,,25,0.286494117379189,0.193577116131783,702.770078125,
,13933896.52,4370,2.31660008430481,0.13400000333786,0,-0.147045981884003,0.00999999977648258,0.472095079421997,0.00999999977648258,709.241638183594,0.00999999977648258,,,2.48879620080723,2.77216942241589,11.8223091579077,,25,-0.147045981884003,0.472095079421997,709.241638183594,
,13933993.00,4370,2.23644995689392,0.13400000333786,0,0.271323094964027,0.00999999977648258,0.0542645907402039,0.00999999977648258,716.951831054688,0.00999999977648258,,,2.63798885999508,2.73392741443686,10.0253977607464,,25,0.271323094964027,0.0542645907402039,716.951831054688,
,13934089.50,4370,2.15505003929138,0.13400000333786,0,0.372061445713043,0.00999999977648258,-0.434085478782654,0.00999999977648258,723.920092773438,0.00999999977648258,,,2.8454313070613,3.05488470768121,10.6732745284074,,25,0.372061445713043,-0.434085478782654,723.920092773438,
,13934185.95,4370,2.0743499994278,0.13400000333786,0,-0.248052430152893,0.00999999977648258,1.13949070453644,0.00999999977648258,733.072365722656,0.00999999977648258,,,2.69224094440299,2.39820186689922,11.3148710416948,,25,-0.248052430152893,1.13949070453644,733.072365722656,
,13934282.98,4373,1.99970000982285,0.13400000333786,0,0.0232000827789307,0.00999999977648258,-1.05946944952011,0.00999999977648258,739.0224609375,0.00999999977648258,,,2.60093738163385,2.67227373061405,8.01682805896902,,25,0.0232000827789307,-1.05946944952011,739.0224609375,