File: icepp/data/250307/250307-ch1Nb100-ch2Nb150-ch3NbAl.dat
[Header]
TITLE, default name
FILEOPENTIME,13799082.11,3/7/2025,4:16 PM
BYAPP, Resistivity, 2.1, 1.0
INFO, APPNAME, PPMS MultiVu Application, 1.5.11
INFO, , Sample1 Name
INFO, 1, Sample1 Cross Section
INFO, 1, Sample1 Length
INFO, Ohm, Sample1 Units
INFO, , Sample2 Name
INFO, 1, Sample2 Cross Section
INFO, 1, Sample2 Length
INFO, Ohm, Sample2 Units
INFO, , Sample3 Name
INFO, 1, Sample3 Cross Section
INFO, 1, Sample3 Length
INFO, Ohm, Sample3 Units
INFO, , Sample4 Name
INFO, 1, Sample4 Cross Section
INFO, 1, Sample4 Length
INFO, Ohm, Sample4 Units
FIELDGROUP, Resistivity,2,3,4,5,6,7,8,9,10,11,12,13,14,15,16,17,18,19,20,21,22,23,24,25,26,27,28,29,30,31,32,33,34,35,36,37,38,39,40,41
STARTUPGROUP, Resistivity
STARTUPAXIS, X, 2, LINEAR, AUTO
STARTUPAXIS, Y1, 7, LINEAR, AUTO
STARTUPAXIS, Y2, 9, LINEAR, AUTO
STARTUPAXIS, Y3, 11, LINEAR, AUTO
PLOT_APPEARANCE, ALL, HORZ_GRID_ON, VERT_GRID_ON, MARKERS_AND_LINES, ALL_LINES
DATATYPE, TIME, 2
DATATYPE, COMMENT, 1
[Data]
Comment,Time Stamp (sec),Status (code),Temperature (K),Magnetic Field (Oe),Sample Position (deg),Bridge 1 Resistivity (Ohm),Bridge 1 Excitation (uA),Bridge 2 Resistivity (Ohm),Bridge 2 Excitation (uA),Bridge 3 Resistivity (Ohm),Bridge 3 Excitation (uA),Bridge 4 Resistivity (Ohm),Bridge 4 Excitation (uA),Bridge 1 Std. Dev. (Ohm),Bridge 2 Std. Dev. (Ohm),Bridge 3 Std. Dev. (Ohm),Bridge 4 Std. Dev. (Ohm),Number of Readings,Bridge 1 Resistance (Ohms),Bridge 2 Resistance (Ohms),Bridge 3 Resistance (Ohms),Bridge 4 Resistance (Ohms),Signal 1 Vin (V),Signal 2 Vin (V),Digital Inputs (code),Drive 1 Iout (mA),Drive 1 Ipower (watts),Drive 2 Iout (mA),Drive 2 Ipower (watts),Pressure (),Map 20 (),Map 21 (),Map 22 (),Map 23 (),Map 24 (),Map 25 (),Map 26 (),Map 27 (),Map 28 (),Map 29 ()
,13799394.38,4370,298.077499389648,0.13400000333786,0,260.732020263672,99.9020004272461,123.268305358887,99.9020004272461,124.989606933594,99.9020004272461,,,0.00620961712426712,0.00523076200684731,0.00499396561799956,,25,260.732020263672,123.268305358887,124.989606933594,
,13799503.92,4374,291.289749145508,0.13400000333786,0,257.667485351563,99.9020004272461,121.636335754395,99.9020004272461,123.523826293945,99.9020004272461,,,0.153063202704797,0.0840538902314112,0.0742585597111278,,25,257.667485351563,121.636335754395,123.523826293945,
,13799543.91,4374,284.901351928711,0.13400000333786,0,254.365727539063,99.9020004272461,119.889867553711,99.9020004272461,121.941741027832,99.9020004272461,,,0.257363521703492,0.136271194385875,0.123442492653926,,25,254.365727539063,119.889867553711,121.941741027832,
,13799574.80,4374,279.080200195313,0.13400000333786,0,251.083375854492,99.9020004272461,118.118075561523,99.9020004272461,120.342401733398,99.9020004272461,,,0.295920316452161,0.158124973188334,0.141734813966637,,25,251.083375854492,118.118075561523,120.342401733398,
,13799605.28,4374,273.040802001953,0.13400000333786,0,247.537811889648,99.9020004272461,116.220283203125,99.9020004272461,118.626984863281,99.9020004272461,,,0.313746734431599,0.168267026461633,0.151433051510455,,25,247.537811889648,116.220283203125,118.626984863281,
,13799634.95,4370,266.998840332031,0.13400000333786,0,243.815701293945,99.9020004272461,114.227124328613,99.9020004272461,116.81455291748,99.9020004272461,,,0.322729358426245,0.174005447049572,0.157653173178804,,25,243.815701293945,114.227124328613,116.81455291748,
,13799670.77,4370,261.366806030273,0.13400000333786,0,240.001616821289,99.9020004272461,112.196997070313,99.9020004272461,114.954328613281,99.9020004272461,,,0.269330776652733,0.14362529154908,0.132381926783459,,25,240.001616821289,112.196997070313,114.954328613281,
,13799705.22,4370,255.545196533203,0.13400000333786,0,236.349775390625,99.9020004272461,110.23697845459,99.9020004272461,113.155223999023,99.9020004272461,,,0.272906427084492,0.145208661172704,0.134364774353165,,25,236.349775390625,110.23697845459,113.155223999023,
,13799742.06,4370,249.41015625,0.13400000333786,0,232.491867675781,99.9020004272461,108.133822937012,99.9020004272461,111.230567932129,99.9020004272461,,,0.275759908171748,0.14715497222085,0.1372786587951,,25,232.491867675781,108.133822937012,111.230567932129,
,13799778.00,4370,243.445648193359,0.13400000333786,0,228.660150756836,99.9020004272461,106.061541748047,99.9020004272461,109.355479736328,99.9020004272461,,,0.279118872778757,0.1527326192594,0.136866378461758,,25,228.660150756836,106.061541748047,109.355479736328,
,13799813.92,4370,237.429847717285,0.13400000333786,0,224.842842407227,99.9020004272461,103.983947753906,99.9020004272461,107.457830810547,99.9020004272461,,,0.290368630968066,0.157128072124958,0.144630234232672,,25,224.842842407227,103.983947753906,107.457830810547,
,13799851.98,4370,231.63680267334,0.13400000333786,0,221.100549316406,99.9020004272461,101.937542114258,99.9020004272461,105.626903381348,99.9020004272461,,,0.235538630648051,0.128778475707413,0.115484727501573,,25,221.100549316406,101.937542114258,105.626903381348,
,13799904.09,4374,225.814552307129,0.13400000333786,0,217.244715576172,99.9020004272461,99.804577331543,99.9020004272461,103.739678344727,99.9020004272461,,,0.207255143784715,0.115334906101444,0.103023067919608,,25,217.244715576172,99.804577331543,103.739678344727,
,13799938.94,4374,219.716400146484,0.13400000333786,0,213.642551879883,99.9020004272461,97.7980502319336,99.9020004272461,102.010075683594,99.9020004272461,,,0.310637439615563,0.174197739028737,0.150619430468788,,25,213.642551879883,97.7980502319336,102.010075683594,
,13799970.97,4374,213.489952087402,0.13400000333786,0,209.608428955078,99.9020004272461,95.5338436889649,99.9020004272461,100.069546813965,99.9020004272461,,,0.334725357270698,0.187598946391164,0.160869489222992,,25,209.608428955078,95.5338436889649,100.069546813965,
,13800001.17,4374,207.728393554688,0.13400000333786,0,205.772636108398,99.9020004272461,93.336982421875,99.9020004272461,98.240676574707,99.9020004272461,,,0.334350980657548,0.189271816840137,0.158398134360987,,25,205.772636108398,93.336982421875,98.240676574707,
,13800033.17,4370,201.839599609375,0.13400000333786,0,201.695443115234,99.9020004272461,91.0406182861328,99.9020004272461,96.30716796875,99.9020004272461,,,0.318300966586176,0.181953720553564,0.148501932704627,,25,201.695443115234,91.0406182861328,96.30716796875,
,13800069.92,4370,195.850303649902,0.13400000333786,0,197.473192749023,99.9020004272461,88.598401184082,99.9020004272461,94.2982629394531,99.9020004272461,,,0.301636116350541,0.172832174583657,0.140689627440954,,25,197.473192749023,88.598401184082,94.2982629394531,
,13800104.89,4370,189.990547180176,0.13400000333786,0,193.431868286133,99.9020004272461,86.2818634033203,99.9020004272461,92.4219491577148,99.9020004272461,,,0.298163440952592,0.171374582813057,0.138127347624093,,25,193.431868286133,86.2818634033203,92.4219491577148,
,13800140.86,4370,184.050598144531,0.13400000333786,0,189.283321533203,99.9020004272461,83.9004287719727,99.9020004272461,90.5158242797852,99.9020004272461,,,0.302916390709413,0.173338799608324,0.138192301460184,,25,189.283321533203,83.9004287719727,90.5158242797852,
,13800175.73,4370,178.17960357666,0.13400000333786,0,185.184925537109,99.9020004272461,81.5564294433594,99.9020004272461,88.6447625732422,99.9020004272461,,,0.325381253453664,0.196612439047526,0.146987430500703,,25,185.184925537109,81.5564294433594,88.6447625732422,
,13800211.98,4370,172.185050964355,0.13400000333786,0,180.927759399414,99.9020004272461,79.1357510375977,99.9020004272461,86.7174087524414,99.9020004272461,,,0.310905925294218,0.175132000070799,0.138290938567261,,25,180.927759399414,79.1357510375977,86.7174087524414,
,13800247.78,4370,166.20240020752,0.13400000333786,0,176.683963012695,99.9020004272461,76.7223587036133,99.9020004272461,84.8182415771484,99.9020004272461,,,0.309982359318372,0.176188905456648,0.138070176877333,,25,176.683963012695,76.7223587036133,84.8182415771484,
,13800283.84,4370,160.297203063965,0.13400000333786,0,172.423372192383,99.9020004272461,74.2874548339844,99.9020004272461,82.9047738647461,99.9020004272461,,,0.30414081896767,0.17163088539109,0.135777787032583,,25,172.423372192383,74.2874548339844,82.9047738647461,
,13800320.53,4370,154.517593383789,0.13400000333786,0,168.17983581543,99.9020004272461,71.9149523925781,99.9020004272461,81.0505331420898,99.9020004272461,,,0.297882425096062,0.16782136406775,0.131644559077699,,25,168.17983581543,71.9149523925781,81.0505331420898,
,13800358.78,4374,148.499847412109,0.13400000333786,0,163.791826782227,99.9020004272461,69.4358627319336,99.9020004272461,79.1284140014648,99.9020004272461,,,0.31023056726824,0.173016015716101,0.136196319236688,,25,163.791826782227,69.4358627319336,79.1284140014648,
,13800397.22,4374,142.683647155762,0.13400000333786,0,159.452408447266,99.9020004272461,67.0528945922852,99.9020004272461,77.2505157470703,99.9020004272461,,,0.292106591958051,0.162002076811233,0.126052775191478,,25,159.452408447266,67.0528945922852,77.2505157470703,
,13800437.48,4374,136.623901367188,0.13400000333786,0,154.923468017578,99.9020004272461,64.5380819702148,99.9020004272461,75.3118310546875,99.9020004272461,,,0.293340280851848,0.160835464865993,0.123717500650812,,25,154.923468017578,64.5380819702148,75.3118310546875,
,13800477.63,4374,130.774604797363,0.13400000333786,0,150.451019287109,99.9020004272461,62.089468536377,99.9020004272461,73.4168087768555,99.9020004272461,,,0.302038006645315,0.166464314675924,0.128007213622778,,25,150.451019287109,62.089468536377,73.4168087768555,
,13800518.64,4374,124.881950378418,0.13400000333786,0,145.895635375977,99.9020004272461,59.6297665405273,99.9020004272461,71.5067669677734,99.9020004272461,,,0.288819681840581,0.155859075636808,0.120751640012061,,25,145.895635375977,59.6297665405273,71.5067669677734,
,13800560.56,4374,118.974899291992,0.13400000333786,0,141.291326904297,99.9020004272461,57.1361585998535,99.9020004272461,69.5987658691406,99.9020004272461,,,0.287430352476129,0.15383307596898,0.117233440359365,,25,141.291326904297,57.1361585998535,69.5987658691406,
,13800603.17,4374,113.025352478027,0.13400000333786,0,136.648891601563,99.9020004272461,54.6078189086914,99.9020004272461,67.7002838134766,99.9020004272461,,,0.28878584962301,0.153232779939932,0.116357675844161,,25,136.648891601563,54.6078189086914,67.7002838134766,
,13800646.50,4374,107.099552154541,0.13400000333786,0,131.929986572266,99.9020004272461,52.0896078491211,99.9020004272461,65.7984051513672,99.9020004272461,,,0.282751542580671,0.152197319403386,0.113355006651731,,25,131.929986572266,52.0896078491211,65.7984051513672,
,13800690.27,4374,101.147846221924,0.13400000333786,0,127.154473876953,99.9020004272461,49.522339630127,99.9020004272461,63.9035789489746,99.9020004272461,,,0.286250076347003,0.151560266442958,0.110851061442781,,25,127.154473876953,49.522339630127,63.9035789489746,
,13800734.78,4374,95.2119483947754,0.13400000333786,0,122.325323181152,99.9020004272461,46.9347286987305,99.9020004272461,62.0249966430664,99.9020004272461,,,0.28308155602856,0.152021104651433,0.10928315512799,,25,122.325323181152,46.9347286987305,62.0249966430664,
,13800779.16,4374,89.2766494750977,0.13400000333786,0,117.486441345215,99.9020004272461,44.318910369873,99.9020004272461,60.1633451843262,99.9020004272461,,,0.291719431529356,0.159005340222093,0.113415243561999,,25,117.486441345215,44.318910369873,60.1633451843262,
,13800824.33,4374,83.2932014465332,0.13400000333786,0,112.56854309082,99.9020004272461,41.6826342773438,99.9020004272461,58.3436283874512,99.9020004272461,,,0.290119933317368,0.154659196143039,0.105185019419204,,25,112.56854309082,41.6826342773438,58.3436283874512,
,13800867.00,4374,77.3427505493164,0.13400000333786,0,107.801795959473,99.9020004272461,39.133856048584,99.9020004272461,56.619342956543,99.9020004272461,,,0.292446189530459,0.157154559809876,0.104911349911667,,25,107.801795959473,39.133856048584,56.619342956543,
,13800910.09,4374,71.2506484985352,0.13400000333786,0,102.943588562012,99.9020004272461,36.534880065918,99.9020004272461,54.8978709411621,99.9020004272461,,,0.300276882621644,0.1600221028274,0.103256749754477,,25,102.943588562012,36.534880065918,54.8978709411621,
,13800950.75,4374,65.5053482055664,0.13400000333786,0,98.4016250610352,99.9020004272461,34.1103186035156,99.9020004272461,53.3583903503418,99.9020004272461,,,0.298996700844821,0.159135182344382,0.0991816959440428,,25,98.4016250610352,34.1103186035156,53.3583903503418,
,13800990.19,4374,59.5120506286621,0.13400000333786,0,93.7622863769531,99.9020004272461,31.6732004547119,99.9020004272461,51.8690010070801,99.9020004272461,,,0.305566543906291,0.161147908614326,0.0974057165390678,,25,93.7622863769531,31.6732004547119,51.8690010070801,
,13801029.23,4374,53.3632984161377,0.13400000333786,0,89.3020419311523,99.9020004272461,29.2981861877441,99.9020004272461,50.4813403320313,99.9020004272461,,,0.301769509507007,0.160569008924695,0.0919353985733573,,25,89.3020419311523,29.2981861877441,50.4813403320313,
,13801063.36,4374,47.2668991088867,0.13400000333786,0,85.2517813110352,99.9020004272461,27.1287076568604,99.9020004272461,49.2829872131348,99.9020004272461,,,0.313990945813206,0.16624173098151,0.0891752119915018,,25,85.2517813110352,27.1287076568604,49.2829872131348,
,13801095.55,4374,41.2113494873047,0.13400000333786,0,81.5440420532227,99.9020004272461,25.1900552368164,99.9020004272461,48.2485202026367,99.9020004272461,,,0.299975577777395,0.158130254400884,0.080775360893323,,25,81.5440420532227,25.1900552368164,48.2485202026367,
,13801121.73,4374,35.2031497955322,0.13400000333786,0,78.4751211547852,99.9020004272461,23.5720217132568,99.9020004272461,47.449881439209,99.9020004272461,,,0.294495563571996,0.154030301052573,0.0729437726015441,,25,78.4751211547852,23.5720217132568,47.449881439209,
,13801157.14,4370,29.515100479126,0.13400000333786,0,76.1166345214844,99.9020004272461,22.3303844451904,99.9020004272461,46.8802990722656,99.9020004272461,,,0.175086288742944,0.0928450179867623,0.0402721218932635,,25,76.1166345214844,22.3303844451904,46.8802990722656,
,13801192.69,4370,23.8529500961304,0.13400000333786,0,74.4314236450195,99.9020004272461,21.4219747924805,99.9020004272461,46.5043333435059,99.9020004272461,,,0.0818711223633798,0.0435866447425259,0.0169696776374101,,25,74.4314236450195,21.4219747924805,46.5043333435059,
,13801227.95,4374,17.3968000411987,0.13400000333786,0,73.3006652832031,99.9020004272461,20.8099765014648,99.9020004272461,46.2769989013672,99.9020004272461,,,0.0771702760807943,0.0418407244437583,0.0150027139367982,,25,73.3006652832031,20.8099765014648,46.2769989013672,
,13801262.45,4370,11.9550499916077,0.13400000333786,0,72.7972299194336,99.9020004272461,20.5375473022461,99.9020004272461,46.1804893493652,99.9020004272461,,,0.0203941620585396,0.0112613069029643,0.0035663629396793,,25,72.7972299194336,20.5375473022461,46.1804893493652,
,13801534.59,4375,9.78865003585815,0.13400000333786,0,72.6607739257813,9.98999977111816,20.4715840148926,9.98999977111816,46.1470936584473,9.98999977111816,,,0.00699259450046945,0.00782487566405504,0.00878330082112999,,25,72.6607739257813,20.4715840148926,46.1470936584473,
,13801574.22,4375,9.65794992446899,0.13400000333786,0,72.6379873657227,9.98999977111816,18.0073840881744,9.98999977111816,46.1450088500977,9.98999977111816,,,0.0206784966279596,6.64975359439181,0.00450647075166798,,25,72.6379873657227,18.0073840881744,46.1450088500977,
,13801847.34,4375,9.10660028457642,0.13400000333786,0,51.1901063153613,9.98999977111816,5.72740462697577,9.98999977111816,46.1475189208984,9.98999977111816,,,32.3515635862762,9.18178182533196,0.00382913955024729,,25,51.1901063153613,5.72740462697577,46.1475189208984,
,13802040.59,4375,8.62024974822998,0.13400000333786,0,3.09700413544313,9.98999977111816,-6.8760720314458e-005,9.98999977111816,46.1491040039063,9.98999977111816,,,13.9493778975898,0.00353797379411289,0.00760268635685033,,25,3.09700413544313,-6.8760720314458e-005,46.1491040039063,
,13802506.27,4375,7.80175018310547,0.13400000333786,0,0.00019096726551652,9.98999977111816,0.000160412471741438,9.98999977111816,0.000351379718631506,9.98999977111816,,,0.00377130065444785,0.00367280381152552,0.00330441961656629,,25,0.00019096726551652,0.000160412471741438,0.000351379718631506,
,13802861.97,4375,7.33664989471436,0.13400000333786,0,-0.00016039777896367,9.98999977111816,-0.00056513246614486,9.98999977111816,-0.00119897934026085,9.98999977111816,,,0.00316599302716498,0.00314153359161811,0.0031975407533621,,25,-0.00016039777896367,-0.00056513246614486,-0.00119897934026085,
,13803368.20,4374,6.5657000541687,0.13400000333786,0,-0.000992934860405512,9.98999977111816,0.000992934801615775,9.98999977111816,0.000519381284248084,9.98999977111816,,,0.0038867386489222,0.00328609862664331,0.00325197746498262,,25,-0.000992934860405512,0.000992934801615775,0.000519381284248084,
,13803531.64,4370,5.98245000839233,0.13400000333786,0,0.000442959424108267,9.98999977111816,-9.92839923128486e-005,9.98999977111816,0.000114558455534279,9.98999977111816,,,0.00204267039337343,0.00347520057072799,0.00333380691086504,,25,0.000442959424108267,-9.92839923128486e-005,0.000114558455534279,
,13803682.59,4370,5.47810006141663,0.13400000333786,0,-0.000213891500607133,9.98999977111816,0.000481255794875324,9.98999977111816,-0.000106945688603446,9.98999977111816,,,0.00256180508752613,0.00258719111401031,0.00278381926972342,,25,-0.000213891500607133,0.000481255794875324,-0.000106945688603446,
,13803831.73,4370,4.98114991188049,0.13400000333786,0,-0.00138248411123641,9.98999977111816,-0.000190950817195699,9.98999977111816,-0.000183312790468335,9.98999977111816,,,0.00226405544720926,0.00247205762298115,0.00292820735430523,,25,-0.00138248411123641,-0.000190950817195699,-0.000183312790468335,
,13803982.69,4370,4.47510004043579,0.13400000333786,0,0.000886062565841712,9.98999977111816,0.000496500619337894,9.98999977111816,-0.000672185425646603,9.98999977111816,,,0.00343173969523145,0.0030620645761933,0.00251497151219132,,25,0.000886062565841712,0.000496500619337894,-0.000672185425646603,
,13804137.58,4370,3.97804999351501,0.13400000333786,0,0.00113051523454487,9.98999977111816,-0.000519425928941928,9.98999977111816,-0.000420123892254196,9.98999977111816,,,0.00242874369366931,0.00306284701431714,0.00202675394201433,,25,0.00113051523454487,-0.000519425928941928,-0.000420123892254196,
,13804283.06,4370,3.47599995136261,0.13400000333786,0,-0.000190923510817811,9.98999977111816,-0.000206197362858802,9.98999977111816,-0.000374210020527244,9.98999977111816,,,0.00295777394282278,0.00293844581856163,0.00214955093196738,,25,-0.000190923510817811,-0.000206197362858802,-0.000374210020527244,
,13804432.81,4370,2.9768500328064,0.13400000333786,0,0.000320926727727056,9.98999977111816,-0.000840252051712014,9.98999977111816,9.16911178501323e-005,9.98999977111816,,,0.00281985648296839,0.00270064899177774,0.00304332924202651,,25,0.000320926727727056,-0.000840252051712014,9.16911178501323e-005,
,13804582.17,4370,2.47804999351501,0.13400000333786,0,-0.0010085189860547,9.98999977111816,-0.000122244687518105,9.98999977111816,3.05611890507862e-005,9.98999977111816,,,0.00329752872964826,0.00247979073286611,0.00320012552164315,,25,-0.0010085189860547,-0.000122244687518105,3.05611890507862e-005,
,13804731.95,4370,2.00010007619858,0.13400000333786,0,3.06116335559636e-005,9.98999977111816,-6.87453406862915e-005,9.98999977111816,-0.000404864744050428,9.98999977111816,,,0.00238876734537923,0.00212719496730518,0.00211495298929883,,25,3.06116335559636e-005,-6.87453406862915e-005,-0.000404864744050428,
,13808391.67,4370,6.08634996414185,0.13400000333786,0,-0.000435372099746019,9.98999977111816,0.000427733906544745,9.98999977111816,0.000328438578289933,9.98999977111816,,,0.00381428407921662,0.00332204070096684,0.00293770353573633,,25,-0.000435372099746019,0.000427733906544745,0.000328438578289933,
,13808432.98,4370,6.19809985160828,0.13400000333786,0,-0.000252043092623353,9.98999977111816,0.000442984772380441,9.98999977111816,-0.000267318425467238,9.98999977111816,,,0.00270880018349262,0.00299953333935441,0.00257197850717646,,25,-0.000252043092623353,0.000442984772380441,-0.000267318425467238,
,13808470.00,4370,6.32410001754761,0.13400000333786,0,0.000397158773848787,9.98999977111816,0.000305506727308966,9.98999977111816,-0.000282593730953522,9.98999977111816,,,0.00266275458779446,0.00349000512823486,0.00299340098727705,,25,0.000397158773848787,0.000305506727308966,-0.000282593730953522,
,13808505.45,4370,6.44309997558594,0.13400000333786,0,-0.000908891235012561,9.98999977111816,-2.09547579288483e-011,9.98999977111816,-0.000794325156603008,9.98999977111816,,,0.00206309518872254,0.00329796587618241,0.00353309741164554,,25,-0.000908891235012561,-2.09547579288483e-011,-0.000794325156603008,
,13808541.16,4370,6.56029987335205,0.13400000333786,0,-0.000320797399035655,9.98999977111816,-0.000206226984155364,9.98999977111816,0.000274979901732877,9.98999977111816,,,0.00289623784909339,0.00318142242038488,0.00305664059120403,,25,-0.000320797399035655,-0.000206226984155364,0.000274979901732877,
,13808577.48,4370,6.68190002441406,0.13400000333786,0,0.00100057274044957,9.98999977111816,-0.00119152173923794,9.98999977111816,-0.000122207399690524,9.98999977111816,,,0.00332504876848125,0.00339364456472328,0.003123113145974,,25,0.00100057274044957,-0.00119152173923794,-0.000122207399690524,
,13808613.36,4370,6.80214977264404,0.13400000333786,0,0.000114591249730438,9.98999977111816,0.000534759280271828,9.98999977111816,-0.000145148932351731,9.98999977111816,,,0.00329647764644748,0.00292849899763915,0.00341144300534473,,25,0.000114591249730438,0.000534759280271828,-0.000145148932351731,
,13808648.89,4370,6.92000007629395,0.13400000333786,0,-0.000641711159260012,9.98999977111816,-0.000649350544554181,9.98999977111816,-0.00142857125785667,9.98999977111816,,,0.00292594719261792,0.00282864879125424,0.00269018189149641,,25,-0.000641711159260012,-0.000649350544554181,-0.00142857125785667,
,13808684.55,4370,7.03810000419617,0.13400000333786,0,-0.000595760885626078,9.98999977111816,-0.000595760904834606,9.98999977111816,-0.000168035145034082,9.98999977111816,,,0.00263167347045049,0.00259427671726788,0.00291411939534517,,25,-0.000595760885626078,-0.000595760904834606,-0.000168035145034082,
,13808721.53,4370,7.16110014915466,0.13400000333786,0,-0.000832695246208459,9.98999977111816,-0.000634408605401404,9.98999977111816,0.00084807054256089,9.98999977111816,,,0.00329965589866691,0.0025715826840844,0.00256157786231669,,25,-0.000832695246208459,-0.000634408605401404,0.00084807054256089,
,13808756.41,4370,7.2763500213623,0.13400000333786,0,-0.000168121801689267,9.98999977111816,-0.000382094979286194,9.98999977111816,-0.000863534724339843,9.98999977111816,,,0.00251505603826579,0.00231979188759799,0.00334027098044515,,25,-0.000168121801689267,-0.000382094979286194,-0.000863534724339843,
,13808793.44,4370,7.40079998970032,0.13400000333786,0,-0.00029018989065662,9.98999977111816,7.63657037168741e-005,9.98999977111816,-4.58194175735116e-005,9.98999977111816,,,0.00287064133613384,0.00299583533651671,0.00272160088119768,,25,-0.00029018989065662,7.63657037168741e-005,-4.58194175735116e-005,
,13808827.78,4370,7.51559996604919,0.13400000333786,0,-2.29097087867558e-005,9.98999977111816,5.34560577943921e-005,9.98999977111816,0.000305462970864028,9.98999977111816,,,0.0033545867503888,0.00396275716374175,0.00336226193814792,,25,-2.29097087867558e-005,5.34560577943921e-005,0.000305462970864028,
,13808864.70,4370,7.64000010490417,0.13400000333786,0,0.000557555125560611,9.98999977111816,-0.000213856797199696,9.98999977111816,-0.000664483504369855,9.98999977111816,,,0.00281143593180666,0.00256821253013938,0.00314268700083803,,25,0.000557555125560611,-0.000213856797199696,-0.000664483504369855,
,13808901.39,4370,7.76059985160828,0.13400000333786,0,-0.000313136229524389,9.98999977111816,-0.00136717749235686,9.98999977111816,0.0124422517488711,9.98999977111816,,,0.00322960301161347,0.00256163699555074,0.0168029574362864,,25,-0.000313136229524389,-0.00136717749235686,0.0124422517488711,
,13808937.39,4370,7.8816499710083,0.13400000333786,0,0.000206224925932474,9.98999977111816,-0.000779071945580654,9.98999977111816,3.8481111240387,9.98999977111816,,,0.00378172363398121,0.00262645891836639,1.4953301390986,,25,0.000206224925932474,-0.000779071945580654,3.8481111240387,
,13808972.61,4370,7.99734997749329,0.13400000333786,0,-0.000588061129674315,9.98999977111816,-0.000114557383349165,9.98999977111816,16.6702199554443,9.98999977111816,,,0.00295090925506747,0.00336728525300049,2.70582033513135,,25,-0.000588061129674315,-0.000114557383349165,16.6702199554443,
,13809008.23,4370,8.11710023880005,0.13400000333786,0,0.000152743177022785,9.98999977111816,-0.000397132238722406,9.98999977111816,46.1110943603516,9.98999977111816,,,0.00295193697976866,0.00285139200240493,0.00418511522943807,,25,0.000152743177022785,-0.000397132238722406,46.1110943603516,
,13809044.66,4370,8.23769998550415,0.13400000333786,0,0.000420164039824158,9.98999977111816,-0.000466000051237643,9.98999977111816,46.1362982177734,9.98999977111816,,,0.00325860852038825,0.00321265136053227,0.00351066000756679,,25,0.000420164039824158,-0.000466000051237643,46.1362982177734,
,13809079.70,4370,8.35579967498779,0.13400000333786,0,0.00047361203469336,9.98999977111816,0.000496544023626484,9.98999977111816,46.1391969299316,9.98999977111816,,,0.00317282456706942,0.00336119705175402,0.0038887967321266,,25,0.00047361203469336,0.000496544023626484,46.1391969299316,
,13809115.97,4370,8.47425031661987,0.13400000333786,0,0.000420131955179386,9.98999977111816,-0.00105414928053506,9.98999977111816,46.141647644043,9.98999977111816,,,0.00263010936204207,0.00330817532745818,0.00326640887767527,,25,0.000420131955179386,-0.00105414928053506,46.141647644043,
,13809152.19,4370,8.5967001914978,0.13400000333786,0,-0.000450648295809515,9.98999977111816,-0.00149706890573725,9.98999977111816,46.1406617736816,9.98999977111816,,,0.00281932020989816,0.00242663497801331,0.00390851205144247,,25,-0.000450648295809515,-0.00149706890573725,46.1406617736816,
,13809188.44,4370,8.71634960174561,0.13400000333786,0,-0.000328438594006002,9.98999977111816,-0.000381905327085406,9.98999977111816,46.1428700256348,9.98999977111816,,,0.00279001114570684,0.00268368324881604,0.0030501308425603,,25,-0.000328438594006002,-0.000381905327085406,46.1428700256348,
,13809223.28,4370,8.83319997787476,0.13400000333786,0,0.000198607862694189,9.98999977111816,-0.00103887175791897,9.98999977111816,46.1485000610352,9.98999977111816,,,0.00378503592191999,0.00307315696811356,0.00252826966471852,,25,0.000198607862694189,-0.00103887175791897,46.1485000610352,
,13809260.09,4370,8.95644998550415,0.13400000333786,0,72.4698007202148,9.98999977111816,0.00103887438075617,9.98999977111816,46.1496937561035,9.98999977111816,,,0.0222126195312304,0.00340290646500354,0.00325222245535597,,25,72.4698007202148,0.00103887438075617,46.1496937561035,
,13809296.92,4370,9.07684993743896,0.13400000333786,0,72.5825537109375,9.98999977111816,0.0004048466833774,9.98999977111816,46.1501518249512,9.98999977111816,,,0.00373009078669414,0.00229623972755589,0.00347600525843912,,25,72.5825537109375,0.0004048466833774,46.1501518249512,
,13809332.34,4370,9.19474983215332,0.13400000333786,0,72.6080541992188,9.98999977111816,4.58259857259691e-005,9.98999977111816,46.1463218688965,9.98999977111816,,,0.00305672970717581,0.00379057732078028,0.00303351920110214,,25,72.6080541992188,4.58259857259691e-005,46.1463218688965,
,13809368.19,4370,9.31624984741211,0.13400000333786,0,72.6247329711914,9.98999977111816,20.438438873291,9.98999977111816,46.1473680114746,9.98999977111816,,,0.00318055460258829,0.0080274271749728,0.00303265733526923,,25,72.6247329711914,20.438438873291,46.1473680114746,
,13809403.47,4370,9.4330997467041,0.13400000333786,0,72.6269049072266,9.98999977111816,20.4570452880859,9.98999977111816,46.1412211608887,9.98999977111816,,,0.00290260738573531,0.00251055687579333,0.00286953383393301,,25,72.6269049072266,20.4570452880859,46.1412211608887,
,13809439.44,4370,9.5516996383667,0.13400000333786,0,72.6372381591797,9.98999977111816,20.4622383880615,9.98999977111816,46.1428816223145,9.98999977111816,,,0.00485169171536623,0.00271414574272568,0.00477575098280746,,25,72.6372381591797,20.4622383880615,46.1428816223145,
,13809476.52,4370,9.67700004577637,0.13400000333786,0,72.686735534668,9.98999977111816,20.4768975067139,9.98999977111816,46.1697010803223,9.98999977111816,,,0.00397956636808009,0.00379402251768467,0.0036095310526737,,25,72.686735534668,20.4768975067139,46.1697010803223,
,13809511.64,4370,9.79329967498779,0.13400000333786,0,72.6536102294922,9.98999977111816,20.4704690551758,9.98999977111816,46.1457800292969,9.98999977111816,,,0.00261411245716679,0.00339119998659508,0.00391104377723447,,25,72.6536102294922,20.4704690551758,46.1457800292969,
,13809548.19,4370,9.91515016555786,0.13400000333786,0,72.6637295532227,9.98999977111816,20.473752746582,9.98999977111816,46.1463070678711,9.98999977111816,,,0.00363132569496162,0.00342502002859745,0.00309108649721767,,25,72.6637295532227,20.473752746582,46.1463070678711,
,13809583.61,4370,10.0337500572205,0.13400000333786,0,72.6767510986328,9.98999977111816,20.4779544830322,9.98999977111816,46.1538316345215,9.98999977111816,,,0.00287498801072544,0.00409543847190923,0.00316058790624735,,25,72.6767510986328,20.4779544830322,46.1538316345215,
,13809619.73,4370,10.1538500785828,0.13400000333786,0,72.6841796875,9.98999977111816,20.4809175872803,9.98999977111816,46.1532746887207,9.98999977111816,,,0.00456837123710525,0.00341071187248725,0.00380439995691311,,25,72.6841796875,20.4809175872803,46.1532746887207,
,13809656.14,4370,10.2744998931885,0.13400000333786,0,72.6965780639649,9.98999977111816,20.4864737701416,9.98999977111816,46.159090423584,9.98999977111816,,,0.00391806911300472,0.00392436806660193,0.00376281323030495,,25,72.6965780639649,20.4864737701416,46.159090423584,
,13809690.23,4370,10.3896999359131,0.13400000333786,0,72.7199359130859,9.98999977111816,20.4939388275146,9.98999977111816,46.1717524719238,9.98999977111816,,,0.0039201359024796,0.00309102484593022,0.00367287664724542,,25,72.7199359130859,20.4939388275146,46.1717524719238,
,13809728.03,4370,10.5139002799988,0.13400000333786,0,72.7289208984375,9.98999977111816,20.4975541687012,9.98999977111816,46.1744444274902,9.98999977111816,,,0.0046973376331478,0.00274943917772375,0.00383869798698792,,25,72.7289208984375,20.4975541687012,46.1744444274902,
,13809763.69,4370,10.6336498260498,0.13400000333786,0,72.7396014404297,9.98999977111816,20.5011107635498,9.98999977111816,46.1790371704102,9.98999977111816,,,0.00406326034190833,0.00342073180690098,0.00392868620393179,,25,72.7396014404297,20.5011107635498,46.1790371704102,
,13809798.73,4370,10.7502503395081,0.13400000333786,0,72.7462637329102,9.98999977111816,20.505771484375,9.98999977111816,46.1786096191406,9.98999977111816,,,0.00356807632780707,0.0031791895280422,0.00335981891189094,,25,72.7462637329102,20.505771484375,46.1786096191406,
,13809835.31,4370,10.8736000061035,0.13400000333786,0,72.7155352783203,9.98999977111816,20.4972032928467,9.98999977111816,46.15806640625,9.98999977111816,,,0.00397771658312915,0.00438546720919135,0.00346624052383844,,25,72.7155352783203,20.4972032928467,46.15806640625,
,13809871.25,4370,10.9911003112793,0.13400000333786,0,72.7536267089844,9.98999977111816,20.5085976409912,9.98999977111816,46.1763717651367,9.98999977111816,,,0.00409381848877548,0.003455859326003,0.00562175656692235,,25,72.7536267089844,20.5085976409912,46.1763717651367,
,13809882.41,4370,11.0046997070313,0.13400000333786,0,72.7556741333008,9.98999977111816,20.5103095245361,9.98999977111816,46.1780247497559,9.98999977111816,,,0.00339241579575017,0.00495140245257259,0.00331589528997842,,25,72.7556741333008,20.5103095245361,46.1780247497559,