File: icepp/data/250318/250318_meas03_3D_mh_photolitho_IV1.dat
[Header]
TITLE, IV scan (0.1 to 1.0 & 1.0 to 15)
FILEOPENTIME,14745520.08,3/18/2025,3:10 PM
BYAPP, Resistivity, 2.1, 1.0
INFO, APPNAME, PPMS MultiVu Application, 1.5.11
INFO, , Sample1 Name
INFO, 1, Sample1 Cross Section
INFO, 1, Sample1 Length
INFO, Ohm, Sample1 Units
INFO, , Sample2 Name
INFO, 1, Sample2 Cross Section
INFO, 1, Sample2 Length
INFO, Ohm, Sample2 Units
INFO, , Sample3 Name
INFO, 1, Sample3 Cross Section
INFO, 1, Sample3 Length
INFO, Ohm, Sample3 Units
INFO, , Sample4 Name
INFO, 1, Sample4 Cross Section
INFO, 1, Sample4 Length
INFO, Ohm, Sample4 Units
FIELDGROUP, Resistivity,2,3,4,5,6,7,8,9,10,11,12,13,14,15,16,17,18,19,20,21,22,23,24,25,26,27,28,29,30,31,32,33,34,35,36,37,38,39,40,41
STARTUPGROUP, Resistivity
STARTUPAXIS, X, 2, LINEAR, AUTO
STARTUPAXIS, Y1, 7, LINEAR, AUTO
STARTUPAXIS, Y2, 9, LINEAR, AUTO
STARTUPAXIS, Y3, 11, LINEAR, AUTO
PLOT_APPEARANCE, ALL, HORZ_GRID_ON, VERT_GRID_ON, MARKERS_AND_LINES, ALL_LINES
DATATYPE, TIME, 2
DATATYPE, COMMENT, 1
[Data]
Comment,Time Stamp (sec),Status (code),Temperature (K),Magnetic Field (Oe),Sample Position (deg),Bridge 1 Resistivity (Ohm),Bridge 1 Excitation (uA),Bridge 2 Resistivity (Ohm),Bridge 2 Excitation (uA),Bridge 3 Resistivity (Ohm),Bridge 3 Excitation (uA),Bridge 4 Resistivity (Ohm),Bridge 4 Excitation (uA),Bridge 1 Std. Dev. (Ohm),Bridge 2 Std. Dev. (Ohm),Bridge 3 Std. Dev. (Ohm),Bridge 4 Std. Dev. (Ohm),Number of Readings,Bridge 1 Resistance (Ohms),Bridge 2 Resistance (Ohms),Bridge 3 Resistance (Ohms),Bridge 4 Resistance (Ohms),Signal 1 Vin (V),Signal 2 Vin (V),Digital Inputs (code),Drive 1 Iout (mA),Drive 1 Ipower (watts),Drive 2 Iout (mA),Drive 2 Ipower (watts),Pressure (),Map 20 (),Map 21 (),Map 22 (),Map 23 (),Map 24 (),Map 25 (),Map 26 (),Map 27 (),Map 28 (),Map 29 ()
,14747131.39,4369,1.9998499751091,0.0920000001788139,0,1345.3103515625,0.100000001490116,3.8905172252655,0.100000001490116,2803.23869140625,0.100000001490116,,,1.88021004974544,0.767420288103249,2.08576608785779,,25,1345.3103515625,3.8905172252655,2803.23869140625,
,14747141.81,4369,1.99970000982285,0.0920000001788139,0,1350.52560058594,0.200000002980232,5.09720607757568,0.200000002980232,2795.44149414062,0.200000002980232,,,1.19641203939145,0.452399601771968,1.05625354830439,,25,1350.52560058594,5.09720607757568,2795.44149414062,
,14747153.41,4369,1.9998499751091,0.0920000001788139,0,1358.57802246094,0.300000011920929,5.32849006652832,0.300000011920929,2789.80727539062,0.300000011920929,,,1.12060005803765,0.364671457211835,0.624144916172296,,25,1358.57802246094,5.32849006652832,2789.80727539062,
,14747164.14,4369,2.00020003318787,0.0920000001788139,0,1365.27361816406,0.400999993085861,5.62267221450806,0.400999993085861,2787.35250976563,0.400999993085861,,,0.64357312741149,0.483108500277902,0.488716534190787,,25,1365.27361816406,5.62267221450806,2787.35250976563,
,14747174.92,4369,1.99975001811981,0.0920000001788139,0,1372.45884765625,0.500999987125397,6.83179656982422,0.500999987125397,2786.58365234375,0.500999987125397,,,0.711651257258749,4.10389409649708,0.464411968761033,,25,1372.45884765625,6.83179656982422,2786.58365234375,
,14747185.66,4369,1.99919998645782,0.0920000001788139,0,1377.20431152344,0.601000010967255,4.18882452487946,0.601000010967255,2789.7096875,0.601000010967255,,,0.778474376530066,3.47435659809185,0.65246496887437,,25,1377.20431152344,4.18882452487946,2789.7096875,
,14747196.69,4369,2.0003000497818,0.0920000001788139,0,1382.13404296875,0.700999975204468,5.75048056125641,0.700999975204468,2794.58630859375,0.700999975204468,,,0.907590107250081,4.49051761176495,0.558066230722899,,25,1382.13404296875,5.75048056125641,2794.58630859375,
,14747207.70,4369,1.99965000152588,0.0920000001788139,0,1388.99903808594,0.800999999046326,6.45165596008301,0.800999999046326,2799.60637695313,0.800999999046326,,,0.650685228427023,3.64922037858373,0.460048707658644,,25,1388.99903808594,6.45165596008301,2799.60637695313,
,14747218.64,4369,1.99959999322891,0.0920000001788139,0,1394.54263183594,0.898999989032745,7.39920078277588,0.898999989032745,2804.82900390625,0.898999989032745,,,0.85916681314714,3.85435646881886,0.233506223697369,,25,1394.54263183594,7.39920078277588,2804.82900390625,
,14747228.78,4369,1.9996999502182,0.0920000001788139,0,1400.1694921875,0.999000012874603,13.3612923240662,0.999000012874603,2811.9626171875,0.999000012874603,,,1.19504199140175,23.7528265906864,1.48485757487341,,25,1400.1694921875,13.3612923240662,2811.9626171875,
,14747241.75,4369,2.00024998188019,0.0920000001788139,0,1399.81899902344,0.999000012874603,5.24044134140015,0.999000012874603,2811.88712890625,0.999000012874603,,,0.544034827672509,0.421085737731403,0.394569390407928,,25,1399.81899902344,5.24044134140015,2811.88712890625,
,14747252.25,4369,2,0.0920000001788139,0,1460.98998046875,2,5.8656085395813,2,2873.3520703125,2,,,0.6210996864443,1.05630116707769,1.14918130026558,,25,1460.98998046875,5.8656085395813,2873.3520703125,
,14747262.70,4369,1.99989992380142,0.0920000001788139,0,1506.82618164063,3,16.094065990448,3,2905.66145507813,3,,,0.8794283725342,5.16459091186898,0.722985008566848,,25,1506.82618164063,16.094065990448,2905.66145507813,
,14747273.52,4369,1.99989998340607,0.0920000001788139,0,1540.67258300781,4.00099992752075,1403.60029785156,4.00099992752075,2968.43453125,4.00099992752075,,,1.84944109229191,0.149789052113739,1.97781625147229,,25,1540.67258300781,1403.60029785156,2968.43453125,
,14747284.73,4369,1.99945002794266,0.0920000001788139,0,1556.72704589844,5,1895.45476074219,5,3264.97251953125,5,,,1.38643542269789,0.0717554999868179,2.96035519752146,,25,1556.72704589844,1895.45476074219,3264.97251953125,
,14747294.34,4369,1.99970000982285,0.0920000001788139,0,1568.08299804688,5.98400020599365,2721.78788085938,5.98400020599365,3864.30723632812,5.98400020599365,,,5.59069180411691,289.866164183581,3.24151680742406,,25,1568.08299804688,2721.78788085938,3864.30723632812,
,14747304.80,4369,2.00004994869232,0.0920000001788139,0,1578.64388183594,6.98600006103516,4630.016640625,6.98600006103516,4236.6546875,6.98600006103516,,,6.65937460982452,0.217874050419544,0.947188421426398,,25,1578.64388183594,4630.016640625,4236.6546875,
,14747315.53,4369,1.99989998340607,0.0920000001788139,0,1586.00228027344,7.98699998855591,4758.02505859375,7.98699998855591,4410.248828125,7.98699998855591,,,6.09625260819255,0.157694587942088,1.09227237003296,,25,1586.00228027344,4758.02505859375,4410.248828125,
,14747326.17,4369,1.99959999322891,0.0920000001788139,0,1588.800625,8.98900032043457,4818.65833984375,8.98900032043457,4481.82546875,8.98900032043457,,,6.35526461136395,0.105557757366512,1.04160748631531,,25,1588.800625,4818.65833984375,4481.82546875,
,14747336.86,4369,1.99979996681213,0.0920000001788139,0,1593.91717773437,9.98999977111816,4838.172421875,9.98999977111816,4534.305,9.98999977111816,,,7.49744955543796,0.108062498517365,0.838835090582706,,25,1593.91717773437,4838.172421875,4534.305,
,14747348.11,4369,1.99985003471375,0.0920000001788139,0,1596.38700195313,10.9919996261597,4853.4621484375,10.9919996261597,4562.80728515625,10.9919996261597,,,6.07958570838973,0.0914260801992111,0.67972337145802,,25,1596.38700195313,4853.4621484375,4562.80728515625,
,14747358.33,4369,1.99974995851517,0.0920000001788139,0,1598.08425292969,11.9930000305176,4866.87283203125,11.9930000305176,4573.5078125,11.9930000305176,,,5.28242117230073,0.109213914777829,1.45903089492558,,25,1598.08425292969,4866.87283203125,4573.5078125,
,14747369.17,4369,2.00009995698929,0.0920000001788139,0,1596.43272460938,12.9949998855591,4882.226640625,12.9949998855591,4587.40201171875,12.9949998855591,,,3.90479505968669,0.0975867596387722,0.558290192345343,,25,1596.43272460938,4882.226640625,4587.40201171875,
,14747379.81,4369,1.99990004301071,0.0920000001788139,0,1595.39327636719,13.996000289917,4891.3062109375,13.996000289917,4591.41689453125,13.996000289917,,,2.24799923821461,0.114217457613959,1.61677504315306,,25,1595.39327636719,4891.3062109375,4591.41689453125,
,14747390.78,4369,1.99989998340607,0.0920000001788139,0,1592.63219238281,14.9980001449585,4899.97396484375,14.9980001449585,4594.081171875,14.9980001449585,,,1.27348793714635,0.0815742341366566,1.01850821150375,,25,1592.63219238281,4899.97396484375,4594.081171875,