File: icepp/250308_3D_mh_photolitho_IV1.dat
[Header]
TITLE, IV scan 0.01 to 0.1
FILEOPENTIME,13890892.27,3/8/2025,5:46 PM
BYAPP, Resistivity, 2.1, 1.0
INFO, APPNAME, PPMS MultiVu Application, 1.5.11
INFO, , Sample1 Name
INFO, 1, Sample1 Cross Section
INFO, 1, Sample1 Length
INFO, Ohm, Sample1 Units
INFO, , Sample2 Name
INFO, 1, Sample2 Cross Section
INFO, 1, Sample2 Length
INFO, Ohm, Sample2 Units
INFO, , Sample3 Name
INFO, 1, Sample3 Cross Section
INFO, 1, Sample3 Length
INFO, Ohm, Sample3 Units
INFO, , Sample4 Name
INFO, 1, Sample4 Cross Section
INFO, 1, Sample4 Length
INFO, Ohm, Sample4 Units
FIELDGROUP, Resistivity,2,3,4,5,6,7,8,9,10,11,12,13,14,15,16,17,18,19,20,21,22,23,24,25,26,27,28,29,30,31,32,33,34,35,36,37,38,39,40,41
STARTUPGROUP, Resistivity
STARTUPAXIS, X, 2, LINEAR, AUTO
STARTUPAXIS, Y1, 7, LINEAR, AUTO
STARTUPAXIS, Y2, 9, LINEAR, AUTO
STARTUPAXIS, Y3, 11, LINEAR, AUTO
PLOT_APPEARANCE, ALL, HORZ_GRID_ON, VERT_GRID_ON, MARKERS_AND_LINES, ALL_LINES
DATATYPE, TIME, 2
DATATYPE, COMMENT, 1
[Data]
Comment,Time Stamp (sec),Status (code),Temperature (K),Magnetic Field (Oe),Sample Position (deg),Bridge 1 Resistivity (Ohm),Bridge 1 Excitation (uA),Bridge 2 Resistivity (Ohm),Bridge 2 Excitation (uA),Bridge 3 Resistivity (Ohm),Bridge 3 Excitation (uA),Bridge 4 Resistivity (Ohm),Bridge 4 Excitation (uA),Bridge 1 Std. Dev. (Ohm),Bridge 2 Std. Dev. (Ohm),Bridge 3 Std. Dev. (Ohm),Bridge 4 Std. Dev. (Ohm),Number of Readings,Bridge 1 Resistance (Ohms),Bridge 2 Resistance (Ohms),Bridge 3 Resistance (Ohms),Bridge 4 Resistance (Ohms),Signal 1 Vin (V),Signal 2 Vin (V),Digital Inputs (code),Drive 1 Iout (mA),Drive 1 Ipower (watts),Drive 2 Iout (mA),Drive 2 Ipower (watts),Pressure (),Map 20 (),Map 21 (),Map 22 (),Map 23 (),Map 24 (),Map 25 (),Map 26 (),Map 27 (),Map 28 (),Map 29 ()
,13891112.98,4369,3.00055003166199,0.13400000333786,0,312.12107421875,0.00999999977648258,26.1236487197876,0.00999999977648258,29.3445838165283,0.00999999977648258,,,7.99351216219937,8.72627549114894,10.0206552250438,,25,312.12107421875,26.1236487197876,29.3445838165283,
,13891121.67,4369,3.00069999694824,0.13400000333786,0,298.252008056641,0.0199999995529652,18.9992642593384,0.0199999995529652,32.2700676727295,0.0199999995529652,,,2.75399837967277,2.68830991638362,3.26127566154482,,25,298.252008056641,18.9992642593384,32.2700676727295,
,13891130.44,4369,2.99954998493195,0.13400000333786,0,300.810474853516,0.028999999165535,25.9248007202148,0.028999999165535,29.7384885406494,0.028999999165535,,,2.11891076469735,1.38318015581012,2.2254798955522,,25,300.810474853516,25.9248007202148,29.7384885406494,
,13891138.02,4369,2.99925005435944,0.13400000333786,0,299.620220947266,0.0390000008046627,21.2795797729492,0.0390000008046627,29.276463394165,0.0390000008046627,,,1.69340925800778,1.27240773673236,2.22025389949176,,25,299.620220947266,21.2795797729492,29.276463394165,
,13891146.22,4369,2.99909996986389,0.13400000333786,0,301.100191650391,0.0489999987185001,23.2368092346191,0.0489999987185001,31.259709777832,0.0489999987185001,,,1.60329312877025,0.664861778151808,1.67070705525908,,25,301.100191650391,23.2368092346191,31.259709777832,
,13891154.14,4369,2.99919998645782,0.13400000333786,0,302.211408691406,0.0610000006854534,21.4999449157715,0.0610000006854534,29.6434857177734,0.0610000006854534,,,1.2452068687672,0.665767496722187,1.64965948366882,,25,302.211408691406,21.4999449157715,29.6434857177734,
,13891162.41,4369,2.99940001964569,0.13400000333786,0,299.484304199219,0.0710000023245811,23.0860636901855,0.0710000023245811,31.2058706665039,0.0710000023245811,,,1.08466703637964,0.68758195597271,1.57758976839776,,25,299.484304199219,23.0860636901855,31.2058706665039,
,13891170.64,4369,3.00080001354218,0.13400000333786,0,300.850936279297,0.0810000002384186,25.4931841278076,0.0810000002384186,33.8517290496826,0.0810000002384186,,,1.51408025885852,8.48932603623375,10.3173343835212,,25,300.850936279297,25.4931841278076,33.8517290496826,
,13891179.25,4369,3.00109994411469,0.13400000333786,0,299.135141601563,0.0900000035762787,22.3593167114258,0.0900000035762787,30.6900843048096,0.0900000035762787,,,0.76905389306847,0.533428707774758,1.66115276072468,,25,299.135141601563,22.3593167114258,30.6900843048096,
,13891187.72,4369,2.99880003929138,0.13400000333786,0,300.744989013672,0.100000001490116,22.1102464294434,0.100000001490116,31.5825889587402,0.100000001490116,,,1.11239204133587,0.426878366912206,1.4231756152023,,25,300.744989013672,22.1102464294434,31.5825889587402,