File: icepp/250308_3D_mh_photolitho_IV_plus_fineDown1.dat
[Header]
TITLE, IV scan 10 to 5 (0.033 scan)
FILEOPENTIME,13903103.97,3/8/2025,9:10 PM
BYAPP, Resistivity, 2.1, 1.0
INFO, APPNAME, PPMS MultiVu Application, 1.5.11
INFO, , Sample1 Name
INFO, 1, Sample1 Cross Section
INFO, 1, Sample1 Length
INFO, Ohm, Sample1 Units
INFO, , Sample2 Name
INFO, 1, Sample2 Cross Section
INFO, 1, Sample2 Length
INFO, Ohm, Sample2 Units
INFO, , Sample3 Name
INFO, 1, Sample3 Cross Section
INFO, 1, Sample3 Length
INFO, Ohm, Sample3 Units
INFO, , Sample4 Name
INFO, 1, Sample4 Cross Section
INFO, 1, Sample4 Length
INFO, Ohm, Sample4 Units
FIELDGROUP, Resistivity,2,3,4,5,6,7,8,9,10,11,12,13,14,15,16,17,18,19,20,21,22,23,24,25,26,27,28,29,30,31,32,33,34,35,36,37,38,39,40,41
STARTUPGROUP, Resistivity
STARTUPAXIS, X, 2, LINEAR, AUTO
STARTUPAXIS, Y1, 7, LINEAR, AUTO
STARTUPAXIS, Y2, 9, LINEAR, AUTO
STARTUPAXIS, Y3, 11, LINEAR, AUTO
PLOT_APPEARANCE, ALL, HORZ_GRID_ON, VERT_GRID_ON, MARKERS_AND_LINES, ALL_LINES
DATATYPE, TIME, 2
DATATYPE, COMMENT, 1
[Data]
Comment,Time Stamp (sec),Status (code),Temperature (K),Magnetic Field (Oe),Sample Position (deg),Bridge 1 Resistivity (Ohm),Bridge 1 Excitation (uA),Bridge 2 Resistivity (Ohm),Bridge 2 Excitation (uA),Bridge 3 Resistivity (Ohm),Bridge 3 Excitation (uA),Bridge 4 Resistivity (Ohm),Bridge 4 Excitation (uA),Bridge 1 Std. Dev. (Ohm),Bridge 2 Std. Dev. (Ohm),Bridge 3 Std. Dev. (Ohm),Bridge 4 Std. Dev. (Ohm),Number of Readings,Bridge 1 Resistance (Ohms),Bridge 2 Resistance (Ohms),Bridge 3 Resistance (Ohms),Bridge 4 Resistance (Ohms),Signal 1 Vin (V),Signal 2 Vin (V),Digital Inputs (code),Drive 1 Iout (mA),Drive 1 Ipower (watts),Drive 2 Iout (mA),Drive 2 Ipower (watts),Pressure (),Map 20 (),Map 21 (),Map 22 (),Map 23 (),Map 24 (),Map 25 (),Map 26 (),Map 27 (),Map 28 (),Map 29 ()
,13904830.91,4369,2.99935007095337,0.13400000333786,0,792.059167480469,9.98999977111816,592.925043945313,9.98999977111816,633.143137207031,9.98999977111816,,,0.820784642876703,0.178712972026198,0.614361486030654,,25,792.059167480469,592.925043945313,633.143137207031,
,13904840.52,4369,3.00015008449554,0.13400000333786,0,790.77841796875,9.96599960327148,598.714096679687,9.96599960327148,631.721242675781,9.96599960327148,,,0.673099357310031,24.8390896152391,0.57998885671381,,25,790.77841796875,598.714096679687,631.721242675781,
,13904849.86,4369,3.00020003318787,0.13400000333786,0,788.754084472656,9.91699981689453,574.265791015625,9.91699981689453,627.90298828125,9.91699981689453,,,0.655929844874151,32.2672522412619,0.678504345089236,,25,788.754084472656,574.265791015625,627.90298828125,
,13904858.88,4369,2.99814999103546,0.13400000333786,0,792.698369140625,9.89299964904785,593.058364257813,9.89299964904785,627.563713378906,9.89299964904785,,,23.0573862501833,58.0378728656961,4.58360925226336,,25,792.698369140625,593.058364257813,627.563713378906,
,13904867.92,4369,2.99949991703033,0.13400000333786,0,787.351489257813,9.86800003051758,564.281870117188,9.86800003051758,624.211457519531,9.86800003051758,,,0.557628818739724,23.4293463301214,0.934705421480862,,25,787.351489257813,564.281870117188,624.211457519531,
,13904876.63,4369,2.99995005130768,0.13400000333786,0,785.902729492188,9.81900024414063,576.178996582031,9.81900024414063,621.829133300781,9.81900024414063,,,0.483826514554119,42.0450611443064,0.457096769784858,,25,785.902729492188,576.178996582031,621.829133300781,
,13904885.02,4369,3.00089991092682,0.13400000333786,0,785.458002929688,9.79500007629395,556.515187988281,9.79500007629395,620.698618164063,9.79500007629395,,,0.445175815506626,0.625802084454895,0.574389244454318,,25,785.458002929688,556.515187988281,620.698618164063,
,13904893.84,4369,2.99989998340607,0.13400000333786,0,785.143420410156,9.77000045776367,572.723957519531,9.77000045776367,619.677214355469,9.77000045776367,,,0.545850579803229,43.0731065521071,0.516807416492023,,25,785.143420410156,572.723957519531,619.677214355469,
,13904903.39,4369,2.99979996681213,0.13400000333786,0,783.739885253906,9.72200012207031,548.53361328125,9.72200012207031,616.627517089844,9.72200012207031,,,1.38640233009476,1.03215985882813,0.67751684785241,,25,783.739885253906,548.53361328125,616.627517089844,
,13904912.98,4369,2.99914991855621,0.13400000333786,0,775.505424804688,9.69699954986572,550.307993164063,9.69699954986572,613.267766113281,9.69699954986572,,,17.3826344416137,24.3084369552092,1.56710223586286,,25,775.505424804688,550.307993164063,613.267766113281,
,13904921.97,4369,2.9991500377655,0.13400000333786,0,726.449833984375,9.64799976348877,547.469091796875,9.64799976348877,607.452084960938,9.64799976348877,,,0.667861058382469,24.7488636089329,0.574163232127806,,25,726.449833984375,547.469091796875,607.452084960938,
,13904931.70,4369,2.99985003471375,0.13400000333786,0,726.220146484375,9.62399959564209,555.654748535156,9.62399959564209,606.028100585938,9.62399959564209,,,1.04825802434004,41.418500021287,0.541329975665487,,25,726.220146484375,555.654748535156,606.028100585938,
,13904940.63,4369,2.99960005283356,0.13400000333786,0,725.859182128906,9.59899997711182,553.547780761719,9.59899997711182,605.052744140625,9.59899997711182,,,0.474640477303431,42.0440551751897,0.575394610022049,,25,725.859182128906,553.547780761719,605.052744140625,
,13904948.84,4369,2.99840009212494,0.13400000333786,0,725.469482421875,9.55099964141846,531.726147460937,9.55099964141846,603.004077148438,9.55099964141846,,,0.414920188906084,1.20250322849395,0.505835467276676,,25,725.469482421875,531.726147460937,603.004077148438,
,13904958.19,4369,2.99960005283356,0.13400000333786,0,725.140581054687,9.52600002288818,533.623479003906,9.52600002288818,601.602866210937,9.52600002288818,,,0.453664411839296,27.0030617853409,0.560701966325535,,25,725.140581054687,533.623479003906,601.602866210937,
,13904967.73,4369,3.00165009498596,0.13400000333786,0,724.944167480469,9.5019998550415,540.993415527344,9.5019998550415,600.698854980469,9.5019998550415,,,0.47437862366546,43.6843377895909,0.470971536295221,,25,724.944167480469,540.993415527344,600.698854980469,
,13904977.05,4369,2.9993999004364,0.13400000333786,0,724.853132324219,9.45300006866455,548.780966796875,9.45300006866455,598.978176269531,9.45300006866455,,,1.16625650137711,49.9383331171593,0.765560768359206,,25,724.853132324219,548.780966796875,598.978176269531,
,13904986.14,4369,3.00094997882843,0.13400000333786,0,724.134382324219,9.42800045013428,537.914821777344,9.42800045013428,597.200715332031,9.42800045013428,,,0.415142992835283,44.1339994541652,0.554133618511728,,25,724.134382324219,537.914821777344,597.200715332031,
,13904994.38,4369,2.99919998645782,0.13400000333786,0,724.046469726562,9.4040002822876,517.302543945313,9.4040002822876,596.193452148437,9.4040002822876,,,0.426209342695671,8.09920378529834,0.502288535078796,,25,724.046469726562,517.302543945313,596.193452148437,
,13905003.38,4369,3.0003000497818,0.13400000333786,0,723.537014160156,9.35499954223633,504.597296142578,9.35499954223633,593.547536621094,9.35499954223633,,,0.433881230730649,17.6656112073265,0.928083464421796,,25,723.537014160156,504.597296142578,593.547536621094,
,13905012.72,4369,3.00159990787506,0.13400000333786,0,723.227058105469,9.33100032806396,496.918784179688,9.33100032806396,592.056127929687,9.33100032806396,,,0.455942876092682,16.2770152753554,1.0602428912698,,25,723.227058105469,496.918784179688,592.056127929687,
,13905022.14,4369,3.00004994869232,0.13400000333786,0,723.06431640625,9.30599975585938,502.496420898438,9.30599975585938,590.389948730469,9.30599975585938,,,0.409768915853545,35.1313660241871,1.05147743475419,,25,723.06431640625,502.496420898438,590.389948730469,
,13905031.23,4369,2.9991500377655,0.13400000333786,0,722.444235839844,9.25699996948242,497.482199707031,9.25699996948242,586.921765136719,9.25699996948242,,,0.465609369134602,21.3076859495933,0.670790854246401,,25,722.444235839844,497.482199707031,586.921765136719,
,13905040.19,4369,2.99930000305176,0.13400000333786,0,722.143332519531,9.23299980163574,504.506727294922,9.23299980163574,585.712741699219,9.23299980163574,,,0.333600285417775,46.3667796532653,0.792958388413538,,25,722.143332519531,504.506727294922,585.712741699219,
,13905049.30,4369,3.00009989738464,0.13400000333786,0,722.036638183594,9.20899963378906,491.775212402344,9.20899963378906,584.399465332031,9.20899963378906,,,0.434965101545663,21.0430130430327,0.176199436615523,,25,722.036638183594,491.775212402344,584.399465332031,
,13905058.09,4369,2.99989998340607,0.13400000333786,0,721.688979492188,9.15999984741211,488.983609619141,9.15999984741211,581.573854980469,9.15999984741211,,,0.511090900195862,21.5882379415659,0.585240417266063,,25,721.688979492188,488.983609619141,581.573854980469,
,13905067.27,4369,2.99880003929138,0.13400000333786,0,721.254099121094,9.13500022888184,483.328548583984,9.13500022888184,579.924045410156,9.13500022888184,,,0.397317771747157,16.0899793993337,0.580716228433416,,25,721.254099121094,483.328548583984,579.924045410156,
,13905076.55,4369,3.00055003166199,0.13400000333786,0,720.825302734375,9.11100006103516,484.370869140625,9.11100006103516,578.344248046875,9.11100006103516,,,0.39497325772657,22.7558307452317,0.715194290736259,,25,720.825302734375,484.370869140625,578.344248046875,
,13905086.17,4369,3.00004994869232,0.13400000333786,0,720.50544921875,9.0620002746582,473.937181396484,9.0620002746582,575.162241210938,9.0620002746582,,,0.384600087563563,0.425528453516182,0.74135727966709,,25,720.50544921875,473.937181396484,575.162241210938,
,13905095.28,4369,3.00039994716644,0.13400000333786,0,729.771948242187,9.03800010681152,485.577451171875,9.03800010681152,573.733037109375,9.03800010681152,,,32.014837499735,34.2675706399378,2.34848548289264,,25,729.771948242187,485.577451171875,573.733037109375,
,13905105.20,4369,3.00104999542236,0.13400000333786,0,719.952941894531,9.01299953460693,471.198657226562,9.01299953460693,570.646154785156,9.01299953460693,,,0.438553215072632,0.229621628643493,0.783634771992359,,25,719.952941894531,471.198657226562,570.646154785156,
,13905114.25,4369,3.00059998035431,0.13400000333786,0,719.705085449219,8.96399974822998,480.564848632813,8.96399974822998,562.168515625,8.96399974822998,,,0.466365819997102,31.1673437489541,3.68483132622812,,25,719.705085449219,480.564848632813,562.168515625,
,13905124.08,4369,2.99930000305176,0.13400000333786,0,719.337631835937,8.9399995803833,467.981848144531,8.9399995803833,554.548952636719,8.9399995803833,,,0.409831313795181,0.242611656709111,2.93286121429417,,25,719.337631835937,467.981848144531,554.548952636719,
,13905133.38,4369,2.99975001811981,0.13400000333786,0,718.827619628906,8.89099979400635,425.650656738281,8.89099979400635,546.125183105469,8.89099979400635,,,0.451889927579979,0.251337967850301,2.5386110709716,,25,718.827619628906,425.650656738281,546.125183105469,
,13905144.70,4369,3.00129997730255,0.13400000333786,0,718.839672851562,8.86699962615967,424.542915039063,8.86699962615967,542.582055664063,8.86699962615967,,,0.494730667565216,0.236302652986249,1.54869956206636,,25,718.839672851562,424.542915039063,542.582055664063,
,13905155.38,4369,2.99974989891052,0.13400000333786,0,719.669201660156,8.84200000762939,454.611632080078,8.84200000762939,541.691413574219,8.84200000762939,,,3.75681173180844,52.0568451572242,5.07032950542231,,25,719.669201660156,454.611632080078,541.691413574219,
,13905166.00,4369,2.99944996833801,0.13400000333786,0,718.229731445313,8.79300022125244,423.316975097656,8.79300022125244,535.970402832031,8.79300022125244,,,0.50556396579485,11.2695489839432,1.24432946990303,,25,718.229731445313,423.316975097656,535.970402832031,
,13905175.97,4369,3.00029993057251,0.13400000333786,0,717.634899902344,8.76900005340576,427.609188232422,8.76900005340576,533.321223144531,8.76900005340576,,,0.375695044766539,15.8282484741863,1.5265855324695,,25,717.634899902344,427.609188232422,533.321223144531,
,13905185.59,4369,2.99864995479584,0.13400000333786,0,717.173662109375,8.74499988555908,427.613194580078,8.74499988555908,530.171840820312,8.74499988555908,,,0.509345912649071,16.6734280497174,1.52165044171228,,25,717.173662109375,427.613194580078,530.171840820312,
,13905194.39,4369,3.00049996376038,0.13400000333786,0,711.702375488281,8.69600009918213,424.327764892578,8.69600009918213,525.171494140625,8.69600009918213,,,2.0219010765841,15.8098173274839,1.19851529211122,,25,711.702375488281,424.327764892578,525.171494140625,
,13905203.50,4369,3.00104999542236,0.13400000333786,0,706.612307128906,8.67099952697754,426.303316650391,8.67099952697754,523.0376171875,8.67099952697754,,,1.33631745681843,16.803331104219,1.38240460998241,,25,706.612307128906,426.303316650391,523.0376171875,
,13905212.66,4369,3.00065004825592,0.13400000333786,0,704.080539550781,8.64700031280518,420.798796386719,8.64700031280518,520.580158691406,8.64700031280518,,,0.9738406454645,36.6008164508945,1.32280777804878,,25,704.080539550781,420.798796386719,520.580158691406,
,13905222.63,4369,2.99954998493195,0.13400000333786,0,702.464379882813,8.59799957275391,336.585115966797,8.59799957275391,515.491782226562,8.59799957275391,,,0.384228160711709,87.5787477008841,1.34939812284013,,25,702.464379882813,336.585115966797,515.491782226562,
,13905231.66,4369,2.99955010414124,0.13400000333786,0,702.421901855469,8.57400035858154,351.934467773438,8.57400035858154,513.655310058594,8.57400035858154,,,0.432406523330476,90.1677009179247,0.854518707408813,,25,702.421901855469,351.934467773438,513.655310058594,
,13905241.14,4369,3.00094997882843,0.13400000333786,0,701.987341308594,8.54899978637695,429.759887695313,8.54899978637695,512.122645263672,8.54899978637695,,,0.415534121114056,36.106771406206,1.02601472427285,,25,701.987341308594,429.759887695313,512.122645263672,
,13905250.97,4369,2.99985003471375,0.13400000333786,0,691.976062011719,8.5,419.543940429688,8.5,508.888217773437,8.5,,,2.69981992260947,48.6623030606876,0.776995121662535,,25,691.976062011719,419.543940429688,508.888217773437,
,13905259.98,4369,3.00065004825592,0.13400000333786,0,685.553947753906,8.47599983215332,425.049661254883,8.47599983215332,507.608226318359,8.47599983215332,,,1.38353189571132,35.303733852162,1.45720791027381,,25,685.553947753906,425.049661254883,507.608226318359,
,13905268.97,4369,2.99934995174408,0.13400000333786,0,684.322797851563,8.45100021362305,387.780521850586,8.45100021362305,506.304935302734,8.45100021362305,,,0.880775243189214,76.6071374976311,1.56376051303975,,25,684.322797851563,387.780521850586,506.304935302734,
,13905278.14,4369,2.99919998645782,0.13400000333786,0,683.587058105469,8.40299987792969,405.699224243164,8.40299987792969,502.543292236328,8.40299987792969,,,1.46317884409269,57.5483987521695,1.14999042477866,,25,683.587058105469,405.699224243164,502.543292236328,
,13905286.86,4369,2.99970006942749,0.13400000333786,0,682.898193359375,8.37800025939941,393.924276123047,8.37800025939941,500.608153076172,8.37800025939941,,,0.444271963355836,64.0025897453287,0.569996344527689,,25,682.898193359375,393.924276123047,500.608153076172,
,13905296.19,4369,3.00169992446899,0.13400000333786,0,682.475649414062,8.35400009155273,365.149302368164,8.35400009155273,499.086428222656,8.35400009155273,,,0.496679482783903,74.3070559809348,0.914690221764494,,25,682.475649414062,365.149302368164,499.086428222656,
,13905305.14,4369,3,0.13400000333786,0,681.570791015625,8.30500030517578,350.299252319336,8.30500030517578,493.625997314453,8.30500030517578,,,0.434200168207867,67.2843498122049,4.66686159311527,,25,681.570791015625,350.299252319336,493.625997314453,
,13905314.08,4369,2.9996999502182,0.13400000333786,0,681.484128417969,8.27999973297119,324.356857910156,8.27999973297119,492.725162353516,8.27999973297119,,,0.475174970537844,65.7192952737333,3.76016163991812,,25,681.484128417969,324.356857910156,492.725162353516,
,13905322.66,4369,2.99985003471375,0.13400000333786,0,656.782960205078,8.25599956512451,323.700333251953,8.25599956512451,489.991899414063,8.25599956512451,,,81.4657972371659,66.7731912543803,5.787065164665,,25,656.782960205078,323.700333251953,489.991899414063,
,13905331.72,4369,3.00100004673004,0.13400000333786,0,599.613527832031,8.20699977874756,292.587634887695,8.20699977874756,488.011968994141,8.20699977874756,,,123.196805608886,56.930639546346,1.82150844640203,,25,599.613527832031,292.587634887695,488.011968994141,
,13905341.38,4369,3,0.13400000333786,0,493.219114990234,8.18299961090088,280.216135253906,8.18299961090088,486.210142822266,8.18299961090088,,,138.173204035138,53.7039219770017,1.13046409945748,,25,493.219114990234,280.216135253906,486.210142822266,
,13905351.92,4369,3.00034999847412,0.13400000333786,0,649.858503417969,8.15799999237061,256.98739440918,8.15799999237061,483.930869140625,8.15799999237061,,,55.04028826343,42.3773584192248,1.72320452144465,,25,649.858503417969,256.98739440918,483.930869140625,
,13905361.30,4369,2.99985003471375,0.13400000333786,0,514.375102539062,8.10900020599365,267.217852172852,8.10900020599365,478.225223388672,8.10900020599365,,,139.619008073822,52.0683917460795,0.705344955834315,,25,514.375102539062,267.217852172852,478.225223388672,
,13905371.45,4369,2.99909996986389,0.13400000333786,0,614.202777099609,8.08500003814697,233.394215698242,8.08500003814697,476.143140869141,8.08500003814697,,,102.070950369199,0.295046675424409,0.87759032459104,,25,614.202777099609,233.394215698242,476.143140869141,
,13905381.64,4369,3.00114989280701,0.13400000333786,0,657.529187011719,8.03600025177002,216.648877716064,8.03600025177002,470.804263916016,8.03600025177002,,,0.425900768426547,46.6964361517753,0.976339308819079,,25,657.529187011719,216.648877716064,470.804263916016,
,13905391.67,4369,3.00034999847412,0.13400000333786,0,623.738416748047,8.01200008392334,215.231970367432,8.01200008392334,468.520469970703,8.01200008392334,,,89.9848126754654,46.3859466025858,0.749276760854693,,25,623.738416748047,215.231970367432,468.520469970703,
,13905401.38,4369,3.00014996528625,0.13400000333786,0,479.376024169922,7.98699998855591,213.982232055664,7.98699998855591,466.958559570313,7.98699998855591,,,132.430971456839,46.1490667086259,0.760434631050303,,25,479.376024169922,213.982232055664,466.958559570313,
,13905412.63,4369,2.99994993209839,0.13400000333786,0,379.79720703125,7.93800020217896,208.612180938721,7.93800020217896,462.549422607422,7.93800020217896,,,0.164062561023792,44.6920497265837,0.744736797282663,,25,379.79720703125,208.612180938721,462.549422607422,
,13905424.06,4369,2.99879992008209,0.13400000333786,0,639.8020703125,7.91400003433228,186.25845123291,7.91400003433228,460.202269287109,7.91400003433228,,,2.15703669933373,64.7502336507424,1.50623469798631,,25,639.8020703125,186.25845123291,460.202269287109,
,13905433.97,4369,3.00069999694824,0.13400000333786,0,574.847586669922,7.8899998664856,203.820695037842,7.8899998664856,454.216104736328,7.8899998664856,,,109.672780999541,43.3062257885417,6.52093260660574,,25,574.847586669922,203.820695037842,454.216104736328,
,13905443.86,4369,2.99979996681213,0.13400000333786,0,522.805866699219,7.84100008010864,194.954743041992,7.84100008010864,440.033814697266,7.84100008010864,,,126.842019733892,51.3250759005264,5.7292475972583,,25,522.805866699219,194.954743041992,440.033814697266,
,13905453.94,4369,3.00034999847412,0.13400000333786,0,532.672862548828,7.81599998474121,169.762031707764,7.81599998474121,434.609597167969,7.81599998474121,,,125.081085275473,71.6850908306255,5.31362890459288,,25,532.672862548828,169.762031707764,434.609597167969,
,13905464.11,4369,3.00125002861023,0.13400000333786,0,430.364405517578,7.79199981689453,185.940686645508,7.79199981689453,430.81734375,7.79199981689453,,,101.704383435793,57.0544460313831,3.02783041408068,,25,430.364405517578,185.940686645508,430.81734375,
,13905474.98,4369,2.99975001811981,0.13400000333786,0,379.439451904297,7.74300003051758,171.119415893555,7.74300003051758,425.187121582031,7.74300003051758,,,0.214297075127662,65.5803123349887,1.78159419851828,,25,379.439451904297,171.119415893555,425.187121582031,
,13905486.16,4369,2.99989998340607,0.13400000333786,0,632.723547363281,7.7189998626709,187.713092498779,7.7189998626709,423.560067138672,7.7189998626709,,,0.407703509715722,49.3487417475275,2.22283310172341,,25,632.723547363281,187.713092498779,423.560067138672,
,13905494.53,4369,2.99985003471375,0.13400000333786,0,379.308684082031,7.69399976730347,155.482624664307,7.69399976730347,421.239975585937,7.69399976730347,,,0.180833057270843,69.7614448521832,1.39988469097575,,25,379.308684082031,155.482624664307,421.239975585937,
,13905505.83,4369,3.00005006790161,0.13400000333786,0,379.226094970703,7.64499998092651,181.696188812256,7.64499998092651,417.208389892578,7.64499998092651,,,0.207615401618289,47.655754496591,1.39511224379914,,25,379.226094970703,181.696188812256,417.208389892578,
,13905516.88,4369,3.00020003318787,0.13400000333786,0,379.135158691406,7.62099981307983,167.580948181152,7.62099981307983,415.090714111328,7.62099981307983,,,0.200138616965647,57.4104064850492,2.93624958524895,,25,379.135158691406,167.580948181152,415.090714111328,
,13905527.44,4369,3.00079989433289,0.13400000333786,0,379.053326416016,7.59600019454956,183.056562347412,7.59600019454956,410.478441162109,7.59600019454956,,,0.184852790604128,38.5303780173822,1.78319243113247,,25,379.053326416016,183.056562347412,410.478441162109,
,13905539.36,4369,2.99935007095337,0.13400000333786,0,379.108330078125,7.5479998588562,180.448670654297,7.5479998588562,405.602856445313,7.5479998588562,,,0.215572646666829,37.9626545107056,1.32463944430687,,25,379.108330078125,180.448670654297,405.602856445313,
,13905550.42,4369,2.99980008602142,0.13400000333786,0,378.948382568359,7.52299976348877,146.891226654053,7.52299976348877,403.135222167969,7.52299976348877,,,0.208225648276338,66.0248693023898,1.28095671539669,,25,378.948382568359,146.891226654053,403.135222167969,
,13905561.70,4369,3.0005499124527,0.13400000333786,0,379.041129150391,7.49900007247925,166.548639068604,7.49900007247925,400.811196289062,7.49900007247925,,,0.242350084931829,50.5519261753057,1.46944258811249,,25,379.041129150391,166.548639068604,400.811196289062,
,13905573.47,4369,2.99910008907318,0.13400000333786,0,426.279749755859,7.44999980926514,113.010040893555,7.44999980926514,395.352298583984,7.44999980926514,,,94.9933256002041,66.1951588717845,1.0357357949091,,25,426.279749755859,113.010040893555,395.352298583984,
,13905584.42,4369,2.99959993362427,0.13400000333786,0,378.756788330078,7.42600011825562,75.8996696472168,7.42600011825562,392.882777099609,7.42600011825562,,,0.118818207378013,52.9678000759382,1.20471269556013,,25,378.756788330078,75.8996696472168,392.882777099609,
,13905595.42,4369,3.0003000497818,0.13400000333786,0,378.788063964844,7.40100002288818,69.7556469726563,7.40100002288818,390.859997558594,7.40100002288818,,,0.193200346650022,51.977091429552,1.27186117741967,,25,378.788063964844,69.7556469726563,390.859997558594,
,13905606.23,4369,3.00010001659393,0.13400000333786,0,378.701560058594,7.35200023651123,70.110209197998,7.35200023651123,386.587850341797,7.35200023651123,,,0.221472335393906,58.8642646066237,0.820267263013812,,25,378.701560058594,70.110209197998,386.587850341797,
,13905616.78,4369,2.99984991550446,0.13400000333786,0,378.611357421875,7.32800006866455,61.2851617431641,7.32800006866455,384.619506835938,7.32800006866455,,,0.24038471592803,45.070332108897,0.951465995720558,,25,378.611357421875,61.2851617431641,384.619506835938,
,13905627.78,4369,3.0011500120163,0.13400000333786,0,378.476901855469,7.30299997329712,54.3105978393555,7.30299997329712,382.683504638672,7.30299997329712,,,0.182713159944477,32.3532795020368,0.655219488922906,,25,378.476901855469,54.3105978393555,382.683504638672,
,13905638.92,4369,2.99940001964569,0.13400000333786,0,566.141748046875,7.25500011444092,53.2471572875977,7.25500011444092,378.598781738281,7.25500011444092,,,81.8713431913393,32.1680500319302,1.89895631669084,,25,566.141748046875,53.2471572875977,378.598781738281,
,13905648.48,4369,3.00020003318787,0.13400000333786,0,378.396873779297,7.23000001907349,65.9550955200195,7.23000001907349,376.456181640625,7.23000001907349,,,0.219118174860237,53.2137942330872,1.05362436604134,,25,378.396873779297,65.9550955200195,376.456181640625,
,13905659.11,4369,2.99905002117157,0.13400000333786,0,378.2312109375,7.18100023269653,58.4664642333984,7.18100023269653,371.842791748047,7.18100023269653,,,0.242690441750848,44.1191246321169,0.961616497272991,,25,378.2312109375,58.4664642333984,371.842791748047,
,13905669.48,4369,3.00064992904663,0.13400000333786,0,378.192229003906,7.15700006484985,64.3602885437012,7.15700006484985,369.854500732422,7.15700006484985,,,0.147099820025095,52.7503572870353,1.07176909377012,,25,378.192229003906,64.3602885437012,369.854500732422,
,13905680.17,4369,2.99930000305176,0.13400000333786,0,378.14416015625,7.13199996948242,63.9905830383301,7.13199996948242,366.609060058594,7.13199996948242,,,0.178458958488232,52.5625844634873,1.19419050474086,,25,378.14416015625,63.9905830383301,366.609060058594,
,13905690.48,4369,2.99779999256134,0.13400000333786,0,378.133555908203,7.08400011062622,62.8728707885742,7.08400011062622,358.694603271484,7.08400011062622,,,0.174160411284031,52.217911551811,1.40281765921647,,25,378.133555908203,62.8728707885742,358.694603271484,
,13905701.56,4369,3.0011500120163,0.13400000333786,0,378.201011962891,7.05900001525879,56.0674642944336,7.05900001525879,356.562406005859,7.05900001525879,,,0.2116213823166,43.5063367036876,0.924157587341276,,25,378.201011962891,56.0674642944336,356.562406005859,
,13905712.77,4369,3.00039994716644,0.13400000333786,0,378.069698486328,7.03499984741211,68.6808760070801,7.03499984741211,354.691478271484,7.03499984741211,,,0.162304217698522,58.528016812768,0.952333836119371,,25,378.069698486328,68.6808760070801,354.691478271484,
,13905723.66,4369,3.00010001659393,0.13400000333786,0,378.042348632812,6.98600006103516,61.138751373291,6.98600006103516,350.483068847656,6.98600006103516,,,0.17051635375115,51.755172505799,0.944929275829538,,25,378.042348632812,61.138751373291,350.483068847656,
,13905734.05,4369,3.00014996528625,0.13400000333786,0,377.890402832031,6.96099996566772,67.049822845459,6.96099996566772,347.765339355469,6.96099996566772,,,0.213468100757675,58.2575393250031,1.36828494545173,,25,377.890402832031,67.049822845459,347.765339355469,
,13905745.36,4369,3.00139999389648,0.13400000333786,0,377.83796875,6.93699979782104,47.5461045837402,6.93699979782104,344.385480957031,6.93699979782104,,,0.190964554309845,31.0073931434028,1.45699706219536,,25,377.83796875,47.5461045837402,344.385480957031,
,13905756.05,4369,3.00010001659393,0.13400000333786,0,434.405572509766,6.88800001144409,66.0847212219238,6.88800001144409,339.121120605469,6.88800001144409,,,89.3864104001814,57.7987893560242,0.934838740347948,,25,434.405572509766,66.0847212219238,339.121120605469,
,13905765.38,4369,3.00024998188019,0.13400000333786,0,454.406746826172,6.86399984359741,39.977649230957,6.86399984359741,337.212191162109,6.86399984359741,,,93.9186153219709,0.248562746135196,1.03976028545749,,25,454.406746826172,39.977649230957,337.212191162109,
,13905775.05,4369,2.99940001964569,0.13400000333786,0,437.586145019531,6.83900022506714,71.1631025695801,6.83900022506714,335.520833740234,6.83900022506714,,,87.1703067813838,63.0693073508818,0.997039410391478,,25,437.586145019531,71.1631025695801,335.520833740234,
,13905784.39,4369,2.99954998493195,0.13400000333786,0,493.501439208984,6.78999996185303,45.3011708068848,6.78999996185303,331.463223876953,6.78999996185303,,,86.874261019082,30.8009989347279,0.969353174621793,,25,493.501439208984,45.3011708068848,331.463223876953,
,13905793.88,4369,3.00119996070862,0.13400000333786,0,526.788802490234,6.76599979400635,44.8503115844727,6.76599979400635,329.396246337891,6.76599979400635,,,65.1073754505916,30.8107215484537,1.07085789829651,,25,526.788802490234,44.8503115844727,329.396246337891,
,13905803.36,4369,2.99950003623962,0.13400000333786,0,497.312066650391,6.74200010299683,63.4140419006348,6.74200010299683,327.082385253906,6.74200010299683,,,82.0463543520411,57.5243719708115,1.25436212277208,,25,497.312066650391,63.4140419006348,327.082385253906,
,13905812.47,4369,2.99905002117157,0.13400000333786,0,482.289851074219,6.69299983978271,56.4427503967285,6.69299983978271,322.519733886719,6.69299983978271,,,85.533389038958,50.9369913575488,0.928057497819101,,25,482.289851074219,56.4427503967285,322.519733886719,
,13905820.42,4369,2.99944996833801,0.13400000333786,0,509.836196289063,6.66800022125244,50.3218986511231,6.66800022125244,321.00392578125,6.66800022125244,,,74.3867494649818,42.4588541095499,1.429149951419,,25,509.836196289063,50.3218986511231,321.00392578125,
,13905828.98,4369,2.99930000305176,0.13400000333786,0,481.503482666016,6.64400005340576,43.0775267028809,6.64400005340576,317.951339111328,6.64400005340576,,,84.9561672899546,30.6732760703178,1.32582847921918,,25,481.503482666016,43.0775267028809,317.951339111328,
,13905838.06,4369,3.00045001506805,0.13400000333786,0,405.152255859375,6.59499979019165,42.5106452941895,6.59499979019165,312.080078125,6.59499979019165,,,63.2724315607579,30.6207087454955,1.83540859408008,,25,405.152255859375,42.5106452941895,312.080078125,
,13905847.34,4369,2.99950003623962,0.13400000333786,0,418.566944580078,6.57100009918213,42.2412446594238,6.57100009918213,308.548139648437,6.57100009918213,,,73.4004260513206,30.59312017776,2.61245861544446,,25,418.566944580078,42.2412446594238,308.548139648437,
,13905855.98,4369,2.99979996681213,0.13400000333786,0,384.141810302734,6.5460000038147,48.2171139526367,6.5460000038147,304.257894287109,6.5460000038147,,,33.5864107412387,42.330202880015,2.87743459026419,,25,384.141810302734,48.2171139526367,304.257894287109,
,13905864.86,4369,3.00014996528625,0.13400000333786,0,384.0349609375,6.49700021743774,41.4832507324219,6.49700021743774,289.893125,6.49700021743774,,,33.4941593153855,30.4945295532422,6.37444358282002,,25,384.0349609375,41.4832507324219,289.893125,
,13905874.09,4369,2.99975001811981,0.13400000333786,0,384.52822265625,6.47300004959106,49.5792710876465,6.47300004959106,281.895383300781,6.47300004959106,,,36.0671878654372,44.289665626117,7.32320462641585,,25,384.52822265625,49.5792710876465,281.895383300781,
,13905883.55,4369,3.00020003318787,0.13400000333786,0,377.113269042969,6.42399978637695,59.2866546630859,6.42399978637695,270.556182861328,6.42399978637695,,,0.206661443107289,56.9228040233904,4.08129399974658,,25,377.113269042969,59.2866546630859,270.556182861328,
,13905892.14,4369,3.00039994716644,0.13400000333786,0,376.996427001953,6.40000009536743,40.4653205871582,6.40000009536743,266.771647949219,6.40000009536743,,,0.190006330124359,30.4162880057963,3.87595113584141,,25,376.996427001953,40.4653205871582,266.771647949219,
,13905901.38,4369,2.99994993209839,0.13400000333786,0,377.00611328125,6.375,52.6174040222168,6.375,262.129317626953,6.375,,,0.18281858070933,50.3735861777241,2.64020900076356,,25,377.00611328125,52.6174040222168,262.129317626953,
,13905910.13,4369,3.00230002403259,0.13400000333786,0,376.885684814453,6.32600021362305,33.4259747314453,6.32600021362305,255.19705078125,6.32600021362305,,,0.131691356472975,0.199388918363331,2.022808652736,,25,376.885684814453,33.4259747314453,255.19705078125,
,13905918.92,4369,2.99944996833801,0.13400000333786,0,376.999174804688,6.30200004577637,70.2695866394043,6.30200004577637,252.045368041992,6.30200004577637,,,0.172529756579875,65.9723972914857,1.64274960229552,,25,376.999174804688,70.2695866394043,252.045368041992,
,13905927.42,4369,2.99940001964569,0.13400000333786,0,376.905030517578,6.27699995040894,39.2452459716797,6.27699995040894,249.68333190918,6.27699995040894,,,0.176941145942491,30.1694778358488,1.71009919508992,,25,376.905030517578,39.2452459716797,249.68333190918,
,13905936.00,4369,3.00020003318787,0.13400000333786,0,377.250546875,6.22900009155273,33.5002241516113,6.22900009155273,246.396484985352,6.22900009155273,,,2.38588030182242,2.35174796769052,4.33375729131727,,25,377.250546875,33.5002241516113,246.396484985352,
,13905945.42,4369,2.99944996833801,0.13400000333786,0,376.686240234375,6.2039999961853,50.8178753662109,6.2039999961853,242.914748535156,6.2039999961853,,,0.193615092259725,49.9052705476458,1.52569775572746,,25,376.686240234375,50.8178753662109,242.914748535156,
,13905954.02,4369,3.00059998035431,0.13400000333786,0,376.606861572266,6.17999982833862,50.5367539215088,6.17999982833862,240.71935546875,6.17999982833862,,,0.210542305458188,49.7963527818319,1.5163736505802,,25,376.606861572266,50.5367539215088,240.71935546875,
,13905963.78,4369,2.99914991855621,0.13400000333786,0,376.603321533203,6.13100004196167,37.8969343566895,6.13100004196167,235.345803833008,6.13100004196167,,,0.174917342188126,29.8944697920257,1.6045667046447,,25,376.603321533203,37.8969343566895,235.345803833008,
,13905972.11,4369,2.99925005435944,0.13400000333786,0,376.551583251953,6.10599994659424,56.0534620666504,6.10599994659424,233.195003662109,6.10599994659424,,,0.191141726697018,55.7800728695061,1.61942898361171,,25,376.551583251953,56.0534620666504,233.195003662109,
,13905981.03,4369,3,0.13400000333786,0,376.557971191406,6.08199977874756,34.885326461792,6.08199977874756,230.215288696289,6.08199977874756,,,0.212344992433804,16.4841144162703,1.90206405482428,,25,376.557971191406,34.885326461792,230.215288696289,
,13905990.05,4369,3,0.13400000333786,0,376.351987304688,6.03299999237061,31.2333046722412,6.03299999237061,221.143353881836,6.03299999237061,,,0.169187179876306,0.185544061050306,3.47397316350619,,25,376.351987304688,31.2333046722412,221.143353881836,
,13905999.67,4369,3.00059998035431,0.13400000333786,0,378.212055664063,6.00899982452393,35.3325374603271,6.00899982452393,219.839739379883,6.00899982452393,,,6.29267786633015,11.6634472784473,7.47781353503655,,25,378.212055664063,35.3325374603271,219.839739379883,
,13906008.33,4369,3.00024998188019,0.13400000333786,0,376.210858154297,5.98400020599365,30.8898743438721,5.98400020599365,210.986096191406,5.98400020599365,,,0.16380294627452,0.129096057416115,4.7043110068407,,25,376.210858154297,30.8898743438721,210.986096191406,
,13906016.20,4369,3,0.13400000333786,0,376.118962402344,5.93599987030029,30.596788482666,5.93599987030029,195.355077514648,5.93599987030029,,,0.212700636477324,0.211763792663542,6.73594614018641,,25,376.118962402344,30.596788482666,195.355077514648,
,13906024.63,4369,3.00165009498596,0.13400000333786,0,375.981506347656,5.91099977493286,30.4815446472168,5.91099977493286,186.855773925781,5.91099977493286,,,0.163822136276157,0.19514553274201,6.06631512728346,,25,375.981506347656,30.4815446472168,186.855773925781,
,13906033.88,4369,3.00019991397858,0.13400000333786,0,376.031783447266,5.88700008392334,30.3547225189209,5.88700008392334,179.988502197266,5.88700008392334,,,0.15693442083923,0.206798507509336,4.69690807217097,,25,376.031783447266,30.3547225189209,179.988502197266,
,13906042.14,4369,2.99940001964569,0.13400000333786,0,375.724542236328,5.83799982070923,29.9934815216064,5.83799982070923,168.112220458984,5.83799982070923,,,0.182321266466858,0.1475229788172,4.54998192191025,,25,375.724542236328,29.9934815216064,168.112220458984,
,13906050.39,4369,2.99970006942749,0.13400000333786,0,375.612613525391,5.81300020217896,29.9755699920654,5.81300020217896,166.727380981445,5.81300020217896,,,0.191511546321878,0.177429872418886,3.39560678976802,,25,375.612613525391,29.9755699920654,166.727380981445,
,13906059.33,4369,2.99940001964569,0.13400000333786,0,375.860238037109,5.78900003433228,30.2387838745117,5.78900003433228,162.613624267578,5.78900003433228,,,1.51406637469216,1.47228622532092,3.51613351299302,,25,375.860238037109,30.2387838745117,162.613624267578,
,13906068.34,4369,3.00004994869232,0.13400000333786,0,375.364735107422,5.73999977111816,29.5744702911377,5.73999977111816,156.306842651367,5.73999977111816,,,0.18736655242687,0.19046293049975,3.38294203658934,,25,375.364735107422,29.5744702911377,156.306842651367,
,13906076.77,4369,2.99940001964569,0.13400000333786,0,375.407521972656,5.71600008010864,29.4665523529053,5.71600008010864,155.411939697266,5.71600008010864,,,0.247327597924018,0.141584107608577,3.11627110906179,,25,375.407521972656,29.4665523529053,155.411939697266,
,13906085.38,4369,3.00034999847412,0.13400000333786,0,375.134058837891,5.69099998474121,29.2986340332031,5.69099998474121,152.734392700195,5.69099998474121,,,0.154083081579841,0.158065360941877,3.93057355535758,,25,375.134058837891,29.2986340332031,152.734392700195,
,13906094.30,4369,3.00119996070862,0.13400000333786,0,374.962227783203,5.64200019836426,29.0908126068115,5.64200019836426,148.648417358398,5.64200019836426,,,0.258846618385651,0.129620963960044,2.53857662533153,,25,374.962227783203,29.0908126068115,148.648417358398,
,13906103.83,4369,3,0.13400000333786,0,374.625119628906,5.61800003051758,28.9906810760498,5.61800003051758,146.355032958984,5.61800003051758,,,0.106906693838654,0.128044134600668,3.49542798633108,,25,374.625119628906,28.9906810760498,146.355032958984,
,13906112.61,4369,2.99975001811981,0.13400000333786,0,374.41017578125,5.56899976730347,28.8288096618652,5.56899976730347,141.357880249023,5.56899976730347,,,0.130890209320354,0.140718621582685,1.83380158333396,,25,374.41017578125,28.8288096618652,141.357880249023,
,13906120.69,4369,3,0.13400000333786,0,374.228468017578,5.54500007629395,28.7713645172119,5.54500007629395,140.136713867188,5.54500007629395,,,0.106385407740004,0.143687781843007,2.21791284935507,,25,374.228468017578,28.7713645172119,140.136713867188,
,13906128.48,4369,2.99954998493195,0.13400000333786,0,374.122741699219,5.51999998092651,28.6117273712158,5.51999998092651,137.588668823242,5.51999998092651,,,0.24784665892908,0.140000764043594,1.98270058348455,,25,374.122741699219,28.6117273712158,137.588668823242,
,13906137.53,4369,2.99979996681213,0.13400000333786,0,373.771943359375,5.47100019454956,28.3903971862793,5.47100019454956,133.702904052734,5.47100019454956,,,0.24770895006557,0.132047271022325,1.85861736431529,,25,373.771943359375,28.3903971862793,133.702904052734,
,13906146.23,4369,2.99899995326996,0.13400000333786,0,373.535498046875,5.44700002670288,28.2594583892822,5.44700002670288,132.499719238281,5.44700002670288,,,0.203773899228655,0.114179749892337,1.97817996369809,,25,373.535498046875,28.2594583892822,132.499719238281,
,13906154.47,4369,2.99935007095337,0.13400000333786,0,373.341696777344,5.4229998588562,28.2100332641602,5.4229998588562,130.66786895752,5.4229998588562,,,0.169342841900794,0.108743597890393,1.98916269615617,,25,373.341696777344,28.2100332641602,130.66786895752,
,13906162.83,4369,3.00100004673004,0.13400000333786,0,373.064958496094,5.37400007247925,27.9740392303467,5.37400007247925,127.727641906738,5.37400007247925,,,0.25125532449248,0.131633060682315,1.91372972317221,,25,373.064958496094,27.9740392303467,127.727641906738,
,13906171.42,4369,3.00185000896454,0.13400000333786,0,372.859010009766,5.34899997711182,27.9426097869873,5.34899997711182,126.781141357422,5.34899997711182,,,0.143055881879663,0.148423339665801,1.9371315512531,,25,372.859010009766,27.9426097869873,126.781141357422,
,13906179.73,4369,3.00049996376038,0.13400000333786,0,374.965189208984,5.32499980926514,30.2034766387939,5.32499980926514,126.934280395508,5.32499980926514,,,7.26433990098535,8.74137457934396,5.88997144920517,,25,374.965189208984,30.2034766387939,126.934280395508,
,13906187.78,4369,3,0.13400000333786,0,372.396411132812,5.27600002288818,27.7432740020752,5.27600002288818,122.946969909668,5.27600002288818,,,0.160754163035677,0.121264837733156,1.89176133889915,,25,372.396411132812,27.7432740020752,122.946969909668,
,13906196.03,4369,3.00045001506805,0.13400000333786,0,372.055401611328,5.2519998550415,27.6084136962891,5.2519998550415,121.54027557373,5.2519998550415,,,0.196241494083016,0.0908786207234806,1.8052694943726,,25,372.055401611328,27.6084136962891,121.54027557373,
,13906205.33,4369,3,0.13400000333786,0,372.041005859375,5.22700023651123,27.5637689971924,5.22700023651123,120.582053222656,5.22700023651123,,,0.195979263675257,0.0976764294569955,1.69313820282771,,25,372.041005859375,27.5637689971924,120.582053222656,
,13906214.34,4369,2.99985003471375,0.13400000333786,0,371.672144775391,5.17799997329712,27.4008476257324,5.17799997329712,119.115699768066,5.17799997329712,,,0.234876407226264,0.129785796775646,2.0198317165734,,25,371.672144775391,27.4008476257324,119.115699768066,
,13906223.44,4369,2.99965000152588,0.13400000333786,0,371.421771240234,5.15399980545044,27.3921656799316,5.15399980545044,117.718756103516,5.15399980545044,,,0.158011168695809,0.086681955802366,1.76688986621127,,25,371.421771240234,27.3921656799316,117.718756103516,
,13906232.02,4369,2.99985003471375,0.13400000333786,0,371.245427246094,5.12900018692017,27.3031722259521,5.12900018692017,116.765909118652,5.12900018692017,,,0.175610833626108,0.0892629057309197,1.5794643098955,,25,371.245427246094,27.3031722259521,116.765909118652,
,13906240.94,4369,2.99954998493195,0.13400000333786,0,370.847801513672,5.08099985122681,27.8272375488281,5.08099985122681,115.190531616211,5.08099985122681,,,0.200527908970059,3.23918907852449,1.80215758342477,,25,370.847801513672,27.8272375488281,115.190531616211,
,13906249.36,4369,3.00075006484985,0.13400000333786,0,370.695100097656,5.05600023269653,27.0838749694824,5.05600023269653,114.015594177246,5.05600023269653,,,0.2218519490857,0.0846765291850593,1.69937322513469,,25,370.695100097656,27.0838749694824,114.015594177246,
,13906257.31,4369,3.00049996376038,0.13400000333786,0,370.529976806641,5.03200006484985,27.0188543701172,5.03200006484985,113.305509033203,5.03200006484985,,,0.217771753662275,0.110411226069566,1.51040535308813,,25,370.529976806641,27.0188543701172,113.305509033203,
,13906265.53,4369,3.00139999389648,0.13400000333786,0,370.51119140625,5,27.1202151489258,5,112.799604492188,5,,,0.206684524180311,0.0921663162127135,1.58990725905141,,25,370.51119140625,27.1202151489258,112.799604492188,