File: icepp/250308_3D_mh_photolitho_coarseUp1.dat
[Header]
TITLE, 2K to 300K
FILEOPENTIME,13912661.56,3/8/2025,11:49 PM
BYAPP, Resistivity, 2.1, 1.0
INFO, APPNAME, PPMS MultiVu Application, 1.5.11
INFO, , Sample1 Name
INFO, 1, Sample1 Cross Section
INFO, 1, Sample1 Length
INFO, Ohm, Sample1 Units
INFO, , Sample2 Name
INFO, 1, Sample2 Cross Section
INFO, 1, Sample2 Length
INFO, Ohm, Sample2 Units
INFO, , Sample3 Name
INFO, 1, Sample3 Cross Section
INFO, 1, Sample3 Length
INFO, Ohm, Sample3 Units
INFO, , Sample4 Name
INFO, 1, Sample4 Cross Section
INFO, 1, Sample4 Length
INFO, Ohm, Sample4 Units
FIELDGROUP, Resistivity,2,3,4,5,6,7,8,9,10,11,12,13,14,15,16,17,18,19,20,21,22,23,24,25,26,27,28,29,30,31,32,33,34,35,36,37,38,39,40,41
STARTUPGROUP, Resistivity
STARTUPAXIS, X, 2, LINEAR, AUTO
STARTUPAXIS, Y1, 7, LINEAR, AUTO
STARTUPAXIS, Y2, 9, LINEAR, AUTO
STARTUPAXIS, Y3, 11, LINEAR, AUTO
PLOT_APPEARANCE, ALL, HORZ_GRID_ON, VERT_GRID_ON, MARKERS_AND_LINES, ALL_LINES
DATATYPE, TIME, 2
DATATYPE, COMMENT, 1
[Data]
Comment,Time Stamp (sec),Status (code),Temperature (K),Magnetic Field (Oe),Sample Position (deg),Bridge 1 Resistivity (Ohm),Bridge 1 Excitation (uA),Bridge 2 Resistivity (Ohm),Bridge 2 Excitation (uA),Bridge 3 Resistivity (Ohm),Bridge 3 Excitation (uA),Bridge 4 Resistivity (Ohm),Bridge 4 Excitation (uA),Bridge 1 Std. Dev. (Ohm),Bridge 2 Std. Dev. (Ohm),Bridge 3 Std. Dev. (Ohm),Bridge 4 Std. Dev. (Ohm),Number of Readings,Bridge 1 Resistance (Ohms),Bridge 2 Resistance (Ohms),Bridge 3 Resistance (Ohms),Bridge 4 Resistance (Ohms),Signal 1 Vin (V),Signal 2 Vin (V),Digital Inputs (code),Drive 1 Iout (mA),Drive 1 Ipower (watts),Drive 2 Iout (mA),Drive 2 Ipower (watts),Pressure (),Map 20 (),Map 21 (),Map 22 (),Map 23 (),Map 24 (),Map 25 (),Map 26 (),Map 27 (),Map 28 (),Map 29 ()
,13913069.52,4370,2.11489999294281,0.13400000333786,0,289.90017578125,0.00999999977648258,8.42602496147156,0.00999999977648258,1.98259417057037,0.00999999977648258,,,9.60252021001062,6.94529978951062,8.76640707157699,,25,289.90017578125,8.42602496147156,1.98259417057037,
,13913092.50,4374,3.74535000324249,0.13400000333786,0,432.918002929687,0.00999999977648258,323.449387664795,0.00999999977648258,653.148589782715,0.00999999977648258,,,151.557786575573,370.619827097655,503.252221658927,,25,432.918002929687,323.449387664795,653.148589782715,
,13913108.16,4370,6.0860002040863,0.13400000333786,0,5011.8894140625,0.00999999977648258,4877.708125,0.00999999977648258,4623.7423046875,0.00999999977648258,,,86.2869948666559,56.8749777186987,60.3087881575457,,25,5011.8894140625,4877.708125,4623.7423046875,
,13913120.61,4374,8.20625019073486,0.13400000333786,0,5063.44033203125,0.00999999977648258,4895.80345703125,0.00999999977648258,4656.5496484375,0.00999999977648258,,,13.2167249825305,18.0910532868657,55.4937803589163,,25,5063.44033203125,4895.80345703125,4656.5496484375,
,13913137.59,4370,11.0443000793457,0.13400000333786,0,5053.71798828125,0.00999999977648258,4888.34388671875,0.00999999977648258,4676.3423828125,0.00999999977648258,,,7.40220288442078,12.1712196212527,59.5049075311797,,25,5053.71798828125,4888.34388671875,4676.3423828125,
,13913151.14,4374,13.2170000076294,0.13400000333786,0,5043.40291015625,0.00999999977648258,4892.6727734375,0.00999999977648258,4652.846953125,0.00999999977648258,,,9.96659662754583,10.5793920362821,53.9121382032647,,25,5043.40291015625,4892.6727734375,4652.846953125,
,13913163.06,4374,15.2131500244141,0.13400000333786,0,5039.5153125,0.00999999977648258,4888.72333984375,0.00999999977648258,4639.47291015625,0.00999999977648258,,,7.63211073206815,9.9983427943266,40.0520308657821,,25,5039.5153125,4888.72333984375,4639.47291015625,
,13913180.47,4370,17.9652004241943,0.13400000333786,0,5029.26224609375,0.00999999977648258,4887.995390625,0.00999999977648258,4640.37900390625,0.00999999977648258,,,8.90662793457678,12.7911496210004,64.5733988210366,,25,5029.26224609375,4887.995390625,4640.37900390625,
,13913193.23,4374,20.2876501083374,0.13400000333786,0,5022.46611328125,0.00999999977648258,4883.51103515625,0.00999999977648258,4652.73130859375,0.00999999977648258,,,7.80994424882319,8.88459913651677,40.8573450972843,,25,5022.46611328125,4883.51103515625,4652.73130859375,
,13913209.25,4370,22.905650138855,0.13400000333786,0,5020.5078515625,0.00999999977648258,4881.088359375,0.00999999977648258,4635.4546875,0.00999999977648258,,,11.1622942102369,9.3880049835879,39.2419712612525,,25,5020.5078515625,4881.088359375,4635.4546875,
,13913221.92,4370,25.0832500457764,0.13400000333786,0,5017.75228515625,0.00999999977648258,4883.66578125,0.00999999977648258,4647.15814453125,0.00999999977648258,,,9.5710996206806,17.6937199471736,22.5311453956723,,25,5017.75228515625,4883.66578125,4647.15814453125,
,13913235.00,4370,27.2277498245239,0.13400000333786,0,5018.36384765625,0.00999999977648258,4879.3234765625,0.00999999977648258,4658.2733984375,0.00999999977648258,,,15.4546821639449,16.3421833899449,30.9363865547231,,25,5018.36384765625,4879.3234765625,4658.2733984375,
,13913251.73,4370,30.0139999389648,0.13400000333786,0,5020.09537109375,0.00999999977648258,4884.72146484375,0.00999999977648258,4654.1094140625,0.00999999977648258,,,8.60187229976703,10.2957673810281,26.868395101441,,25,5020.09537109375,4884.72146484375,4654.1094140625,
,13913264.48,4370,32.1414499282837,0.13400000333786,0,5021.46701171875,0.00999999977648258,4889.689140625,0.00999999977648258,4679.34298828125,0.00999999977648258,,,9.23236432974522,10.8094235219939,35.0218337589247,,25,5021.46701171875,4889.689140625,4679.34298828125,
,13913275.59,4370,34.0078506469727,0.13400000333786,0,5021.73052734375,0.00999999977648258,4893.137734375,0.00999999977648258,4665.11419921875,0.00999999977648258,,,9.25909187494447,9.38575227197287,38.0050758631177,,25,5021.73052734375,4893.137734375,4665.11419921875,
,13913288.48,4370,36.1704998016357,0.13400000333786,0,5022.33494140625,0.00999999977648258,4896.29970703125,0.00999999977648258,4679.9862109375,0.00999999977648258,,,8.72440318207036,10.8104286440662,31.6788189914763,,25,5022.33494140625,4896.29970703125,4679.9862109375,
,13913299.86,4370,38.0089492797852,0.13400000333786,0,5021.5678125,0.00999999977648258,4898.75630859375,0.00999999977648258,4663.39373046875,0.00999999977648258,,,10.703576468079,14.0886554158731,48.2611433554497,,25,5021.5678125,4898.75630859375,4663.39373046875,
,13913312.50,4370,40.175199508667,0.13400000333786,0,5018.35431640625,0.00999999977648258,4900.3749609375,0.00999999977648258,4690.0016015625,0.00999999977648258,,,11.1590841645946,13.8355295268135,59.5167589478317,,25,5018.35431640625,4900.3749609375,4690.0016015625,
,13913323.84,4370,42.0293006896973,0.13400000333786,0,5026.033125,0.00999999977648258,4904.11751953125,0.00999999977648258,4678.69634765625,0.00999999977648258,,,9.69022877873278,11.9079928505483,41.651490835213,,25,5026.033125,4904.11751953125,4678.69634765625,
,13913335.88,4370,44.0366516113281,0.13400000333786,0,5025.7464453125,0.00999999977648258,4908.34048828125,0.00999999977648258,4685.04248046875,0.00999999977648258,,,6.79154146866843,10.8234808550531,37.2856581994845,,25,5025.7464453125,4908.34048828125,4685.04248046875,
,13913348.98,4370,46.240650177002,0.13400000333786,0,5034.0760546875,0.00999999977648258,4911.4011328125,0.00999999977648258,4688.8082421875,0.00999999977648258,,,9.01932829413343,13.6092249482091,32.101505072984,,25,5034.0760546875,4911.4011328125,4688.8082421875,
,13913365.81,4370,49.0488986968994,0.13400000333786,0,5031.7243359375,0.00999999977648258,4910.50701171875,0.00999999977648258,4679.7244140625,0.00999999977648258,,,15.7598313333662,15.7659957693753,31.8985807222677,,25,5031.7243359375,4910.50701171875,4679.7244140625,
,13913377.83,4370,51.0557498931885,0.13400000333786,0,5024.5406640625,0.00999999977648258,4913.41486328125,0.00999999977648258,4702.24537109375,0.00999999977648258,,,34.7623555716852,44.8784480796594,33.202857793967,,25,5024.5406640625,4913.41486328125,4702.24537109375,
,13913390.36,4370,53.1648998260498,0.13400000333786,0,5026.4894921875,0.00999999977648258,4911.25712890625,0.00999999977648258,4697.094765625,0.00999999977648258,,,15.7477054905499,24.3392598206549,44.7413124525032,,25,5026.4894921875,4911.25712890625,4697.094765625,
,13913402.50,4370,55.1599998474121,0.13400000333786,0,5040.06228515625,0.00999999977648258,4921.3032421875,0.00999999977648258,4700.13408203125,0.00999999977648258,,,13.6608772339823,12.1178577260488,34.4184003106829,,25,5040.06228515625,4921.3032421875,4700.13408203125,
,13913413.80,4370,57.0118999481201,0.13400000333786,0,5040.51083984375,0.00999999977648258,4927.17314453125,0.00999999977648258,4706.05822265625,0.00999999977648258,,,10.5146446809065,18.6161173895338,21.7050133043988,,25,5040.51083984375,4927.17314453125,4706.05822265625,
,13913425.72,4370,59.0655498504639,0.13400000333786,0,5044.123203125,0.00999999977648258,4930.6211328125,0.00999999977648258,4714.1158203125,0.00999999977648258,,,13.6621016948861,14.8587091043007,32.7533593134405,,25,5044.123203125,4930.6211328125,4714.1158203125,
,13913438.00,4370,61.0822486877441,0.13400000333786,0,5045.949921875,0.00999999977648258,4940.09990234375,0.00999999977648258,4719.8779296875,0.00999999977648258,,,10.5806352504938,9.79954632474115,22.067423527101,,25,5045.949921875,4940.09990234375,4719.8779296875,
,13913450.30,4370,63.1858005523682,0.13400000333786,0,5054.44091796875,0.00999999977648258,4943.1390234375,0.00999999977648258,4729.36646484375,0.00999999977648258,,,10.9068121131618,12.9586917910285,10.9513669420969,,25,5054.44091796875,4943.1390234375,4729.36646484375,
,13913467.45,4370,66.0396003723145,0.13400000333786,0,5062.112109375,0.00999999977648258,4951.34375,0.00999999977648258,4737.55576171875,0.00999999977648258,,,7.3652180600953,7.42302378171265,7.59906907049396,,25,5062.112109375,4951.34375,4737.55576171875,
,13913480.17,4370,68.1078491210938,0.13400000333786,0,5066.55095703125,0.00999999977648258,4958.59734375,0.00999999977648258,4744.012734375,0.00999999977648258,,,13.605317499096,9.88417946461229,9.20465253319199,,25,5066.55095703125,4958.59734375,4744.012734375,
,13913491.77,4370,70.0914001464844,0.13400000333786,0,5071.1661328125,0.00999999977648258,4971.20703125,0.00999999977648258,4750.46458984375,0.00999999977648258,,,24.8442278826534,22.9443212822061,12.7472511723765,,25,5071.1661328125,4971.20703125,4750.46458984375,
,13913504.36,4370,72.1454010009766,0.13400000333786,0,5085.87435546875,0.00999999977648258,4980.07701171875,0.00999999977648258,4760.796875,0.00999999977648258,,,16.6947120116485,20.8610076783255,19.543997958892,,25,5085.87435546875,4980.07701171875,4760.796875,
,13913515.75,4370,74.0880012512207,0.13400000333786,0,5079.17923828125,0.00999999977648258,4961.40833984375,0.00999999977648258,4770.77369140625,0.00999999977648258,,,28.3749220842156,35.8387780973845,33.6314153810289,,25,5079.17923828125,4961.40833984375,4770.77369140625,
,13913527.33,4370,75.9703025817871,0.13400000333786,0,5084.1637890625,0.00999999977648258,4977.2364453125,0.00999999977648258,4787.963984375,0.00999999977648258,,,37.0824567562333,46.5665186233947,25.7128058475961,,25,5084.1637890625,4977.2364453125,4787.963984375,
,13913540.25,4370,78.1061477661133,0.13400000333786,0,5089.9919921875,0.00999999977648258,4987.14357421875,0.00999999977648258,4782.73951171875,0.00999999977648258,,,27.6060339434069,32.6597510233303,28.9192229470706,,25,5089.9919921875,4987.14357421875,4782.73951171875,
,13913552.56,4370,80.2363014221191,0.13400000333786,0,5118.3479296875,0.00999999977648258,5001.20443359375,0.00999999977648258,4801.3308984375,0.00999999977648258,,,46.8640330218884,53.3639140102395,31.8327819886307,,25,5118.3479296875,5001.20443359375,4801.3308984375,
,13913570.33,4370,83.1540489196777,0.13400000333786,0,5124.135390625,0.00999999977648258,5007.54966796875,0.00999999977648258,4803.881171875,0.00999999977648258,,,45.8923582397348,52.1966991097634,45.9920111174593,,25,5124.135390625,5007.54966796875,4803.881171875,
,13913582.78,4370,85.2220993041992,0.13400000333786,0,5117.867578125,0.00999999977648258,5034.3330859375,0.00999999977648258,4818.3691796875,0.00999999977648258,,,56.5407787194366,80.0228153581837,62.6447097862955,,25,5117.867578125,5034.3330859375,4818.3691796875,
,13913599.94,4370,88.0507469177246,0.13400000333786,0,5113.8543359375,0.00999999977648258,5025.40017578125,0.00999999977648258,4807.90224609375,0.00999999977648258,,,84.278927509681,55.9128449643767,51.8140883927372,,25,5113.8543359375,5025.40017578125,4807.90224609375,
,13913612.31,4370,90.1472969055176,0.13400000333786,0,5118.55404296875,0.00999999977648258,5041.6561328125,0.00999999977648258,4848.12474609375,0.00999999977648258,,,27.783276753856,40.2752722652922,31.9391120095105,,25,5118.55404296875,5041.6561328125,4848.12474609375,
,13913623.98,4370,92.0882987976074,0.13400000333786,0,5133.2183984375,0.00999999977648258,5064.77806640625,0.00999999977648258,4839.0798828125,0.00999999977648258,,,59.1126552794546,92.9665312340983,47.3743617402786,,25,5133.2183984375,5064.77806640625,4839.0798828125,
,13913635.86,4370,94.0640487670898,0.13400000333786,0,5129.21115234375,0.00999999977648258,5046.67974609375,0.00999999977648258,4845.303984375,0.00999999977648258,,,69.177609785937,60.8285612951568,59.9830216823741,,25,5129.21115234375,5046.67974609375,4845.303984375,
,13913648.92,4370,96.2565498352051,0.13400000333786,0,5164.61712890625,0.00999999977648258,5045.28455078125,0.00999999977648258,4855.4730078125,0.00999999977648258,,,63.3652070447864,86.5671719819791,62.9290100530038,,25,5164.61712890625,5045.28455078125,4855.4730078125,
,13913666.22,4370,99.1355972290039,0.13400000333786,0,5154.3766015625,0.00999999977648258,5096.03876953125,0.00999999977648258,4855.568828125,0.00999999977648258,,,68.9912724186947,47.0132431784729,62.9706697902566,,25,5154.3766015625,5096.03876953125,4855.568828125,
,13913677.98,4370,101.095050811768,0.13400000333786,0,5159.55939453125,0.00999999977648258,5072.22357421875,0.00999999977648258,4858.50796875,0.00999999977648258,,,11.030698319721,10.4003175183086,8.3775217246194,,25,5159.55939453125,5072.22357421875,4858.50796875,
,13913690.36,4370,103.188152313232,0.13400000333786,0,5158.7004296875,0.00999999977648258,5082.68685546875,0.00999999977648258,4873.359375,0.00999999977648258,,,24.5274479950082,29.0038459703352,18.4557587803588,,25,5158.7004296875,5082.68685546875,4873.359375,
,13913702.02,4370,105.13134765625,0.13400000333786,0,5157.16798828125,0.00999999977648258,5077.72603515625,0.00999999977648258,4877.5925390625,0.00999999977648258,,,32.6735950082899,37.332539792193,32.1623864111283,,25,5157.16798828125,5077.72603515625,4877.5925390625,
,13913713.31,4370,107.031448364258,0.13400000333786,0,5177.65330078125,0.00999999977648258,5091.51724609375,0.00999999977648258,4888.427421875,0.00999999977648258,,,20.9070557731606,29.3103437586979,21.1597468654508,,25,5177.65330078125,5091.51724609375,4888.427421875,
,13913726.41,4370,109.209453582764,0.13400000333786,0,5192.70708984375,0.00999999977648258,5093.9173828125,0.00999999977648258,4901.85599609375,0.00999999977648258,,,39.9570275334763,46.6855197677084,42.657980085097,,25,5192.70708984375,5093.9173828125,4901.85599609375,
,13913737.73,4370,111.073650360107,0.13400000333786,0,5191.37564453125,0.00999999977648258,5108.52736328125,0.00999999977648258,4905.42791015625,0.00999999977648258,,,31.3036408902142,35.4619066671046,18.9051655053388,,25,5191.37564453125,5108.52736328125,4905.42791015625,
,13913750.06,4370,113.120899200439,0.13400000333786,0,5205.2380078125,0.00999999977648258,5122.67638671875,0.00999999977648258,4911.045703125,0.00999999977648258,,,25.9936335634085,19.9602114288762,14.397989071783,,25,5205.2380078125,5122.67638671875,4911.045703125,
,13913761.70,4370,115.079399108887,0.13400000333786,0,5200.0697265625,0.00999999977648258,5125.876484375,0.00999999977648258,4921.4443359375,0.00999999977648258,,,73.8032322320231,70.6527968919838,59.6126744893913,,25,5200.0697265625,5125.876484375,4921.4443359375,
,13913774.48,4370,117.190250396729,0.13400000333786,0,5200.41841796875,0.00999999977648258,5156.5533203125,0.00999999977648258,4934.17544921875,0.00999999977648258,,,53.02462252507,52.6605035741968,43.9983278909812,,25,5200.41841796875,5156.5533203125,4934.17544921875,
,13913785.91,4370,119.149951934814,0.13400000333786,0,5206.00259765625,0.00999999977648258,5172.60037109375,0.00999999977648258,4940.317890625,0.00999999977648258,,,58.0107985849875,73.654248917085,65.2047554200662,,25,5206.00259765625,5172.60037109375,4940.317890625,
,13913797.22,4370,120.985248565674,0.13400000333786,0,5243.33158203125,0.00999999977648258,5161.9619921875,0.00999999977648258,4950.554609375,0.00999999977648258,,,72.5734804432496,73.4872527298155,33.1770518293848,,25,5243.33158203125,5161.9619921875,4950.554609375,
,13913810.02,4370,123.094249725342,0.13400000333786,0,5237.41763671875,0.00999999977648258,5150.90138671875,0.00999999977648258,4953.19755859375,0.00999999977648258,,,79.545172794543,72.1177123703802,72.4419281673323,,25,5237.41763671875,5150.90138671875,4953.19755859375,
,13913822.20,4370,125.158348083496,0.13400000333786,0,5231.852421875,0.00999999977648258,5165.50419921875,0.00999999977648258,4942.3927734375,0.00999999977648258,,,60.3239695133134,52.8137191380984,39.0943744492915,,25,5231.852421875,5165.50419921875,4942.3927734375,
,13913833.84,4370,127.07825088501,0.13400000333786,0,5235.8208984375,0.00999999977648258,5155.66037109375,0.00999999977648258,4965.56037109375,0.00999999977648258,,,46.9166651830042,79.3464957720324,45.4823701253103,,25,5235.8208984375,5155.66037109375,4965.56037109375,
,13913845.58,4370,129.058502197266,0.13400000333786,0,5243.78888671875,0.00999999977648258,5162.12779296875,0.00999999977648258,4977.36916015625,0.00999999977648258,,,47.8822981089387,54.3856086108044,46.5807512156637,,25,5243.78888671875,5162.12779296875,4977.36916015625,
,13913857.19,4370,130.977447509766,0.13400000333786,0,5251.9415234375,0.00999999977648258,5178.6147265625,0.00999999977648258,4972.32013671875,0.00999999977648258,,,18.2261884033075,11.3712545178448,13.0148672127142,,25,5251.9415234375,5178.6147265625,4972.32013671875,
,13913870.03,4370,133.10725402832,0.13400000333786,0,5274.16748046875,0.00999999977648258,5187.45697265625,0.00999999977648258,4993.51529296875,0.00999999977648258,,,37.1071386995588,53.9272806008211,38.8912218750393,,25,5274.16748046875,5187.45697265625,4993.51529296875,
,13913881.28,4370,134.982154846191,0.13400000333786,0,5250.965078125,0.00999999977648258,5185.3801953125,0.00999999977648258,5006.4725390625,0.00999999977648258,,,63.4532685780774,71.7900651923905,56.5583021178619,,25,5250.965078125,5185.3801953125,5006.4725390625,
,13913894.30,4370,137.141448974609,0.13400000333786,0,5260.295625,0.00999999977648258,5188.1312890625,0.00999999977648258,4999.7769140625,0.00999999977648258,,,57.0513979360663,66.9771008203737,55.4138243735123,,25,5260.295625,5188.1312890625,4999.7769140625,
,13913906.09,4370,139.139053344727,0.13400000333786,0,5285.00396484375,0.00999999977648258,5217.20181640625,0.00999999977648258,5009.32271484375,0.00999999977648258,,,46.7185695412669,46.1221591154475,26.8372326319037,,25,5285.00396484375,5217.20181640625,5009.32271484375,
,13913917.81,4370,141.056999206543,0.13400000333786,0,5266.51783203125,0.00999999977648258,5201.093046875,0.00999999977648258,5003.71375,0.00999999977648258,,,55.0482888830266,60.97738279601,25.8295152881935,,25,5266.51783203125,5201.093046875,5003.71375,
,13913929.53,4370,143.038795471191,0.13400000333786,0,5265.48275390625,0.00999999977648258,5214.23359375,0.00999999977648258,5009.5075390625,0.00999999977648258,,,18.7694260628022,34.1179138936226,10.9908458527067,,25,5265.48275390625,5214.23359375,5009.5075390625,
,13913942.73,4370,145.262153625488,0.13400000333786,0,5294.0969140625,0.00999999977648258,5223.32626953125,0.00999999977648258,5025.66888671875,0.00999999977648258,,,60.8260601611211,70.2422720618031,41.7614335682924,,25,5294.0969140625,5223.32626953125,5025.66888671875,
,13913959.72,4370,148.104850769043,0.13400000333786,0,5292.35880859375,0.00999999977648258,5223.92091796875,0.00999999977648258,5024.764921875,0.00999999977648258,,,16.6795101178674,18.4844270117561,14.7631450992598,,25,5292.35880859375,5223.92091796875,5024.764921875,
,13913971.14,4370,150.011604309082,0.13400000333786,0,5286.17880859375,0.00999999977648258,5241.91802734375,0.00999999977648258,5039.3737890625,0.00999999977648258,,,28.957299456698,38.1771310413762,30.522779002872,,25,5286.17880859375,5241.91802734375,5039.3737890625,
,13913984.08,4370,152.123748779297,0.13400000333786,0,5316.73970703125,0.00999999977648258,5265.309609375,0.00999999977648258,5061.91228515625,0.00999999977648258,,,48.3426728429507,35.1480563758987,40.5582035910787,,25,5316.73970703125,5265.309609375,5061.91228515625,
,13913996.31,4370,154.179695129395,0.13400000333786,0,5323.1045703125,0.00999999977648258,5235.53703125,0.00999999977648258,5052.9302734375,0.00999999977648258,,,56.505749329889,37.4022657441902,31.3474983242846,,25,5323.1045703125,5235.53703125,5052.9302734375,
,13914007.61,4370,156.060752868652,0.13400000333786,0,5337.74693359375,0.00999999977648258,5266.4168359375,0.00999999977648258,5047.0455078125,0.00999999977648258,,,65.8512387447067,82.8015868965288,38.4377010409013,,25,5337.74693359375,5266.4168359375,5047.0455078125,
,13914020.23,4370,158.145652770996,0.13400000333786,0,5335.17609375,0.00999999977648258,5298.53552734375,0.00999999977648258,5085.41287109375,0.00999999977648258,,,67.1989844141332,64.7981722143114,52.4052743954217,,25,5335.17609375,5298.53552734375,5085.41287109375,
,13914031.34,4370,160.018402099609,0.13400000333786,0,5351.85689453125,0.00999999977648258,5258.77693359375,0.00999999977648258,5077.07564453125,0.00999999977648258,,,37.9678297607338,42.6990286536954,42.6112007050559,,25,5351.85689453125,5258.77693359375,5077.07564453125,
,13914043.94,4370,162.138252258301,0.13400000333786,0,5332.50138671875,0.00999999977648258,5272.76787109375,0.00999999977648258,5081.2557421875,0.00999999977648258,,,29.6414465774035,43.2476042416172,28.5403517246007,,25,5332.50138671875,5272.76787109375,5081.2557421875,
,13914055.38,4370,164.04069519043,0.13400000333786,0,5342.23154296875,0.00999999977648258,5285.90642578125,0.00999999977648258,5089.77255859375,0.00999999977648258,,,12.1488805507629,11.3329386173619,8.16940155716141,,25,5342.23154296875,5285.90642578125,5089.77255859375,
,13914068.31,4370,166.172203063965,0.13400000333786,0,5344.39556640625,0.00999999977648258,5297.04306640625,0.00999999977648258,5092.04474609375,0.00999999977648258,,,29.104790210558,42.9765363062807,31.0390979030685,,25,5344.39556640625,5297.04306640625,5092.04474609375,
,13914079.44,4370,168.042503356934,0.13400000333786,0,5363.13716796875,0.00999999977648258,5310.3439453125,0.00999999977648258,5107.92671875,0.00999999977648258,,,22.6588690907076,22.7456502243102,16.7888890660631,,25,5363.13716796875,5310.3439453125,5107.92671875,
,13914091.95,4370,170.11499786377,0.13400000333786,0,5373.86125,0.00999999977648258,5319.73203125,0.00999999977648258,5117.75484375,0.00999999977648258,,,13.8964735269672,22.909495496124,15.5091808042142,,25,5373.86125,5319.73203125,5117.75484375,
,13914104.28,4370,172.185852050781,0.13400000333786,0,5390.11029296875,0.00999999977648258,5326.5776171875,0.00999999977648258,5133.03,0.00999999977648258,,,40.6614076487958,36.3302714632525,25.3833440034907,,25,5390.11029296875,5326.5776171875,5133.03,
,13914116.28,4370,174.157905578613,0.13400000333786,0,5385.33384765625,0.00999999977648258,5330.8973046875,0.00999999977648258,5134.0595703125,0.00999999977648258,,,27.7106635009834,29.8951759583511,14.8578997146894,,25,5385.33384765625,5330.8973046875,5134.0595703125,
,13914128.36,4370,176.159698486328,0.13400000333786,0,5393.57833984375,0.00999999977648258,5336.80384765625,0.00999999977648258,5147.95509765625,0.00999999977648258,,,16.0938018532955,19.9904474699909,16.2238358211841,,25,5393.57833984375,5336.80384765625,5147.95509765625,
,13914139.72,4370,178.049301147461,0.13400000333786,0,5404.62517578125,0.00999999977648258,5344.699921875,0.00999999977648258,5161.50244140625,0.00999999977648258,,,44.541274446732,41.1476730287345,22.1101695801699,,25,5404.62517578125,5344.699921875,5161.50244140625,
,13914152.19,4370,180.168998718262,0.13400000333786,0,5410.27890625,0.00999999977648258,5346.64205078125,0.00999999977648258,5163.10890625,0.00999999977648258,,,21.3900768701441,19.0822494084393,16.2341122074767,,25,5410.27890625,5346.64205078125,5163.10890625,
,13914162.75,4370,181.94075012207,0.13400000333786,0,5408.08626953125,0.00999999977648258,5353.79857421875,0.00999999977648258,5162.11693359375,0.00999999977648258,,,38.0738844914576,54.6619762888324,37.4916391413559,,25,5408.08626953125,5353.79857421875,5162.11693359375,
,13914175.55,4370,184.02840423584,0.13400000333786,0,5412.02310546875,0.00999999977648258,5369.9015625,0.00999999977648258,5171.31310546875,0.00999999977648258,,,52.0048445003264,80.3052208843353,37.5005551412341,,25,5412.02310546875,5369.9015625,5171.31310546875,
,13914187.89,4370,186.127548217773,0.13400000333786,0,5433.09171875,0.00999999977648258,5375.52447265625,0.00999999977648258,5179.4342578125,0.00999999977648258,,,46.669142412572,72.7872426866069,39.8355743234916,,25,5433.09171875,5375.52447265625,5179.4342578125,
,13914199.58,4370,188.047950744629,0.13400000333786,0,5419.64154296875,0.00999999977648258,5377.45818359375,0.00999999977648258,5190.28552734375,0.00999999977648258,,,32.6725848168492,58.3812831367669,35.3187829994111,,25,5419.64154296875,5377.45818359375,5190.28552734375,
,13914212.38,4370,190.227401733398,0.13400000333786,0,5432.08771484375,0.00999999977648258,5373.45091796875,0.00999999977648258,5193.15912109375,0.00999999977648258,,,66.0387191018351,56.5646642895235,74.2251674323811,,25,5432.08771484375,5373.45091796875,5193.15912109375,
,13914229.69,4370,193.057502746582,0.13400000333786,0,5460.23306640625,0.00999999977648258,5421.98265625,0.00999999977648258,5213.36669921875,0.00999999977648258,,,66.4514134705967,67.1482811738459,58.9107406104225,,25,5460.23306640625,5421.98265625,5213.36669921875,
,13914241.22,4370,194.988655090332,0.13400000333786,0,5469.5575390625,0.00999999977648258,5407.64744140625,0.00999999977648258,5211.1130859375,0.00999999977648258,,,91.3303135972273,57.4892777996271,49.6849008512409,,25,5469.5575390625,5407.64744140625,5211.1130859375,
,13914254.05,4370,197.149147033691,0.13400000333786,0,5473.7396875,0.00999999977648258,5431.578125,0.00999999977648258,5241.66544921875,0.00999999977648258,,,30.1990570698211,31.551886926792,29.5625805991054,,25,5473.7396875,5431.578125,5241.66544921875,
,13914265.97,4370,199.138748168945,0.13400000333786,0,5480.09025390625,0.00999999977648258,5443.0865625,0.00999999977648258,5246.7071875,0.00999999977648258,,,26.4071250244335,29.913099496603,22.1810265500834,,25,5480.09025390625,5443.0865625,5246.7071875,
,13914277.42,4370,200.998596191406,0.13400000333786,0,5495.3952734375,0.00999999977648258,5447.39994140625,0.00999999977648258,5260.260078125,0.00999999977648258,,,64.0115163604592,54.7268670388447,41.3797507745014,,25,5495.3952734375,5447.39994140625,5260.260078125,
,13914289.95,4370,203.092300415039,0.13400000333786,0,5490.08388671875,0.00999999977648258,5444.3655859375,0.00999999977648258,5266.18994140625,0.00999999977648258,,,43.7820176734831,59.8573954523623,44.6199390918108,,25,5490.08388671875,5444.3655859375,5266.18994140625,
,13914301.23,4370,204.989250183105,0.13400000333786,0,5500.594921875,0.00999999977648258,5439.13330078125,0.00999999977648258,5278.9876953125,0.00999999977648258,,,95.9551691132008,77.9942751187073,54.3596886971582,,25,5500.594921875,5439.13330078125,5278.9876953125,
,13914313.55,4370,207.030151367188,0.13400000333786,0,5464.03884765625,0.00999999977648258,5468.17830078125,0.00999999977648258,5294.568125,0.00999999977648258,,,88.0847104111226,74.9171049292601,63.6036998557514,,25,5464.03884765625,5468.17830078125,5294.568125,
,13914326.34,4370,209.211349487305,0.13400000333786,0,5525.94232421875,0.00999999977648258,5448.1328515625,0.00999999977648258,5313.02447265625,0.00999999977648258,,,87.0494065152427,94.4619813373474,69.1036201337014,,25,5525.94232421875,5448.1328515625,5313.02447265625,
,13914338.28,4370,211.181747436523,0.13400000333786,0,5516.8277734375,0.00999999977648258,5471.51529296875,0.00999999977648258,5299.58470703125,0.00999999977648258,,,66.0627025604357,72.7965046001103,39.0829638933675,,25,5516.8277734375,5471.51529296875,5299.58470703125,
,13914349.34,4370,213.035751342773,0.13400000333786,0,5510.320234375,0.00999999977648258,5496.84802734375,0.00999999977648258,5307.97482421875,0.00999999977648258,,,86.0750324398426,65.5835490395909,92.6392999570332,,25,5510.320234375,5496.84802734375,5307.97482421875,
,13914361.28,4370,214.987152099609,0.13400000333786,0,5532.99583984375,0.00999999977648258,5500.6441015625,0.00999999977648258,5308.89669921875,0.00999999977648258,,,58.5603927860218,68.8883895890682,57.1834740287971,,25,5532.99583984375,5500.6441015625,5308.89669921875,
,13914373.94,4370,217.097152709961,0.13400000333786,0,5521.6308984375,0.00999999977648258,5511.00966796875,0.00999999977648258,5338.103046875,0.00999999977648258,,,67.5879871314531,59.0014289944243,92.9418076382396,,25,5521.6308984375,5511.00966796875,5338.103046875,
,13914386.36,4370,219.202499389648,0.13400000333786,0,5561.96982421875,0.00999999977648258,5509.3905078125,0.00999999977648258,5348.104609375,0.00999999977648258,,,89.4585756818447,61.4443712545269,67.529639336772,,25,5561.96982421875,5509.3905078125,5348.104609375,
,13914397.91,4370,221.11344909668,0.13400000333786,0,5516.97671875,0.00999999977648258,5534.306484375,0.00999999977648258,5343.568203125,0.00999999977648258,,,96.9065307786033,66.7953881784235,74.3753131814782,,25,5516.97671875,5534.306484375,5343.568203125,
,13914409.70,4370,223.126502990723,0.13400000333786,0,5571.96818359375,0.00999999977648258,5517.29966796875,0.00999999977648258,5349.7378515625,0.00999999977648258,,,63.423739718363,70.0859950564963,46.4353253314954,,25,5571.96818359375,5517.29966796875,5349.7378515625,
,13914421.77,4370,225.051048278809,0.13400000333786,0,5592.51541015625,0.00999999977648258,5536.29736328125,0.00999999977648258,5365.17921875,0.00999999977648258,,,89.9602793332595,96.1885881383509,65.1905794360107,,25,5592.51541015625,5536.29736328125,5365.17921875,
,13914433.75,4370,227.081451416016,0.13400000333786,0,5574.18400390625,0.00999999977648258,5548.45357421875,0.00999999977648258,5356.780546875,0.00999999977648258,,,27.9038006650367,36.719927725623,28.3464100329071,,25,5574.18400390625,5548.45357421875,5356.780546875,
,13914445.17,4370,229.01774597168,0.13400000333786,0,5596.048359375,0.00999999977648258,5545.0214453125,0.00999999977648258,5376.2120703125,0.00999999977648258,,,37.0119274054511,55.8657085764801,31.8745199275446,,25,5596.048359375,5545.0214453125,5376.2120703125,
,13914457.75,4370,231.10050201416,0.13400000333786,0,5585.64458984375,0.00999999977648258,5549.3792578125,0.00999999977648258,5366.898203125,0.00999999977648258,,,67.7258749075584,53.4654604918805,43.3951551926232,,25,5585.64458984375,5549.3792578125,5366.898203125,
,13914470.39,4370,233.108848571777,0.13400000333786,0,5576.35927734375,0.00999999977648258,5548.132578125,0.00999999977648258,5386.27640625,0.00999999977648258,,,50.5682481249434,56.4149662063179,49.0092981375722,,25,5576.35927734375,5548.132578125,5386.27640625,
,13914481.83,4370,235.096855163574,0.13400000333786,0,5606.15330078125,0.00999999977648258,5543.80888671875,0.00999999977648258,5388.50771484375,0.00999999977648258,,,85.8893434872374,95.0560589673025,78.9590445248465,,25,5606.15330078125,5543.80888671875,5388.50771484375,
,13914493.41,4370,237.029098510742,0.13400000333786,0,5576.49056640625,0.00999999977648258,5583.78654296875,0.00999999977648258,5396.82287109375,0.00999999977648258,,,113.74006187193,106.474780330872,99.1089158951704,,25,5576.49056640625,5583.78654296875,5396.82287109375,
,13914505.92,4370,239.110801696777,0.13400000333786,0,5610.31470703125,0.00999999977648258,5554.3707421875,0.00999999977648258,5384.64736328125,0.00999999977648258,,,52.5638892476226,63.2082017711258,60.3787607344375,,25,5610.31470703125,5554.3707421875,5384.64736328125,
,13914517.70,4370,241.039901733398,0.13400000333786,0,5639.59693359375,0.00999999977648258,5583.01166015625,0.00999999977648258,5416.20408203125,0.00999999977648258,,,59.6428226671491,59.9960320853522,37.5045539123393,,25,5639.59693359375,5583.01166015625,5416.20408203125,
,13914529.92,4370,243.086303710938,0.13400000333786,0,5615.63388671875,0.00999999977648258,5595.448515625,0.00999999977648258,5432.65759765625,0.00999999977648258,,,106.549741656276,100.172528847282,84.7049482227995,,25,5615.63388671875,5595.448515625,5432.65759765625,
,13914542.55,4370,245.18384552002,0.13400000333786,0,5632.03451171875,0.00999999977648258,5611.7716796875,0.00999999977648258,5434.79375,0.00999999977648258,,,61.8906862244885,44.039846957515,37.627539743543,,25,5632.03451171875,5611.7716796875,5434.79375,
,13914553.28,4370,246.956649780273,0.13400000333786,0,5646.0048046875,0.00999999977648258,5605.30119140625,0.00999999977648258,5439.9251953125,0.00999999977648258,,,26.6034085849423,25.8501036986185,27.0118144006753,,25,5646.0048046875,5605.30119140625,5439.9251953125,
,13914566.23,4370,249.159149169922,0.13400000333786,0,5651.03576171875,0.00999999977648258,5627.545390625,0.00999999977648258,5448.80279296875,0.00999999977648258,,,23.7015006182851,25.3903616081661,15.9345189673683,,25,5651.03576171875,5627.545390625,5448.80279296875,
,13914577.56,4370,251.027954101563,0.13400000333786,0,5639.5323046875,0.00999999977648258,5633.22984375,0.00999999977648258,5439.4276171875,0.00999999977648258,,,70.1174160739499,99.4911761662694,89.2266758209822,,25,5639.5323046875,5633.22984375,5439.4276171875,
,13914589.81,4370,253.080307006836,0.13400000333786,0,5669.08376953125,0.00999999977648258,5607.83197265625,0.00999999977648258,5478.77953125,0.00999999977648258,,,61.4084069380061,69.4283351348508,69.1573135281647,,25,5669.08376953125,5607.83197265625,5478.77953125,
,13914624.88,4374,255.433746337891,0.13400000333786,0,5664.0271484375,0.00999999977648258,5644.9603125,0.00999999977648258,5470.70751953125,0.00999999977648258,,,48.1189901801931,41.1933406161301,29.4324115451841,,25,5664.0271484375,5644.9603125,5470.70751953125,
,13914638.41,4374,258.143203735352,0.13400000333786,0,5643.5209375,0.00999999977648258,5646.766171875,0.00999999977648258,5502.1521484375,0.00999999977648258,,,80.0342979531749,62.2535177343957,57.6035090008547,,25,5643.5209375,5646.766171875,5502.1521484375,
,13914655.45,4374,261.10205078125,0.13400000333786,0,5688.30392578125,0.00999999977648258,5671.79341796875,0.00999999977648258,5513.95609375,0.00999999977648258,,,77.191893070778,95.3538079838144,69.6572080918681,,25,5688.30392578125,5671.79341796875,5513.95609375,
,13914666.81,4374,263.024551391602,0.13400000333786,0,5694.63568359375,0.00999999977648258,5684.689140625,0.00999999977648258,5536.50427734375,0.00999999977648258,,,87.3978763187042,101.359290150093,90.8880331800462,,25,5694.63568359375,5684.689140625,5536.50427734375,
,13914679.16,4374,265.049606323242,0.13400000333786,0,5698.6065625,0.00999999977648258,5676.78611328125,0.00999999977648258,5557.07861328125,0.00999999977648258,,,74.6483087568256,97.6896596521576,89.8029549568046,,25,5698.6065625,5676.78611328125,5557.07861328125,
,13914692.08,4374,267.182998657227,0.13400000333786,0,5696.35787109375,0.00999999977648258,5681.95732421875,0.00999999977648258,5523.12880859375,0.00999999977648258,,,68.2665951489461,97.6466708266871,93.4276545767186,,25,5696.35787109375,5681.95732421875,5523.12880859375,
,13914703.38,4374,268.927703857422,0.13400000333786,0,5749.75662109375,0.00999999977648258,5667.5976171875,0.00999999977648258,5560.6405859375,0.00999999977648258,,,96.7469656226284,65.6259790480334,79.7058467390926,,25,5749.75662109375,5667.5976171875,5560.6405859375,
,13914717.08,4374,271.085800170898,0.13400000333786,0,5725.0127734375,0.00999999977648258,5715.597265625,0.00999999977648258,5580.43244140625,0.00999999977648258,,,115.831875329531,103.324214309236,58.5683288799622,,25,5725.0127734375,5715.597265625,5580.43244140625,
,13914729.88,4374,273.063400268555,0.13400000333786,0,5736.92361328125,0.00999999977648258,5709.35134765625,0.00999999977648258,5603.02197265625,0.00999999977648258,,,42.6067490527853,48.2982035955989,66.8318896538516,,25,5736.92361328125,5709.35134765625,5603.02197265625,
,13914742.59,4374,275.02424621582,0.13400000333786,0,5740.348828125,0.00999999977648258,5719.47970703125,0.00999999977648258,5569.30435546875,0.00999999977648258,,,34.2863416018639,45.7647002632788,32.2948870071255,,25,5740.348828125,5719.47970703125,5569.30435546875,
,13914755.66,4374,277.047302246094,0.13400000333786,0,5750.23537109375,0.00999999977648258,5720.85046875,0.00999999977648258,5558.71361328125,0.00999999977648258,,,20.3835128275124,19.6788566306251,22.1779331671214,,25,5750.23537109375,5720.85046875,5558.71361328125,
,13914768.28,4374,278.952896118164,0.13400000333786,0,5757.30880859375,0.00999999977648258,5730.474375,0.00999999977648258,5567.26697265625,0.00999999977648258,,,35.941943029629,32.6451322640123,23.3534573526908,,25,5757.30880859375,5730.474375,5567.26697265625,
,13914782.52,4374,281.129638671875,0.13400000333786,0,5760.63396484375,0.00999999977648258,5738.1248046875,0.00999999977648258,5568.5148828125,0.00999999977648258,,,19.0006669785811,32.781788039099,25.5205524066706,,25,5760.63396484375,5738.1248046875,5568.5148828125,
,13914795.05,4374,282.988250732422,0.13400000333786,0,5766.82705078125,0.00999999977648258,5752.24728515625,0.00999999977648258,5580.0407421875,0.00999999977648258,,,19.7444989753676,26.0380801861955,20.1241358464496,,25,5766.82705078125,5752.24728515625,5580.0407421875,
,13914808.14,4374,285.002044677734,0.13400000333786,0,5781.72470703125,0.00999999977648258,5754.75087890625,0.00999999977648258,5597.60482421875,0.00999999977648258,,,33.189024502843,46.0536913633401,49.4754436488163,,25,5781.72470703125,5754.75087890625,5597.60482421875,
,13914822.17,4374,287.06755065918,0.13400000333786,0,5753.92990234375,0.00999999977648258,5752.75546875,0.00999999977648258,5559.2805859375,0.00999999977648258,,,39.9226451335256,44.9741243255593,40.0221881321017,,25,5753.92990234375,5752.75546875,5559.2805859375,
,13914834.56,4374,288.9541015625,0.13400000333786,0,5764.2449609375,0.00999999977648258,5756.49513671875,0.00999999977648258,5598.68630859375,0.00999999977648258,,,28.7462244672326,29.6233763027857,28.0840444081338,,25,5764.2449609375,5756.49513671875,5598.68630859375,
,13914848.44,4374,290.968200683594,0.13400000333786,0,5774.36677734375,0.00999999977648258,5758.7744921875,0.00999999977648258,5580.83787109375,0.00999999977648258,,,31.6097590791549,50.3209516470316,39.2246050993496,,25,5774.36677734375,5758.7744921875,5580.83787109375,
,13914862.33,4374,292.993804931641,0.13400000333786,0,5783.89376953125,0.00999999977648258,5768.1391796875,0.00999999977648258,5597.38830078125,0.00999999977648258,,,33.4387705274097,43.8070750093581,32.9047290946042,,25,5783.89376953125,5768.1391796875,5597.38830078125,
,13914875.27,4374,294.895950317383,0.13400000333786,0,5774.71763671875,0.00999999977648258,5776.18794921875,0.00999999977648258,5602.65412109375,0.00999999977648258,,,32.383691034548,36.3357649707615,23.9502493774706,,25,5774.71763671875,5776.18794921875,5602.65412109375,
,13914889.30,4374,296.955307006836,0.13400000333786,0,5789.3950390625,0.00999999977648258,5779.78728515625,0.00999999977648258,5622.74763671875,0.00999999977648258,,,24.4519814321373,24.0717884583603,23.5975145503998,,25,5789.3950390625,5779.78728515625,5622.74763671875,
,13914903.11,4374,298.959838867188,0.13400000333786,0,5786.2105078125,0.00999999977648258,5793.90130859375,0.00999999977648258,5622.6317578125,0.00999999977648258,,,19.8570799241425,24.7285745936535,20.5349189923465,,25,5786.2105078125,5793.90130859375,5622.6317578125,
,13914916.61,4370,300.792694091797,0.13400000333786,0,5802.8905859375,0.00999999977648258,5795.408515625,0.00999999977648258,5627.60177734375,0.00999999977648258,,,12.4124473837893,15.2403860564935,14.386935116179,,25,5802.8905859375,5795.408515625,5627.60177734375,