File: icepp/250307-ch1Nb100-ch2Nb150-ch3NbAl_fineUp2.dat
[Header]
TITLE, 7.7 to 8.2 for channel 3
FILEOPENTIME,13812140.67,3/7/2025,7:53 PM
BYAPP, Resistivity, 2.1, 1.0
INFO, APPNAME, PPMS MultiVu Application, 1.5.11
INFO, , Sample1 Name
INFO, 1, Sample1 Cross Section
INFO, 1, Sample1 Length
INFO, Ohm, Sample1 Units
INFO, , Sample2 Name
INFO, 1, Sample2 Cross Section
INFO, 1, Sample2 Length
INFO, Ohm, Sample2 Units
INFO, , Sample3 Name
INFO, 1, Sample3 Cross Section
INFO, 1, Sample3 Length
INFO, Ohm, Sample3 Units
INFO, , Sample4 Name
INFO, 1, Sample4 Cross Section
INFO, 1, Sample4 Length
INFO, Ohm, Sample4 Units
FIELDGROUP, Resistivity,2,3,4,5,6,7,8,9,10,11,12,13,14,15,16,17,18,19,20,21,22,23,24,25,26,27,28,29,30,31,32,33,34,35,36,37,38,39,40,41
STARTUPGROUP, Resistivity
STARTUPAXIS, X, 2, LINEAR, AUTO
STARTUPAXIS, Y1, 7, LINEAR, AUTO
STARTUPAXIS, Y2, 9, LINEAR, AUTO
STARTUPAXIS, Y3, 11, LINEAR, AUTO
PLOT_APPEARANCE, ALL, HORZ_GRID_ON, VERT_GRID_ON, MARKERS_AND_LINES, ALL_LINES
DATATYPE, TIME, 2
DATATYPE, COMMENT, 1
[Data]
Comment,Time Stamp (sec),Status (code),Temperature (K),Magnetic Field (Oe),Sample Position (deg),Bridge 1 Resistivity (Ohm),Bridge 1 Excitation (uA),Bridge 2 Resistivity (Ohm),Bridge 2 Excitation (uA),Bridge 3 Resistivity (Ohm),Bridge 3 Excitation (uA),Bridge 4 Resistivity (Ohm),Bridge 4 Excitation (uA),Bridge 1 Std. Dev. (Ohm),Bridge 2 Std. Dev. (Ohm),Bridge 3 Std. Dev. (Ohm),Bridge 4 Std. Dev. (Ohm),Number of Readings,Bridge 1 Resistance (Ohms),Bridge 2 Resistance (Ohms),Bridge 3 Resistance (Ohms),Bridge 4 Resistance (Ohms),Signal 1 Vin (V),Signal 2 Vin (V),Digital Inputs (code),Drive 1 Iout (mA),Drive 1 Ipower (watts),Drive 2 Iout (mA),Drive 2 Ipower (watts),Pressure (),Map 20 (),Map 21 (),Map 22 (),Map 23 (),Map 24 (),Map 25 (),Map 26 (),Map 27 (),Map 28 (),Map 29 ()
,13813201.20,4370,7.70230007171631,0.13400000333786,0,0.000259668343933299,9.98999977111816,0.000412414406891912,9.98999977111816,-0.000496424798038788,9.98999977111816,,,0.00386642265787038,0.00349095842439231,0.00377795767600547,,25,0.000259668343933299,0.000412414406891912,-0.000496424798038788,
,13813217.73,4370,7.70675015449524,0.13400000333786,0,-0.000374227950815111,9.98999977111816,-0.000351315998123027,9.98999977111816,-0.000511699430062436,9.98999977111816,,,0.00358810290420659,0.00373630492487186,0.00299111408010831,,25,-0.000374227950815111,-0.000351315998123027,-0.000511699430062436,
,13813232.81,4370,7.71165013313293,0.13400000333786,0,0.000672082823002711,9.98999977111816,-0.00100048686377704,9.98999977111816,1.52745639206842e-005,9.98999977111816,,,0.00448431415923428,0.00401531964008265,0.00390172837164341,,25,0.000672082823002711,-0.00100048686377704,1.52745639206842e-005,
,13813248.75,4370,7.71635007858276,0.13400000333786,0,-0.000511780775268562,9.98999977111816,-9.93069965625182e-005,9.98999977111816,0.000381883548106998,9.98999977111816,,,0.00335081987576423,0.00351617606599726,0.0033412876040575,,25,-0.000511780775268562,-9.93069965625182e-005,0.000381883548106998,
,13813263.20,4370,7.72119998931885,0.13400000333786,0,-0.000106926334556192,9.98999977111816,-0.000397155005484819,9.98999977111816,-0.000290228638332337,9.98999977111816,,,0.00278750276399819,0.0046337993367047,0.00373778972803936,,25,-0.000106926334556192,-0.000397155005484819,-0.000290228638332337,
,13813279.27,4370,7.72744989395142,0.13400000333786,0,0.0017948349902872,9.98999977111816,-0.000504081305116415,9.98999977111816,0.00148933121352457,9.98999977111816,,,0.00356193757889017,0.00370910460330854,0.00336401200251779,,25,0.0017948349902872,-0.000504081305116415,0.00148933121352457,
,13813291.83,4370,7.73099994659424,0.13400000333786,0,-0.00144350561895408,9.98999977111816,-1.52752397116274e-005,9.98999977111816,-0.000160389494849369,9.98999977111816,,,0.00276491515218224,0.00406622901829391,0.00412383505930246,,25,-0.00144350561895408,-1.52752397116274e-005,-0.000160389494849369,
,13813307.36,4370,7.73714995384216,0.13400000333786,0,-0.000145154781639576,9.98999977111816,-0.00067982169915922,9.98999977111816,0.000137566612102091,9.98999977111816,,,0.00335508734222553,0.00469491262681987,0.00314429385853093,,25,-0.000145154781639576,-0.00067982169915922,0.000137566612102091,
,13813332.66,4370,7.74620008468628,0.13400000333786,0,0.000267354138195515,9.98999977111816,0.000168051160871983,9.98999977111816,-0.000519430860877037,9.98999977111816,,,0.00411993818416375,0.00350894474275821,0.00335299300088434,,25,0.000267354138195515,0.000168051160871983,-0.000519430860877037,
,13813348.69,4370,7.75055003166199,0.13400000333786,0,-0.00080206235870719,9.98999977111816,0.000236799363046885,9.98999977111816,-7.63868726789951e-005,9.98999977111816,,,0.00314580472200262,0.00429647589353843,0.00294807885450183,,25,-0.00080206235870719,0.000236799363046885,-7.63868726789951e-005,
,13813365.11,4370,7.75594997406006,0.13400000333786,0,0.000389573145657778,9.98999977111816,0.00108469387516379,9.98999977111816,-0.00106177780777216,9.98999977111816,,,0.00263312162646005,0.00354015132056711,0.0028931781242249,,25,0.000389573145657778,0.00108469387516379,-0.00106177780777216,
,13813381.44,4370,7.76079988479614,0.13400000333786,0,-2.29122984455898e-005,9.98999977111816,-0.000381872527650557,9.98999977111816,0.000809569686534815,9.98999977111816,,,0.00291692606721857,0.00289921471626028,0.00354721529787232,,25,-2.29122984455898e-005,-0.000381872527650557,0.000809569686534815,
,13813395.25,4370,7.76605010032654,0.13400000333786,0,0.000435334643116221,9.98999977111816,-0.000481159348855726,9.98999977111816,0.00904274105560035,9.98999977111816,,,0.0032607171852702,0.00239462989691953,0.00518078148063529,,25,0.000435334643116221,-0.000481159348855726,0.00904274105560035,
,13813408.06,4370,7.76959991455078,0.13400000333786,0,-0.000274948189035058,9.98999977111816,-0.000435334639623761,9.98999977111816,0.0264637646824121,9.98999977111816,,,0.00342924059172377,0.00351800548131139,0.0056682022836874,,25,-0.000274948189035058,-0.000435334639623761,0.0264637646824121,
,13813424.09,4370,7.77574992179871,0.13400000333786,0,-0.000282585699460469,9.98999977111816,-0.00090121911955066,9.98999977111816,0.0717996682226658,9.98999977111816,,,0.00316752604044938,0.00281163988453256,0.0109880435172505,,25,-0.000282585699460469,-0.00090121911955066,0.0717996682226658,
,13813437.38,4370,7.78024983406067,0.13400000333786,0,-0.0017031838465482,9.98999977111816,0.000137476709205657,9.98999977111816,0.110294507443905,9.98999977111816,,,0.00337479765260501,0.00322841815818675,0.0126856354819773,,25,-0.0017031838465482,0.000137476709205657,0.110294507443905,
,13813455.75,4370,7.78680014610291,0.13400000333786,0,-0.000519356511067599,9.98999977111816,-0.000267315866658464,9.98999977111816,0.182760019898415,9.98999977111816,,,0.00365509840167213,0.00417840016964024,0.00646284103124253,,25,-0.000519356511067599,-0.000267315866658464,0.182760019898415,
,13813473.22,4370,7.79294991493225,0.13400000333786,0,-0.000114563911920413,9.98999977111816,-0.000328416633419693,9.98999977111816,0.273960571885109,9.98999977111816,,,0.00387189198660086,0.00346923451805404,0.0161431690620419,,25,-0.000114563911920413,-0.000328416633419693,0.273960571885109,
,13813484.84,4370,7.79635000228882,0.13400000333786,0,-0.00109217621036805,9.98999977111816,-0.000603370075114071,9.98999977111816,0.336787421703339,9.98999977111816,,,0.00350769426742501,0.00359197679396146,0.00920539607803744,,25,-0.00109217621036805,-0.000603370075114071,0.336787421703339,
,13813500.94,4370,7.80159997940063,0.13400000333786,0,-0.000504081336548552,9.98999977111816,-0.00127547850483097,9.98999977111816,0.43880279302597,9.98999977111816,,,0.00305736688025188,0.00285452018347554,0.0197311277758942,,25,-0.000504081336548552,-0.00127547850483097,0.43880279302597,
,13813513.36,4370,7.80425000190735,0.13400000333786,0,-0.000259678263682872,9.98999977111816,-0.000442980558145791,9.98999977111816,0.488004170656204,9.98999977111816,,,0.00330359350483715,0.00227897460240974,0.00577357325416949,,25,-0.000259678263682872,-0.000442980558145791,0.488004170656204,
,13813537.19,4370,7.81234979629517,0.13400000333786,0,-6.87383057083935e-005,9.98999977111816,0.0017795598320663,9.98999977111816,0.62975031375885,9.98999977111816,,,0.00364725396546864,0.00309945272879279,0.0148858438430178,,25,-6.87383057083935e-005,0.0017795598320663,0.62975031375885,
,13813548.16,4370,7.81559991836548,0.13400000333786,0,0.000206218594685197,9.98999977111816,-0.00128318500472233,9.98999977111816,0.685431573390961,9.98999977111816,,,0.00280775056576494,0.003670107598394,0.0150473089956606,,25,0.000206218594685197,-0.00128318500472233,0.685431573390961,
,13813560.09,4370,7.8215000629425,0.13400000333786,0,0.000412587734172121,9.98999977111816,0.000420228246366605,9.98999977111816,0.745599520206451,9.98999977111816,,,0.00268815809065375,0.00347790270381396,0.0156890111733706,,25,0.000412587734172121,0.000420228246366605,0.745599520206451,
,13813572.81,4370,7.82550001144409,0.13400000333786,0,0.00160450784140266,9.98999977111816,-0.00105439089122228,9.98999977111816,0.798288497924805,9.98999977111816,,,0.00296260857644018,0.0030809939091139,0.0145015055813508,,25,0.00160450784140266,-0.00105439089122228,0.798288497924805,
,13813592.08,4370,7.83170008659363,0.13400000333786,0,-0.00114607707015239,9.98999977111816,-0.000137529250932857,9.98999977111816,0.912865643501282,9.98999977111816,,,0.00366027654582904,0.00260199590100341,0.0139530890343703,,25,-0.00114607707015239,-0.000137529250932857,0.912865643501282,
,13813606.22,4370,7.83689999580383,0.13400000333786,0,0.000328542112838477,9.98999977111816,0.000809894414851442,9.98999977111816,0.978887317180634,9.98999977111816,,,0.00285908385841478,0.00383865670380092,0.0166913675114838,,25,0.000328542112838477,0.000809894414851442,0.978887317180634,
,13813623.38,4370,7.84209990501404,0.13400000333786,0,0.000404827371239662,9.98999977111816,0.000618698446196504,9.98999977111816,1.0686678647995,9.98999977111816,,,0.00335445388697954,0.00327523404887958,0.0158528271520533,,25,0.000404827371239662,0.000618698446196504,1.0686678647995,
,13813652.33,4370,7.85205006599426,0.13400000333786,0,0.000611060176161118,9.98999977111816,0.000358997836010531,9.98999977111816,1.22653524875641,9.98999977111816,,,0.00404647187105706,0.00279361702055385,0.017777299771595,,25,0.000611060176161118,0.000358997836010531,1.22653524875641,
,13813667.55,4370,7.85634994506836,0.13400000333786,0,0.000252062302315608,9.98999977111816,-0.000962419768911786,9.98999977111816,1.33659484386444,9.98999977111816,,,0.0041580164216092,0.00330590750377239,0.0331984196818808,,25,0.000252062302315608,-0.000962419768911786,1.33659484386444,
,13813680.77,4370,7.86124992370605,0.13400000333786,0,9.93133860174567e-005,9.98999977111816,-0.000565322444890626,9.98999977111816,1.53572124004364,9.98999977111816,,,0.00280074648730816,0.00296244883789514,0.0480161596293871,,25,9.93133860174567e-005,-0.000565322444890626,1.53572124004364,
,13813696.33,4370,7.86634993553162,0.13400000333786,0,-0.001115365815931,9.98999977111816,-0.00220017378742341,9.98999977111816,1.91531232357025,9.98999977111816,,,0.0038150371617491,0.00287529220017323,0.0727830779719177,,25,-0.001115365815931,-0.00220017378742341,1.91531232357025,
,13813713.36,4370,7.87150001525879,0.13400000333786,0,-0.00035905612341594,9.98999977111816,0.000649356861249544,9.98999977111816,2.5295350933075,9.98999977111816,,,0.00368058642097361,0.00349835367461993,0.141787263042114,,25,-0.00035905612341594,0.000649356861249544,2.5295350933075,
,13813724.66,4370,7.87665009498596,0.13400000333786,0,0.00127579518477432,9.98999977111816,0.000168068818165921,9.98999977111816,3.16792165756226,9.98999977111816,,,0.00380164339817213,0.00318591549844834,0.0852189687500196,,25,0.00127579518477432,0.000168068818165921,3.16792165756226,
,13813742.84,4370,7.88199996948242,0.13400000333786,0,0.000183298840420321,9.98999977111816,-0.000565171330817975,9.98999977111816,4.33825496673584,9.98999977111816,,,0.00502608056791328,0.0029079936116883,0.170377356144753,,25,0.000183298840420321,-0.000565171330817975,4.33825496673584,
,13813755.30,4370,7.88669991493225,0.13400000333786,0,0.00022912350774277,9.98999977111816,-0.00151985262287781,9.98999977111816,5.11774070739746,9.98999977111816,,,0.00275372177714376,0.00467212234777869,0.206654422025674,,25,0.00022912350774277,-0.00151985262287781,5.11774070739746,
,13813767.64,4370,7.89079999923706,0.13400000333786,0,0.000122199226170778,9.98999977111816,0.000137474100920372,9.98999977111816,5.89299535751343,9.98999977111816,,,0.00320221444415248,0.00367174741876043,0.141781976506258,,25,0.000122199226170778,0.000137474100920372,5.89299535751343,
,13813784.94,4370,7.89685010910034,0.13400000333786,0,0.000504071755567566,9.98999977111816,-7.63744988944381e-005,9.98999977111816,7.15114303588867,9.98999977111816,,,0.00390066649918766,0.00350699534375243,0.166763993413582,,25,0.000504071755567566,-7.63744988944381e-005,7.15114303588867,
,13813800.95,4370,7.9025502204895,0.13400000333786,0,0.000633956869132817,9.98999977111816,0.000970030293101445,9.98999977111816,7.89598531723022,9.98999977111816,,,0.00548762835169616,0.00438436440178892,0.15802969216463,,25,0.000633956869132817,0.000970030293101445,7.89598531723022,
,13813828.14,4370,7.91029977798462,0.13400000333786,0,-0.00179493797360919,9.98999977111816,-0.000595766655169427,9.98999977111816,8.93109180450439,9.98999977111816,,,0.00362223235039665,0.00326936395194718,0.0672079250019439,,25,-0.00179493797360919,-0.000595766655169427,8.93109180450439,
,13813845.53,4370,7.91789984703064,0.13400000333786,0,0.000740889279404655,9.98999977111816,-0.00122972346609458,9.98999977111816,9.45567161560059,9.98999977111816,,,0.00434070207618969,0.00481652987137136,0.0642579240841262,,25,0.000740889279404655,-0.00122972346609458,9.45567161560059,
,13813862.77,4370,7.92285013198853,0.13400000333786,0,-0.000802292115986347,9.98999977111816,-0.000489016198553145,9.98999977111816,9.7836699295044,9.98999977111816,,,0.00542152452004557,0.00403271889674879,0.0362045848534759,,25,-0.000802292115986347,-0.000489016198553145,9.7836699295044,
,13813879.31,4370,7.92739987373352,0.13400000333786,0,-0.00045081177726388,9.98999977111816,-0.0009627506416291,9.98999977111816,9.98651248931885,9.98999977111816,,,0.00383640551370339,0.00460722762194435,0.0272389826964672,,25,-0.00045081177726388,-0.0009627506416291,9.98651248931885,
,13813891.58,4370,7.93340015411377,0.13400000333786,0,-0.000680038100108504,9.98999977111816,0.00090162361972034,9.98999977111816,10.1219700622559,9.98999977111816,,,0.00478183440769556,0.00427599790326653,0.0456005305737796,,25,-0.000680038100108504,0.00090162361972034,10.1219700622559,
,13813903.03,4370,7.9372501373291,0.13400000333786,0,-0.000129894893616438,9.98999977111816,-7.64088006690145e-005,9.98999977111816,10.2922315597534,9.98999977111816,,,0.00608607312339104,0.00327177710129098,0.0173588455648834,,25,-0.000129894893616438,-7.64088006690145e-005,10.2922315597534,
,13813921.11,4370,7.94199991226196,0.13400000333786,0,-0.00185652077139821,9.98999977111816,0.00076400030462537,9.98999977111816,10.4684466171265,9.98999977111816,,,0.00445403652907183,0.00477882039029612,0.0205297133322932,,25,-0.00185652077139821,0.00076400030462537,10.4684466171265,
,13813937.34,4370,7.94700002670288,0.13400000333786,0,-0.000313240148825571,9.98999977111816,0.000382000134559348,9.98999977111816,10.6398650741577,9.98999977111816,,,0.00453757004273051,0.00377272282894628,0.0212469665033823,,25,-0.000313240148825571,0.000382000134559348,10.6398650741577,
,13813952.25,4370,7.95215010643005,0.13400000333786,0,5.34800300374627e-005,9.98999977111816,0.000504240207374096,9.98999977111816,10.8125219345093,9.98999977111816,,,0.00422089250707091,0.00330551764889021,0.0303320449747603,,25,5.34800300374627e-005,0.000504240207374096,10.8125219345093,
,13813964.67,4370,7.95615005493164,0.13400000333786,0,0.000175720121478662,9.98999977111816,7.64003023505211e-006,9.98999977111816,10.9865531158447,9.98999977111816,,,0.00423380253436806,0.00388194859373192,0.0312669495999303,,25,0.000175720121478662,7.64003023505211e-006,10.9865531158447,
,13813981.91,4370,7.9629499912262,0.13400000333786,0,-0.000679817402269691,9.98999977111816,2.29151715757325e-005,9.98999977111816,11.3859407043457,9.98999977111816,,,0.00286520356655869,0.00326996587515013,0.0550999975652202,,25,-0.000679817402269691,2.29151715757325e-005,11.3859407043457,
,13813995.27,4370,7.96595001220703,0.13400000333786,0,-0.000389558291644789,9.98999977111816,-0.000970076543162577,9.98999977111816,11.5842566680908,9.98999977111816,,,0.00430418118798457,0.00384125597343515,0.0520717152253438,,25,-0.000389558291644789,-0.000970076543162577,11.5842566680908,
,13814013.66,4370,7.97149991989136,0.13400000333786,0,-0.000481219063512981,9.98999977111816,-0.000954799704486504,9.98999977111816,12.0123355484009,9.98999977111816,,,0.00301504887626749,0.00279924085078503,0.074463188534457,,25,-0.000481219063512981,-0.000954799704486504,12.0123355484009,
,13814028.19,4370,7.97644996643066,0.13400000333786,0,-0.000970076518715359,9.98999977111816,-0.000633987013134174,9.98999977111816,12.490521774292,9.98999977111816,,,0.00360744310135799,0.00403525787852292,0.127511741051487,,25,-0.000970076518715359,-0.000633987013134174,12.490521774292,
,13814042.20,4370,7.98250007629395,0.13400000333786,0,-0.000114593427279033,9.98999977111816,-0.000183349546859972,9.98999977111816,13.2030016708374,9.98999977111816,,,0.00387552651663745,0.00347263396830092,0.0986973834320713,,25,-0.000114593427279033,-0.000183349546859972,13.2030016708374,
,13814055.80,4370,7.98689985275269,0.13400000333786,0,0.000572967376792803,9.98999977111816,-0.000389617808395997,9.98999977111816,13.9862022781372,9.98999977111816,,,0.00312895913057814,0.00251380001920625,0.140339259323075,,25,0.000572967376792803,-0.000389617808395997,13.9862022781372,
,13814071.03,4370,7.99160003662109,0.13400000333786,0,0.00120705126144458,9.98999977111816,0.000657002618536353,9.98999977111816,15.1329848098755,9.98999977111816,,,0.00272236628417677,0.00358249168995211,0.202302118287619,,25,0.00120705126144458,0.000657002618536353,15.1329848098755,
,13814086.72,4370,7.99635004997253,0.13400000333786,0,0.000336140876752324,9.98999977111816,-0.000190989124821499,9.98999977111816,16.5840358734131,9.98999977111816,,,0.00327044763919089,0.00332562467447419,0.181136579106385,,25,0.000336140876752324,-0.000190989124821499,16.5840358734131,
,13814104.53,4370,8.00234985351563,0.13400000333786,0,-0.000343599952757359,9.98999977111816,-0.000664293185109273,9.98999977111816,18.767398147583,9.98999977111816,,,0.00331729471925553,0.00272703683394924,0.450480145680285,,25,-0.000343599952757359,-0.000664293185109273,18.767398147583,
,13814117.66,4370,8.00604963302612,0.13400000333786,0,-0.000374142194632441,9.98999977111816,0.000710106508340687,9.98999977111816,20.4667747497559,9.98999977111816,,,0.00283775660869475,0.0038525590515877,0.39047430157692,,25,-0.000374142194632441,0.000710106508340687,20.4667747497559,
,13814130.84,4370,8.01095008850098,0.13400000333786,0,-0.00123695972841233,9.98999977111816,0.000954444246599451,9.98999977111816,23.026953125,9.98999977111816,,,0.00368889735915323,0.00259889402351298,0.618043214956267,,25,-0.00123695972841233,0.000954444246599451,23.026953125,
,13814145.98,4370,8.01595020294189,0.13400000333786,0,-0.000832275415305048,9.98999977111816,-0.000847546578152105,9.98999977111816,26.2633130645752,9.98999977111816,,,0.00328811467951055,0.00334925049483154,0.69755427250899,,25,-0.000832275415305048,-0.000847546578152105,26.2633130645752,
,13814164.30,4370,8.02265024185181,0.13400000333786,0,7.64014851301909e-005,9.98999977111816,-0.00127590480144136,9.98999977111816,30.581527633667,9.98999977111816,,,0.003112833130784,0.00314209871039482,0.617201905506443,,25,7.64014851301909e-005,-0.00127590480144136,30.581527633667,
,13814175.38,4370,8.02629995346069,0.13400000333786,0,-0.000252124919206835,9.98999977111816,0.000573011103551835,9.98999977111816,33.7525717163086,9.98999977111816,,,0.00314116974205877,0.00416860945286968,0.713895144256461,,25,-0.000252124919206835,0.000573011103551835,33.7525717163086,
,13814191.47,4370,8.03095006942749,0.13400000333786,0,-0.000672333096736111,9.98999977111816,0.000550090688047931,9.98999977111816,37.6096089172363,9.98999977111816,,,0.0030133195188563,0.00335572164682426,0.597274781089627,,25,-0.000672333096736111,0.000550090688047931,37.6096089172363,
,13814208.50,4370,8.03690004348755,0.13400000333786,0,0.000420208215364255,9.98999977111816,0.000573011130909435,9.98999977111816,41.0598002624512,9.98999977111816,,,0.00334948850245271,0.00238869213338615,0.471470310899864,,25,0.000420208215364255,0.000573011130909435,41.0598002624512,
,13814222.00,4370,8.04174995422363,0.13400000333786,0,0.000183369722217321,9.98999977111816,-7.65048328321427e-005,9.98999977111816,42.9191427612305,9.98999977111816,,,0.00315890232581847,0.00321644835788097,0.338831301524314,,25,0.000183369722217321,-7.65048328321427e-005,42.9191427612305,
,13814239.27,4370,8.04725027084351,0.13400000333786,0,0.000488773472607136,9.98999977111816,-0.00066442638868466,9.98999977111816,44.6574810791016,9.98999977111816,,,0.00259440678518714,0.00269802121713476,0.137566634590168,,25,0.000488773472607136,-0.00066442638868466,44.6574810791016,
,13814252.89,4370,8.05235004425049,0.13400000333786,0,-0.000305483376141638,9.98999977111816,0.000526958864647895,9.98999977111816,45.3196690368652,9.98999977111816,,,0.00298188801553483,0.00322493041557045,0.10730074833244,,25,-0.000305483376141638,0.000526958864647895,45.3196690368652,
,13814269.48,4370,8.05670022964478,0.13400000333786,0,-0.000603329709265381,9.98999977111816,0.00020620126510039,9.98999977111816,45.7710430908203,9.98999977111816,,,0.00231561148656946,0.00322024281466619,0.0541360982099946,,25,-0.000603329709265381,0.00020620126510039,45.7710430908203,
,13814282.16,4370,8.06174993515015,0.13400000333786,0,-0.000740887647261843,9.98999977111816,-0.000488852135022171,9.98999977111816,45.9487400817871,9.98999977111816,,,0.00380479016309695,0.00331248982735735,0.0216779015033866,,25,-0.000740887647261843,-0.000488852135022171,45.9487400817871,
,13814296.00,4370,8.06640005111694,0.13400000333786,0,0.000236797094694339,9.98999977111816,0.00115343104000203,9.98999977111816,46.030246887207,9.98999977111816,,,0.00322602919193529,0.00312085857598682,0.014295821684045,,25,0.000236797094694339,0.00115343104000203,46.030246887207,
,13814311.06,4370,8.07054996490479,0.13400000333786,0,-0.000664559604483657,9.98999977111816,0.00118398557591718,9.98999977111816,46.0764144897461,9.98999977111816,,,0.00295601617327191,0.00381510462616768,0.00582069156082122,,25,-0.000664559604483657,0.00118398557591718,46.0764144897461,
,13814325.97,4370,8.07560014724731,0.13400000333786,0,-0.000641643768176436,9.98999977111816,0.000725668552331626,9.98999977111816,46.0948846435547,9.98999977111816,,,0.00344961128906888,0.00316104000797859,0.00377328248442847,,25,-0.000641643768176436,0.000725668552331626,46.0948846435547,
,13814341.89,4370,8.08239984512329,0.13400000333786,0,0.00114570937061217,9.98999977111816,0.000282577773905359,9.98999977111816,46.101872253418,9.98999977111816,,,0.00293150902765622,0.00311445606397774,0.00391313292912113,,25,0.00114570937061217,0.000282577773905359,46.101872253418,
,13814357.20,4370,8.08585023880005,0.13400000333786,0,-0.000366629104246385,9.98999977111816,-0.00126792564988136,9.98999977111816,46.1065335083008,9.98999977111816,,,0.00315478761883876,0.00327899910050285,0.00261811904558274,,25,-0.000366629104246385,-0.00126792564988136,46.1065335083008,
,13814371.20,4370,8.09050035476685,0.13400000333786,0,-3.81905329413712e-005,9.98999977111816,-0.00031316238688305,9.98999977111816,46.1097346496582,9.98999977111816,,,0.00332367359169082,0.00298857940391088,0.00347768098059835,,25,-3.81905329413712e-005,-0.00031316238688305,46.1097346496582,
,13814387.70,4370,8.09709978103638,0.13400000333786,0,0.000305524222785607,9.98999977111816,-0.000465924494783394,9.98999977111816,46.1121488952637,9.98999977111816,,,0.00341202008017261,0.00384192964112068,0.0025779611685215,,25,0.000305524222785607,-0.000465924494783394,46.1121488952637,
,13814399.33,4370,8.10045003890991,0.13400000333786,0,0.000947110011475161,9.98999977111816,0.0005117752001388,9.98999977111816,46.1121543884277,9.98999977111816,,,0.00327059048319498,0.0034979230954631,0.00480886578959395,,25,0.000947110011475161,0.0005117752001388,46.1121543884277,
,13814418.47,4370,8.10739994049072,0.13400000333786,0,-0.000511699408525601,9.98999977111816,-0.000442963648820296,9.98999977111816,46.1101919555664,9.98999977111816,,,0.00304666237876628,0.00325626936071112,0.00382164055030604,,25,-0.000511699408525601,-0.000442963648820296,46.1101919555664,
,13814434.34,4370,8.11245012283325,0.13400000333786,0,0.000633896224317141,9.98999977111816,7.63729796744883e-006,9.98999977111816,46.1115596008301,9.98999977111816,,,0.0025155152421713,0.00319878180165648,0.00308545787498487,,25,0.000633896224317141,7.63729796744883e-006,46.1115596008301,
,13814447.80,4370,8.11644983291626,0.13400000333786,0,0.000580435133888386,9.98999977111816,9.16476681595668e-005,9.98999977111816,46.1128045654297,9.98999977111816,,,0.00404073319996074,0.00315962964487767,0.00283783336161855,,25,0.000580435133888386,9.16476681595668e-005,46.1128045654297,
,13814463.95,4370,8.12199974060059,0.13400000333786,0,-0.000129861505702138,9.98999977111816,0.000206250488990918,9.98999977111816,46.123727722168,9.98999977111816,,,0.00457975350781036,0.0037293680976919,0.00648356523812452,,25,-0.000129861505702138,0.000206250488990918,46.123727722168,
,13814477.88,4370,8.12674999237061,0.13400000333786,0,9.1666883090511e-005,9.98999977111816,-0.000473612344358116,9.98999977111816,46.1243695068359,9.98999977111816,,,0.00296450679124465,0.00363916834069623,0.00334837402035633,,25,9.1666883090511e-005,-0.000473612344358116,46.1243695068359,
,13814492.77,4370,8.13149976730347,0.13400000333786,0,-0.000160417080041952,9.98999977111816,0.00035902870236896,9.98999977111816,46.1240176391602,9.98999977111816,,,0.00359868000554201,0.0035802449065002,0.00389548520180686,,25,-0.000160417080041952,0.00035902870236896,46.1240176391602,
,13814507.31,4370,8.13674974441528,0.13400000333786,0,0.000496529000229202,9.98999977111816,-0.000381945443805307,9.98999977111816,46.1249430847168,9.98999977111816,,,0.00272656607869969,0.00313707197541222,0.00295520297169747,,25,0.000496529000229202,-0.000381945443805307,46.1249430847168,
,13814522.25,4370,8.1414999961853,0.13400000333786,0,0.000129780806601048,9.98999977111816,-0.000473435181193054,9.98999977111816,46.1112965393066,9.98999977111816,,,0.00329747717303874,0.00319035782713037,0.00788193995002424,,25,0.000129780806601048,-0.000473435181193054,46.1112965393066,
,13814538.14,4370,8.14690017700195,0.13400000333786,0,0.00040469984523952,9.98999977111816,-0.000740677106659859,9.98999977111816,46.1084231567383,9.98999977111816,,,0.00387601768179163,0.00305830661678342,0.003111838198424,,25,0.00040469984523952,-0.000740677106659859,46.1084231567383,
,13814554.03,4370,8.15245008468628,0.13400000333786,0,-0.000206167853903025,9.98999977111816,-0.000221439553424716,9.98999977111816,46.1088430786133,9.98999977111816,,,0.00549778822522137,0.00379866282456536,0.00316373229189375,,25,-0.000206167853903025,-0.000221439553424716,46.1088430786133,
,13814567.03,4370,8.15655040740967,0.13400000333786,0,0.00112246939912438,9.98999977111816,9.92659968324006e-005,9.98999977111816,46.106805267334,9.98999977111816,,,0.00430878305657075,0.00339607223630011,0.00330418252349262,,25,0.00112246939912438,9.92659968324006e-005,46.106805267334,
,13814583.13,4370,8.16174983978271,0.13400000333786,0,0.000748465433716774,9.98999977111816,0.000511907374020666,9.98999977111816,46.124888458252,9.98999977111816,,,0.00288242586891839,0.00345833184069761,0.00752115792284135,,25,0.000748465433716774,0.000511907374020666,46.124888458252,
,13814597.27,4370,8.16734981536865,0.13400000333786,0,0.000756244757212698,9.98999977111816,0.000145137896761298,9.98999977111816,46.1268557739258,9.98999977111816,,,0.00291953469652619,0.00409561299216824,0.00347610232901236,,25,0.000756244757212698,0.000145137896761298,46.1268557739258,
,13814611.59,4370,8.17145013809204,0.13400000333786,0,0.00119165836134925,9.98999977111816,-0.000595829198136926,9.98999977111816,46.1283682250977,9.98999977111816,,,0.00342313612427769,0.00363921386961405,0.00305822640560097,,25,0.00119165836134925,-0.000595829198136926,46.1283682250977,
,13814629.23,4370,8.17755031585693,0.13400000333786,0,-0.000305553379002959,9.98999977111816,-0.000435413608793169,9.98999977111816,46.1286503601074,9.98999977111816,,,0.00406906950818453,0.00380085627361002,0.00392613475551503,,25,-0.000305553379002959,-0.000435413608793169,46.1286503601074,
,13814642.81,4370,8.18190002441406,0.13400000333786,0,0.000603374199708924,9.98999977111816,0.000290217994479462,9.98999977111816,46.1259301757812,9.98999977111816,,,0.00330727287685837,0.00416621910449569,0.00435331151892366,,25,0.000603374199708924,0.000290217994479462,46.1259301757812,
,13814657.44,4370,8.18704986572266,0.13400000333786,0,0.00117625719984062,9.98999977111816,0.000420091876294464,9.98999977111816,46.1256944274902,9.98999977111816,,,0.00265177308576473,0.00320615514292613,0.00323673585739295,,25,0.00117625719984062,0.000420091876294464,46.1256944274902,
,13814672.09,4370,8.1919002532959,0.13400000333786,0,3.05521325208247e-005,9.98999977111816,0.000236779032275081,9.98999977111816,46.1270080566406,9.98999977111816,,,0.0029521173167484,0.00359688954222139,0.00367282885538189,,25,3.05521325208247e-005,0.000236779032275081,46.1270080566406,
,13814688.33,4370,8.19740009307861,0.13400000333786,0,0.000611042701639235,9.98999977111816,0.000824907636269927,9.98999977111816,46.1268704223633,9.98999977111816,,,0.00384262188543425,0.00314308570901421,0.00321943485459437,,25,0.000611042701639235,0.000824907636269927,46.1268704223633,
,13814702.33,4373,8.20070028305054,0.13400000333786,0,-6.11372501589358e-005,9.98999977111816,-0.000993038825690746,9.98999977111816,46.128373260498,9.98999977111816,,,0.00262145816543635,0.00450726386250005,0.00400326505575485,,25,-6.11372501589358e-005,-0.000993038825690746,46.128373260498,