File: icepp/250307-ch1Nb100-ch2Nb150-ch3NbAl_coarseUp1.dat
[Header]
TITLE, 5K to 300K
FILEOPENTIME,13821474.77,3/7/2025,10:29 PM
BYAPP, Resistivity, 2.1, 1.0
INFO, APPNAME, PPMS MultiVu Application, 1.5.11
INFO, , Sample1 Name
INFO, 1, Sample1 Cross Section
INFO, 1, Sample1 Length
INFO, Ohm-m, Sample1 Units
INFO, , Sample2 Name
INFO, 1, Sample2 Cross Section
INFO, 1, Sample2 Length
INFO, Ohm-m, Sample2 Units
INFO, , Sample3 Name
INFO, 1, Sample3 Cross Section
INFO, 1, Sample3 Length
INFO, Ohm-m, Sample3 Units
INFO, , Sample4 Name
INFO, 1, Sample4 Cross Section
INFO, 1, Sample4 Length
INFO, Ohm-m, Sample4 Units
FIELDGROUP, Resistivity,2,3,4,5,6,7,8,9,10,11,12,13,14,15,16,17,18,19,20,21,22,23,24,25,26,27,28,29,30,31,32,33,34,35,36,37,38,39,40,41
STARTUPGROUP, Resistivity
STARTUPAXIS, X, 2, LINEAR, AUTO
STARTUPAXIS, Y1, 7, LINEAR, AUTO
STARTUPAXIS, Y2, 9, LINEAR, AUTO
STARTUPAXIS, Y3, 11, LINEAR, AUTO
PLOT_APPEARANCE, ALL, HORZ_GRID_ON, VERT_GRID_ON, MARKERS_AND_LINES, ALL_LINES
DATATYPE, TIME, 2
DATATYPE, COMMENT, 1
[Data]
Comment,Time Stamp (sec),Status (code),Temperature (K),Magnetic Field (Oe),Sample Position (deg),Bridge 1 Resistivity (Ohm-m),Bridge 1 Excitation (uA),Bridge 2 Resistivity (Ohm-m),Bridge 2 Excitation (uA),Bridge 3 Resistivity (Ohm-m),Bridge 3 Excitation (uA),Bridge 4 Resistivity (Ohm-m),Bridge 4 Excitation (uA),Bridge 1 Std. Dev. (Ohm-m),Bridge 2 Std. Dev. (Ohm-m),Bridge 3 Std. Dev. (Ohm-m),Bridge 4 Std. Dev. (Ohm-m),Number of Readings,Bridge 1 Resistance (Ohms),Bridge 2 Resistance (Ohms),Bridge 3 Resistance (Ohms),Bridge 4 Resistance (Ohms),Signal 1 Vin (V),Signal 2 Vin (V),Digital Inputs (code),Drive 1 Iout (mA),Drive 1 Ipower (watts),Drive 2 Iout (mA),Drive 2 Ipower (watts),Pressure (),Map 20 (),Map 21 (),Map 22 (),Map 23 (),Map 24 (),Map 25 (),Map 26 (),Map 27 (),Map 28 (),Map 29 ()
,13821946.67,4370,5.11325001716614,0.13400000333786,0,2.13829952990636e-007,9.98999977111816,-1.36720219510607e-006,9.98999977111816,8.55459780432284e-007,9.98999977111816,,,4.63641231466973e-006,7.58355044304731e-006,3.75823862959363e-006,,25,0.000213829952990636,-0.00136720219510607,0.000855459780432284,
,13821992.67,4370,8.54044961929321,0.13400000333786,0,1.90203355625272e-006,9.98999977111816,-1.22219026088715e-007,9.98999977111816,0.0461382231140137,9.98999977111816,,,7.43791810140603e-006,3.12947687340652e-006,1.05353498609261e-005,,25,0.00190203355625272,-0.000122219026088715,46.1382231140137,
,13822017.06,4370,10.5199499130249,0.13400000333786,0,0.0727290209960937,9.98999977111816,0.0204983654785156,9.98999977111816,0.0461745137023926,9.98999977111816,,,1.35403379365079e-005,6.67829455076132e-006,5.11325682032179e-006,,25,72.7290209960938,20.4983654785156,46.1745137023926,
,13822040.55,4370,12.4993500709534,0.13400000333786,0,0.0728403012084961,9.98999977111816,0.020554766998291,9.98999977111816,0.0461959266662598,9.98999977111816,,,1.4571634908565e-005,7.24063493367078e-006,3.70021368151361e-006,,25,72.8403012084961,20.554766998291,46.1959266662598,
,13822065.22,4370,14.5468997955322,0.13400000333786,0,0.0729934741210937,9.98999977111816,0.0206406289672852,9.98999977111816,0.0462276344299316,9.98999977111816,,,2.01000483936302e-005,1.10733744815815e-005,3.7062493501483e-006,,25,72.9934741210938,20.6406289672852,46.2276344299316,
,13822089.44,4370,16.5599498748779,0.13400000333786,0,0.0731791082763672,9.98999977111816,0.0207436491394043,9.98999977111816,0.0462540853881836,9.98999977111816,,,2.51127777354556e-005,1.49615067703906e-005,5.66761328460878e-006,,25,73.1791082763672,20.7436491394043,46.2540853881836,
,13822113.75,4370,18.5749998092651,0.13400000333786,0,0.0734355645751953,9.98999977111816,0.0208835456085205,9.98999977111816,0.0463036305236817,9.98999977111816,,,3.04874817187937e-005,1.69099542658677e-005,6.84307186017024e-006,,25,73.4355645751953,20.8835456085205,46.3036305236816,
,13822136.77,4370,20.5403499603271,0.13400000333786,0,0.0737489782714844,9.98999977111816,0.0210565209197998,9.98999977111816,0.046370308227539,9.98999977111816,,,3.95829854463323e-005,2.19837696795447e-005,9.3448318213222e-006,,25,73.7489782714844,21.0565209197998,46.3703082275391,
,13822161.98,4370,22.610800743103,0.13400000333786,0,0.074137135925293,9.98999977111816,0.0212649118041992,9.98999977111816,0.0464510847473145,9.98999977111816,,,4.5446273050768e-005,2.45717832465724e-005,1.00254463119667e-005,,25,74.137135925293,21.2649118041992,46.4510847473145,
,13822185.73,4370,24.6234502792358,0.13400000333786,0,0.0745946298217774,9.98999977111816,0.0215063910675049,9.98999977111816,0.0465441186523438,9.98999977111816,,,5.46525216362329e-005,2.94238630823898e-005,1.11583352351776e-005,,25,74.5946298217773,21.5063910675049,46.5441186523437,
,13822221.03,4370,27.5556497573853,0.13400000333786,0,0.0753887640380859,9.98999977111816,0.0219274514007568,9.98999977111816,0.0467208644104004,9.98999977111816,,,6.46614809892145e-005,3.42393820950119e-005,1.41902173499642e-005,,25,75.3887640380859,21.9274514007568,46.7208644104004,
,13822245.64,4370,29.5757007598877,0.13400000333786,0,0.0760180557250977,9.98999977111816,0.0222665633392334,9.98999977111816,0.046865378112793,9.98999977111816,,,7.36936785368447e-005,3.80335020647926e-005,1.66105838390413e-005,,25,76.0180557250977,22.2665633392334,46.865378112793,
,13822268.61,4370,31.5100498199463,0.13400000333786,0,0.0766653747558594,9.98999977111816,0.0226145858001709,9.98999977111816,0.0470074920654297,9.98999977111816,,,8.01571924039381e-005,4.18478624295335e-005,1.86951466796514e-005,,25,76.6653747558594,22.6145858001709,47.0074920654297,
,13822293.39,4370,33.5603008270264,0.13400000333786,0,0.0774648706054688,9.98999977111816,0.0230361225128174,9.98999977111816,0.0471988729858398,9.98999977111816,,,8.75237969785681e-005,4.54386239298609e-005,2.14576770607279e-005,,25,77.4648706054687,23.0361225128174,47.1988729858398,
,13822317.06,4370,35.5398502349854,0.13400000333786,0,0.0782970135498047,9.98999977111816,0.0234764503479004,9.98999977111816,0.0473963203430176,9.98999977111816,,,9.49019673063594e-005,5.02286779138912e-005,2.28932468823033e-005,,25,78.2970135498047,23.4764503479004,47.3963203430176,
,13822340.94,4370,37.5128002166748,0.13400000333786,0,0.0791964767456055,9.98999977111816,0.0239438653564453,9.98999977111816,0.0476208403015137,9.98999977111816,,,0.000102449435977715,5.45315871649145e-005,2.61962446980775e-005,,25,79.1964767456055,23.9438653564453,47.6208403015137,
,13822364.70,4370,39.5048503875732,0.13400000333786,0,0.0801645791625977,9.98999977111816,0.024459739074707,9.98999977111816,0.0478701959228516,9.98999977111816,,,0.000110604147604918,5.87301951966631e-005,2.76420256311342e-005,,25,80.1645791625977,24.459739074707,47.8701959228516,
,13822388.83,4370,41.5356502532959,0.13400000333786,0,0.081218600769043,9.98999977111816,0.0250064513397217,9.98999977111816,0.0481478433227539,9.98999977111816,,,0.000117065205514348,6.0698937418029e-005,3.07700684442775e-005,,25,81.218600769043,25.0064513397217,48.1478433227539,
,13822413.17,4370,43.5414505004883,0.13400000333786,0,0.0823146585083008,9.98999977111816,0.025585587387085,9.98999977111816,0.0484448731994629,9.98999977111816,,,0.000120957389409263,6.43134596292601e-005,3.24849347284427e-005,,25,82.3146585083008,25.585587387085,48.4448731994629,
,13822436.88,4370,45.5244007110596,0.13400000333786,0,0.0834491030883789,9.98999977111816,0.0261838154602051,9.98999977111816,0.0487563648986816,9.98999977111816,,,0.000129895144042468,6.84345560399182e-005,3.5672447536047e-005,,25,83.4491030883789,26.1838154602051,48.7563648986816,
,13822461.22,4370,47.5687007904053,0.13400000333786,0,0.0846458554077148,9.98999977111816,0.026825142288208,9.98999977111816,0.049092507019043,9.98999977111816,,,0.000130506112783654,6.92740055413645e-005,3.77173958751671e-005,,25,84.6458554077148,26.825142288208,49.092507019043,
,13822484.31,4370,49.4932498931885,0.13400000333786,0,0.0858350967407227,9.98999977111816,0.0274545095825195,9.98999977111816,0.0494388032531738,9.98999977111816,,,0.000136708664541561,7.39291535907692e-005,4.0115244703803e-005,,25,85.8350967407227,27.4545095825195,49.4388032531738,
,13822509.47,4370,51.5827503204346,0.13400000333786,0,0.0872100503540039,9.98999977111816,0.0281772216033936,9.98999977111816,0.0498421461486816,9.98999977111816,,,0.000142557092108573,7.53836660551119e-005,4.19446595484066e-005,,25,87.2100503540039,28.1772216033936,49.8421461486816,
,13822533.00,4370,53.5487499237061,0.13400000333786,0,0.0885210598754883,9.98999977111816,0.0288610722351074,9.98999977111816,0.0502326992797852,9.98999977111816,,,0.000148036658005908,7.79627303107104e-005,4.41571514959707e-005,,25,88.5210598754883,28.8610722351074,50.2326992797852,
,13822557.28,4370,55.5841503143311,0.13400000333786,0,0.0898876412963867,9.98999977111816,0.0295893388366699,9.98999977111816,0.0506431553649902,9.98999977111816,,,0.000142886175388219,7.71068133129458e-005,4.20154595492325e-005,,25,89.8876412963867,29.5893388366699,50.6431553649902,
,13822593.13,4370,58.5659503936768,0.13400000333786,0,0.0919498696899414,9.98999977111816,0.0306832984924316,9.98999977111816,0.0512761499023437,9.98999977111816,,,0.000152143328859239,8.03080428312857e-005,5.1070393942899e-005,,25,91.9498696899414,30.6832984924316,51.2761499023437,
,13822617.31,4370,60.6042499542236,0.13400000333786,0,0.0933973706054688,9.98999977111816,0.0314608887481689,9.98999977111816,0.0517503851318359,9.98999977111816,,,0.000177493629930958,9.92218455019262e-005,6.77553225451341e-005,,25,93.3973706054688,31.4608887481689,51.7503851318359,
,13822652.80,4370,63.5330009460449,0.13400000333786,0,0.0955657876586914,9.98999977111816,0.0326139041137695,9.98999977111816,0.0524383692932129,9.98999977111816,,,0.000159553982051601,8.55656763465308e-005,5.17147147785928e-005,,25,95.5657876586914,32.6139041137695,52.4383692932129,
,13822675.88,4370,65.4473495483398,0.13400000333786,0,0.0969870907592774,9.98999977111816,0.0333774481201172,9.98999977111816,0.0528931002807617,9.98999977111816,,,0.000161038371478717,7.99371115442192e-005,5.90496262972438e-005,,25,96.9870907592774,33.3774481201172,52.8931002807617,
,13822701.19,4370,67.581600189209,0.13400000333786,0,0.098555617980957,9.98999977111816,0.0342127020263672,9.98999977111816,0.0534255181884766,9.98999977111816,,,0.000164860442233227,8.8686418866856e-005,5.64980199121579e-005,,25,98.555617980957,34.2127020263672,53.4255181884766,
,13822724.61,4370,69.5358505249023,0.13400000333786,0,0.100060165405273,9.98999977111816,0.0350160461425781,9.98999977111816,0.0539196994018555,9.98999977111816,,,0.00016402587811827,9.10671931901469e-005,5.41284550090304e-005,,25,100.060165405273,35.0160461425781,53.9196994018555,
,13822748.75,4370,71.5301513671875,0.13400000333786,0,0.101586161804199,9.98999977111816,0.0358291777038574,9.98999977111816,0.0544458270263672,9.98999977111816,,,0.000164523164844255,8.81241024547917e-005,5.67884807718016e-005,,25,101.586161804199,35.8291777038574,54.4458270263672,
,13822772.64,4370,73.5139999389648,0.13400000333786,0,0.103106575012207,9.98999977111816,0.0366406579589844,9.98999977111816,0.0549687493896484,9.98999977111816,,,0.00016852567253552,9.00279829696417e-005,5.77091110467105e-005,,25,103.106575012207,36.6406579589844,54.9687493896484,
,13822797.45,4370,75.5797004699707,0.13400000333786,0,0.104714158630371,9.98999977111816,0.0375004531860351,9.98999977111816,0.0555265194702148,9.98999977111816,,,0.000166815706135551,9.0208072654574e-005,5.7144119983339e-005,,25,104.714158630371,37.5004531860352,55.5265194702148,
,13822820.45,4370,77.5050010681152,0.13400000333786,0,0.106207692871094,9.98999977111816,0.0383019143676758,9.98999977111816,0.0560410615539551,9.98999977111816,,,0.000169603569810718,9.04478720425023e-005,6.0060006975754e-005,,25,106.207692871094,38.3019143676758,56.0410615539551,
,13822844.59,4370,79.4977989196777,0.13400000333786,0,0.107780352478027,9.98999977111816,0.0391301765441895,9.98999977111816,0.0566004232788086,9.98999977111816,,,0.000167942613383325,9.11768200571195e-005,6.05818101710811e-005,,25,107.780352478027,39.1301765441895,56.6004232788086,
,13822869.36,4370,81.5794486999512,0.13400000333786,0,0.109402239685059,9.98999977111816,0.0400096385192871,9.98999977111816,0.0571806101989746,9.98999977111816,,,0.000172688757390093,9.20239012363231e-005,6.13774829674952e-005,,25,109.402239685059,40.0096385192871,57.1806101989746,
,13822893.20,4370,83.5457992553711,0.13400000333786,0,0.110969774780273,9.98999977111816,0.0408476766967774,9.98999977111816,0.0577487351989746,9.98999977111816,,,0.000170161131135194,9.10597398292218e-005,6.20399067204738e-005,,25,110.969774780273,40.8476766967773,57.7487351989746,
,13822918.25,4370,85.6554527282715,0.13400000333786,0,0.112645508728027,9.98999977111816,0.0417310147094727,9.98999977111816,0.058360934753418,9.98999977111816,,,0.000182094642544053,9.67782333776863e-005,6.69386793833732e-005,,25,112.645508728027,41.7310147094727,58.360934753418,
,13822953.52,4370,88.5631484985352,0.13400000333786,0,0.114986311645508,9.98999977111816,0.0429840701293945,9.98999977111816,0.0592274864196777,9.98999977111816,,,0.000173234180669524,9.28407345795299e-005,6.35218605043639e-005,,25,114.986311645508,42.9840701293945,59.2274864196777,
,13822977.27,4370,90.5740966796875,0.13400000333786,0,0.116585942687988,9.98999977111816,0.0438527597045898,9.98999977111816,0.059823911895752,9.98999977111816,,,0.000177711563556451,9.65534980170857e-005,6.63363016795758e-005,,25,116.585942687988,43.8527597045898,59.823911895752,
,13823001.44,4370,92.5707015991211,0.13400000333786,0,0.118187157287598,9.98999977111816,0.044712098236084,9.98999977111816,0.0604361408996582,9.98999977111816,,,0.00017247508689945,9.30993575629495e-005,6.52428195780837e-005,,25,118.187157287598,44.712098236084,60.4361408996582,
,13823024.88,4370,94.5314025878906,0.13400000333786,0,0.119775505065918,9.98999977111816,0.0455500520324707,9.98999977111816,0.0610301318359375,9.98999977111816,,,0.000176040841300048,9.30996699452371e-005,6.58108372788333e-005,,25,119.775505065918,45.5500520324707,61.0301318359375,
,13823060.84,4370,97.5139503479004,0.13400000333786,0,0.122162529296875,9.98999977111816,0.046829715423584,9.98999977111816,0.0619448870849609,9.98999977111816,,,0.000173239177107373,9.2506459353529e-005,6.70639947628356e-005,,25,122.162529296875,46.829715423584,61.9448870849609,
,13823085.66,4370,99.6022491455078,0.13400000333786,0,0.123810435791016,9.98999977111816,0.047712826385498,9.98999977111816,0.0625822071838379,9.98999977111816,,,0.000170576715346456,9.17397041061395e-005,6.67152962013386e-005,,25,123.810435791016,47.712826385498,62.5822071838379,
,13823109.02,4370,101.52970123291,0.13400000333786,0,0.125354515380859,9.98999977111816,0.0485514184570313,9.98999977111816,0.0631856779479981,9.98999977111816,,,0.000170432618182017,9.11177458721124e-005,6.60355517430823e-005,,25,125.354515380859,48.5514184570312,63.185677947998,
,13823132.66,4370,103.504398345947,0.13400000333786,0,0.126915223083496,9.98999977111816,0.049376949005127,9.98999977111816,0.0637960662841797,9.98999977111816,,,0.000168591059760857,9.09617882329204e-005,6.66653662031521e-005,,25,126.915223083496,49.376949005127,63.7960662841797,
,13823157.38,4370,105.572700500488,0.13400000333786,0,0.128517183227539,9.98999977111816,0.050248684387207,9.98999977111816,0.0644365014648438,9.98999977111816,,,0.000168482801832599,9.13793960707072e-005,6.68067996614229e-005,,25,128.517183227539,50.248684387207,64.4365014648437,
,13823180.61,4370,107.511249542236,0.13400000333786,0,0.130019868164063,9.98999977111816,0.0510596015930176,9.98999977111816,0.0650208868408203,9.98999977111816,,,0.000169772573937817,9.14597731935134e-005,6.714408154755e-005,,25,130.019868164063,51.0596015930176,65.0208868408203,
,13823204.64,4370,109.511898040771,0.13400000333786,0,0.131592428588867,9.98999977111816,0.0519029368591309,9.98999977111816,0.0656469586181641,9.98999977111816,,,0.000169534877817468,9.08952787507323e-005,6.78672972940787e-005,,25,131.592428588867,51.9029368591309,65.6469586181641,
,13823228.25,4370,111.489353179932,0.13400000333786,0,0.133110456542969,9.98999977111816,0.0527213648986816,9.98999977111816,0.0662620593261719,9.98999977111816,,,0.000168734130056009,9.13075709644323e-005,6.84797615242667e-005,,25,133.110456542969,52.7213648986816,66.2620593261719,
,13823252.36,4370,113.492702484131,0.13400000333786,0,0.134669635620117,9.98999977111816,0.0535482154846192,9.98999977111816,0.0668807467651367,9.98999977111816,,,0.000167775545187402,9.00429591763323e-005,6.74605843100244e-005,,25,134.669635620117,53.5482154846191,66.8807467651367,
,13823277.22,4370,115.57799911499,0.13400000333786,0,0.136272251586914,9.98999977111816,0.0544234657287598,9.98999977111816,0.0675381555175781,9.98999977111816,,,0.000165926745543796,9.15013242672056e-005,6.95492157946386e-005,,25,136.272251586914,54.4234657287598,67.5381555175781,
,13823301.00,4370,117.542297363281,0.13400000333786,0,0.137807538452148,9.98999977111816,0.0552494676208496,9.98999977111816,0.0681646154785156,9.98999977111816,,,0.000166214351008374,8.9576682231884e-005,6.79878948748083e-005,,25,137.807538452148,55.2494676208496,68.1646154785156,
,13823324.56,4370,119.512802124023,0.13400000333786,0,0.139332753295898,9.98999977111816,0.0560709747314453,9.98999977111816,0.0687776675415039,9.98999977111816,,,0.000166783520440439,9.03754227174693e-005,6.83556355517299e-005,,25,139.332753295898,56.0709747314453,68.7776675415039,
,13823349.34,4370,121.578502655029,0.13400000333786,0,0.140912993164063,9.98999977111816,0.056924567565918,9.98999977111816,0.0694247183227539,9.98999977111816,,,0.00016552698125776,9.03530357247314e-005,6.82024089778178e-005,,25,140.912993164063,56.924567565918,69.4247183227539,
,13823372.52,4370,123.505699157715,0.13400000333786,0,0.142385853881836,9.98999977111816,0.0577209150695801,9.98999977111816,0.0700412936401367,9.98999977111816,,,0.000164938891652568,8.98619302541062e-005,6.92491036310394e-005,,25,142.385853881836,57.7209150695801,70.0412936401367,
,13823396.72,4370,125.516250610352,0.13400000333786,0,0.143924332885742,9.98999977111816,0.0585534339904785,9.98999977111816,0.0706765029907226,9.98999977111816,,,0.000165260126253122,8.98757476247796e-005,6.92275697875566e-005,,25,143.924332885742,58.5534339904785,70.6765029907227,
,13823420.66,4370,127.510547637939,0.13400000333786,0,0.145468716430664,9.98999977111816,0.0593886866760254,9.98999977111816,0.0713106719970703,9.98999977111816,,,0.000163773635741901,8.85544958190671e-005,6.78643342346339e-005,,25,145.468716430664,59.3886866760254,71.3106719970703,
,13823444.55,4370,129.508399963379,0.13400000333786,0,0.146998143310547,9.98999977111816,0.0602042985534668,9.98999977111816,0.071948450012207,9.98999977111816,,,0.000164065047840684,8.9365486182702e-005,6.88321622626416e-005,,25,146.998143310547,60.2042985534668,71.948450012207,
,13823468.34,4370,131.480598449707,0.13400000333786,0,0.148447660522461,9.98999977111816,0.0610105223083496,9.98999977111816,0.0725506430053711,9.98999977111816,,,0.000164966261512209,9.0271150417209e-005,6.89662106240319e-005,,25,148.447660522461,61.0105223083496,72.5506430053711,
,13823492.81,4370,133.528549194336,0.13400000333786,0,0.149996186523437,9.98999977111816,0.0618538526916504,9.98999977111816,0.0732103817749023,9.98999977111816,,,0.000164320969792779,8.83135589684532e-005,6.99471406340208e-005,,25,149.996186523438,61.8538526916504,73.2103817749023,
,13823516.70,4370,135.530296325684,0.13400000333786,0,0.151514167480469,9.98999977111816,0.0626813201904297,9.98999977111816,0.0738412078857422,9.98999977111816,,,0.000163612735211211,8.95988185921635e-005,6.86434964395052e-005,,25,151.514167480469,62.6813201904297,73.8412078857422,
,13823540.47,4370,137.498649597168,0.13400000333786,0,0.153024866943359,9.98999977111816,0.0634997113037109,9.98999977111816,0.0744820184326172,9.98999977111816,,,0.00016121990501708,8.87243720609752e-005,6.80670564343878e-005,,25,153.024866943359,63.4997113037109,74.4820184326172,
,13823564.30,4370,139.496253967285,0.13400000333786,0,0.154501938476562,9.98999977111816,0.0643078503417969,9.98999977111816,0.0751087753295898,9.98999977111816,,,0.000161460203242811,8.8029947592491e-005,6.90527050848585e-005,,25,154.501938476562,64.3078503417969,75.1087753295898,
,13823589.23,4370,141.586151123047,0.13400000333786,0,0.156070122070313,9.98999977111816,0.065163157043457,9.98999977111816,0.0757860943603516,9.98999977111816,,,0.000160505592075398,8.93025013649647e-005,6.90573278436059e-005,,25,156.070122070312,65.163157043457,75.7860943603516,
,13823613.11,4370,143.564605712891,0.13400000333786,0,0.15755645324707,9.98999977111816,0.0659683203125,9.98999977111816,0.0764122399902344,9.98999977111816,,,0.000160707156372446,8.82106582410118e-005,6.95408801603727e-005,,25,157.55645324707,65.9683203125,76.4122399902344,
,13823636.42,4370,145.506149291992,0.13400000333786,0,0.158975748291016,9.98999977111816,0.0667586462402344,9.98999977111816,0.077019716796875,9.98999977111816,,,0.000159191741231179,8.89738303145702e-005,6.89786226424089e-005,,25,158.975748291016,66.7586462402344,77.019716796875,
,13823661.23,4370,147.569549560547,0.13400000333786,0,0.160454373779297,9.98999977111816,0.0675784448242188,9.98999977111816,0.0776530496215821,9.98999977111816,,,0.000159807069833702,8.8015385446893e-005,6.80401174075749e-005,,25,160.454373779297,67.5784448242187,77.653049621582,
,13823685.22,4370,149.571350097656,0.13400000333786,0,0.161929962768555,9.98999977111816,0.068391242980957,9.98999977111816,0.0782887817382812,9.98999977111816,,,0.000157593885051936,8.86700254869418e-005,6.84243105709272e-005,,25,161.929962768555,68.391242980957,78.2887817382812,
,13823708.44,4370,151.506500244141,0.13400000333786,0,0.163396739501953,9.98999977111816,0.0691978125,9.98999977111816,0.0789267428588867,9.98999977111816,,,0.000170283338435313,9.17857605315492e-005,7.28333650860991e-005,,25,163.396739501953,69.1978125,78.9267428588867,
,13823733.53,4370,153.586502075195,0.13400000333786,0,0.164918779907227,9.98999977111816,0.0700393908691406,9.98999977111816,0.0795869143676758,9.98999977111816,,,0.000158166560435807,8.77316936685777e-005,6.84458674320107e-005,,25,164.918779907227,70.0393908691406,79.5869143676758,
,13823757.28,4370,155.571250915527,0.13400000333786,0,0.166362002563477,9.98999977111816,0.0708404354858398,9.98999977111816,0.0802140350341797,9.98999977111816,,,0.000157635030569274,8.61803458947147e-005,6.78940007210491e-005,,25,166.362002563477,70.8404354858398,80.2140350341797,
,13823781.03,4370,157.547752380371,0.13400000333786,0,0.167778256225586,9.98999977111816,0.071628889465332,9.98999977111816,0.0808406750488281,9.98999977111816,,,0.000156938675904256,8.73858476314237e-005,6.82278736433984e-005,,25,167.778256225586,71.628889465332,80.8406750488281,
,13823804.41,4370,159.508605957031,0.13400000333786,0,0.169212929077148,9.98999977111816,0.0724166506958008,9.98999977111816,0.0814598556518555,9.98999977111816,,,0.00015818908575398,8.69024568377396e-005,6.82400458816214e-005,,25,169.212929077148,72.4166506958008,81.4598556518555,
,13823829.20,4370,161.57194519043,0.13400000333786,0,0.17069403503418,9.98999977111816,0.0732568295288086,9.98999977111816,0.0821094390869141,9.98999977111816,,,0.000160100972776829,8.74625484712493e-005,6.90673033245921e-005,,25,170.69403503418,73.2568295288086,82.1094390869141,
,13823852.83,4370,163.543350219727,0.13400000333786,0,0.172101089477539,9.98999977111816,0.0740425830078125,9.98999977111816,0.0827375241088867,9.98999977111816,,,0.000155338790824433,8.7218212134698e-005,7.04932176845356e-005,,25,172.101089477539,74.0425830078125,82.7375241088867,
,13823888.70,4370,166.531150817871,0.13400000333786,0,0.174242001342773,9.98999977111816,0.0752336419677734,9.98999977111816,0.0836728817749024,9.98999977111816,,,0.000151996820656759,8.541761318573e-005,6.72487268738838e-005,,25,174.242001342773,75.2336419677734,83.6728817749024,
,13823912.22,4370,168.489448547363,0.13400000333786,0,0.175635228271484,9.98999977111816,0.076017991027832,9.98999977111816,0.0842906317138672,9.98999977111816,,,0.000156170644735113,8.73755605589228e-005,6.88146182024808e-005,,25,175.635228271484,76.017991027832,84.2906317138672,
,13823937.45,4370,170.601005554199,0.13400000333786,0,0.177136209716797,9.98999977111816,0.0768623681640625,9.98999977111816,0.0849585116577149,9.98999977111816,,,0.000155567930310032,8.73229197483233e-005,6.89196510866232e-005,,25,177.136209716797,76.8623681640625,84.9585116577148,
,13823960.81,4370,172.545349121094,0.13400000333786,0,0.178560860595703,9.98999977111816,0.0776601983642578,9.98999977111816,0.0855943841552734,9.98999977111816,,,0.000153989421238672,8.73283529192744e-005,6.83672307017935e-005,,25,178.560860595703,77.6601983642578,85.5943841552734,
,13823984.09,4370,174.502349853516,0.13400000333786,0,0.179963042602539,9.98999977111816,0.0784533441162109,9.98999977111816,0.0862218255615234,9.98999977111816,,,0.00015677105462484,8.80569181560306e-005,6.91299520861878e-005,,25,179.963042602539,78.4533441162109,86.2218255615234,
,13824008.91,4370,176.558601379395,0.13400000333786,0,0.181405427246094,9.98999977111816,0.0792796429443359,9.98999977111816,0.0868774499511719,9.98999977111816,,,0.000163524428165076,9.15053092375895e-005,7.44924434119411e-005,,25,181.405427246094,79.2796429443359,86.8774499511719,
,13824033.06,4370,178.548797607422,0.13400000333786,0,0.182831099243164,9.98999977111816,0.0800746801757812,9.98999977111816,0.0875100747680664,9.98999977111816,,,0.000152164408445788,8.65007397970143e-005,6.86102365840665e-005,,25,182.831099243164,80.0746801757813,87.5100747680664,
,13824056.41,4370,180.495956420898,0.13400000333786,0,0.184202651977539,9.98999977111816,0.0808525006103516,9.98999977111816,0.0881291644287109,9.98999977111816,,,0.000151668842915909,8.62986121666147e-005,6.83009940767812e-005,,25,184.202651977539,80.8525006103516,88.1291644287109,
,13824080.06,4370,182.483947753906,0.13400000333786,0,0.185559836425781,9.98999977111816,0.0816380322265625,9.98999977111816,0.0887424914550781,9.98999977111816,,,0.000151387911944379,8.48424969271227e-005,6.76887277736224e-005,,25,185.559836425781,81.6380322265625,88.7424914550781,
,13824104.97,4370,184.552101135254,0.13400000333786,0,0.187005811157227,9.98999977111816,0.0824588143920898,9.98999977111816,0.089408410949707,9.98999977111816,,,0.0001508506067463,8.61885637626411e-005,7.00399445101656e-005,,25,187.005811157227,82.4588143920898,89.408410949707,
,13824128.56,4370,186.543746948242,0.13400000333786,0,0.188396497802734,9.98999977111816,0.0832501675415039,9.98999977111816,0.0900323638916016,9.98999977111816,,,0.000159179019571043,9.16060872534992e-005,7.34617824593498e-005,,25,188.396497802734,83.2501675415039,90.0323638916016,
,13824152.20,4370,188.489303588867,0.13400000333786,0,0.189775025024414,9.98999977111816,0.0840139733886719,9.98999977111816,0.0906537042236328,9.98999977111816,,,0.000168188667820787,8.71633416378654e-005,6.82947958114713e-005,,25,189.775025024414,84.0139733886719,90.6537042236328,
,13824176.66,4370,190.523750305176,0.13400000333786,0,0.191188162231445,9.98999977111816,0.08482048828125,9.98999977111816,0.0913008126831055,9.98999977111816,,,0.000148885527042278,8.53235002350286e-005,6.90299157008085e-005,,25,191.188162231445,84.82048828125,91.3008126831055,
,13824201.19,4370,192.590950012207,0.13400000333786,0,0.192621591796875,9.98999977111816,0.0856216821289063,9.98999977111816,0.0919437677001953,9.98999977111816,,,0.000149395804735984,8.55216296764128e-005,6.93922073925632e-005,,25,192.621591796875,85.6216821289062,91.9437677001953,
,13824224.27,4370,194.497901916504,0.13400000333786,0,0.193927561035156,9.98999977111816,0.0863793927001953,9.98999977111816,0.092547216796875,9.98999977111816,,,0.000149063949315798,8.58250530825995e-005,6.8530303170894e-005,,25,193.927561035156,86.3793927001953,92.547216796875,
,13824249.08,4370,196.557846069336,0.13400000333786,0,0.195346524047852,9.98999977111816,0.0871719393920898,9.98999977111816,0.093193271484375,9.98999977111816,,,0.000150454071006599,8.03151167049555e-005,6.30640611545554e-005,,25,195.346524047852,87.1719393920898,93.193271484375,
,13824272.70,4370,198.533950805664,0.13400000333786,0,0.196685908813477,9.98999977111816,0.0879400506591797,9.98999977111816,0.0938061782836914,9.98999977111816,,,0.000154753410296594,8.57252033120158e-005,6.95753009081348e-005,,25,196.685908813477,87.9400506591797,93.8061782836914,
,13824296.64,4370,200.545051574707,0.13400000333786,0,0.198062881469727,9.98999977111816,0.0887210324096679,9.98999977111816,0.0944443627929688,9.98999977111816,,,0.000148038605698902,8.53506063320087e-005,6.71981700395299e-005,,25,198.062881469727,88.721032409668,94.4443627929687,
,13824320.77,4370,202.543350219727,0.13400000333786,0,0.199414044189453,9.98999977111816,0.0894869522094727,9.98999977111816,0.0950655587768554,9.98999977111816,,,0.000145829502409185,8.39861245226963e-005,6.75910632296157e-005,,25,199.414044189453,89.4869522094727,95.0655587768555,
,13824344.61,4370,204.542198181152,0.13400000333786,0,0.200747687988281,9.98999977111816,0.0902528219604492,9.98999977111816,0.0957012188720703,9.98999977111816,,,0.000145349553494617,8.46450884273315e-005,6.89840278255098e-005,,25,200.747687988281,90.2528219604492,95.7012188720703,
,13824368.50,4370,206.524147033691,0.13400000333786,0,0.202088430175781,9.98999977111816,0.0910274731445313,9.98999977111816,0.0963282345581055,9.98999977111816,,,0.000150965963478403,9.40516283704006e-005,7.78752676588144e-005,,25,202.088430175781,91.0274731445313,96.3282345581055,
,13824393.66,4370,208.633949279785,0.13400000333786,0,0.2035098828125,9.98999977111816,0.0918466696166992,9.98999977111816,0.0970052517700195,9.98999977111816,,,0.000147808196233489,8.62289066709639e-005,6.95998340436157e-005,,25,203.5098828125,91.8466696166992,97.0052517700195,
,13824428.91,4370,211.556900024414,0.13400000333786,0,0.205461071777344,9.98999977111816,0.0929628598022461,9.98999977111816,0.097928479309082,9.98999977111816,,,0.000149204663071049,8.62824549024911e-005,7.19882331928966e-005,,25,205.461071777344,92.9628598022461,97.928479309082,
,13824452.59,4370,213.553047180176,0.13400000333786,0,0.206792646484375,9.98999977111816,0.0937095974731445,9.98999977111816,0.0985580792236328,9.98999977111816,,,0.00014916023562289,8.33898933827449e-005,6.93211885566791e-005,,25,206.792646484375,93.7095974731445,98.5580792236328,
,13824476.70,4370,215.544654846191,0.13400000333786,0,0.208114668579102,9.98999977111816,0.0944736343383789,9.98999977111816,0.0991945498657226,9.98999977111816,,,0.000142349813228182,8.21575905863754e-005,6.91513897509521e-005,,25,208.114668579102,94.4736343383789,99.1945498657226,
,13824501.06,4370,217.568450927734,0.13400000333786,0,0.209456997070312,9.98999977111816,0.0952292669677735,9.98999977111816,0.0998270446777344,9.98999977111816,,,0.000142356374398368,8.19571213340469e-005,6.779946748362e-005,,25,209.456997070313,95.2292669677734,99.8270446777344,
,13824525.58,4370,219.596801757813,0.13400000333786,0,0.210782180786133,9.98999977111816,0.0959905123901367,9.98999977111816,0.100466249389648,9.98999977111816,,,0.000142133717855643,8.0183106521298e-005,6.77825961407809e-005,,25,210.782180786133,95.9905123901367,100.466249389648,
,13824549.28,4370,221.598251342773,0.13400000333786,0,0.212087620849609,9.98999977111816,0.0967286608886719,9.98999977111816,0.101088864135742,9.98999977111816,,,0.000145765166692819,8.14631238242235e-005,6.74771730043067e-005,,25,212.087620849609,96.7286608886719,101.088864135742,
,13824572.42,4370,223.53295135498,0.13400000333786,0,0.213353933105469,9.98999977111816,0.097441703491211,9.98999977111816,0.101692386474609,9.98999977111816,,,0.000140460147554302,7.83038167783897e-005,6.7446229838281e-005,,25,213.353933105469,97.4417034912109,101.692386474609,
,13824596.36,4370,225.49324798584,0.13400000333786,0,0.214658831176758,9.98999977111816,0.0981767706298828,9.98999977111816,0.102310077819824,9.98999977111816,,,0.000141323627329877,7.97127485874178e-005,6.86095159683698e-005,,25,214.658831176758,98.1767706298828,102.310077819824,
,13824620.69,4370,227.56224822998,0.13400000333786,0,0.216009176025391,9.98999977111816,0.0989217098999023,9.98999977111816,0.102944797668457,9.98999977111816,,,0.000143973594028915,8.14275865250179e-005,7.01194508094293e-005,,25,216.009176025391,98.9217098999023,102.944797668457,
,13824643.98,4370,229.482452392578,0.13400000333786,0,0.217243348388672,9.98999977111816,0.0996227648925781,9.98999977111816,0.103548618164063,9.98999977111816,,,0.000137903849606424,7.82367320076108e-005,6.60570696355585e-005,,25,217.243348388672,99.6227648925781,103.548618164063,
,13824668.42,4370,231.542900085449,0.13400000333786,0,0.218558265380859,9.98999977111816,0.100366141052246,9.98999977111816,0.104189469299316,9.98999977111816,,,0.000144952810754812,9.15803180645877e-005,7.78029145598713e-005,,25,218.558265380859,100.366141052246,104.189469299316,
,13824692.25,4370,233.504051208496,0.13400000333786,0,0.219825946044922,9.98999977111816,0.101097333984375,9.98999977111816,0.104828397521973,9.98999977111816,,,0.000137765905294911,7.78579899716808e-005,6.74472411834357e-005,,25,219.825946044922,101.097333984375,104.828397521973,
,13824716.13,4370,235.484954833984,0.13400000333786,0,0.22111033203125,9.98999977111816,0.1018073828125,9.98999977111816,0.105449863891602,9.98999977111816,,,0.000138198860005676,7.9466148853619e-005,6.7716854937266e-005,,25,221.11033203125,101.8073828125,105.449863891602,
,13824740.77,4370,237.540649414063,0.13400000333786,0,0.222425949707031,9.98999977111816,0.102489174194336,9.98999977111816,0.106049501342773,9.98999977111816,,,0.000135255002116949,7.58311515683132e-005,6.58014682951829e-005,,25,222.425949707031,102.489174194336,106.049501342773,
,13824765.78,4370,239.633651733398,0.13400000333786,0,0.223744370117188,9.98999977111816,0.103231212768555,9.98999977111816,0.106701471557617,9.98999977111816,,,0.000139289567561034,7.55245469039652e-005,6.85408633667961e-005,,25,223.744370117187,103.231212768555,106.701471557617,
,13824801.03,4370,242.575950622559,0.13400000333786,0,0.225629633178711,9.98999977111816,0.104299812316895,9.98999977111816,0.107658963623047,9.98999977111816,,,0.000140150475231049,7.58256304529268e-005,6.73256399505579e-005,,25,225.629633178711,104.299812316895,107.658963623047,
,13824824.83,4370,244.561050415039,0.13400000333786,0,0.226869243774414,9.98999977111816,0.104995045776367,9.98999977111816,0.108276902160645,9.98999977111816,,,0.000136439789375105,7.54331600394848e-005,6.89031367701141e-005,,25,226.869243774414,104.995045776367,108.276902160645,
,13824848.70,4370,246.548004150391,0.13400000333786,0,0.228124188842773,9.98999977111816,0.105683113708496,9.98999977111816,0.108893420715332,9.98999977111816,,,0.000137865875574041,7.68696224610883e-005,6.6509318244175e-005,,25,228.124188842773,105.683113708496,108.893420715332,
,13824872.59,4370,248.544746398926,0.13400000333786,0,0.229408120117188,9.98999977111816,0.106386896057129,9.98999977111816,0.109529838256836,9.98999977111816,,,0.000139319965476356,7.44702901559413e-005,6.78505237557258e-005,,25,229.408120117188,106.386896057129,109.529838256836,
,13824896.86,4370,250.546699523926,0.13400000333786,0,0.230667574462891,9.98999977111816,0.107083016967773,9.98999977111816,0.11014748260498,9.98999977111816,,,0.000135493734114079,7.45922454610556e-005,6.62093383336141e-005,,25,230.667574462891,107.083016967773,110.14748260498,
,13824920.33,4370,252.515045166016,0.13400000333786,0,0.23190964050293,9.98999977111816,0.107728870239258,9.98999977111816,0.11073743347168,9.98999977111816,,,0.000136892796311191,7.49370032805709e-005,6.87401887187936e-005,,25,231.90964050293,107.728870239258,110.73743347168,
,13824944.20,4370,254.508445739746,0.13400000333786,0,0.233163572387695,9.98999977111816,0.108406660766602,9.98999977111816,0.111341368103027,9.98999977111816,,,0.000133556131395997,7.45422532691884e-005,6.73550668785281e-005,,25,233.163572387695,108.406660766602,111.341368103027,
,13824968.34,4370,256.514495849609,0.13400000333786,0,0.234418472290039,9.98999977111816,0.109086070861816,9.98999977111816,0.111958730773926,9.98999977111816,,,0.000135083226663167,7.36641239456326e-005,6.64974475614056e-005,,25,234.418472290039,109.086070861816,111.958730773926,
,13824992.38,4370,258.515045166016,0.13400000333786,0,0.235666497802734,9.98999977111816,0.109761536254883,9.98999977111816,0.112571295776367,9.98999977111816,,,0.000135572859310267,7.43409392213753e-005,6.69656311404566e-005,,25,235.666497802734,109.761536254883,112.571295776367,
,13825016.50,4370,260.532012939453,0.13400000333786,0,0.236920487670898,9.98999977111816,0.110430644226074,9.98999977111816,0.113192450256348,9.98999977111816,,,0.000134607737912452,7.26758811411511e-005,6.69912144336016e-005,,25,236.920487670898,110.430644226074,113.192450256348,
,13825052.28,4370,263.492095947266,0.13400000333786,0,0.238755383300781,9.98999977111816,0.111444775085449,9.98999977111816,0.114110829467773,9.98999977111816,,,0.000133231134088093,7.22546642048921e-005,6.64361628144264e-005,,25,238.755383300781,111.444775085449,114.110829467773,
,13825076.63,4370,265.540390014648,0.13400000333786,0,0.240018444824219,9.98999977111816,0.112126348876953,9.98999977111816,0.114735874328613,9.98999977111816,,,0.000134115601273484,7.26753163909717e-005,6.46926190999743e-005,,25,240.018444824219,112.126348876953,114.735874328613,
,13825099.72,4370,267.469253540039,0.13400000333786,0,0.241202055053711,9.98999977111816,0.112765709838867,9.98999977111816,0.115330014343262,9.98999977111816,,,0.00013447909677404,7.20733753267175e-005,6.7469475718476e-005,,25,241.202055053711,112.765709838867,115.330014343262,
,13825124.89,4370,269.544387817383,0.13400000333786,0,0.242496545410156,9.98999977111816,0.113458471679688,9.98999977111816,0.115962330322266,9.98999977111816,,,0.000133750322231774,7.26768096396259e-005,6.538409843331e-005,,25,242.496545410156,113.458471679688,115.962330322266,
,13825148.72,4370,271.514450073242,0.13400000333786,0,0.243706832275391,9.98999977111816,0.114106000976563,9.98999977111816,0.116557988586426,9.98999977111816,,,0.000132141026624566,7.11517669608999e-005,6.55833707656741e-005,,25,243.706832275391,114.106000976563,116.557988586426,
,13825172.48,4370,273.52799987793,0.13400000333786,0,0.244929078369141,9.98999977111816,0.114739274291992,9.98999977111816,0.117135339050293,9.98999977111816,,,0.000132523673949935,7.17800631971666e-005,6.59584563962865e-005,,25,244.929078369141,114.739274291992,117.135339050293,
,13825197.19,4370,275.573806762695,0.13400000333786,0,0.246185159301758,9.98999977111816,0.115412179260254,9.98999977111816,0.117747494812012,9.98999977111816,,,0.000132267408351588,7.4067301273527e-005,6.41696559047586e-005,,25,246.185159301758,115.412179260254,117.747494812012,
,13825220.56,4370,277.529159545898,0.13400000333786,0,0.247368942871094,9.98999977111816,0.116073809204102,9.98999977111816,0.11836154510498,9.98999977111816,,,0.000132808885915792,7.15707356994082e-005,6.65466026440106e-005,,25,247.368942871094,116.073809204102,118.36154510498,
,13825244.03,4370,279.498107910156,0.13400000333786,0,0.248567750854492,9.98999977111816,0.116708753662109,9.98999977111816,0.118943180541992,9.98999977111816,,,0.000133175748038371,7.23060328561263e-005,6.48514216661548e-005,,25,248.567750854492,116.708753662109,118.943180541992,
,13825267.75,4370,281.442749023438,0.13400000333786,0,0.249737756347656,9.98999977111816,0.117346147766113,9.98999977111816,0.119527512817383,9.98999977111816,,,0.000127558478956928,6.73112358326291e-005,6.14164366674906e-005,,25,249.737756347656,117.346147766113,119.527512817383,
,13825293.23,4370,283.583557128906,0.13400000333786,0,0.251019144897461,9.98999977111816,0.118008354492187,9.98999977111816,0.120131527404785,9.98999977111816,,,0.000128554263320656,6.81868231519583e-005,6.23012602888101e-005,,25,251.019144897461,118.008354492187,120.131527404785,
,13825316.97,4370,285.533599853516,0.13400000333786,0,0.252226727294922,9.98999977111816,0.118650258178711,9.98999977111816,0.120709855957031,9.98999977111816,,,0.000130307913306763,6.92926938966685e-005,6.38457080879611e-005,,25,252.226727294922,118.650258178711,120.709855957031,
,13825340.91,4370,287.54264831543,0.13400000333786,0,0.253431434326172,9.98999977111816,0.119294703063965,9.98999977111816,0.121311445007324,9.98999977111816,,,0.000131527805904231,7.10000574491127e-005,6.36925681960897e-005,,25,253.431434326172,119.294703063965,121.311445007324,
,13825364.78,4370,289.544906616211,0.13400000333786,0,0.254601751708984,9.98999977111816,0.119941352539063,9.98999977111816,0.121892841491699,9.98999977111816,,,0.00012531606101045,6.86596190964994e-005,6.34517996461892e-005,,25,254.601751708984,119.941352539063,121.892841491699,
,13825388.73,4370,291.515258789063,0.13400000333786,0,0.255772736816406,9.98999977111816,0.120570459594727,9.98999977111816,0.122475641784668,9.98999977111816,,,0.00012896360981504,6.87753917565357e-005,6.36377785082234e-005,,25,255.772736816406,120.570459594727,122.475641784668,
,13825412.53,4370,293.535751342773,0.13400000333786,0,0.256967822265625,9.98999977111816,0.121190588378906,9.98999977111816,0.12303835723877,9.98999977111816,,,0.000128397025073552,6.86663186140831e-005,6.32216483136569e-005,,25,256.967822265625,121.190588378906,123.03835723877,
,13825437.52,4370,295.564453125,0.13400000333786,0,0.258222684326172,9.98999977111816,0.121844431152344,9.98999977111816,0.123627870483398,9.98999977111816,,,0.000131375526219399,6.93083682797879e-005,6.30759635914004e-005,,25,258.222684326172,121.844431152344,123.627870483398,
,13825460.05,4370,297.498992919922,0.13400000333786,0,0.259364749755859,9.98999977111816,0.122459158935547,9.98999977111816,0.124196719665527,9.98999977111816,,,0.000130240554426972,7.56447885102469e-005,6.94817381658569e-005,,25,259.364749755859,122.459158935547,124.196719665527,
,13825485.30,4370,299.486190795898,0.13400000333786,0,0.260561726074219,9.98999977111816,0.123113840026855,9.98999977111816,0.124792965698242,9.98999977111816,,,0.00012160905379549,6.7324085807793e-005,6.05165041356567e-005,,25,260.561726074219,123.113840026855,124.792965698242,
,13825500.17,4370,300.163146972656,0.13400000333786,0,0.261154736328125,9.98999977111816,0.123430902404785,9.98999977111816,0.125083807373047,9.98999977111816,,,8.47022931782338e-005,4.63840957057423e-005,4.13589477580563e-005,,25,261.154736328125,123.430902404785,125.083807373047,