File: icepp/250308_3D_mh_photolitho_IV3.dat
[Header]
TITLE, IV scan 1.0 to 10.0
FILEOPENTIME,13891356.69,3/8/2025,5:54 PM
BYAPP, Resistivity, 2.1, 1.0
INFO, APPNAME, PPMS MultiVu Application, 1.5.11
INFO, , Sample1 Name
INFO, 1, Sample1 Cross Section
INFO, 1, Sample1 Length
INFO, Ohm, Sample1 Units
INFO, , Sample2 Name
INFO, 1, Sample2 Cross Section
INFO, 1, Sample2 Length
INFO, Ohm, Sample2 Units
INFO, , Sample3 Name
INFO, 1, Sample3 Cross Section
INFO, 1, Sample3 Length
INFO, Ohm, Sample3 Units
INFO, , Sample4 Name
INFO, 1, Sample4 Cross Section
INFO, 1, Sample4 Length
INFO, Ohm, Sample4 Units
FIELDGROUP, Resistivity,2,3,4,5,6,7,8,9,10,11,12,13,14,15,16,17,18,19,20,21,22,23,24,25,26,27,28,29,30,31,32,33,34,35,36,37,38,39,40,41
STARTUPGROUP, Resistivity
STARTUPAXIS, X, 2, LINEAR, AUTO
STARTUPAXIS, Y1, 7, LINEAR, AUTO
STARTUPAXIS, Y2, 9, LINEAR, AUTO
STARTUPAXIS, Y3, 11, LINEAR, AUTO
PLOT_APPEARANCE, ALL, HORZ_GRID_ON, VERT_GRID_ON, MARKERS_AND_LINES, ALL_LINES
DATATYPE, TIME, 2
DATATYPE, COMMENT, 1
[Data]
Comment,Time Stamp (sec),Status (code),Temperature (K),Magnetic Field (Oe),Sample Position (deg),Bridge 1 Resistivity (Ohm),Bridge 1 Excitation (uA),Bridge 2 Resistivity (Ohm),Bridge 2 Excitation (uA),Bridge 3 Resistivity (Ohm),Bridge 3 Excitation (uA),Bridge 4 Resistivity (Ohm),Bridge 4 Excitation (uA),Bridge 1 Std. Dev. (Ohm),Bridge 2 Std. Dev. (Ohm),Bridge 3 Std. Dev. (Ohm),Bridge 4 Std. Dev. (Ohm),Number of Readings,Bridge 1 Resistance (Ohms),Bridge 2 Resistance (Ohms),Bridge 3 Resistance (Ohms),Bridge 4 Resistance (Ohms),Signal 1 Vin (V),Signal 2 Vin (V),Digital Inputs (code),Drive 1 Iout (mA),Drive 1 Ipower (watts),Drive 2 Iout (mA),Drive 2 Ipower (watts),Pressure (),Map 20 (),Map 21 (),Map 22 (),Map 23 (),Map 24 (),Map 25 (),Map 26 (),Map 27 (),Map 28 (),Map 29 ()
,13891547.50,4369,2.99994993209839,0.13400000333786,0,305.751373291016,0.999000012874603,23.0133895874023,0.999000012874603,32.9383284759521,0.999000012874603,,,1.41181475772812,0.302681021157403,1.48468883621501,,25,305.751373291016,23.0133895874023,32.9383284759521,
,13891555.53,4369,2.99980008602142,0.13400000333786,0,318.657717285156,2,23.40887840271,2,40.537017364502,2,,,0.458077614911279,0.34833213988348,3.61053943671525,,25,318.657717285156,23.40887840271,40.537017364502,
,13891564.41,4369,3,0.13400000333786,0,337.932813720703,3,24.0221415710449,3,53.7060325622559,3,,,0.231953123079813,0.0557822618641632,1.5868742034771,,25,337.932813720703,24.0221415710449,53.7060325622559,
,13891572.50,4369,3.00029993057251,0.13400000333786,0,360.369493408203,4.00099992752075,25.7012256622314,4.00099992752075,80.5730151367188,4.00099992752075,,,0.276176243770926,1.21282726313287,3.62442098010575,,25,360.369493408203,25.7012256622314,80.5730151367188,
,13891581.47,4369,3.00034999847412,0.13400000333786,0,370.708356933594,5,27.6054364776611,5,115.241860351562,5,,,0.115202524164834,0.929812784471531,6.07501133112083,,25,370.708356933594,27.6054364776611,115.241860351562,
,13891589.75,4369,2.99934995174408,0.13400000333786,0,377.496306152344,5.98400020599365,33.200798034668,5.98400020599365,213.777651977539,5.98400020599365,,,3.34384547398452,6.45187013799888,8.28247072354651,,25,377.496306152344,33.200798034668,213.777651977539,
,13891598.52,4369,2.99880003929138,0.13400000333786,0,378.091840820312,6.98600006103516,60.8717691040039,6.98600006103516,349.319501953125,6.98600006103516,,,0.222863382077542,51.6741689511061,1.15257403902077,,25,378.091840820312,60.8717691040039,349.319501953125,
,13891609.88,4369,2.99919998645782,0.13400000333786,0,379.867390136719,7.98699998855591,212.635366821289,7.98699998855591,465.452225341797,7.98699998855591,,,0.168492777804928,45.8405964513796,0.874400318078125,,25,379.867390136719,212.635366821289,465.452225341797,
,13891621.02,4369,2.99924993515015,0.13400000333786,0,719.057761230469,8.98900032043457,473.731324462891,8.98900032043457,566.456372070312,8.98900032043457,,,0.367194090454963,20.8577544562719,2.12221619402309,,25,719.057761230469,473.731324462891,566.456372070312,
,13891631.08,4369,3.00094997882843,0.13400000333786,0,790.068664550781,9.98999977111816,599.725759277344,9.98999977111816,632.634670410156,9.98999977111816,,,0.524814633759484,22.4139457377078,0.855102133938015,,25,790.068664550781,599.725759277344,632.634670410156,