File: icepp/250308_3D_mh_photolitho_IV5.dat
[Header]
TITLE, IV scan 6 to 10
FILEOPENTIME,13893530.78,3/8/2025,6:30 PM
BYAPP, Resistivity, 2.1, 1.0
INFO, APPNAME, PPMS MultiVu Application, 1.5.11
INFO, , Sample1 Name
INFO, 1, Sample1 Cross Section
INFO, 1, Sample1 Length
INFO, Ohm, Sample1 Units
INFO, , Sample2 Name
INFO, 1, Sample2 Cross Section
INFO, 1, Sample2 Length
INFO, Ohm, Sample2 Units
INFO, , Sample3 Name
INFO, 1, Sample3 Cross Section
INFO, 1, Sample3 Length
INFO, Ohm, Sample3 Units
INFO, , Sample4 Name
INFO, 1, Sample4 Cross Section
INFO, 1, Sample4 Length
INFO, Ohm, Sample4 Units
FIELDGROUP, Resistivity,2,3,4,5,6,7,8,9,10,11,12,13,14,15,16,17,18,19,20,21,22,23,24,25,26,27,28,29,30,31,32,33,34,35,36,37,38,39,40,41
STARTUPGROUP, Resistivity
STARTUPAXIS, X, 2, LINEAR, AUTO
STARTUPAXIS, Y1, 7, LINEAR, AUTO
STARTUPAXIS, Y2, 9, LINEAR, AUTO
STARTUPAXIS, Y3, 11, LINEAR, AUTO
PLOT_APPEARANCE, ALL, HORZ_GRID_ON, VERT_GRID_ON, MARKERS_AND_LINES, ALL_LINES
DATATYPE, TIME, 2
DATATYPE, COMMENT, 1
[Data]
Comment,Time Stamp (sec),Status (code),Temperature (K),Magnetic Field (Oe),Sample Position (deg),Bridge 1 Resistivity (Ohm),Bridge 1 Excitation (uA),Bridge 2 Resistivity (Ohm),Bridge 2 Excitation (uA),Bridge 3 Resistivity (Ohm),Bridge 3 Excitation (uA),Bridge 4 Resistivity (Ohm),Bridge 4 Excitation (uA),Bridge 1 Std. Dev. (Ohm),Bridge 2 Std. Dev. (Ohm),Bridge 3 Std. Dev. (Ohm),Bridge 4 Std. Dev. (Ohm),Number of Readings,Bridge 1 Resistance (Ohms),Bridge 2 Resistance (Ohms),Bridge 3 Resistance (Ohms),Bridge 4 Resistance (Ohms),Signal 1 Vin (V),Signal 2 Vin (V),Digital Inputs (code),Drive 1 Iout (mA),Drive 1 Ipower (watts),Drive 2 Iout (mA),Drive 2 Ipower (watts),Pressure (),Map 20 (),Map 21 (),Map 22 (),Map 23 (),Map 24 (),Map 25 (),Map 26 (),Map 27 (),Map 28 (),Map 29 ()
,13893889.66,4369,2.99965000152588,0.13400000333786,0,376.196845703125,5.98400020599365,30.7386193847656,5.98400020599365,207.896338500977,5.98400020599365,,,0.248432092384725,0.122651771589558,5.79094429595872,,25,376.196845703125,30.7386193847656,207.896338500977,
,13893898.80,4369,3.00124990940094,0.13400000333786,0,376.196046142578,5.98400020599365,30.784556350708,5.98400020599365,209.583012695313,5.98400020599365,,,0.187444951375786,0.163597505848582,4.84580339835299,,25,376.196046142578,30.784556350708,209.583012695313,
,13893907.59,4369,2.99944996833801,0.13400000333786,0,376.157481689453,5.98400020599365,30.7878470611572,5.98400020599365,210.984317016602,5.98400020599365,,,0.229220621638947,0.124615747334195,4.88668987116053,,25,376.157481689453,30.7878470611572,210.984317016602,
,13893915.75,4369,2.99954998493195,0.13400000333786,0,376.156915283203,5.98400020599365,30.7466535949707,5.98400020599365,210.487329711914,5.98400020599365,,,0.228697631589979,0.129136361053954,4.12590708270186,,25,376.156915283203,30.7466535949707,210.487329711914,
,13893924.56,4369,3.00010001659393,0.13400000333786,0,376.198001708984,6.00899982452393,30.9125403594971,6.00899982452393,216.009938964844,6.00899982452393,,,0.104325340102173,0.159844670899307,2.77120816124563,,25,376.198001708984,30.9125403594971,216.009938964844,
,13893933.20,4369,2.99979996681213,0.13400000333786,0,378.923732910156,6.00899982452393,32.8226702880859,6.00899982452393,218.08344543457,6.00899982452393,,,8.07393457770881,6.48066033746942,8.10622077108029,,25,378.923732910156,32.8226702880859,218.08344543457,
,13893941.91,4369,3.00010001659393,0.13400000333786,0,376.403344726563,6.00899982452393,30.9385766601563,6.00899982452393,215.299869384766,6.00899982452393,,,0.242702712420205,0.159005393711375,3.00918373690364,,25,376.403344726563,30.9385766601563,215.299869384766,
,13893950.81,4369,2.9996999502182,0.13400000333786,0,376.325650634766,6.00899982452393,30.9460193634033,6.00899982452393,214.805200805664,6.00899982452393,,,0.201210976693377,0.150383941642147,3.3344172716826,,25,376.325650634766,30.9460193634033,214.805200805664,
,13893959.30,4369,3.00090003013611,0.13400000333786,0,376.355380859375,6.00899982452393,31.0281927490234,6.00899982452393,216.235551147461,6.00899982452393,,,0.242496267695868,0.188662022429424,2.73848651811354,,25,376.355380859375,31.0281927490234,216.235551147461,
,13893968.70,4369,2.99955010414124,0.13400000333786,0,376.261719970703,6.00899982452393,30.9657817077637,6.00899982452393,216.245534667969,6.00899982452393,,,0.166058490807936,0.127301819901671,3.01390559959635,,25,376.261719970703,30.9657817077637,216.245534667969,
,13893977.70,4369,2.99890005588531,0.13400000333786,0,376.266397705078,6.00899982452393,30.9433525085449,6.00899982452393,216.203975830078,6.00899982452393,,,0.167323143206854,0.166390793568575,3.61551714628608,,25,376.266397705078,30.9433525085449,216.203975830078,
,13893985.73,4369,2.9991500377655,0.13400000333786,0,376.142437744141,6.00899982452393,30.9194281005859,6.00899982452393,214.073682250977,6.00899982452393,,,0.156696677721208,0.146711211975166,2.60388879780435,,25,376.142437744141,30.9194281005859,214.073682250977,
,13893994.70,4369,3.00065004825592,0.13400000333786,0,377.973393554688,6.00899982452393,32.9765468597412,6.00899982452393,218.319686889648,6.00899982452393,,,5.66094753094108,5.59263198304112,6.82598624475282,,25,377.973393554688,32.9765468597412,218.319686889648,
,13894003.34,4369,2.99960005283356,0.13400000333786,0,376.188162841797,6.00899982452393,30.9265409088135,6.00899982452393,216.696653442383,6.00899982452393,,,0.197787871357955,0.13093593743814,2.84234301962821,,25,376.188162841797,30.9265409088135,216.696653442383,
,13894012.36,4369,3.00010001659393,0.13400000333786,0,376.223427734375,6.00899982452393,30.966017074585,6.00899982452393,215.978431396484,6.00899982452393,,,0.191607531687636,0.139667177043715,2.97633422747915,,25,376.223427734375,30.966017074585,215.978431396484,
,13894021.64,4369,2.99989998340607,0.13400000333786,0,376.308375244141,6.00899982452393,30.992258605957,6.00899982452393,216.542735595703,6.00899982452393,,,0.218141622419664,0.172627222848822,3.0667004375845,,25,376.308375244141,30.992258605957,216.542735595703,
Measurement was Aborted,13894031.34