File: icepp/250308_3D_mh_photolitho_IV7.dat
[Header]
TITLE, IV scan 6 to 10 (0.02 scan)
FILEOPENTIME,13894351.28,3/8/2025,6:44 PM
BYAPP, Resistivity, 2.1, 1.0
INFO, APPNAME, PPMS MultiVu Application, 1.5.11
INFO, , Sample1 Name
INFO, 1, Sample1 Cross Section
INFO, 1, Sample1 Length
INFO, Ohm, Sample1 Units
INFO, , Sample2 Name
INFO, 1, Sample2 Cross Section
INFO, 1, Sample2 Length
INFO, Ohm, Sample2 Units
INFO, , Sample3 Name
INFO, 1, Sample3 Cross Section
INFO, 1, Sample3 Length
INFO, Ohm, Sample3 Units
INFO, , Sample4 Name
INFO, 1, Sample4 Cross Section
INFO, 1, Sample4 Length
INFO, Ohm, Sample4 Units
FIELDGROUP, Resistivity,2,3,4,5,6,7,8,9,10,11,12,13,14,15,16,17,18,19,20,21,22,23,24,25,26,27,28,29,30,31,32,33,34,35,36,37,38,39,40,41
STARTUPGROUP, Resistivity
STARTUPAXIS, X, 2, LINEAR, AUTO
STARTUPAXIS, Y1, 7, LINEAR, AUTO
STARTUPAXIS, Y2, 9, LINEAR, AUTO
STARTUPAXIS, Y3, 11, LINEAR, AUTO
PLOT_APPEARANCE, ALL, HORZ_GRID_ON, VERT_GRID_ON, MARKERS_AND_LINES, ALL_LINES
DATATYPE, TIME, 2
DATATYPE, COMMENT, 1
[Data]
Comment,Time Stamp (sec),Status (code),Temperature (K),Magnetic Field (Oe),Sample Position (deg),Bridge 1 Resistivity (Ohm),Bridge 1 Excitation (uA),Bridge 2 Resistivity (Ohm),Bridge 2 Excitation (uA),Bridge 3 Resistivity (Ohm),Bridge 3 Excitation (uA),Bridge 4 Resistivity (Ohm),Bridge 4 Excitation (uA),Bridge 1 Std. Dev. (Ohm),Bridge 2 Std. Dev. (Ohm),Bridge 3 Std. Dev. (Ohm),Bridge 4 Std. Dev. (Ohm),Number of Readings,Bridge 1 Resistance (Ohms),Bridge 2 Resistance (Ohms),Bridge 3 Resistance (Ohms),Bridge 4 Resistance (Ohms),Signal 1 Vin (V),Signal 2 Vin (V),Digital Inputs (code),Drive 1 Iout (mA),Drive 1 Ipower (watts),Drive 2 Iout (mA),Drive 2 Ipower (watts),Pressure (),Map 20 (),Map 21 (),Map 22 (),Map 23 (),Map 24 (),Map 25 (),Map 26 (),Map 27 (),Map 28 (),Map 29 ()
,13894425.80,4369,3.00079989433289,0.13400000333786,0,376.645784912109,5.98400020599365,30.7337232208252,5.98400020599365,212.244755249023,5.98400020599365,,,0.161332429346843,0.131955668187544,3.41856357344351,,25,376.645784912109,30.7337232208252,212.244755249023,
,13894443.31,4369,2.9996999502182,0.13400000333786,0,376.768812255859,6.03299999237061,31.1079178619385,6.03299999237061,221.606770629883,6.03299999237061,,,0.142466505189529,0.149053060287329,2.14486881733748,,25,376.768812255859,31.1079178619385,221.606770629883,
,13894460.73,4369,3.00039994716644,0.13400000333786,0,376.844129638672,6.05800008773804,37.322741394043,6.05800008773804,226.012756347656,6.05800008773804,,,0.155947631933837,29.6253035832793,2.49900868124528,,25,376.844129638672,37.322741394043,226.012756347656,
,13894478.70,4369,3.00029993057251,0.13400000333786,0,376.245633544922,6.10599994659424,37.6758038330078,6.10599994659424,232.625198364258,6.10599994659424,,,0.161871218103247,29.8625293425881,2.02771791594954,,25,376.245633544922,37.6758038330078,232.625198364258,
,13894496.89,4369,2.99975001811981,0.13400000333786,0,376.371745605469,6.15500020980835,39.0795190429687,6.15500020980835,239.305271606445,6.15500020980835,,,0.131069267561808,29.8038732412326,2.15004470983557,,25,376.371745605469,39.0795190429687,239.305271606445,
,13894514.64,4369,3.00004994869232,0.13400000333786,0,376.431306152344,6.17999982833862,57.0847692871094,6.17999982833862,240.837019042969,6.17999982833862,,,0.277905517620076,56.0721625876304,2.75039895047536,,25,376.431306152344,57.0847692871094,240.837019042969,
,13894531.84,4369,3.00080001354218,0.13400000333786,0,379.502318115234,6.22900009155273,55.5448550415039,6.22900009155273,247.400149536133,6.22900009155273,,,10.3824264222274,49.8644229824444,4.01881367052679,,25,379.502318115234,55.5448550415039,247.400149536133,
,13894549.45,4369,2.99975001811981,0.13400000333786,0,376.58396484375,6.27699995040894,52.0858711242676,6.27699995040894,257.393610839844,6.27699995040894,,,0.156252638321447,49.9176090521342,9.98470775108484,,25,376.58396484375,52.0858711242676,257.393610839844,
,13894566.97,4369,3.00159990787506,0.13400000333786,0,376.735529785156,6.30200004577637,52.8322950744629,6.30200004577637,253.464319458008,6.30200004577637,,,0.180898441696136,49.9174491609066,4.14502868578732,,25,376.735529785156,52.8322950744629,253.464319458008,
,13894584.81,4369,2.9994500875473,0.13400000333786,0,376.768035888672,6.35099983215332,48.8642901611328,6.35099983215332,259.300873413086,6.35099983215332,,,0.0770439503455667,41.4371547043787,3.99661318887767,,25,376.768035888672,48.8642901611328,259.300873413086,
,13894603.25,4369,3.00045001506805,0.13400000333786,0,376.796051025391,6.40000009536743,72.9635366821289,6.40000009536743,269.660921630859,6.40000009536743,,,0.161994552665753,53.2356024870802,5.70034772284512,,25,376.796051025391,72.9635366821289,269.660921630859,
,13894620.66,4369,2.99944996833801,0.13400000333786,0,377.214545898438,6.42399978637695,65.5553816223145,6.42399978637695,271.292777099609,6.42399978637695,,,0.187665226014925,62.188126043442,5.22177675056308,,25,377.214545898438,65.5553816223145,271.292777099609,
,13894637.67,4369,2.99925005435944,0.13400000333786,0,377.260694580078,6.47300004959106,41.7590824890137,6.47300004959106,282.377901611328,6.47300004959106,,,0.116358527184486,30.3446883649871,5.57998295783906,,25,377.260694580078,41.7590824890137,282.377901611328,
,13894656.09,4369,2.99989998340607,0.13400000333786,0,397.747095947266,6.49700021743774,41.5188847351074,6.49700021743774,287.668239746094,6.49700021743774,,,55.2533687579553,30.5653438280459,6.65396144014857,,25,397.747095947266,41.5188847351074,287.668239746094,
,13894674.66,4369,2.99919998645782,0.13400000333786,0,391.076512451172,6.5460000038147,42.1473329162598,6.5460000038147,303.043299560547,6.5460000038147,,,46.4376791015641,30.6328332143164,3.10743762956161,,25,391.076512451172,42.1473329162598,303.043299560547,
,13894692.53,4369,2.99930000305176,0.13400000333786,0,439.576778564453,6.59499979019165,42.428309173584,6.59499979019165,311.940106201172,6.59499979019165,,,82.7411788037454,30.6753558764924,1.94906544774197,,25,439.576778564453,42.428309173584,311.940106201172,
,13894709.53,4369,2.99960005283356,0.13400000333786,0,453.833558349609,6.61899995803833,68.4572467041016,6.61899995803833,315.124499511719,6.61899995803833,,,85.9785842842642,62.3152849953417,1.34122744845155,,25,453.833558349609,68.4572467041016,315.124499511719,
,13894727.53,4369,3.0006000995636,0.13400000333786,0,502.608544921875,6.66800022125244,68.4928469848633,6.66800022125244,319.729033203125,6.66800022125244,,,77.9219752040565,62.6655788672999,1.20447302439168,,25,502.608544921875,68.4928469848633,319.729033203125,
,13894745.14,4369,3.00014996528625,0.13400000333786,0,552.616584472656,6.71700000762939,50.4293478393555,6.71700000762939,324.739725341797,6.71700000762939,,,0.505727458071214,42.598006034002,1.02881533147857,,25,552.616584472656,50.4293478393555,324.739725341797,
,13894763.45,4369,3.00024998188019,0.13400000333786,0,532.233594970703,6.74200010299683,50.5444158935547,6.74200010299683,326.642414550781,6.74200010299683,,,57.1085310781119,42.6755264988255,1.0165383207205,,25,532.233594970703,50.5444158935547,326.642414550781,
,13894781.14,4369,3.00045001506805,0.13400000333786,0,479.093768310547,6.78999996185303,64.1728630065918,6.78999996185303,331.375695800781,6.78999996185303,,,89.914555733748,57.6955849840323,1.18023227415184,,25,479.093768310547,64.1728630065918,331.375695800781,
,13894799.64,4369,3.00074994564056,0.13400000333786,0,438.163818359375,6.83900022506714,52.2526490783691,6.83900022506714,334.924167480469,6.83900022506714,,,87.9098510575763,42.7712938581431,0.961325377886176,,25,438.163818359375,52.2526490783691,334.924167480469,
,13894817.75,4369,3.00049996376038,0.13400000333786,0,446.584898681641,6.86399984359741,46.2861001586914,6.86399984359741,336.944954833984,6.86399984359741,,,91.7110143548774,30.914879660383,1.0344655081508,,25,446.584898681641,46.2861001586914,336.944954833984,
,13894836.72,4369,2.99954998493195,0.13400000333786,0,378.091142578125,6.91300010681152,47.1136241149902,6.91300010681152,341.59212890625,6.91300010681152,,,0.227230367023609,31.0296563383857,1.16810565117949,,25,378.091142578125,47.1136241149902,341.59212890625,
,13894857.84,4369,2.99930000305176,0.13400000333786,0,377.887850341797,6.93699979782104,72.7786666870117,6.93699979782104,343.670646972656,6.93699979782104,,,0.135075077811406,63.3606326835318,1.7647431286516,,25,377.887850341797,72.7786666870117,343.670646972656,
,13894879.08,4369,2.9988499879837,0.13400000333786,0,377.952531738281,6.98600006103516,54.654649810791,6.98600006103516,350.07189453125,6.98600006103516,,,0.0923593753434805,43.1105850691854,1.04391512287544,,25,377.952531738281,54.654649810791,350.07189453125,
,13894900.95,4369,3.00174999237061,0.13400000333786,0,378.052166748047,7.03499984741211,49.1994970703125,7.03499984741211,354.047462158203,7.03499984741211,,,0.0747148885210244,31.3358197920295,1.00171493767446,,25,378.052166748047,49.1994970703125,354.047462158203,
,13894923.00,4369,3.0006000995636,0.13400000333786,0,378.047889404297,7.05900001525879,68.702963104248,7.05900001525879,355.918305664062,7.05900001525879,,,0.0950834564460804,58.6928724967019,0.895772291992211,,25,378.047889404297,68.702963104248,355.918305664062,
,13894945.06,4369,2.99840009212494,0.13400000333786,0,378.133100585937,7.10799980163574,57.0360136413574,7.10799980163574,360.963135986328,7.10799980163574,,,0.0735972555782429,43.6534676331273,1.15508786416641,,25,378.133100585937,57.0360136413574,360.963135986328,
,13894967.06,4369,3,0.13400000333786,0,378.223352050781,7.15700006484985,51.4378218078613,7.15700006484985,369.249814453125,7.15700006484985,,,0.17343628343003,31.6661835002368,0.778361173010262,,25,378.223352050781,51.4378218078613,369.249814453125,
,13894988.69,4369,3.00125002861023,0.13400000333786,0,378.359295654297,7.18100023269653,58.2923768615723,7.18100023269653,371.581306152344,7.18100023269653,,,0.19538720050953,44.0609552700127,1.13025084167705,,25,378.359295654297,58.2923768615723,371.581306152344,
,13895010.98,4369,2.9996999502182,0.13400000333786,0,501.737462158203,7.23000001907349,59.2899739074707,7.23000001907349,376.129155273438,7.23000001907349,,,109.30171744877,44.4269621052358,1.71008259592814,,25,501.737462158203,59.2899739074707,376.129155273438,
,13895032.03,4369,2.99914991855621,0.13400000333786,0,378.482039794922,7.27899980545044,66.9168988037109,7.27899980545044,380.066018066406,7.27899980545044,,,0.171943645847135,53.5418945965806,1.06549176100642,,25,378.482039794922,66.9168988037109,380.066018066406,
,13895054.41,4369,3.0008499622345,0.13400000333786,0,378.526149902344,7.30299997329712,54.2771809387207,7.30299997329712,382.636470947266,7.30299997329712,,,0.162739056278321,32.3832192539487,1.16908996194421,,25,378.526149902344,54.2771809387207,382.636470947266,
,13895076.75,4369,2.99954998493195,0.13400000333786,0,378.712666015625,7.35200023651123,48.3583432006836,7.35200023651123,386.145194091797,7.35200023651123,,,0.159782303385364,0.194359590421965,0.951802200597904,,25,378.712666015625,48.3583432006836,386.145194091797,
,13895098.11,4369,2.99895000457764,0.13400000333786,0,378.695308837891,7.40100002288818,50.5431512451172,7.40100002288818,390.589593505859,7.40100002288818,,,0.163058525804101,5.29500215106426,0.894528240285729,,25,378.695308837891,50.5431512451172,390.589593505859,
,13895120.25,4369,2.99930000305176,0.13400000333786,0,378.748782958984,7.42600011825562,75.5847694396973,7.42600011825562,393.195120849609,7.42600011825562,,,0.146872397041305,53.8047238334872,1.23409555260397,,25,378.748782958984,75.5847694396973,393.195120849609,
,13895141.73,4369,2.99879992008209,0.13400000333786,0,378.792576904297,7.47399997711182,160.097469940186,7.47399997711182,397.585085449219,7.47399997711182,,,0.0789702045560299,62.9081960003315,2.0002246320744,,25,378.792576904297,160.097469940186,397.585085449219,
,13895164.19,4369,3.00005006790161,0.13400000333786,0,378.939851074219,7.49900007247925,178.691069335938,7.49900007247925,400.206782226563,7.49900007247925,,,0.153210668990715,38.2953320229994,1.89918882963234,,25,378.939851074219,178.691069335938,400.206782226563,
,13895186.80,4369,2.99979996681213,0.13400000333786,0,378.970479736328,7.5479998588562,191.309154052734,7.5479998588562,405.107509765625,7.5479998588562,,,0.191871807643318,0.369832973701454,1.36690065792561,,25,378.970479736328,191.309154052734,405.107509765625,
,13895209.22,4369,3.00065004825592,0.13400000333786,0,378.984229736328,7.59600019454956,171.54958114624,7.59600019454956,410.248637695312,7.59600019454956,,,0.132122538452617,52.022646050699,1.50623749770886,,25,378.984229736328,171.54958114624,410.248637695312,
,13895231.63,4369,2.99870002269745,0.13400000333786,0,469.538186035156,7.62099981307983,178.696672058105,7.62099981307983,413.704317626953,7.62099981307983,,,120.59057475459,46.533915303731,1.66607368017027,,25,469.538186035156,178.696672058105,413.704317626953,
,13895252.81,4369,2.99965000152588,0.13400000333786,0,578.031936035156,7.67000007629395,202.205921020508,7.67000007629395,420.219541015625,7.67000007629395,,,100.40783194137,6.89070793348898,5.39614698127057,,25,578.031936035156,202.205921020508,420.219541015625,
,13895273.75,4369,2.99975001811981,0.13400000333786,0,379.344632568359,7.7189998626709,181.438898925781,7.7189998626709,423.085380859375,7.7189998626709,,,0.207009989520087,55.5974661746386,1.5505951940692,,25,379.344632568359,181.438898925781,423.085380859375,
,13895296.02,4369,2.99950003623962,0.13400000333786,0,379.277326660156,7.74300003051758,164.539537658691,7.74300003051758,425.180236816406,7.74300003051758,,,0.163076103775564,68.750780065423,2.24011060534223,,25,379.277326660156,164.539537658691,425.180236816406,
,13895318.34,4369,3.0011500120163,0.13400000333786,0,379.393328857422,7.79199981689453,198.112429199219,7.79199981689453,429.537862548828,7.79199981689453,,,0.165284805927506,42.2644332312426,3.08645535208908,,25,379.393328857422,198.112429199219,429.537862548828,
,13895338.13,4369,3.00174999237061,0.13400000333786,0,379.409571533203,7.84100008010864,188.248447723389,7.84100008010864,438.513989257813,7.84100008010864,,,0.0847458240019441,57.845219618637,7.16200711303368,,25,379.409571533203,188.248447723389,438.513989257813,
,13895359.69,4369,2.9996999502182,0.13400000333786,0,430.686696777344,7.86499977111816,189.340328674316,7.86499977111816,444.660985107422,7.86499977111816,,,102.158612943637,58.1224394379599,6.77022546683633,,25,430.686696777344,189.340328674316,444.660985107422,
,13895381.70,4369,2.99980008602142,0.13400000333786,0,390.056922607422,7.91400003433228,205.477340393066,7.91400003433228,458.523701171875,7.91400003433228,,,51.1482998706795,43.9134938257476,3.95599831593568,,25,390.056922607422,205.477340393066,458.523701171875,
,13895405.08,4369,2.99865007400513,0.13400000333786,0,592.404184570313,7.93800020217896,201.559211730957,7.93800020217896,462.430426025391,7.93800020217896,,,106.37962686522,53.4473177755315,0.801125498717956,,25,592.404184570313,201.559211730957,462.430426025391,
,13895425.67,4369,2.99825000762939,0.13400000333786,0,412.979139404297,7.98699998855591,227.011331787109,7.98699998855591,466.338013916016,7.98699998855591,,,89.7631552777696,0.367107609185748,0.871850057120244,,25,412.979139404297,227.011331787109,466.338013916016,
,13895448.27,4369,2.99965000152588,0.13400000333786,0,379.911865234375,8.03600025177002,223.363060760498,8.03600025177002,470.432370605469,8.03600025177002,,,0.11543653372247,33.7086842936984,0.91577389204354,,25,379.911865234375,223.363060760498,470.432370605469,
,13895471.92,4369,2.99954998493195,0.13400000333786,0,380.082230224609,8.06099987030029,231.843220214844,8.06099987030029,473.327048339844,8.06099987030029,,,0.260136573107068,0.203086462836993,0.851825650570336,,25,380.082230224609,231.843220214844,473.327048339844,
,13895494.72,4369,3.00155007839203,0.13400000333786,0,658.530124511719,8.10900020599365,275.172456665039,8.10900020599365,477.774005126953,8.10900020599365,,,0.572506404879045,54.4363138093742,1.10937415999919,,25,658.530124511719,275.172456665039,477.774005126953,
,13895514.39,4369,2.99909996986389,0.13400000333786,0,603.881345214844,8.15799999237061,279.661146850586,8.15799999237061,482.844431152344,8.15799999237061,,,111.868465296332,55.3723460903756,1.33452026439815,,25,603.881345214844,279.661146850586,482.844431152344,
,13895533.02,4369,3.00085008144379,0.13400000333786,0,537.166636962891,8.18299961090088,276.816897583008,8.18299961090088,485.512847900391,8.18299961090088,,,139.162521321141,53.609314020976,1.41178151373184,,25,537.166636962891,276.816897583008,485.512847900391,
,13895552.00,4369,2.99950003623962,0.13400000333786,0,627.404140625,8.23200035095215,323.062797241211,8.23200035095215,490.572412109375,8.23200035095215,,,107.688651183023,61.7509895187271,1.83206839141117,,25,627.404140625,323.062797241211,490.572412109375,
,13895571.23,4369,2.99954998493195,0.13400000333786,0,668.510769042969,8.27999973297119,340.371228027344,8.27999973297119,490.9765625,8.27999973297119,,,58.8134699655704,61.5495579602849,5.27251370449713,,25,668.510769042969,340.371228027344,490.9765625,
,13895589.70,4369,3.00024998188019,0.13400000333786,0,681.2381640625,8.30500030517578,326.683950195312,8.30500030517578,493.489622802734,8.30500030517578,,,0.351795648132412,72.7533253266151,4.64833725858242,,25,681.2381640625,326.683950195312,493.489622802734,
,13895608.95,4369,3.00074994564056,0.13400000333786,0,681.944577636719,8.35400009155273,379.685606689453,8.35400009155273,498.506127929688,8.35400009155273,,,1.2312693785722,62.217661357313,1.89070175302258,,25,681.944577636719,379.685606689453,498.506127929688,
,13895628.20,4369,3.0005499124527,0.13400000333786,0,681.803413085937,8.37800025939941,396.313275146484,8.37800025939941,500.116248779297,8.37800025939941,,,0.2032109199771,56.2294197902162,0.726971354462895,,25,681.803413085937,396.313275146484,500.116248779297,
,13895646.92,4369,2.99909996986389,0.13400000333786,0,682.460317382812,8.42700004577637,407.629874267578,8.42700004577637,503.838350830078,8.42700004577637,,,0.431742610253921,58.0057478279429,0.89522487647282,,25,682.460317382812,407.629874267578,503.838350830078,
,13895664.48,4369,3.00110006332397,0.13400000333786,0,683.893056640625,8.47599983215332,424.79346496582,8.47599983215332,507.471070556641,8.47599983215332,,,0.949839296452917,35.2724227910554,1.54535800390471,,25,683.893056640625,424.79346496582,507.471070556641,
,13895684.20,4369,2.99965000152588,0.13400000333786,0,687.204660644531,8.5,426.403755493164,8.5,508.550428466797,8.5,,,2.25762726842875,35.166623400846,0.845356661827566,,25,687.204660644531,426.403755493164,508.550428466797,
,13895703.31,4369,2.99994993209839,0.13400000333786,0,701.415375976562,8.54899978637695,438.748115234375,8.54899978637695,512.008653564453,8.54899978637695,,,0.784979133243494,0.999721577761657,0.861255175252839,,25,701.415375976562,438.748115234375,512.008653564453,
,13895723.30,4369,3.00099992752075,0.13400000333786,0,702.42578125,8.59799957275391,351.000930175781,8.59799957275391,515.461953125,8.59799957275391,,,0.3746825149535,88.9460628231225,1.18589986000107,,25,702.42578125,351.000930175781,515.461953125,
,13895741.77,4369,3.00020003318787,0.13400000333786,0,702.363498535156,8.62199974060059,362.460677490234,8.62199974060059,517.981281738281,8.62199974060059,,,0.339941196731304,84.1908831943905,1.36719806990625,,25,702.363498535156,362.460677490234,517.981281738281,
,13895760.56,4369,3.00014996528625,0.13400000333786,0,704.652307128906,8.67099952697754,424.756018066406,8.67099952697754,522.901418457031,8.67099952697754,,,0.936246523351901,16.2578870371372,0.987882097155321,,25,704.652307128906,424.756018066406,522.901418457031,
,13895778.52,4369,3.00174999237061,0.13400000333786,0,715.075844726563,8.72000026702881,426.400744628906,8.72000026702881,527.131652832031,8.72000026702881,,,1.16894508097801,16.5058677676163,1.47235295428785,,25,715.075844726563,426.400744628906,527.131652832031,
,13895797.06,4369,2.9994500875473,0.13400000333786,0,716.765,8.74499988555908,428.431795654297,8.74499988555908,529.425305175781,8.74499988555908,,,0.530024172662805,17.6607726278742,1.72077396885452,,25,716.765,428.431795654297,529.425305175781,
,13895816.34,4369,3.00010001659393,0.13400000333786,0,717.084357910156,8.79300022125244,423.070063476563,8.79300022125244,535.109230957031,8.79300022125244,,,0.243213557564281,11.3426604734578,1.52043362825006,,25,717.084357910156,423.070063476563,535.109230957031,
,13895837.72,4369,2.99985003471375,0.13400000333786,0,717.514482421875,8.81799983978271,420.698134765625,8.81799983978271,537.9373828125,8.81799983978271,,,0.340938446535742,0.352701243859039,1.68882022147429,,25,717.514482421875,420.698134765625,537.9373828125,
,13895859.44,4369,2.99985003471375,0.13400000333786,0,717.746997070313,8.86699962615967,424.290649414063,8.86699962615967,542.796303710938,8.86699962615967,,,0.323035201814022,0.264092340816514,1.69210565680591,,25,717.746997070313,424.290649414063,542.796303710938,
,13895881.64,4369,3,0.13400000333786,0,718.270769042969,8.91499996185303,474.037917480469,8.91499996185303,549.145629882813,8.91499996185303,,,0.350209003794912,24.959986295039,2.29264411935026,,25,718.270769042969,474.037917480469,549.145629882813,
,13895900.27,4369,2.99965000152588,0.13400000333786,0,718.273461914063,8.9399995803833,475.006452636719,8.9399995803833,553.081923828125,8.9399995803833,,,0.297508649633785,24.7251496663494,3.06370089794177,,25,718.273461914063,475.006452636719,553.081923828125,
,13895918.92,4369,2.99904990196228,0.13400000333786,0,719.061325683594,8.98900032043457,476.773109130859,8.98900032043457,568.066357421875,8.98900032043457,,,0.413611903987327,22.7715425897735,1.32941319107795,,25,719.061325683594,476.773109130859,568.066357421875,
,13895937.58,4369,2.99940001964569,0.13400000333786,0,719.45005859375,9.03800010681152,475.881499023438,9.03800010681152,572.903962402344,9.03800010681152,,,0.242356305695997,17.2957092944257,0.929097342563011,,25,719.45005859375,475.881499023438,572.903962402344,
,13895956.64,4369,2.99960005283356,0.13400000333786,0,719.425654296875,9.0620002746582,484.070367431641,9.0620002746582,574.734992675781,9.0620002746582,,,0.142802410701888,28.3368171615086,0.503513825225517,,25,719.425654296875,484.070367431641,574.734992675781,
,13895974.48,4369,2.99975001811981,0.13400000333786,0,719.921281738281,9.11100006103516,485.214520263672,9.11100006103516,579.768366699219,9.11100006103516,,,0.183044654283839,23.0101705879997,7.33965884503016,,25,719.921281738281,485.214520263672,579.768366699219,
,13895993.20,4369,3.00045001506805,0.13400000333786,0,720.585395507812,9.15999984741211,489.654187011719,9.15999984741211,581.417341308594,9.15999984741211,,,0.273397450728549,21.8576736285933,0.213488661867287,,25,720.585395507812,489.654187011719,581.417341308594,
,13896010.97,4369,3.0008499622345,0.13400000333786,0,720.728247070312,9.18400001525879,493.658551025391,9.18400001525879,582.610705566406,9.18400001525879,,,0.275498041740182,35.1662102443393,0.567561749076772,,25,720.728247070312,493.658551025391,582.610705566406,
,13896028.86,4369,3.00069999694824,0.13400000333786,0,721.135341796875,9.23299980163574,502.271558837891,9.23299980163574,585.275639648438,9.23299980163574,,,0.170847897379295,39.3858642969243,0.590858237521218,,25,721.135341796875,502.271558837891,585.275639648438,
,13896046.88,4369,3.00065004825592,0.13400000333786,0,721.391491699219,9.25699996948242,499.00431640625,9.25699996948242,586.657946777344,9.25699996948242,,,0.0978696113585306,35.1936076028094,0.303711322534262,,25,721.391491699219,499.00431640625,586.657946777344,
,13896065.94,4369,2.99855005741119,0.13400000333786,0,721.9650390625,9.30599975585938,499.211766357422,9.30599975585938,589.55794921875,9.30599975585938,,,0.255900030213949,32.8256835399975,0.800824534159361,,25,721.9650390625,499.211766357422,589.55794921875,
,13896084.75,4369,3.0014500617981,0.13400000333786,0,722.391352539063,9.35499954223633,505.506921386719,9.35499954223633,593.156745605469,9.35499954223633,,,0.219186957369112,17.8087652334901,0.622128688533747,,25,722.391352539063,505.506921386719,593.156745605469,
,13896103.67,4369,3.00069999694824,0.13400000333786,0,722.724682617187,9.38000011444092,513.066926269531,9.38000011444092,594.654445800781,9.38000011444092,,,0.14732558783965,33.8526139363784,0.629103375999699,,25,722.724682617187,513.066926269531,594.654445800781,
,13896122.25,4369,3.00045001506805,0.13400000333786,0,723.136240234375,9.42800045013428,531.438067626953,9.42800045013428,597.005454101562,9.42800045013428,,,0.125866905297695,37.3979806882538,0.409568589004052,,25,723.136240234375,531.438067626953,597.005454101562,
,13896140.77,4369,2.9996999502182,0.13400000333786,0,723.758991699219,9.47700023651123,529.111315917969,9.47700023651123,599.730603027344,9.47700023651123,,,0.250421488651789,26.4594924664753,0.234549708616873,,25,723.758991699219,529.111315917969,599.730603027344,
,13896160.39,4369,3.00100004673004,0.13400000333786,0,744.739990234375,9.5019998550415,544.107211914063,9.5019998550415,601.301096191406,9.5019998550415,,,56.6396550490307,52.2573341706279,2.34398741973692,,25,744.739990234375,544.107211914063,601.301096191406,
,13896179.25,4369,2.99980008602142,0.13400000333786,0,724.122670898437,9.55099964141846,535.637416992187,9.55099964141846,602.616877441406,9.55099964141846,,,0.32809405716677,25.9281479680024,0.514301329800529,,25,724.122670898437,535.637416992187,602.616877441406,
,13896197.27,4369,3.00075006484985,0.13400000333786,0,724.7572265625,9.59899997711182,542.962036132813,9.59899997711182,604.918559570312,9.59899997711182,,,0.416967573544992,25.3216760940217,0.331106999277973,,25,724.7572265625,542.962036132813,604.918559570312,
,13896216.50,4369,3.0003000497818,0.13400000333786,0,725.405031738281,9.62399959564209,565.798837890625,9.62399959564209,606.258041992187,9.62399959564209,,,1.38848847335516,47.8849519294471,0.614170118284248,,25,725.405031738281,565.798837890625,606.258041992187,
,13896234.47,4369,3.0008499622345,0.13400000333786,0,725.544514160156,9.67300033569336,558.599191894531,9.67300033569336,608.321513671875,9.67300033569336,,,1.89658930948092,40.6446296641997,0.612887246641971,,25,725.544514160156,558.599191894531,608.321513671875,
,13896253.48,4369,2.99975001811981,0.13400000333786,0,761.004011230469,9.69699954986572,564.957890625,9.69699954986572,612.6100390625,9.69699954986572,,,24.7039801083471,45.5251175190598,1.35668026520469,,25,761.004011230469,564.957890625,612.6100390625,
,13896271.42,4369,2.99980008602142,0.13400000333786,0,783.497644042969,9.74600028991699,561.127758789062,9.74600028991699,617.889147949219,9.74600028991699,,,0.523876622943275,32.2694379905655,0.27007990885509,,25,783.497644042969,561.127758789062,617.889147949219,
,13896289.52,4369,2.99950003623962,0.13400000333786,0,784.190686035156,9.79500007629395,565.791293945313,9.79500007629395,620.682556152344,9.79500007629395,,,0.44010640290793,31.2009345590606,0.283248789266893,,25,784.190686035156,565.791293945313,620.682556152344,
,13896307.38,4369,2.99965000152588,0.13400000333786,0,784.494404296875,9.81900024414063,562.495219726562,9.81900024414063,621.869416503906,9.81900024414063,,,0.230733508495666,22.5008708462653,0.617705600003686,,25,784.494404296875,562.495219726562,621.869416503906,
,13896324.67,4369,3.00129997730255,0.13400000333786,0,786.035795898438,9.86800003051758,569.146918945312,9.86800003051758,624.188620605469,9.86800003051758,,,0.432538626154162,32.3935044111129,0.725991856452978,,25,786.035795898438,569.146918945312,624.188620605469,
,13896343.33,4369,2.99849998950958,0.13400000333786,0,787.156069335937,9.91699981689453,587.56330078125,9.91699981689453,627.656369628906,9.91699981689453,,,0.278355801979899,44.0687447178654,0.899010879866112,,25,787.156069335937,587.56330078125,627.656369628906,
,13896361.50,4369,3.00039994716644,0.13400000333786,0,787.923747558594,9.94099998474121,589.073291015625,9.94099998474121,629.192614746094,9.94099998474121,,,0.407087181558274,19.685653106261,0.807399157937321,,25,787.923747558594,589.073291015625,629.192614746094,
,13896379.34,4369,2.99984991550446,0.13400000333786,0,790.30984375,9.98999977111816,599.61751953125,9.98999977111816,632.827827148437,9.98999977111816,,,0.359442837450461,24.7344521592184,0.766361982006021,,25,790.30984375,599.61751953125,632.827827148437,