File: icepp/250309_3D_mh_photolitho_IV3.dat
[Header]
TITLE, IV scan (10 to 100)
FILEOPENTIME,13953955.38,3/9/2025,11:17 AM
BYAPP, Resistivity, 2.1, 1.0
INFO, APPNAME, PPMS MultiVu Application, 1.5.11
INFO, , Sample1 Name
INFO, 1, Sample1 Cross Section
INFO, 1, Sample1 Length
INFO, Ohm, Sample1 Units
INFO, , Sample2 Name
INFO, 1, Sample2 Cross Section
INFO, 1, Sample2 Length
INFO, Ohm, Sample2 Units
INFO, , Sample3 Name
INFO, 1, Sample3 Cross Section
INFO, 1, Sample3 Length
INFO, Ohm, Sample3 Units
INFO, , Sample4 Name
INFO, 1, Sample4 Cross Section
INFO, 1, Sample4 Length
INFO, Ohm, Sample4 Units
FIELDGROUP, Resistivity,2,3,4,5,6,7,8,9,10,11,12,13,14,15,16,17,18,19,20,21,22,23,24,25,26,27,28,29,30,31,32,33,34,35,36,37,38,39,40,41
STARTUPGROUP, Resistivity
STARTUPAXIS, X, 2, LINEAR, AUTO
STARTUPAXIS, Y1, 7, LINEAR, AUTO
STARTUPAXIS, Y2, 9, LINEAR, AUTO
STARTUPAXIS, Y3, 11, LINEAR, AUTO
PLOT_APPEARANCE, ALL, HORZ_GRID_ON, VERT_GRID_ON, MARKERS_AND_LINES, ALL_LINES
DATATYPE, TIME, 2
DATATYPE, COMMENT, 1
[Data]
Comment,Time Stamp (sec),Status (code),Temperature (K),Magnetic Field (Oe),Sample Position (deg),Bridge 1 Resistivity (Ohm),Bridge 1 Excitation (uA),Bridge 2 Resistivity (Ohm),Bridge 2 Excitation (uA),Bridge 3 Resistivity (Ohm),Bridge 3 Excitation (uA),Bridge 4 Resistivity (Ohm),Bridge 4 Excitation (uA),Bridge 1 Std. Dev. (Ohm),Bridge 2 Std. Dev. (Ohm),Bridge 3 Std. Dev. (Ohm),Bridge 4 Std. Dev. (Ohm),Number of Readings,Bridge 1 Resistance (Ohms),Bridge 2 Resistance (Ohms),Bridge 3 Resistance (Ohms),Bridge 4 Resistance (Ohms),Signal 1 Vin (V),Signal 2 Vin (V),Digital Inputs (code),Drive 1 Iout (mA),Drive 1 Ipower (watts),Drive 2 Iout (mA),Drive 2 Ipower (watts),Pressure (),Map 20 (),Map 21 (),Map 22 (),Map 23 (),Map 24 (),Map 25 (),Map 26 (),Map 27 (),Map 28 (),Map 29 ()
,13953979.80,4369,3.0005499124527,0.13400000333786,0,-0.00429327124962583,9.98999977111816,0.000718091616872698,9.98999977111816,488.683610839844,9.98999977111816,,,0.0056129476294458,0.00471451457691808,0.0618009929213321,,25,-0.00429327124962583,0.000718091616872698,488.683610839844,
,13953988.59,4369,2.99900007247925,0.13400000333786,0,0.00315402596490458,19.9799995422363,0.00403990245657042,19.9799995422363,472.759514160156,19.9799995422363,,,0.0021199149627282,0.00184053238564,0.0478918431517611,,25,0.00315402596490458,0.00403990245657042,472.759514160156,
,13954127.50,4369,3.00024998188019,0.13400000333786,0,0.00594187953043729,9.98999977111816,0.0062473746528849,9.98999977111816,488.560677490234,9.98999977111816,,,0.00434200846785299,0.00380932901235275,0.0673222442361753,,25,0.00594187953043729,0.0062473746528849,488.560677490234,
,13954136.41,4369,2.99980008602142,0.13400000333786,0,-0.0015885744523257,19.9799995422363,0.00106159543385729,19.9799995422363,472.781115722656,19.9799995422363,,,0.00207317868384138,0.00259338163952688,0.0590939394027852,,25,-0.0015885744523257,0.00106159543385729,472.781115722656,
,13954144.56,4369,2.9996999502182,0.13400000333786,0,0.00124145373003557,29.9950008392334,-0.000875123121077195,29.9950008392334,465.06509765625,29.9950008392334,,,0.00144951405837587,0.00159412093258812,0.0585575662588233,,25,0.00124145373003557,-0.000875123121077195,465.06509765625,
,13954153.22,4369,3.00109994411469,0.13400000333786,0,0.0407980215421412,39.9850006103516,-6.86963822226971e-005,39.9850006103516,459.260883789063,39.9850006103516,,,0.0459923525911568,0.00108266616324986,0.0401120676032482,,25,0.0407980215421412,-6.86963822226971e-005,459.260883789063,
,13954162.28,4369,2.99989998340607,0.13400000333786,0,14.524052696228,50,-0.000445607625879347,50,454.226761474609,50,,,0.00682799726974474,0.00108739855436744,0.0360186119693749,,25,14.524052696228,-0.000445607625879347,454.226761474609,
,13954171.44,4369,2.99944996833801,0.13400000333786,0,21.9864185333252,59.8440017700195,-0.00014789174485486,59.8440017700195,450.043752441406,59.8440017700195,,,0.0208480960801713,0.000667536981351175,0.0317153329598612,,25,21.9864185333252,-0.00014789174485486,450.043752441406,
,13954180.44,4369,3.00045001506805,0.13400000333786,0,25.7901608276367,69.8580017089844,-5.02409710315988e-005,69.8580017089844,446.588133544922,69.8580017089844,,,0.0110773881146337,0.000478555883863527,2.09007035790195,,25,25.7901608276367,-5.02409710315988e-005,446.588133544922,
,13954188.75,4369,3.00074994564056,0.13400000333786,0,28.2393510437012,79.8730010986328,0.000745115459139925,79.8730010986328,442.728928222656,79.8730010986328,,,0.00466722403405609,0.000501497291002185,0.0348628766539949,,25,28.2393510437012,0.000745115459139925,442.728928222656,
,13954197.77,4369,2.99889993667603,0.13400000333786,0,30.8059440612793,89.8880004882813,0.000200349086662754,89.8880004882813,439.617746582031,89.8880004882813,,,0.00818754925049482,0.000744344590493135,0.023614991183721,,25,30.8059440612793,0.000200349086662754,439.617746582031,
,13954209.09,4369,3.00069999694824,0.13400000333786,0,32.5638621520996,99.9020004272461,1.22123971232213e-005,99.9020004272461,461.397446289062,99.9020004272461,,,0.00425951984980946,0.000526779608859525,0.0392163911001766,,25,32.5638621520996,1.22123971232213e-005,461.397446289062,