File: icepp/250309_3D_mh_photolitho_coarseUp1.dat
[Header]
TITLE, 2K to 300K
FILEOPENTIME,13966736.47,3/9/2025,2:50 PM
BYAPP, Resistivity, 2.1, 1.0
INFO, APPNAME, PPMS MultiVu Application, 1.5.11
INFO, , Sample1 Name
INFO, 1, Sample1 Cross Section
INFO, 1, Sample1 Length
INFO, Ohm, Sample1 Units
INFO, , Sample2 Name
INFO, 1, Sample2 Cross Section
INFO, 1, Sample2 Length
INFO, Ohm, Sample2 Units
INFO, , Sample3 Name
INFO, 1, Sample3 Cross Section
INFO, 1, Sample3 Length
INFO, Ohm, Sample3 Units
INFO, , Sample4 Name
INFO, 1, Sample4 Cross Section
INFO, 1, Sample4 Length
INFO, Ohm, Sample4 Units
FIELDGROUP, Resistivity,2,3,4,5,6,7,8,9,10,11,12,13,14,15,16,17,18,19,20,21,22,23,24,25,26,27,28,29,30,31,32,33,34,35,36,37,38,39,40,41
STARTUPGROUP, Resistivity
STARTUPAXIS, X, 2, LINEAR, AUTO
STARTUPAXIS, Y1, 7, LINEAR, AUTO
STARTUPAXIS, Y2, 9, LINEAR, AUTO
STARTUPAXIS, Y3, 11, LINEAR, AUTO
PLOT_APPEARANCE, ALL, HORZ_GRID_ON, VERT_GRID_ON, MARKERS_AND_LINES, ALL_LINES
DATATYPE, TIME, 2
DATATYPE, COMMENT, 1
[Data]
Comment,Time Stamp (sec),Status (code),Temperature (K),Magnetic Field (Oe),Sample Position (deg),Bridge 1 Resistivity (Ohm),Bridge 1 Excitation (uA),Bridge 2 Resistivity (Ohm),Bridge 2 Excitation (uA),Bridge 3 Resistivity (Ohm),Bridge 3 Excitation (uA),Bridge 4 Resistivity (Ohm),Bridge 4 Excitation (uA),Bridge 1 Std. Dev. (Ohm),Bridge 2 Std. Dev. (Ohm),Bridge 3 Std. Dev. (Ohm),Bridge 4 Std. Dev. (Ohm),Number of Readings,Bridge 1 Resistance (Ohms),Bridge 2 Resistance (Ohms),Bridge 3 Resistance (Ohms),Bridge 4 Resistance (Ohms),Signal 1 Vin (V),Signal 2 Vin (V),Digital Inputs (code),Drive 1 Iout (mA),Drive 1 Ipower (watts),Drive 2 Iout (mA),Drive 2 Ipower (watts),Pressure (),Map 20 (),Map 21 (),Map 22 (),Map 23 (),Map 24 (),Map 25 (),Map 26 (),Map 27 (),Map 28 (),Map 29 ()
,13967132.66,4370,2.11525011062622,0.13400000333786,0,1.1547254127264,0.00999999977648258,0.65098621070385,0.00999999977648258,734.761904296875,0.00999999977648258,,,5.85471206760748,6.43396931043211,17.4066217040024,,25,1.1547254127264,0.65098621070385,734.761904296875,
,13967154.97,4374,3.7545999288559,0.13400000333786,0,0.170496387481689,0.00999999977648258,0.441740573048592,0.00999999977648258,589.692722167969,0.00999999977648258,,,3.30815417512069,3.06217573748719,22.2396508752851,,25,0.170496387481689,0.441740573048592,589.692722167969,
,13967171.36,4370,6.21699976921082,0.13400000333786,0,1628.99497070313,0.00999999977648258,1413.26523193359,0.00999999977648258,1804.85059326172,0.00999999977648258,,,394.166697786029,396.908359494422,408.054820387308,,25,1628.99497070313,1413.26523193359,1804.85059326172,
,13967183.81,4370,8.13470005989075,0.13400000333786,0,1983.78301757813,0.00999999977648258,1759.91801269531,0.00999999977648258,2148.6307421875,0.00999999977648258,,,10.5276913212397,17.6990680028971,14.1884558959969,,25,1983.78301757813,1759.91801269531,2148.6307421875,
,13967195.20,4374,9.99524974822998,0.13400000333786,0,1982.27392578125,0.00999999977648258,1762.76596191406,0.00999999977648258,2143.40694335938,0.00999999977648258,,,8.61819991479824,9.97084041738187,13.9845744440106,,25,1982.27392578125,1762.76596191406,2143.40694335938,
,13967206.83,4370,12.0896000862122,0.13400000333786,0,1980.24629882813,0.00999999977648258,1762.99040039062,0.00999999977648258,2142.36220703125,0.00999999977648258,,,3.11006361842704,4.54710135012225,12.591991241741,,25,1980.24629882813,1762.99040039062,2142.36220703125,
,13967219.02,4370,14.1902499198914,0.13400000333786,0,1978.37349609375,0.00999999977648258,1763.005859375,0.00999999977648258,2136.441875,0.00999999977648258,,,3.87223275999582,4.70548088037174,13.4158560782187,,25,1978.37349609375,1763.005859375,2136.441875,
,13967231.77,4370,16.0359997749329,0.13400000333786,0,1978.54373046875,0.00999999977648258,1762.3856640625,0.00999999977648258,2134.54938476562,0.00999999977648258,,,4.00859449305878,4.15734089812213,12.434454661369,,25,1978.54373046875,1762.3856640625,2134.54938476562,
,13967244.44,4374,18.2712001800537,0.13400000333786,0,1974.82314453125,0.00999999977648258,1762.06040527344,0.00999999977648258,2136.170859375,0.00999999977648258,,,4.01355699916598,5.49811214934234,11.2452126955274,,25,1974.82314453125,1762.06040527344,2136.170859375,
,13967255.80,4370,20.0848503112793,0.13400000333786,0,1975.92299804687,0.00999999977648258,1760.581015625,0.00999999977648258,2130.34619140625,0.00999999977648258,,,5.29893475947067,6.25448551025442,11.6422285813174,,25,1975.92299804687,1760.581015625,2130.34619140625,
,13967267.56,4370,22.1054000854492,0.13400000333786,0,1979.18387695313,0.00999999977648258,1761.73509765625,0.00999999977648258,2129.68005859375,0.00999999977648258,,,5.66059065711463,6.86726451460082,10.8969362873404,,25,1979.18387695313,1761.73509765625,2129.68005859375,
,13967279.14,4370,24.0313997268677,0.13400000333786,0,1974.43586425781,0.00999999977648258,1762.78074707031,0.00999999977648258,2130.78767578125,0.00999999977648258,,,3.43919613679344,6.09689778004002,12.6427377876435,,25,1974.43586425781,1762.78074707031,2130.78767578125,
,13967291.88,4370,26.0188007354736,0.13400000333786,0,1974.00985351563,0.00999999977648258,1763.36845214844,0.00999999977648258,2126.38046875,0.00999999977648258,,,5.5989415615361,5.58233760187622,11.9709980730401,,25,1974.00985351563,1763.36845214844,2126.38046875,
,13967304.23,4370,28.1942501068115,0.13400000333786,0,1973.57029296875,0.00999999977648258,1765.90639648437,0.00999999977648258,2125.77190429688,0.00999999977648258,,,4.75356289109256,4.31446198684435,13.4882937929312,,25,1973.57029296875,1765.90639648437,2125.77190429688,
,13967321.98,4370,31.1768503189087,0.13400000333786,0,1973.77170410156,0.00999999977648258,1763.17164550781,0.00999999977648258,2126.84876953125,0.00999999977648258,,,3.4273555957281,6.08095911918669,8.71356051045463,,25,1973.77170410156,1763.17164550781,2126.84876953125,
,13967333.11,4370,32.9886989593506,0.13400000333786,0,1975.40637207031,0.00999999977648258,1762.83852050781,0.00999999977648258,2123.85834960938,0.00999999977648258,,,4.9921869331029,5.50075617280512,16.9084888817249,,25,1975.40637207031,1762.83852050781,2123.85834960938,
,13967345.84,4370,35.1755504608154,0.13400000333786,0,1975.17397460937,0.00999999977648258,1763.7604296875,0.00999999977648258,2127.4840625,0.00999999977648258,,,5.1395864481144,5.71040610088788,19.5894316697921,,25,1975.17397460937,1763.7604296875,2127.4840625,
,13967356.98,4370,37.0607490539551,0.13400000333786,0,1976.83078125,0.00999999977648258,1766.19547363281,0.00999999977648258,2121.47474609375,0.00999999977648258,,,4.99791724106592,6.17192013835698,15.5037657760983,,25,1976.83078125,1766.19547363281,2121.47474609375,
,13967369.73,4370,39.1401500701904,0.13400000333786,0,1979.78594726563,0.00999999977648258,1767.72115234375,0.00999999977648258,2128.48712890625,0.00999999977648258,,,5.73610611026651,4.87150754868782,12.5046240784654,,25,1979.78594726563,1767.72115234375,2128.48712890625,
,13967381.44,4370,41.0896492004395,0.13400000333786,0,1977.81650390625,0.00999999977648258,1768.70588378906,0.00999999977648258,2132.48034179688,0.00999999977648258,,,6.0641989930359,8.12015089712182,14.2331286931528,,25,1977.81650390625,1768.70588378906,2132.48034179688,
,13967393.73,4370,43.1961498260498,0.13400000333786,0,1981.07307128906,0.00999999977648258,1772.22607421875,0.00999999977648258,2128.47168945312,0.00999999977648258,,,5.42331474098674,5.84240066778381,10.7702394877135,,25,1981.07307128906,1772.22607421875,2128.47168945312,
,13967411.36,4370,46.1431999206543,0.13400000333786,0,1982.91845703125,0.00999999977648258,1774.28856445313,0.00999999977648258,2130.45661132812,0.00999999977648258,,,8.30970730619875,8.9472443923717,12.8098195219987,,25,1982.91845703125,1774.28856445313,2130.45661132812,
,13967423.16,4370,48.1107501983643,0.13400000333786,0,1985.86961425781,0.00999999977648258,1773.40730957031,0.00999999977648258,2126.94026367188,0.00999999977648258,,,8.95913579246601,9.22754011175364,15.8398003082232,,25,1985.86961425781,1773.40730957031,2126.94026367188,
,13967434.59,4370,50.0018997192383,0.13400000333786,0,1985.62163574219,0.00999999977648258,1774.16672851563,0.00999999977648258,2134.16239257813,0.00999999977648258,,,6.8260906357904,6.61613976647924,10.4349349312543,,25,1985.62163574219,1774.16672851563,2134.16239257813,
,13967447.75,4370,52.1482486724854,0.13400000333786,0,1987.27992675781,0.00999999977648258,1776.0109765625,0.00999999977648258,2129.35028320312,0.00999999977648258,,,3.983874681618,2.6975554570183,8.57435038732743,,25,1987.27992675781,1776.0109765625,2129.35028320312,
,13967459.22,4370,54.0604496002197,0.13400000333786,0,1987.52017089844,0.00999999977648258,1776.23567871094,0.00999999977648258,2136.339921875,0.00999999977648258,,,4.10006896233021,3.83423932416158,9.32768841760943,,25,1987.52017089844,1776.23567871094,2136.339921875,
,13967471.20,4370,56.0618495941162,0.13400000333786,0,1988.86073730469,0.00999999977648258,1779.397265625,0.00999999977648258,2129.28053710938,0.00999999977648258,,,4.02426381097951,3.76790676313866,10.3168920781641,,25,1988.86073730469,1779.397265625,2129.28053710938,
,13967484.13,4370,58.1879005432129,0.13400000333786,0,1990.87806152344,0.00999999977648258,1780.40107910156,0.00999999977648258,2137.6955078125,0.00999999977648258,,,4.51120343666264,4.50179489585865,8.72467478849732,,25,1990.87806152344,1780.40107910156,2137.6955078125,
,13967495.45,4370,60.1177501678467,0.13400000333786,0,1991.34267578125,0.00999999977648258,1783.55270507813,0.00999999977648258,2139.68565429687,0.00999999977648258,,,3.22223029543894,4.69691349140156,5.32826178198957,,25,1991.34267578125,1783.55270507813,2139.68565429687,
,13967506.91,4370,62.0349502563477,0.13400000333786,0,1993.2862890625,0.00999999977648258,1784.45095214844,0.00999999977648258,2139.46877929687,0.00999999977648258,,,2.56421951190814,3.48814005128116,8.69749674285449,,25,1993.2862890625,1784.45095214844,2139.46877929687,
,13967519.83,4370,64.2023983001709,0.13400000333786,0,1993.99095214844,0.00999999977648258,1787.12245605469,0.00999999977648258,2144.52532226563,0.00999999977648258,,,3.10932495670567,3.18382824505138,7.52369197627258,,25,1993.99095214844,1787.12245605469,2144.52532226563,
,13967531.16,4370,66.113151550293,0.13400000333786,0,1997.67687011719,0.00999999977648258,1788.76407714844,0.00999999977648258,2139.34490234375,0.00999999977648258,,,3.62872762017132,2.70495586850603,7.56595345839935,,25,1997.67687011719,1788.76407714844,2139.34490234375,
,13967543.06,4370,68.0780982971191,0.13400000333786,0,1997.60959472656,0.00999999977648258,1791.19666503906,0.00999999977648258,2129.22765625,0.00999999977648258,,,4.59846326353832,5.44556913748536,5.62632240440202,,25,1997.60959472656,1791.19666503906,2129.22765625,
,13967554.75,4370,70.0137023925781,0.13400000333786,0,1999.11034179688,0.00999999977648258,1792.62006347656,0.00999999977648258,2140.1640234375,0.00999999977648258,,,5.38535294950572,3.5273962004433,8.49086427112557,,25,1999.11034179688,1792.62006347656,2140.1640234375,
,13967567.58,4370,72.1358985900879,0.13400000333786,0,2001.21444335938,0.00999999977648258,1792.92173828125,0.00999999977648258,2142.71685546875,0.00999999977648258,,,5.66224526546231,5.86226755326174,4.41344752110336,,25,2001.21444335938,1792.92173828125,2142.71685546875,
,13967578.69,4370,73.9634017944336,0.13400000333786,0,2003.09422851563,0.00999999977648258,1796.24810058594,0.00999999977648258,2149.70220703125,0.00999999977648258,,,3.97619758537777,5.34619514856461,8.75791724605603,,25,2003.09422851563,1796.24810058594,2149.70220703125,
,13967591.20,4370,76.1399002075195,0.13400000333786,0,2006.55209960938,0.00999999977648258,1797.89583007813,0.00999999977648258,2134.41634765625,0.00999999977648258,,,6.33979938294563,5.48174573856422,4.89247098070643,,25,2006.55209960938,1797.89583007813,2134.41634765625,
,13967603.84,4370,78.1694488525391,0.13400000333786,0,2010.83150878906,0.00999999977648258,1802.35643554688,0.00999999977648258,2147.51724609375,0.00999999977648258,,,5.93056326641047,7.99638466554483,18.3053972169867,,25,2010.83150878906,1802.35643554688,2147.51724609375,
,13967615.48,4370,80.1536483764648,0.13400000333786,0,2015.757421875,0.00999999977648258,1802.34095214844,0.00999999977648258,2160.2889453125,0.00999999977648258,,,13.7155497008388,14.2734256528787,14.1000127127971,,25,2015.757421875,1802.34095214844,2160.2889453125,
,13967627.70,4370,82.1777000427246,0.13400000333786,0,2011.50534667969,0.00999999977648258,1802.87536132813,0.00999999977648258,2156.47833984375,0.00999999977648258,,,16.1512151327731,11.3173101846065,15.404279801808,,25,2011.50534667969,1802.87536132813,2156.47833984375,
,13967646.63,4370,85.3032989501953,0.13400000333786,0,2017.70140625,0.00999999977648258,1814.66342773438,0.00999999977648258,2161.04791992187,0.00999999977648258,,,19.5576899726746,21.1120140559095,20.7843926870556,,25,2017.70140625,1814.66342773438,2161.04791992187,
,13967664.05,4370,88.2436981201172,0.13400000333786,0,2022.72213378906,0.00999999977648258,1817.989296875,0.00999999977648258,2168.14150390625,0.00999999977648258,,,18.6176930452883,15.3658402875976,13.9160465251513,,25,2022.72213378906,1817.989296875,2168.14150390625,
,13967681.81,4370,91.1701507568359,0.13400000333786,0,2030.04041503906,0.00999999977648258,1816.22953125,0.00999999977648258,2169.99430664062,0.00999999977648258,,,34.8394107336723,34.2902775922579,28.1604821500071,,25,2030.04041503906,1816.22953125,2169.99430664062,
,13967694.39,4370,93.2594985961914,0.13400000333786,0,2024.2494140625,0.00999999977648258,1824.38504394531,0.00999999977648258,2171.885859375,0.00999999977648258,,,24.4394361006919,22.9323392526594,23.8722403659916,,25,2024.2494140625,1824.38504394531,2171.885859375,
,13967712.16,4370,96.211498260498,0.13400000333786,0,2036.23460449219,0.00999999977648258,1825.20680664063,0.00999999977648258,2174.35111328125,0.00999999977648258,,,22.3983027014969,22.63323327836,17.7213176735357,,25,2036.23460449219,1825.20680664063,2174.35111328125,
,13967729.08,4370,99.0831489562988,0.13400000333786,0,2023.99120117188,0.00999999977648258,1835.2403125,0.00999999977648258,2173.826796875,0.00999999977648258,,,42.6721670598175,36.2491431211875,25.9680115951125,,25,2023.99120117188,1835.2403125,2173.826796875,
,13967741.09,4370,101.067050933838,0.13400000333786,0,2030.9309765625,0.00999999977648258,1832.32358398438,0.00999999977648258,2166.52340820313,0.00999999977648258,,,31.7748688084692,34.7007941397682,31.9286036798053,,25,2030.9309765625,1832.32358398438,2166.52340820313,
,13967752.31,4370,102.963802337646,0.13400000333786,0,2041.16653808594,0.00999999977648258,1831.67372070312,0.00999999977648258,2188.44905273438,0.00999999977648258,,,28.0059997904296,22.4392603981228,20.3651125822306,,25,2041.16653808594,1831.67372070312,2188.44905273438,
,13967764.94,4370,105.023349761963,0.13400000333786,0,2043.80478027344,0.00999999977648258,1829.96391113281,0.00999999977648258,2169.88887695313,0.00999999977648258,,,32.9542025474189,19.8978464541972,22.8607523941798,,25,2043.80478027344,1829.96391113281,2169.88887695313,
,13967777.83,4370,107.196750640869,0.13400000333786,0,2041.65458984375,0.00999999977648258,1831.25170410156,0.00999999977648258,2171.25881835937,0.00999999977648258,,,32.2373081737152,26.5420569123327,22.0248796819697,,25,2041.65458984375,1831.25170410156,2171.25881835937,
,13967789.58,4370,109.15650177002,0.13400000333786,0,2043.68428710938,0.00999999977648258,1839.23479003906,0.00999999977648258,2171.48255859375,0.00999999977648258,,,22.8957736241207,28.9615595818591,23.9712172395955,,25,2043.68428710938,1839.23479003906,2171.48255859375,
,13967801.44,4370,111.102996826172,0.13400000333786,0,2042.2867578125,0.00999999977648258,1836.88748046875,0.00999999977648258,2179.520625,0.00999999977648258,,,4.18111529339991,7.25588143298492,7.48639271917524,,25,2042.2867578125,1836.88748046875,2179.520625,
,13967813.86,4370,113.185253143311,0.13400000333786,0,2051.93856445312,0.00999999977648258,1839.1807421875,0.00999999977648258,2172.200703125,0.00999999977648258,,,20.6244245373485,13.0653288429483,16.7754968310776,,25,2051.93856445312,1839.1807421875,2172.200703125,
,13967825.08,4370,115.104999542236,0.13400000333786,0,2049.97732910156,0.00999999977648258,1838.62479003906,0.00999999977648258,2183.45088867188,0.00999999977648258,,,22.4817807942571,20.8103005415136,18.948840292875,,25,2049.97732910156,1838.62479003906,2183.45088867188,
,13967837.09,4370,117.096649169922,0.13400000333786,0,2051.62127929687,0.00999999977648258,1846.32971679687,0.00999999977648258,2192.29817382813,0.00999999977648258,,,22.5424596801194,24.118958717821,21.532051614931,,25,2051.62127929687,1846.32971679687,2192.29817382813,
,13967848.84,4370,119.026500701904,0.13400000333786,0,2048.41585449219,0.00999999977648258,1847.36725097656,0.00999999977648258,2201.13745117188,0.00999999977648258,,,27.2477294873517,21.8167189941513,21.5026129519915,,25,2048.41585449219,1847.36725097656,2201.13745117188,
,13967861.59,4370,121.197551727295,0.13400000333786,0,2054.10143554688,0.00999999977648258,1852.93694335937,0.00999999977648258,2194.9883984375,0.00999999977648258,,,21.0264541160785,29.6644924177937,18.6444310467177,,25,2054.10143554688,1852.93694335937,2194.9883984375,
,13967873.08,4370,123.074150085449,0.13400000333786,0,2057.51586425781,0.00999999977648258,1855.36251953125,0.00999999977648258,2186.30560546875,0.00999999977648258,,,30.0151191822984,28.5125521141871,33.8418078695939,,25,2057.51586425781,1855.36251953125,2186.30560546875,
,13967885.48,4370,125.17329788208,0.13400000333786,0,2061.06157714844,0.00999999977648258,1850.58852539062,0.00999999977648258,2188.17504882813,0.00999999977648258,,,32.5247219384956,31.8800994286165,30.1613612088527,,25,2061.06157714844,1850.58852539062,2188.17504882813,
,13967897.53,4370,127.191501617432,0.13400000333786,0,2056.59432617187,0.00999999977648258,1858.01205566406,0.00999999977648258,2206.91350585938,0.00999999977648258,,,25.5642895173268,30.6638912428717,23.1559225819913,,25,2056.59432617187,1858.01205566406,2206.91350585938,
,13967915.56,4370,130.150703430176,0.13400000333786,0,2063.3870703125,0.00999999977648258,1861.42705566406,0.00999999977648258,2213.21665039063,0.00999999977648258,,,22.4646716534127,42.1565736863041,40.2404301468431,,25,2063.3870703125,1861.42705566406,2213.21665039063,
,13967926.92,4370,132.1103515625,0.13400000333786,0,2077.99044433594,0.00999999977648258,1866.41622070313,0.00999999977648258,2207.0266796875,0.00999999977648258,,,45.4951439811201,29.9133486926354,34.5110956893937,,25,2077.99044433594,1866.41622070313,2207.0266796875,
,13967938.83,4370,134.053497314453,0.13400000333786,0,2075.53456542969,0.00999999977648258,1869.84819335938,0.00999999977648258,2211.79114257812,0.00999999977648258,,,38.9664875053681,29.3669008832133,30.6432778742483,,25,2075.53456542969,1869.84819335938,2211.79114257812,
,13967950.81,4370,136.067001342773,0.13400000333786,0,2069.94113769531,0.00999999977648258,1870.12706542969,0.00999999977648258,2206.06602539062,0.00999999977648258,,,33.3511098940503,37.0515576556945,37.3698947862594,,25,2069.94113769531,1870.12706542969,2206.06602539062,
,13967962.38,4370,138.045547485352,0.13400000333786,0,2081.79647949219,0.00999999977648258,1858.15482421875,0.00999999977648258,2208.31380859375,0.00999999977648258,,,25.5583404312818,24.1560452921078,25.0963806873158,,25,2081.79647949219,1858.15482421875,2208.31380859375,
,13967975.42,4370,140.125045776367,0.13400000333786,0,2070.29563476563,0.00999999977648258,1865.96896972656,0.00999999977648258,2206.07567382813,0.00999999977648258,,,23.0843222095969,22.2847262472559,23.5908614748983,,25,2070.29563476563,1865.96896972656,2206.07567382813,
,13967986.84,4370,142.089553833008,0.13400000333786,0,2080.85250976563,0.00999999977648258,1866.61769042969,0.00999999977648258,2215.559140625,0.00999999977648258,,,26.1728246325823,37.3017039089583,34.1232220923774,,25,2080.85250976563,1866.61769042969,2215.559140625,
,13967998.97,4370,144.091949462891,0.13400000333786,0,2078.41983886719,0.00999999977648258,1871.34396484375,0.00999999977648258,2219.53635742188,0.00999999977648258,,,32.589167255837,26.0940443363193,24.1816861366395,,25,2078.41983886719,1871.34396484375,2219.53635742188,
,13968011.44,4370,146.159446716309,0.13400000333786,0,2077.77118164062,0.00999999977648258,1874.27086914063,0.00999999977648258,2210.77112304687,0.00999999977648258,,,13.8264903354047,21.1028696821993,21.1796537642719,,25,2077.77118164062,1874.27086914063,2210.77112304687,
,13968023.59,4370,148.177047729492,0.13400000333786,0,2088.80521484375,0.00999999977648258,1877.91412109375,0.00999999977648258,2218.79642578125,0.00999999977648258,,,22.7568731228081,19.9676777664609,39.3339333712674,,25,2088.80521484375,1877.91412109375,2218.79642578125,
,13968034.86,4370,150.043701171875,0.13400000333786,0,2094.12815429688,0.00999999977648258,1878.13295898437,0.00999999977648258,2237.26024414063,0.00999999977648258,,,34.6007063896861,33.4671071806086,32.918579159518,,25,2094.12815429688,1878.13295898437,2237.26024414063,
,13968047.16,4370,152.091995239258,0.13400000333786,0,2087.59227539063,0.00999999977648258,1879.6972265625,0.00999999977648258,2230.48424804688,0.00999999977648258,,,41.9523864095133,37.8833942186435,45.5890699498062,,25,2087.59227539063,1879.6972265625,2230.48424804688,
,13968059.23,4370,154.120803833008,0.13400000333786,0,2104.92325195313,0.00999999977648258,1883.87127441406,0.00999999977648258,2219.70463867187,0.00999999977648258,,,25.8813771443181,40.3449827006189,34.9893018904639,,25,2104.92325195313,1883.87127441406,2219.70463867187,
,13968071.64,4370,156.157348632813,0.13400000333786,0,2097.24900390625,0.00999999977648258,1885.17997558594,0.00999999977648258,2230.99530273437,0.00999999977648258,,,28.7824667133422,43.9578264244541,33.571988752242,,25,2097.24900390625,1885.17997558594,2230.99530273437,
,13968083.36,4370,158.148345947266,0.13400000333786,0,2096.67485351562,0.00999999977648258,1893.31806152344,0.00999999977648258,2228.02608398438,0.00999999977648258,,,18.0969742548531,14.341531333484,24.0802603426085,,25,2096.67485351562,1893.31806152344,2228.02608398438,
,13968095.08,4370,160.097602844238,0.13400000333786,0,2100.09472167969,0.00999999977648258,1888.7708984375,0.00999999977648258,2230.75715820313,0.00999999977648258,,,27.3466339160497,28.8125873357754,28.8665915602545,,25,2100.09472167969,1888.7708984375,2230.75715820313,
,13968107.44,4370,162.147048950195,0.13400000333786,0,2107.35025390625,0.00999999977648258,1892.75799316406,0.00999999977648258,2244.19422851563,0.00999999977648258,,,28.0225450719045,27.7645522261074,29.7927219965647,,25,2107.35025390625,1892.75799316406,2244.19422851563,
,13968118.91,4370,164.058952331543,0.13400000333786,0,2098.59568359375,0.00999999977648258,1895.47013671875,0.00999999977648258,2230.7803125,0.00999999977648258,,,35.4988264475492,27.7351864724588,36.5670992512227,,25,2098.59568359375,1895.47013671875,2230.7803125,
,13968131.81,4370,166.196998596191,0.13400000333786,0,2089.05289550781,0.00999999977648258,1896.82234375,0.00999999977648258,2242.52525390625,0.00999999977648258,,,37.1081234446714,28.4268006919619,20.1794312990344,,25,2089.05289550781,1896.82234375,2242.52525390625,
,13968142.95,4370,168.057006835938,0.13400000333786,0,2109.29080566406,0.00999999977648258,1905.27913574219,0.00999999977648258,2246.949296875,0.00999999977648258,,,30.4868104415425,19.429077942496,22.8196059793942,,25,2109.29080566406,1905.27913574219,2246.949296875,
,13968155.30,4370,170.086799621582,0.13400000333786,0,2119.68686523438,0.00999999977648258,1908.49604492188,0.00999999977648258,2242.45064453125,0.00999999977648258,,,40.5071483962612,24.4735737405036,31.2363908021001,,25,2119.68686523438,1908.49604492188,2242.45064453125,
,13968167.30,4370,172.12525177002,0.13400000333786,0,2105.76171875,0.00999999977648258,1907.5671875,0.00999999977648258,2248.31791015625,0.00999999977648258,,,19.9367692602896,23.7894770666876,32.8186315382642,,25,2105.76171875,1907.5671875,2248.31791015625,
,13968178.75,4370,174.035400390625,0.13400000333786,0,2115.73917480469,0.00999999977648258,1916.31393066406,0.00999999977648258,2236.73813476563,0.00999999977648258,,,30.9614523527597,30.1960073567928,25.8746933907929,,25,2115.73917480469,1916.31393066406,2236.73813476563,
,13968191.41,4370,176.134101867676,0.13400000333786,0,2123.42547851562,0.00999999977648258,1907.07955566406,0.00999999977648258,2243.75874023438,0.00999999977648258,,,36.3264620197404,27.3059793472642,24.9672488646943,,25,2123.42547851562,1907.07955566406,2243.75874023438,
,13968203.03,4370,178.063102722168,0.13400000333786,0,2124.485078125,0.00999999977648258,1914.98362792969,0.00999999977648258,2258.49720703125,0.00999999977648258,,,32.0794641991083,25.6177668627839,31.2534075490589,,25,2124.485078125,1914.98362792969,2258.49720703125,
,13968215.14,4370,180.082901000977,0.13400000333786,0,2134.43538085938,0.00999999977648258,1922.29969726562,0.00999999977648258,2265.52969726563,0.00999999977648258,,,28.3253403513279,24.0802932680799,26.034067161486,,25,2134.43538085938,1922.29969726562,2265.52969726563,
,13968227.66,4370,182.225296020508,0.13400000333786,0,2141.32694335938,0.00999999977648258,1928.19234863281,0.00999999977648258,2252.29637695313,0.00999999977648258,,,30.6204473314051,15.2177796008401,32.7103012054735,,25,2141.32694335938,1928.19234863281,2252.29637695313,
,13968245.16,4370,185.11319732666,0.13400000333786,0,2130.7496484375,0.00999999977648258,1928.13816894531,0.00999999977648258,2256.31517578125,0.00999999977648258,,,39.0471811112854,30.2642518248833,30.855182416696,,25,2130.7496484375,1928.13816894531,2256.31517578125,
,13968257.13,4370,187.114845275879,0.13400000333786,0,2146.47629882813,0.00999999977648258,1945.29734863281,0.00999999977648258,2268.54955078125,0.00999999977648258,,,42.011877425334,37.8013323457733,45.3048549876322,,25,2146.47629882813,1945.29734863281,2268.54955078125,
,13968269.41,4370,189.126045227051,0.13400000333786,0,2139.90086914063,0.00999999977648258,1937.69446289062,0.00999999977648258,2269.31946289062,0.00999999977648258,,,31.0108549666032,57.0434192954856,42.884847953255,,25,2139.90086914063,1937.69446289062,2269.31946289062,
,13968281.11,4370,191.12629699707,0.13400000333786,0,2137.3538671875,0.00999999977648258,1927.84692871094,0.00999999977648258,2274.3902734375,0.00999999977648258,,,22.4883123546163,13.2264184747664,20.7994130851873,,25,2137.3538671875,1927.84692871094,2274.3902734375,
,13968293.42,4370,193.139549255371,0.13400000333786,0,2143.68659179687,0.00999999977648258,1939.08022949219,0.00999999977648258,2262.33643554687,0.00999999977648258,,,30.7763030000677,33.6364048572967,26.601773144904,,25,2143.68659179687,1939.08022949219,2262.33643554687,
,13968304.81,4370,195.063949584961,0.13400000333786,0,2147.02329589844,0.00999999977648258,1937.67897460938,0.00999999977648258,2267.9414453125,0.00999999977648258,,,36.8940441437438,36.7331919894007,28.6203125628659,,25,2147.02329589844,1937.67897460938,2267.9414453125,
,13968317.70,4370,197.153053283691,0.13400000333786,0,2141.24793945313,0.00999999977648258,1933.46747070312,0.00999999977648258,2282.69716796875,0.00999999977648258,,,41.6793144528351,18.6178840758343,25.3655145316405,,25,2141.24793945313,1933.46747070312,2282.69716796875,
,13968329.17,4370,199.122955322266,0.13400000333786,0,2160.34475585937,0.00999999977648258,1934.71660644531,0.00999999977648258,2280.27693359375,0.00999999977648258,,,46.0266643617651,49.8045959716264,51.4008955420475,,25,2160.34475585937,1934.71660644531,2280.27693359375,
,13968341.05,4370,201.047248840332,0.13400000333786,0,2152.7851171875,0.00999999977648258,1943.74796386719,0.00999999977648258,2284.58345703125,0.00999999977648258,,,30.4322973091678,33.1333126256097,25.398631913363,,25,2152.7851171875,1943.74796386719,2284.58345703125,
,13968353.31,4370,203.125350952148,0.13400000333786,0,2154.40391601562,0.00999999977648258,1936.36643554688,0.00999999977648258,2277.99202148438,0.00999999977648258,,,28.8629473525771,38.467382552215,41.8207846046483,,25,2154.40391601562,1936.36643554688,2277.99202148438,
,13968364.64,4370,204.968849182129,0.13400000333786,0,2165.05403320313,0.00999999977648258,1948.403046875,0.00999999977648258,2291.69392578125,0.00999999977648258,,,27.8258041238016,31.5821986933276,50.5481119186028,,25,2165.05403320313,1948.403046875,2291.69392578125,
,13968376.86,4370,207.058097839355,0.13400000333786,0,2161.83189453125,0.00999999977648258,1944.80136230469,0.00999999977648258,2305.86828125,0.00999999977648258,,,22.8250997996732,31.0497616171969,31.7190529021354,,25,2161.83189453125,1944.80136230469,2305.86828125,
,13968389.73,4370,209.163146972656,0.13400000333786,0,2167.54360351562,0.00999999977648258,1948.49874023438,0.00999999977648258,2269.46975585937,0.00999999977648258,,,20.5571281026456,24.9589244621526,22.8081318212075,,25,2167.54360351562,1948.49874023438,2269.46975585937,
,13968400.75,4370,211.042152404785,0.13400000333786,0,2161.70502929688,0.00999999977648258,1942.83057617188,0.00999999977648258,2288.90561523438,0.00999999977648258,,,35.8346726216482,29.0907185720736,27.8172372236488,,25,2161.70502929688,1942.83057617188,2288.90561523438,
,13968412.69,4370,213.055145263672,0.13400000333786,0,2172.33677734375,0.00999999977648258,1954.56178710938,0.00999999977648258,2290.84919921875,0.00999999977648258,,,59.1709806319834,37.6014883341014,62.0231805106594,,25,2172.33677734375,1954.56178710938,2290.84919921875,
,13968425.72,4370,215.170097351074,0.13400000333786,0,2175.69737304687,0.00999999977648258,1952.71887695312,0.00999999977648258,2302.8049609375,0.00999999977648258,,,59.5290050730592,33.4585228038713,53.2816245611231,,25,2175.69737304687,1952.71887695312,2302.8049609375,
,13968437.31,4370,217.108505249023,0.13400000333786,0,2181.21063476562,0.00999999977648258,1962.07287109375,0.00999999977648258,2296.08370117188,0.00999999977648258,,,34.59727769527,20.7004069459751,22.3718332560916,,25,2181.21063476562,1962.07287109375,2296.08370117188,
,13968449.39,4370,219.158599853516,0.13400000333786,0,2174.60329101563,0.00999999977648258,1961.25507324219,0.00999999977648258,2286.39626953125,0.00999999977648258,,,41.4101761285969,22.3298819135926,17.6534224943952,,25,2174.60329101563,1961.25507324219,2286.39626953125,
,13968461.56,4370,221.115104675293,0.13400000333786,0,2168.55987304688,0.00999999977648258,1971.47716308594,0.00999999977648258,2296.03798828125,0.00999999977648258,,,30.2718001220656,32.3753807940798,34.1462721596857,,25,2168.55987304688,1971.47716308594,2296.03798828125,
,13968473.27,4370,223.092903137207,0.13400000333786,0,2174.487265625,0.00999999977648258,1967.90986328125,0.00999999977648258,2296.44033203125,0.00999999977648258,,,17.7452165516515,20.0618584131668,26.4878310390455,,25,2174.487265625,1967.90986328125,2296.44033203125,
,13968485.59,4370,225.161804199219,0.13400000333786,0,2181.32000976562,0.00999999977648258,1972.1271484375,0.00999999977648258,2303.6523046875,0.00999999977648258,,,33.3079612139395,23.9059403328439,26.5534977536603,,25,2181.32000976562,1972.1271484375,2303.6523046875,
,13968496.98,4370,227.088348388672,0.13400000333786,0,2182.29505859375,0.00999999977648258,1971.04378417969,0.00999999977648258,2301.4159375,0.00999999977648258,,,21.2386868974253,28.8119648015703,30.9851446705236,,25,2182.29505859375,1971.04378417969,2301.4159375,
,13968510.14,4370,229.261352539063,0.13400000333786,0,2184.82750976563,0.00999999977648258,1975.75428710937,0.00999999977648258,2291.86412109375,0.00999999977648258,,,18.9561073012278,21.5271643735032,22.7800356704975,,25,2184.82750976563,1975.75428710937,2291.86412109375,
,13968525.84,4370,231.936950683594,0.13400000333786,0,2186.46063476562,0.00999999977648258,1971.89979003906,0.00999999977648258,2300.26202148438,0.00999999977648258,,,26.9627654563889,22.6297983207713,20.4015015519443,,25,2186.46063476562,1971.89979003906,2300.26202148438,
,13968538.47,4370,233.921249389648,0.13400000333786,0,2189.71918945313,0.00999999977648258,1978.62583496094,0.00999999977648258,2313.52065429687,0.00999999977648258,,,24.9920673758752,23.8231651263761,24.3482753500374,,25,2189.71918945313,1978.62583496094,2313.52065429687,
,13968551.08,4370,236.08374786377,0.13400000333786,0,2190.04424804688,0.00999999977648258,1979.97260253906,0.00999999977648258,2310.80396484375,0.00999999977648258,,,20.9735268635096,18.5180941740065,16.7165982277717,,25,2190.04424804688,1979.97260253906,2310.80396484375,
,13968562.97,4370,238.068000793457,0.13400000333786,0,2192.43045898438,0.00999999977648258,1982.62147460937,0.00999999977648258,2318.26071289063,0.00999999977648258,,,25.2129175283679,19.5161603552055,24.6623693316953,,25,2192.43045898438,1982.62147460937,2318.26071289063,
,13968575.50,4370,240.175704956055,0.13400000333786,0,2192.009765625,0.00999999977648258,1980.00919921875,0.00999999977648258,2304.72899414063,0.00999999977648258,,,15.7264552560438,12.4781616625594,11.316308429899,,25,2192.009765625,1980.00919921875,2304.72899414063,
,13968587.19,4370,242.093902587891,0.13400000333786,0,2194.83796875,0.00999999977648258,1980.41102539062,0.00999999977648258,2312.64958984375,0.00999999977648258,,,19.1383311445181,18.7737603043848,15.6613708365197,,25,2194.83796875,1980.41102539062,2312.64958984375,
,13968599.00,4370,244.088096618652,0.13400000333786,0,2193.95708007812,0.00999999977648258,1979.13601074219,0.00999999977648258,2324.48024414063,0.00999999977648258,,,19.3319480534434,18.1923220573832,18.6556217242166,,25,2193.95708007812,1979.13601074219,2324.48024414063,
,13968611.33,4370,246.1416015625,0.13400000333786,0,2188.46294921875,0.00999999977648258,1986.48472167969,0.00999999977648258,2320.353828125,0.00999999977648258,,,31.0750033654181,22.6083766024217,18.8098171991176,,25,2188.46294921875,1986.48472167969,2320.353828125,
,13968623.39,4370,248.151397705078,0.13400000333786,0,2197.9641796875,0.00999999977648258,1982.14156738281,0.00999999977648258,2313.53736328125,0.00999999977648258,,,21.8963629782009,18.8668116837517,25.7283035930705,,25,2197.9641796875,1982.14156738281,2313.53736328125,
,13968634.77,4370,250.022903442383,0.13400000333786,0,2207.43442382813,0.00999999977648258,1991.85121582031,0.00999999977648258,2322.98770507813,0.00999999977648258,,,6.88143011992599,7.19695634316498,28.5070166322538,,25,2207.43442382813,1991.85121582031,2322.98770507813,
,13968647.67,4370,252.086502075195,0.13400000333786,0,2212.1959765625,0.00999999977648258,1987.24459960938,0.00999999977648258,2328.96470703125,0.00999999977648258,,,22.5747909404484,28.0950225591606,29.0667426985297,,25,2212.1959765625,1987.24459960938,2328.96470703125,
,13968659.75,4370,254.060195922852,0.13400000333786,0,2212.48240234375,0.00999999977648258,2005.81055664063,0.00999999977648258,2322.468984375,0.00999999977648258,,,29.0599616905673,26.8241974360146,24.4097044498224,,25,2212.48240234375,2005.81055664063,2322.468984375,
,13968671.95,4370,256.032402038574,0.13400000333786,0,2214.78958007812,0.00999999977648258,1998.19211914063,0.00999999977648258,2331.03192382812,0.00999999977648258,,,11.2832769050533,8.33614601767801,15.1216414131187,,25,2214.78958007812,1998.19211914063,2331.03192382812,
,13968684.13,4370,258.001998901367,0.13400000333786,0,2210.653046875,0.00999999977648258,2000.85483398438,0.00999999977648258,2335.17005859375,0.00999999977648258,,,18.3976854789222,22.8786302555967,21.3238496655646,,25,2210.653046875,2000.85483398438,2335.17005859375,
,13968696.31,4370,259.926559448242,0.13400000333786,0,2223.90111328125,0.00999999977648258,2004.51305175781,0.00999999977648258,2334.10614257812,0.00999999977648258,,,12.8384554508901,19.9392840437423,23.1357057631386,,25,2223.90111328125,2004.51305175781,2334.10614257812,
,13968709.11,4370,261.907699584961,0.13400000333786,0,2217.963515625,0.00999999977648258,2002.33000976562,0.00999999977648258,2333.03780273438,0.00999999977648258,,,11.1111357948939,12.6473956813694,15.2262596706824,,25,2217.963515625,2002.33000976562,2333.03780273438,
,13968723.06,4374,264.108413696289,0.13400000333786,0,2217.5377734375,0.00999999977648258,2012.11501464844,0.00999999977648258,2337.8141796875,0.00999999977648258,,,21.2017802442859,21.5996505965823,24.4735585664958,,25,2217.5377734375,2012.11501464844,2337.8141796875,
,13968735.33,4374,266.022994995117,0.13400000333786,0,2207.71411132813,0.00999999977648258,2019.39181640625,0.00999999977648258,2339.09921875,0.00999999977648258,,,32.4221700057575,22.5619801556828,24.1591989249294,,25,2207.71411132813,2019.39181640625,2339.09921875,
,13968747.86,4374,267.997100830078,0.13400000333786,0,2220.9333984375,0.00999999977648258,2010.67724609375,0.00999999977648258,2336.00151367187,0.00999999977648258,,,18.4597651407122,16.5444536555604,20.729239506924,,25,2220.9333984375,2010.67724609375,2336.00151367187,
,13968760.52,4374,269.952743530273,0.13400000333786,0,2222.089921875,0.00999999977648258,2007.09979003906,0.00999999977648258,2342.18848632812,0.00999999977648258,,,14.4081016296562,17.5806831965854,17.6804372222211,,25,2222.089921875,2007.09979003906,2342.18848632812,
,13968773.25,4374,271.850402832031,0.13400000333786,0,2224.35474609375,0.00999999977648258,2011.62171386719,0.00999999977648258,2347.65344726562,0.00999999977648258,,,20.4660284377669,18.1224672953472,20.2266858159016,,25,2224.35474609375,2011.62171386719,2347.65344726562,
,13968786.77,4374,273.957504272461,0.13400000333786,0,2230.78596679688,0.00999999977648258,2019.63756835938,0.00999999977648258,2343.44846679688,0.00999999977648258,,,27.0629785499504,18.2073131973779,22.316029229565,,25,2230.78596679688,2019.63756835938,2343.44846679688,
,13968799.73,4374,275.934799194336,0.13400000333786,0,2235.91859375,0.00999999977648258,2018.75643066406,0.00999999977648258,2347.72303710938,0.00999999977648258,,,28.266172708117,25.6859685311941,29.5573976558954,,25,2235.91859375,2018.75643066406,2347.72303710938,
,13968813.31,4374,278.017242431641,0.13400000333786,0,2240.53669921875,0.00999999977648258,2024.20135253906,0.00999999977648258,2359.13568359375,0.00999999977648258,,,7.72138459829919,7.84525857399085,13.6201973428827,,25,2240.53669921875,2024.20135253906,2359.13568359375,
,13968825.84,4374,279.894653320313,0.13400000333786,0,2243.36755859375,0.00999999977648258,2027.91630859375,0.00999999977648258,2361.88889648438,0.00999999977648258,,,12.4055383806435,10.5927550567458,17.8519942064485,,25,2243.36755859375,2027.91630859375,2361.88889648438,
,13968839.86,4374,282.019393920898,0.13400000333786,0,2242.0412890625,0.00999999977648258,2033.00402832031,0.00999999977648258,2357.832734375,0.00999999977648258,,,13.2825412802008,11.137635051137,16.8340733191409,,25,2242.0412890625,2033.00402832031,2357.832734375,
,13968853.42,4374,284.087905883789,0.13400000333786,0,2245.40725585937,0.00999999977648258,2027.93957519531,0.00999999977648258,2362.92817382813,0.00999999977648258,,,4.43460772825551,7.0718950916858,13.0324470430978,,25,2245.40725585937,2027.93957519531,2362.92817382813,
,13968866.39,4374,285.99494934082,0.13400000333786,0,2247.81650390625,0.00999999977648258,2029.30015625,0.00999999977648258,2358.24967773437,0.00999999977648258,,,8.42932406115752,6.72695334714143,14.8304059285859,,25,2247.81650390625,2029.30015625,2358.24967773437,
,13968879.67,4374,287.99479675293,0.13400000333786,0,2248.08423828125,0.00999999977648258,2026.46479980469,0.00999999977648258,2359.21508789063,0.00999999977648258,,,8.83081539911459,10.0169940466023,13.1501373071576,,25,2248.08423828125,2026.46479980469,2359.21508789063,
,13968893.59,4374,289.968048095703,0.13400000333786,0,2246.5670703125,0.00999999977648258,2030.72992675781,0.00999999977648258,2365.93390625,0.00999999977648258,,,9.75094696956379,10.6596806577088,14.7550745490882,,25,2246.5670703125,2030.72992675781,2365.93390625,
,13968907.11,4374,292.029739379883,0.13400000333786,0,2248.03001953125,0.00999999977648258,2032.8508203125,0.00999999977648258,2366.80854492188,0.00999999977648258,,,15.6133817630305,15.8523805485284,13.7310328973397,,25,2248.03001953125,2032.8508203125,2366.80854492188,
,13968920.23,4374,293.893402099609,0.13400000333786,0,2251.69129882813,0.00999999977648258,2034.42987792969,0.00999999977648258,2359.74141601563,0.00999999977648258,,,20.9555465103415,21.9979052415669,19.4711769932476,,25,2251.69129882813,2034.42987792969,2359.74141601563,
,13968934.39,4374,295.943695068359,0.13400000333786,0,2250.91314453125,0.00999999977648258,2037.14180664063,0.00999999977648258,2371.15561523438,0.00999999977648258,,,13.4777060003551,11.5868813291402,15.7671238113947,,25,2250.91314453125,2037.14180664063,2371.15561523438,
,13968948.13,4374,297.974655151367,0.13400000333786,0,2255.120078125,0.00999999977648258,2040.87612304687,0.00999999977648258,2371.42677734375,0.00999999977648258,,,23.1037384236189,18.4360018271249,18.1929531711652,,25,2255.120078125,2040.87612304687,2371.42677734375,
,13968962.53,4374,300.028305053711,0.13400000333786,0,2259.81510742187,0.00999999977648258,2047.53909667969,0.00999999977648258,2384.0785546875,0.00999999977648258,,,23.1410870551009,18.8746660826858,21.1341251867268,,25,2259.81510742187,2047.53909667969,2384.0785546875,
,13968972.98,4374,301.130004882813,0.13400000333786,0,2255.10458007812,0.00999999977648258,2054.39565917969,0.00999999977648258,2384.04755859375,0.00999999977648258,,,27.1929002573385,36.6097422249313,35.1986834986148,,25,2255.10458007812,2054.39565917969,2384.04755859375,