File: icepp/250308-ch1Nb50Al100-ch2Nb100Al20-ch3Nb100Al100_fineUp2.dat
[Header]
TITLE, 8.5K to 9.5K
FILEOPENTIME,13833988.88,3/8/2025,1:58 AM
BYAPP, Resistivity, 2.1, 1.0
INFO, APPNAME, PPMS MultiVu Application, 1.5.11
INFO, , Sample1 Name
INFO, 1, Sample1 Cross Section
INFO, 1, Sample1 Length
INFO, Ohm, Sample1 Units
INFO, , Sample2 Name
INFO, 1, Sample2 Cross Section
INFO, 1, Sample2 Length
INFO, Ohm, Sample2 Units
INFO, , Sample3 Name
INFO, 1, Sample3 Cross Section
INFO, 1, Sample3 Length
INFO, Ohm, Sample3 Units
INFO, , Sample4 Name
INFO, 1, Sample4 Cross Section
INFO, 1, Sample4 Length
INFO, Ohm, Sample4 Units
FIELDGROUP, Resistivity,2,3,4,5,6,7,8,9,10,11,12,13,14,15,16,17,18,19,20,21,22,23,24,25,26,27,28,29,30,31,32,33,34,35,36,37,38,39,40,41
STARTUPGROUP, Resistivity
STARTUPAXIS, X, 2, LINEAR, AUTO
STARTUPAXIS, Y1, 7, LINEAR, AUTO
STARTUPAXIS, Y2, 9, LINEAR, AUTO
STARTUPAXIS, Y3, 11, LINEAR, AUTO
PLOT_APPEARANCE, ALL, HORZ_GRID_ON, VERT_GRID_ON, MARKERS_AND_LINES, ALL_LINES
DATATYPE, TIME, 2
DATATYPE, COMMENT, 1
[Data]
Comment,Time Stamp (sec),Status (code),Temperature (K),Magnetic Field (Oe),Sample Position (deg),Bridge 1 Resistivity (Ohm),Bridge 1 Excitation (uA),Bridge 2 Resistivity (Ohm),Bridge 2 Excitation (uA),Bridge 3 Resistivity (Ohm),Bridge 3 Excitation (uA),Bridge 4 Resistivity (Ohm),Bridge 4 Excitation (uA),Bridge 1 Std. Dev. (Ohm),Bridge 2 Std. Dev. (Ohm),Bridge 3 Std. Dev. (Ohm),Bridge 4 Std. Dev. (Ohm),Number of Readings,Bridge 1 Resistance (Ohms),Bridge 2 Resistance (Ohms),Bridge 3 Resistance (Ohms),Bridge 4 Resistance (Ohms),Signal 1 Vin (V),Signal 2 Vin (V),Digital Inputs (code),Drive 1 Iout (mA),Drive 1 Ipower (watts),Drive 2 Iout (mA),Drive 2 Ipower (watts),Pressure (),Map 20 (),Map 21 (),Map 22 (),Map 23 (),Map 24 (),Map 25 (),Map 26 (),Map 27 (),Map 28 (),Map 29 ()
,13834758.81,4370,8.50075006484985,0.13400000333786,0,0.00130596656352282,9.98999977111816,-0.000267303120344877,9.98999977111816,0.000725537016987801,9.98999977111816,,,0.00318238960759974,0.00243434886692673,0.00254676195499207,,25,0.00130596656352282,-0.000267303120344877,0.000725537016987801,
,13834797.84,4370,8.50815010070801,0.13400000333786,0,4.58347611129284e-005,9.98999977111816,-0.000389595471788198,9.98999977111816,0.000870860470458865,9.98999977111816,,,0.00282403975556044,0.0030749170896224,0.00255030169923243,,25,4.58347611129284e-005,-0.000389595471788198,0.000870860470458865,
,13834836.17,4370,8.51069974899292,0.13400000333786,0,0.000733413990819827,9.98999977111816,-0.000129870677483268,9.98999977111816,-0.000252086179098114,9.98999977111816,,,0.00396382366929011,0.00287462691713185,0.00385467550627056,,25,0.000733413990819827,-0.000129870677483268,-0.000252086179098114,
,13834874.91,4370,8.51725006103516,0.13400000333786,0,-0.000458400203497149,9.98999977111816,-0.000985560401459225,9.98999977111816,0.000886240362888202,9.98999977111816,,,0.00407470800561311,0.00295436056643816,0.00321374517281815,,25,-0.000458400203497149,-0.000985560401459225,0.000886240362888202,
,13834911.33,4370,8.52265024185181,0.13400000333786,0,0.000282564061926678,9.98999977111816,-0.000297837763209827,9.98999977111816,-0.000893513333285227,9.98999977111816,,,0.00234149365855243,0.00257061964042686,0.00323136030247496,,25,0.000282564061926678,-0.000297837763209827,-0.000893513333285227,
,13834948.14,4370,8.53084993362427,0.13400000333786,0,0.000412390797282569,9.98999977111816,0.00126008304127026,9.98999977111816,0.000114552985178307,9.98999977111816,,,0.00210234491913242,0.00340205053725242,0.00288538156505563,,25,0.000412390797282569,0.00126008304127026,0.000114552985178307,
,13834992.47,4370,8.53719997406006,0.13400000333786,0,0.000229184760246426,9.98999977111816,-6.11158739775419e-005,9.98999977111816,-2.29184707859531e-005,9.98999977111816,,,0.00401927324426823,0.00312319783483731,0.00303727219522925,,25,0.000229184760246426,-6.11158739775419e-005,-2.29184707859531e-005,
,13835032.89,4370,8.5440502166748,0.13400000333786,0,0.000595914572477341,9.98999977111816,0.000221557985059917,9.98999977111816,0.000190998283214867,9.98999977111816,,,0.00301429854347322,0.0023951394175074,0.00340512975871585,,25,0.000595914572477341,0.000221557985059917,0.000190998283214867,
,13835083.47,4370,8.5521502494812,0.13400000333786,0,0.000534534768667072,9.98999977111816,0.000343629519920796,9.98999977111816,-0.000901072849519551,9.98999977111816,,,0.0033759479004082,0.0028480097158699,0.00225075277510523,,25,0.000534534768667072,0.000343629519920796,-0.000901072849519551,
,13835121.67,4370,8.5592999458313,0.13400000333786,0,-0.000343629493145272,9.98999977111816,-0.000267267343588173,9.98999977111816,6.87258876860142e-005,9.98999977111816,,,0.00360482527386949,0.00335776263279445,0.00245006963826103,,25,-0.000343629493145272,-0.000267267343588173,6.87258876860142e-005,
,13835179.44,4370,8.56860017776489,0.13400000333786,0,-0.000244412348838523,9.98999977111816,-0.000580479411873966,9.98999977111816,-0.000740875077899545,9.98999977111816,,,0.0029922196871504,0.00308199864335627,0.00342017050425965,,25,-0.000244412348838523,-0.000580479411873966,-0.000740875077899545,
,13835227.23,4370,8.57735013961792,0.13400000333786,0,3.81996622309089e-005,9.98999977111816,3.05597181431949e-005,9.98999977111816,-0.000320877025369555,9.98999977111816,,,0.00250957457060277,0.00385444877146532,0.00308056911869076,,25,3.81996622309089e-005,3.05597181431949e-005,-0.000320877025369555,
,13835270.20,4370,8.58450031280518,0.13400000333786,0,9.92849835893139e-005,9.98999977111816,0.000626258953707293,9.98999977111816,0.000183295291499235,9.98999977111816,,,0.00302379390573348,0.00268911212583808,0.00282759793076194,,25,9.92849835893139e-005,0.000626258953707293,0.000183295291499235,
,13835309.66,4370,8.58890008926392,0.13400000333786,0,-0.00129834176914301,9.98999977111816,-0.000954663049778901,9.98999977111816,-0.00080955429119058,9.98999977111816,,,0.00306492938728636,0.00291870961220296,0.00277964317639812,,25,-0.00129834176914301,-0.000954663049778901,-0.00080955429119058,
,13835351.23,4370,8.59824991226196,0.13400000333786,0,-0.000779213286004961,9.98999977111816,0.000580590202007443,9.98999977111816,0.000160426248330623,9.98999977111816,,,0.00331230600901863,0.00309392557888475,0.00307841932138783,,25,-0.000779213286004961,0.000580590202007443,0.000160426248330623,
,13835390.56,4370,8.60330009460449,0.13400000333786,0,0.000137522661243565,9.98999977111816,0.000679973190417513,9.98999977111816,-0.000351446825661697,9.98999977111816,,,0.00274595049604467,0.00298410164427531,0.00314950238784151,,25,0.000137522661243565,0.000679973190417513,-0.000351446825661697,
,13835426.31,4370,8.61109972000122,0.13400000333786,0,-0.00140578731545247,9.98999977111816,-0.000236844577011652,9.98999977111816,0.000198643829207867,9.98999977111816,,,0.00339229473983005,0.00320898965505878,0.00294045480207266,,25,-0.00140578731545247,-0.000236844577011652,0.000198643829207867,
,13835474.23,4370,8.61984968185425,0.13400000333786,0,-0.000313096624449827,9.98999977111816,0.000206185563001782,9.98999977111816,0.000824742271797732,9.98999977111816,,,0.00253669853924905,0.00290082577575392,0.00294660169056103,,25,-0.000313096624449827,0.000206185563001782,0.000824742271797732,
,13835513.70,4370,8.62310028076172,0.13400000333786,0,-0.000588145400979556,9.98999977111816,0.000549954170710407,9.98999977111816,-0.000145126829156652,9.98999977111816,,,0.0034663361187402,0.00269421413269415,0.00415891439472133,,25,-0.000588145400979556,0.000549954170710407,-0.000145126829156652,
,13835559.08,4370,8.6346001625061,0.13400000333786,0,-0.000565234878449701,9.98999977111816,-0.00105407642724458,9.98999977111816,0.000206254663644359,9.98999977111816,,,0.00335329524719894,0.0032810134527406,0.00315767925877576,,25,-0.000565234878449701,-0.00105407642724458,0.000206254663644359,
,13835610.20,4370,8.64055013656616,0.13400000333786,0,-0.000244431064347737,9.98999977111816,0.000206238698447123,9.98999977111816,0.000137492484645918,9.98999977111816,,,0.00208945334581037,0.00325998979257579,0.00303744242012523,,25,-0.000244431064347737,0.000206238698447123,0.000137492484645918,
,13835654.27,4370,8.64520025253296,0.13400000333786,0,-5.34723774762824e-005,9.98999977111816,0.000351389771094546,9.98999977111816,-0.000588195939781144,9.98999977111816,,,0.0026885919582747,0.00351168848657534,0.00252541898148628,,25,-5.34723774762824e-005,0.000351389771094546,-0.000588195939781144,
,13835692.61,4370,8.65884971618652,0.13400000333786,0,-0.000511841071420349,9.98999977111816,-0.00129106173291802,9.98999977111816,0.000901451384997927,9.98999977111816,,,0.00279738354363172,0.00267449487531112,0.00248282280111695,,25,-0.000511841071420349,-0.00129106173291802,0.000901451384997927,
,13835731.86,4370,8.66454982757568,0.13400000333786,0,-0.000106951869092882,9.98999977111816,-0.00101604263298213,9.98999977111816,0.000366692093084566,9.98999977111816,,,0.00334571640806106,0.00267200603857958,0.0026358318058197,,25,-0.000106951869092882,-0.00101604263298213,0.000366692093084566,
,13835781.14,4370,8.67320013046265,0.13400000333786,0,0.000122208525426686,9.98999977111816,0.000290245258947834,9.98999977111816,7.6380327809602e-005,9.98999977111816,,,0.00216634889026864,0.00403484868416337,0.00318882188778351,,25,0.000122208525426686,0.000290245258947834,7.6380327809602e-005,
,13835930.36,4370,8.69474983215332,0.13400000333786,0,0.000221526245586574,9.98999977111816,-0.000519440821371973,9.98999977111816,0.000122221384663135,9.98999977111816,,,0.00298241513065111,0.00266786822822734,0.00280506541369875,,25,0.000221526245586574,-0.000519440821371973,0.000122221384663135,
,13835973.84,4370,8.70120000839233,0.13400000333786,0,0.000710411765612662,9.98999977111816,-0.000786800107453018,9.98999977111816,0.000328469970263541,9.98999977111816,,,0.00280695779979992,0.00337551853784836,0.00307007084005403,,25,0.000710411765612662,-0.000786800107453018,0.000328469970263541,
,13836016.63,4370,8.70705032348633,0.13400000333786,0,-0.000206256431993097,9.98999977111816,7.6391058973968e-006,9.98999977111816,-0.000389595443848521,9.98999977111816,,,0.00251507169478921,0.00282672475751276,0.00214677133929143,,25,-0.000206256431993097,7.6391058973968e-006,-0.000389595443848521,
,13836057.47,4370,8.71669960021973,0.13400000333786,0,0.000473490214208141,9.98999977111816,0.000420031648827717,9.98999977111816,-0.000320751435356215,9.98999977111816,,,0.00328038327190263,0.0029984106138189,0.00333486874061562,,25,0.000473490214208141,0.000420031648827717,-0.000320751435356215,
,13836095.91,4370,8.72114992141724,0.13400000333786,0,0.000641502918442711,9.98999977111816,0.000282566759269685,9.98999977111816,-1.52738683391362e-005,9.98999977111816,,,0.00284617159986768,0.00249876180383054,0.00291653108413144,,25,0.000641502918442711,0.000282566759269685,-1.52738683391362e-005,
,13836129.89,4370,8.72875022888184,0.13400000333786,0,-0.000412351406412199,9.98999977111816,0.00171813098015264,9.98999977111816,0.000274900940712541,9.98999977111816,,,0.00269203915093812,0.00276381774500203,0.00273682845353575,,25,-0.000412351406412199,0.00171813098015264,0.000274900940712541,
,13836176.02,4370,8.73509979248047,0.13400000333786,0,-4.58356074523181e-005,9.98999977111816,-0.000939630597131327,9.98999977111816,-0.000389602920040488,9.98999977111816,,,0.00317663343889773,0.00313997353133121,0.00307924292540974,,25,-4.58356074523181e-005,-0.000939630597131327,-0.000389602920040488,
,13836210.14,4370,8.74040031433105,0.13400000333786,0,-0.000718091621529311,9.98999977111816,-0.000259735278086737,9.98999977111816,0.000404881440335885,9.98999977111816,,,0.00282873916988895,0.00294329191395407,0.002710768797483,,25,-0.000718091621529311,-0.000259735278086737,0.000404881440335885,
,13836248.11,4370,8.74780035018921,0.13400000333786,0,0.000427733961842023,9.98999977111816,-0.000863106055185199,9.98999977111816,-0.000565219882992096,9.98999977111816,,,0.00285448623707554,0.00285899950702826,0.00310988202317858,,25,0.000427733961842023,-0.000863106055185199,-0.000565219882992096,
,13836283.30,4370,8.75230026245117,0.13400000333786,0,-0.000740907901199535,9.98999977111816,0.000137482644058764,9.98999977111816,0.000947150769643486,9.98999977111816,,,0.00286372610069073,0.00304454766004476,0.00364463646890907,,25,-0.000740907901199535,0.000137482644058764,0.000947150769643486,
,13836317.67,4370,8.75874996185303,0.13400000333786,0,-0.000206234802026302,9.98999977111816,0.000328447966603562,9.98999977111816,3.05532675702125e-005,9.98999977111816,,,0.00314886183094014,0.00266166852059974,0.002928418630953,,25,-0.000206234802026302,0.000328447966603562,3.05532675702125e-005,
,13836363.30,4370,8.76700019836426,0.13400000333786,0,0.00295637039758731,9.98999977111816,0.00141325199743733,9.98999977111816,-0.000679888783488423,9.98999977111816,,,0.00292648173297873,0.00265620159324171,0.00262475168664341,,25,0.00295637039758731,0.00141325199743733,-0.000679888783488423,
,13836398.14,4370,8.77199983596802,0.13400000333786,0,0.00961011374834925,9.98999977111816,-0.000618775215698406,9.98999977111816,-8.40312172658742e-005,9.98999977111816,,,0.00428535295345799,0.00291006399023403,0.00301341026632946,,25,0.00961011374834925,-0.000618775215698406,-8.40312172658742e-005,
,13836436.25,4370,8.77920007705688,0.13400000333786,0,0.016037419885397,9.98999977111816,-3.05474520428106e-005,9.98999977111816,0.000526943781296723,9.98999977111816,,,0.00327228817854839,0.0033898914806629,0.00337679061329622,,25,0.016037419885397,-3.05474520428106e-005,0.000526943781296723,
,13836474.03,4370,8.78410005569458,0.13400000333786,0,0.0237278074026108,9.98999977111816,-0.000733377148862928,9.98999977111816,-0.000267377039417624,9.98999977111816,,,0.00308674936259861,0.00296691952155677,0.00360711418017099,,25,0.0237278074026108,-0.000733377148862928,-0.000267377039417624,
,13836510.38,4370,8.79260015487671,0.13400000333786,0,0.331234377622604,9.98999977111816,-0.000168065577745438,9.98999977111816,-0.000664623046759516,9.98999977111816,,,0.0443478947446177,0.00286313461981018,0.00271283902144324,,25,0.331234377622604,-0.000168065577745438,-0.000664623046759516,
,13836544.88,4370,8.79809999465942,0.13400000333786,0,2.69540685653687,9.98999977111816,0.00646904365043156,9.98999977111816,-0.0006568332540337,9.98999977111816,,,0.51741379014084,0.0056039658015699,0.0026074756595187,,25,2.69540685653687,0.00646904365043156,-0.0006568332540337,
,13836580.06,4370,8.80139970779419,0.13400000333786,0,7.50286087036133,9.98999977111816,0.885632681846619,9.98999977111816,-0.000282591078430414,9.98999977111816,,,0.397933192623926,0.303331115513187,0.00278595378755808,,25,7.50286087036133,0.885632681846619,-0.000282591078430414,
,13836613.48,4370,8.80780029296875,0.13400000333786,0,8.11450466156006,9.98999977111816,2.75116025924683,9.98999977111816,0.000313147399574518,9.98999977111816,,,0.0121479593233635,0.277025306981108,0.00293873450904788,,25,8.11450466156006,2.75116025924683,0.000313147399574518,
,13836648.30,4370,8.81444978713989,0.13400000333786,0,8.15671890258789,9.98999977111816,5.02278726577759,9.98999977111816,-0.000122259587515146,9.98999977111816,,,0.00504106061718594,0.353343895637855,0.00288617178653335,,25,8.15671890258789,5.02278726577759,-0.000122259587515146,
,13836683.59,4370,8.81874990463257,0.13400000333786,0,8.17015727996826,9.98999977111816,11.7087608718872,9.98999977111816,-3.05585807655007e-005,9.98999977111816,,,0.00278945370073444,2.1964977139786,0.00231701536238352,,25,8.17015727996826,11.7087608718872,-3.05585807655007e-005,
,13836720.86,4370,8.82774972915649,0.13400000333786,0,8.17854877471924,9.98999977111816,45.7892315673828,9.98999977111816,-0.000549969851272181,9.98999977111816,,,0.00330744419120744,5.29651813754722,0.0028750091184462,,25,8.17854877471924,45.7892315673828,-0.000549969851272181,
,13836754.08,4370,8.83199977874756,0.13400000333786,0,8.18677536010742,9.98999977111816,72.4035638427734,9.98999977111816,-0.000404838959220797,9.98999977111816,,,0.00366234822816798,0.695117765515577,0.00265007597470789,,25,8.18677536010742,72.4035638427734,-0.000404838959220797,
,13836807.55,4370,8.84019994735718,0.13400000333786,0,8.19125282287598,9.98999977111816,76.6084832763672,9.98999977111816,0.000878323535434902,9.98999977111816,,,0.00404244780108054,0.596988034718606,0.00303444286372738,,25,8.19125282287598,76.6084832763672,0.000878323535434902,
,13836843.63,4370,8.84739971160889,0.13400000333786,0,8.19932132720947,9.98999977111816,78.6289459228516,9.98999977111816,-0.00113060158386361,9.98999977111816,,,0.00308299009092496,0.207837725980255,0.00236748653739023,,25,8.19932132720947,78.6289459228516,-0.00113060158386361,
,13836878.81,4370,8.85195016860962,0.13400000333786,0,8.20226982116699,9.98999977111816,79.494748840332,9.98999977111816,0.00113824080966879,9.98999977111816,,,0.00361910503105883,0.0725671241179708,0.00288245953392915,,25,8.20226982116699,79.494748840332,0.00113824080966879,
,13836924.23,4370,8.86090040206909,0.13400000333786,0,8.20271286010742,9.98999977111816,79.8261785888672,9.98999977111816,0.000183277782052755,9.98999977111816,,,0.00248117257045134,0.0375931627008082,0.00311862255786092,,25,8.20271286010742,79.8261785888672,0.000183277782052755,
,13836960.20,4370,8.86570024490356,0.13400000333786,0,8.20992351531982,9.98999977111816,80.0648330688477,9.98999977111816,-0.000542321085231379,9.98999977111816,,,0.0031684977598566,0.0332848605739312,0.00308368936469809,,25,8.20992351531982,80.0648330688477,-0.000542321085231379,
,13836999.78,4370,8.87365007400513,0.13400000333786,0,8.20952640533447,9.98999977111816,80.2931817626953,9.98999977111816,0.00045066119520925,9.98999977111816,,,0.00261945417165255,0.0132136842119576,0.00284924874755924,,25,8.20952640533447,80.2931817626953,0.00045066119520925,
,13837045.05,4370,8.88089990615845,0.13400000333786,0,8.21174350738525,9.98999977111816,80.4134573364258,9.98999977111816,-0.000351366316899657,9.98999977111816,,,0.00306583287527692,0.00336482140030966,0.00308040585170391,,25,8.21174350738525,80.4134573364258,-0.000351366316899657,
,13837083.72,4370,8.88985013961792,0.13400000333786,0,8.21498447418213,9.98999977111816,80.4779904174805,9.98999977111816,-4.58373641595244e-005,9.98999977111816,,,0.00331934474896696,0.00484466562120933,0.0030721501126458,,25,8.21498447418213,80.4779904174805,-4.58373641595244e-005,
,13837118.75,4370,8.89120006561279,0.13400000333786,0,8.2147093963623,9.98999977111816,80.5023501586914,9.98999977111816,0.000481292601325549,9.98999977111816,,,0.00250258861903225,0.0105294292464512,0.00290309500796116,,25,8.2147093963623,80.5023501586914,0.000481292601325549,
,13837155.59,4370,8.89909982681274,0.13400000333786,0,8.21818069458008,9.98999977111816,80.5198831176758,9.98999977111816,-0.000244461395195685,9.98999977111816,,,0.00238957288814087,0.00543138111785949,0.00274940541873191,,25,8.21818069458008,80.5198831176758,-0.000244461395195685,
,13837188.95,4370,8.90380001068115,0.13400000333786,0,8.22007411956787,9.98999977111816,80.5350448608398,9.98999977111816,0.000649316435446963,9.98999977111816,,,0.00196595297289027,0.00598797765330207,0.00253185598834691,,25,8.22007411956787,80.5350448608398,0.000649316435446963,
,13837229.30,4370,8.91200017929077,0.13400000333786,0,8.22499252319336,9.98999977111816,80.5645874023437,9.98999977111816,0.000381927179405466,9.98999977111816,,,0.00219009312145752,0.00366054702750959,0.00299758090280811,,25,8.22499252319336,80.5645874023437,0.000381927179405466,
,13837270.39,4370,8.91929960250854,0.13400000333786,0,8.22562805175781,9.98999977111816,80.5622567749023,9.98999977111816,-0.000526918692630716,9.98999977111816,,,0.00291797677480427,0.00366863337679791,0.00313435406715614,,25,8.22562805175781,80.5622567749023,-0.000526918692630716,
,13837321.95,4370,8.92750024795532,0.13400000333786,0,8.2338427734375,9.98999977111816,80.6047601318359,9.98999977111816,-0.000641692826175131,9.98999977111816,,,0.00335903443189946,0.0036890182467189,0.00343206737060586,,25,8.2338427734375,80.6047601318359,-0.000641692826175131,
,13837356.06,4370,8.93210029602051,0.13400000333786,0,8.23684501647949,9.98999977111816,80.609860534668,9.98999977111816,0.00163478879898321,9.98999977111816,,,0.00255816548228005,0.00389412176660108,0.00284506620661696,,25,8.23684501647949,80.609860534668,0.00163478879898321,
,13837389.03,4370,8.93610000610352,0.13400000333786,0,8.23923946380615,9.98999977111816,80.6068380737305,9.98999977111816,-0.000916598981712013,9.98999977111816,,,0.00274009140749488,0.0043730975730553,0.00298188312577036,,25,8.23923946380615,80.6068380737305,-0.000916598981712013,
,13837428.19,4370,8.94480037689209,0.13400000333786,0,8.24252613067627,9.98999977111816,80.6082446289062,9.98999977111816,-0.000168028096668422,9.98999977111816,,,0.00339746312300325,0.00599083176126482,0.00328722919863867,,25,8.24252613067627,80.6082446289062,-0.000168028096668422,
,13837466.48,4370,8.95190000534058,0.13400000333786,0,8.24591484069824,9.98999977111816,80.6093124389648,9.98999977111816,0.000526994119863957,9.98999977111816,,,0.00304779876031371,0.00353977121684053,0.00360397421599947,,25,8.24591484069824,80.6093124389648,0.000526994119863957,
,13837507.56,4370,8.958899974823,0.13400000333786,0,8.24996757507324,9.98999977111816,80.623200378418,9.98999977111816,-0.000817339736968279,9.98999977111816,,,0.00357989445331744,0.00467315381647334,0.0030884874246616,,25,8.24996757507324,80.623200378418,-0.000817339736968279,
,13837567.28,4370,8.96645021438599,0.13400000333786,0,8.25290985107422,9.98999977111816,80.607825012207,9.98999977111816,0.000847667915513739,9.98999977111816,,,0.00310771669621817,0.00311539155236023,0.00314361019427109,,25,8.25290985107422,80.607825012207,0.000847667915513739,
,13837601.52,4370,8.97440004348755,0.13400000333786,0,8.25358959197998,9.98999977111816,80.6104135131836,9.98999977111816,-0.000488745459006168,9.98999977111816,,,0.00262781401699966,0.00328520108416966,0.00273860901225013,,25,8.25358959197998,80.6104135131836,-0.000488745459006168,
,13837642.81,4370,8.98049974441528,0.13400000333786,0,8.25959552764893,9.98999977111816,80.6560006713867,9.98999977111816,0.000382040253607556,9.98999977111816,,,0.00239369272573498,0.00290797427603126,0.00216923510292831,,25,8.25959552764893,80.6560006713867,0.000382040253607556,
,13837680.81,4370,8.98720026016235,0.13400000333786,0,8.25941791534424,9.98999977111816,80.6492422485352,9.98999977111816,0.000550069596501999,9.98999977111816,,,0.00242047674071677,0.00426198609802308,0.00277534008940656,,25,8.25941791534424,80.6492422485352,0.000550069596501999,
,13837716.88,4370,8.99329996109009,0.13400000333786,0,8.26132785797119,9.98999977111816,80.6527728271484,9.98999977111816,0.000901503043132834,9.98999977111816,,,0.00187961992166912,0.00317622115170185,0.00263797497691643,,25,8.26132785797119,80.6527728271484,0.000901503043132834,
,13837755.91,4370,9.00129985809326,0.13400000333786,0,8.25961963653564,9.98999977111816,80.6296661376953,9.98999977111816,-7.63745338190347e-006,9.98999977111816,,,0.00309116857979186,0.00264226462805523,0.00279027319260927,,25,8.25961963653564,80.6296661376953,-7.63745338190347e-006,
,13837792.00,4370,9.00524997711182,0.13400000333786,0,8.26007396697998,9.98999977111816,80.6353436279297,9.98999977111816,-0.000969986766576767,9.98999977111816,,,0.00292453639326349,0.00867927657240789,0.00255828551085694,,25,8.26007396697998,80.6353436279297,-0.000969986766576767,
,13837831.16,4370,9.01169967651367,0.13400000333786,0,8.26168575286865,9.98999977111816,80.6494982910156,9.98999977111816,0.000511806853464805,9.98999977111816,,,0.00275516486799233,0.00332260241327804,0.00276308939099699,,25,8.26168575286865,80.6494982910156,0.000511806853464805,
,13837868.08,4370,9.01775026321411,0.13400000333786,0,8.26163261413574,9.98999977111816,80.6385208129883,9.98999977111816,-0.000358977264841087,9.98999977111816,,,0.00282596126742092,0.00256715079089064,0.00339832102036809,,25,8.26163261413574,80.6385208129883,-0.000358977264841087,
,13837906.25,4370,9.02495002746582,0.13400000333786,0,8.26128120422363,9.98999977111816,80.6398059082031,9.98999977111816,0.000763781415298581,9.98999977111816,,,0.00257871502495389,0.00378988505486023,0.00338097320155623,,25,8.26128120422363,80.6398059082031,0.000763781415298581,
,13837947.20,4370,9.03154993057251,0.13400000333786,0,8.26133003234863,9.98999977111816,80.6346484375,9.98999977111816,0.000786612294614315,9.98999977111816,,,0.00348479263971203,0.00300727597914051,0.00305734310935947,,25,8.26133003234863,80.6346484375,0.000786612294614315,
,13837985.53,4370,9.03704977035522,0.13400000333786,0,8.26217445373535,9.98999977111816,80.6525048828125,9.98999977111816,0.513396881818771,9.98999977111816,,,0.0032331139360101,0.00349145077543472,0.187747536107758,,25,8.26217445373535,80.6525048828125,0.513396881818771,
,13838027.14,4370,9.04470014572144,0.13400000333786,0,8.26262538909912,9.98999977111816,80.6540628051758,9.98999977111816,5.38024070739746,9.98999977111816,,,0.00342247014829362,0.00297403836337805,1.22939423331147,,25,8.26262538909912,80.6540628051758,5.38024070739746,
,13838085.73,4370,9.05420017242432,0.13400000333786,0,8.26424919128418,9.98999977111816,80.6632263183594,9.98999977111816,11.5914965057373,9.98999977111816,,,0.00311999369319113,0.00322057186301146,0.0192198728794619,,25,8.26424919128418,80.6632263183594,11.5914965057373,
,13838121.95,4370,9.0590500831604,0.13400000333786,0,8.26571594238281,9.98999977111816,80.6838677978516,9.98999977111816,11.6508810043335,9.98999977111816,,,0.00332362373826887,0.0025116644021078,0.00632756453903752,,25,8.26571594238281,80.6838677978516,11.6508810043335,
,13838163.61,4370,9.06864976882935,0.13400000333786,0,8.2637043762207,9.98999977111816,80.6653353881836,9.98999977111816,11.6684119415283,9.98999977111816,,,0.00308993099085268,0.00346647902495711,0.00228996422019492,,25,8.2637043762207,80.6653353881836,11.6684119415283,
,13838210.39,4370,9.0762996673584,0.13400000333786,0,8.26372714996338,9.98999977111816,80.6670397949219,9.98999977111816,11.6815587997437,9.98999977111816,,,0.00341665410998648,0.00265922844623535,0.00368815438104294,,25,8.26372714996338,80.6670397949219,11.6815587997437,
,13838248.25,4370,9.08144998550415,0.13400000333786,0,8.26252666473389,9.98999977111816,80.6568621826172,9.98999977111816,11.7000774765015,9.98999977111816,,,0.00330866922922319,0.00310095940615973,0.00743082853705013,,25,8.26252666473389,80.6568621826172,11.7000774765015,
,13838282.78,4370,9.0873498916626,0.13400000333786,0,8.26361801147461,9.98999977111816,80.6653701782227,9.98999977111816,11.7246011734009,9.98999977111816,,,0.00269363010725962,0.00379115469368922,0.00346970038832029,,25,8.26361801147461,80.6653701782227,11.7246011734009,
,13838316.55,4370,9.0930004119873,0.13400000333786,0,8.2648323059082,9.98999977111816,80.6665390014648,9.98999977111816,11.7349897384644,9.98999977111816,,,0.00292136066831856,0.00295614610708798,0.00343887499569958,,25,8.2648323059082,80.6665390014648,11.7349897384644,
,13838354.41,4370,9.09945011138916,0.13400000333786,0,8.26262111663818,9.98999977111816,80.6538061523437,9.98999977111816,11.7387149429321,9.98999977111816,,,0.00294069721309728,0.00365887750133784,0.00305233550843703,,25,8.26262111663818,80.6538061523437,11.7387149429321,
,13838399.61,4370,9.10794973373413,0.13400000333786,0,8.26019020080566,9.98999977111816,80.6462316894531,9.98999977111816,11.7457810211182,9.98999977111816,,,0.00270592121777837,0.00593397656035724,0.00213523427345691,,25,8.26019020080566,80.6462316894531,11.7457810211182,
,13838441.77,4370,9.11420011520386,0.13400000333786,0,8.26176319122314,9.98999977111816,80.6447909545898,9.98999977111816,11.7507579421997,9.98999977111816,,,0.00243893735772089,0.00328295578813365,0.00355970149125584,,25,8.26176319122314,80.6447909545898,11.7507579421997,
,13838490.56,4370,9.12280035018921,0.13400000333786,0,8.2629797744751,9.98999977111816,80.6647119140625,9.98999977111816,11.7612861633301,9.98999977111816,,,0.00259034199588205,0.00304126889027523,0.00322794444945085,,25,8.2629797744751,80.6647119140625,11.7612861633301,
,13838525.70,4370,9.12734985351563,0.13400000333786,0,8.26161567687988,9.98999977111816,80.6516046142578,9.98999977111816,11.76401222229,9.98999977111816,,,0.0033842284520913,0.00303308991053296,0.00322940101824171,,25,8.26161567687988,80.6516046142578,11.76401222229,
,13838568.77,4370,9.13625001907349,0.13400000333786,0,8.26131778717041,9.98999977111816,80.6554086303711,9.98999977111816,11.7704043579102,9.98999977111816,,,0.00282167824048395,0.00244686607716127,0.00265258290209144,,25,8.26131778717041,80.6554086303711,11.7704043579102,
,13838609.28,4370,9.14324998855591,0.13400000333786,0,8.26491863250732,9.98999977111816,80.6961801147461,9.98999977111816,11.777974395752,9.98999977111816,,,0.00348712246555683,0.0031826075240983,0.00254574041112113,,25,8.26491863250732,80.6961801147461,11.777974395752,
,13838649.61,4370,9.150550365448,0.13400000333786,0,8.2646520614624,9.98999977111816,80.691487121582,9.98999977111816,11.7830386352539,9.98999977111816,,,0.00298670591105511,0.00267486452580288,0.00217181858931745,,25,8.2646520614624,80.691487121582,11.7830386352539,
,13838683.55,4370,9.15435028076172,0.13400000333786,0,8.26474380493164,9.98999977111816,80.6932522583008,9.98999977111816,11.7864156341553,9.98999977111816,,,0.00302123376920203,0.0021965123663633,0.00328327833662996,,25,8.26474380493164,80.6932522583008,11.7864156341553,
,13838720.78,4370,9.1611499786377,0.13400000333786,0,8.26310958862305,9.98999977111816,80.6669464111328,9.98999977111816,11.785029335022,9.98999977111816,,,0.00211046129065113,0.00376403980941696,0.00253149260207928,,25,8.26310958862305,80.6669464111328,11.785029335022,
,13838755.48,4370,9.16830015182495,0.13400000333786,0,8.26354488372803,9.98999977111816,80.6674044799805,9.98999977111816,11.7885809326172,9.98999977111816,,,0.002061150100093,0.00332375146840612,0.00281911164336034,,25,8.26354488372803,80.6674044799805,11.7885809326172,
,13838798.58,4370,9.17415046691895,0.13400000333786,0,8.26351863861084,9.98999977111816,80.6834967041016,9.98999977111816,11.7938417816162,9.98999977111816,,,0.00254104417707009,0.00320845677983294,0.00241981891228318,,25,8.26351863861084,80.6834967041016,11.7938417816162,
,13838837.16,4370,9.17969989776611,0.13400000333786,0,8.26497039794922,9.98999977111816,80.6809323120117,9.98999977111816,11.7930461883545,9.98999977111816,,,0.00400418303056736,0.00296100625276636,0.00242764344765875,,25,8.26497039794922,80.6809323120117,11.7930461883545,
,13838871.73,4370,9.18599987030029,0.13400000333786,0,8.26405372619629,9.98999977111816,80.681787109375,9.98999977111816,11.7944058609009,9.98999977111816,,,0.00276796439308245,0.00340251724270478,0.00299672396971399,,25,8.26405372619629,80.681787109375,11.7944058609009,
,13838909.81,4370,9.19299983978271,0.13400000333786,0,8.26370468139648,9.98999977111816,80.6789450073242,9.98999977111816,11.7936818695068,9.98999977111816,,,0.00267320338885877,0.00302252371936396,0.00357492089722308,,25,8.26370468139648,80.6789450073242,11.7936818695068,
,13838949.48,4370,9.19849967956543,0.13400000333786,0,8.26340145111084,9.98999977111816,80.6810198974609,9.98999977111816,11.7945961761475,9.98999977111816,,,0.00303693742008261,0.00308415103841802,0.00276464969127571,,25,8.26340145111084,80.6810198974609,11.7945961761475,
,13838990.50,4370,9.20504999160767,0.13400000333786,0,8.26350074768066,9.98999977111816,80.6815844726563,9.98999977111816,11.7953296279907,9.98999977111816,,,0.00268014271936208,0.00281010296131591,0.00316913703851626,,25,8.26350074768066,80.6815844726563,11.7953296279907,
,13839026.55,4370,9.2125997543335,0.13400000333786,0,8.26096603393555,9.98999977111816,80.6585900878906,9.98999977111816,11.7903630828857,9.98999977111816,,,0.00280226591912617,0.00268252057279328,0.00276290904653818,,25,8.26096603393555,80.6585900878906,11.7903630828857,
,13839062.27,4370,9.21684980392456,0.13400000333786,0,8.26317764282227,9.98999977111816,80.6729974365234,9.98999977111816,11.7933861923218,9.98999977111816,,,0.0028866844162731,0.014854641986589,0.00292175656510787,,25,8.26317764282227,80.6729974365234,11.7933861923218,
,13839098.22,4370,9.22294998168945,0.13400000333786,0,8.26419132232666,9.98999977111816,80.6876840209961,9.98999977111816,11.7951086044312,9.98999977111816,,,0.0028832085170964,0.00293594380896128,0.00269942688631262,,25,8.26419132232666,80.6876840209961,11.7951086044312,
,13839136.58,4370,9.2308497428894,0.13400000333786,0,8.26447383880615,9.98999977111816,80.6878210449219,9.98999977111816,11.7940316390991,9.98999977111816,,,0.0023912036161082,0.00341558027047507,0.00337301718089796,,25,8.26447383880615,80.6878210449219,11.7940316390991,
,13839184.55,4370,9.23829984664917,0.13400000333786,0,8.26249862670898,9.98999977111816,80.6876089477539,9.98999977111816,11.795018196106,9.98999977111816,,,0.00226694003123009,0.00303245519576205,0.00251951288426092,,25,8.26249862670898,80.6876089477539,11.795018196106,
,13839218.72,4370,9.24330043792725,0.13400000333786,0,8.26420112609863,9.98999977111816,80.6856326293945,9.98999977111816,11.7949726486206,9.98999977111816,,,0.00319700141172883,0.00249070685038247,0.00293816518513333,,25,8.26420112609863,80.6856326293945,11.7949726486206,
,13839263.02,4370,9.25164985656738,0.13400000333786,0,8.26258041381836,9.98999977111816,80.6733261108398,9.98999977111816,11.7929657745361,9.98999977111816,,,0.00370663020451772,0.00313985925033611,0.00394183307119571,,25,8.26258041381836,80.6733261108398,11.7929657745361,
,13839299.03,4370,9.25624990463257,0.13400000333786,0,8.26287815093994,9.98999977111816,80.6734246826172,9.98999977111816,11.7936301040649,9.98999977111816,,,0.00219903778958129,0.00296270327131493,0.0032565390105644,,25,8.26287815093994,80.6734246826172,11.7936301040649,
,13839336.98,4370,9.26419973373413,0.13400000333786,0,8.26451671600342,9.98999977111816,80.6878677368164,9.98999977111816,11.7945962524414,9.98999977111816,,,0.00252030951532795,0.00271554922590843,0.00320731670831666,,25,8.26451671600342,80.6878677368164,11.7945962524414,
,13839376.86,4370,9.27084970474243,0.13400000333786,0,8.26350845336914,9.98999977111816,80.6894415283203,9.98999977111816,11.7951232910156,9.98999977111816,,,0.00219356025094242,0.00288086984999215,0.00338352962386874,,25,8.26350845336914,80.6894415283203,11.7951232910156,
,13839412.64,4370,9.27615022659302,0.13400000333786,0,8.26374526977539,9.98999977111816,80.6889904785156,9.98999977111816,11.795742149353,9.98999977111816,,,0.00294810059865032,0.00394163909193831,0.00261662277917002,,25,8.26374526977539,80.6889904785156,11.795742149353,
,13839447.06,4370,9.28175020217896,0.13400000333786,0,8.2613606262207,9.98999977111816,80.6733303833008,9.98999977111816,11.7934484100342,9.98999977111816,,,0.00273178943861099,0.00388836117288271,0.00357814701471195,,25,8.2613606262207,80.6733303833008,11.7934484100342,
,13839483.88,4370,9.28775024414063,0.13400000333786,0,8.26288017272949,9.98999977111816,80.6804736328125,9.98999977111816,11.7925729751587,9.98999977111816,,,0.00353031418213158,0.0124113410210266,0.00371936082062896,,25,8.26288017272949,80.6804736328125,11.7925729751587,
,13839518.56,4370,9.29395008087158,0.13400000333786,0,8.26556365966797,9.98999977111816,80.7006378173828,9.98999977111816,11.7964605712891,9.98999977111816,,,0.00253817116567891,0.00368360503957964,0.00261853990640919,,25,8.26556365966797,80.7006378173828,11.7964605712891,
,13839554.05,4370,9.29965019226074,0.13400000333786,0,8.26121803283691,9.98999977111816,80.6689297485352,9.98999977111816,11.7914780426025,9.98999977111816,,,0.0027008976266548,0.0030805376614382,0.00280280999860593,,25,8.26121803283691,80.6689297485352,11.7914780426025,
,13839598.14,4370,9.30894994735718,0.13400000333786,0,8.26100425720215,9.98999977111816,80.6692504882813,9.98999977111816,11.79290599823,9.98999977111816,,,0.00300609365576957,0.00320523780370906,0.00280007438179035,,25,8.26100425720215,80.6692504882813,11.79290599823,
,13839633.16,4370,9.31579971313477,0.13400000333786,0,8.26253631591797,9.98999977111816,80.6844863891602,9.98999977111816,11.7942951965332,9.98999977111816,,,0.00274903781922514,0.00326436672661774,0.00324300612914295,,25,8.26253631591797,80.6844863891602,11.7942951965332,
,13839669.91,4370,9.31995010375977,0.13400000333786,0,8.26224872589111,9.98999977111816,80.6886264038086,9.98999977111816,11.7940853500366,9.98999977111816,,,0.00286124808945542,0.00319550122404547,0.00345277447526484,,25,8.26224872589111,80.6886264038086,11.7940853500366,
,13839703.67,4370,9.32644987106323,0.13400000333786,0,8.26315273284912,9.98999977111816,80.6899319458008,9.98999977111816,11.7957373428345,9.98999977111816,,,0.00258347371987554,0.00302312020611326,0.0028451272440132,,25,8.26315273284912,80.6899319458008,11.7957373428345,
,13839739.53,4370,9.33330011367798,0.13400000333786,0,8.26386291503906,9.98999977111816,80.6908251953125,9.98999977111816,11.7951950836182,9.98999977111816,,,0.00225668547584732,0.00411748949613053,0.00266564835705429,,25,8.26386291503906,80.6908251953125,11.7951950836182,
,13839787.23,4370,9.33965015411377,0.13400000333786,0,8.26375392913818,9.98999977111816,80.6958306884766,9.98999977111816,11.7951948547363,9.98999977111816,,,0.0029287414412297,0.00627144097942464,0.0029242672429331,,25,8.26375392913818,80.6958306884766,11.7951948547363,
,13839829.89,4370,9.34680032730103,0.13400000333786,0,8.26455978393555,9.98999977111816,80.7023501586914,9.98999977111816,11.7969335174561,9.98999977111816,,,0.00334688060653467,0.00349957479316063,0.00283998321453073,,25,8.26455978393555,80.7023501586914,11.7969335174561,
,13839879.95,4370,9.3550500869751,0.13400000333786,0,8.26376640319824,9.98999977111816,80.6851272583008,9.98999977111816,11.7943855285645,9.98999977111816,,,0.00278233114783043,0.00346020286879506,0.00244829903457791,,25,8.26376640319824,80.6851272583008,11.7943855285645,
,13839913.36,4370,9.35920000076294,0.13400000333786,0,8.26236629486084,9.98999977111816,80.6877191162109,9.98999977111816,11.7947980117798,9.98999977111816,,,0.00293343529145153,0.00394118150750623,0.00237828938199545,,25,8.26236629486084,80.6877191162109,11.7947980117798,
,13839951.25,4370,9.36790037155151,0.13400000333786,0,8.26353736877441,9.98999977111816,80.686396484375,9.98999977111816,11.7950423431396,9.98999977111816,,,0.00238847346107051,0.00226591833509697,0.00321947741932152,,25,8.26353736877441,80.686396484375,11.7950423431396,
,13839993.39,4370,9.37340021133423,0.13400000333786,0,8.26036624908447,9.98999977111816,80.6660971069336,9.98999977111816,11.7924546051025,9.98999977111816,,,0.00241701950367175,0.00405128280478107,0.00305885049054445,,25,8.26036624908447,80.6660971069336,11.7924546051025,
,13840026.11,4370,9.38030004501343,0.13400000333786,0,8.26201148986816,9.98999977111816,80.6658480834961,9.98999977111816,11.7904457855225,9.98999977111816,,,0.00317023686555139,0.00347409940500553,0.00320399859370581,,25,8.26201148986816,80.6658480834961,11.7904457855225,
,13840065.55,4370,9.38525009155273,0.13400000333786,0,8.26066951751709,9.98999977111816,80.6716757202149,9.98999977111816,11.7912237930298,9.98999977111816,,,0.00268687880165112,0.0038918827241674,0.00284841041270946,,25,8.26066951751709,80.6716757202149,11.7912237930298,
,13840099.91,4370,9.39100027084351,0.13400000333786,0,8.26332817077637,9.98999977111816,80.6913064575195,9.98999977111816,11.7959088897705,9.98999977111816,,,0.00316410374649171,0.00323446879815625,0.00259911077685612,,25,8.26332817077637,80.6913064575195,11.7959088897705,
,13840136.06,4370,9.39690017700195,0.13400000333786,0,8.26322895050049,9.98999977111816,80.6912762451172,9.98999977111816,11.7951985168457,9.98999977111816,,,0.00329036346064413,0.00337611618512249,0.0029684043394777,,25,8.26322895050049,80.6912762451172,11.7951985168457,
,13840179.58,4370,9.40475034713745,0.13400000333786,0,8.26196098327637,9.98999977111816,80.6846771240234,9.98999977111816,11.7934443283081,9.98999977111816,,,0.00275790094169265,0.00312509382352017,0.00219971604291964,,25,8.26196098327637,80.6846771240234,11.7934443283081,
,13840226.48,4370,9.41310024261475,0.13400000333786,0,8.26484329223633,9.98999977111816,80.7027514648437,9.98999977111816,11.7957164382935,9.98999977111816,,,0.00330432435879249,0.00365641842163748,0.00334167781553721,,25,8.26484329223633,80.7027514648437,11.7957164382935,
,13840270.53,4370,9.42295026779175,0.13400000333786,0,8.26435623168945,9.98999977111816,80.6983563232422,9.98999977111816,11.7950322723389,9.98999977111816,,,0.00307330255980649,0.00690894622500969,0.0037814368648022,,25,8.26435623168945,80.6983563232422,11.7950322723389,
,13840332.02,4370,9.43004989624023,0.13400000333786,0,8.2636665725708,9.98999977111816,80.6908908081055,9.98999977111816,11.7954330825806,9.98999977111816,,,0.00316151780928838,0.00453812765074096,0.00222532665277253,,25,8.2636665725708,80.6908908081055,11.7954330825806,
,13840368.91,4370,9.43635034561157,0.13400000333786,0,8.26456024169922,9.98999977111816,80.6934664916992,9.98999977111816,11.7958915710449,9.98999977111816,,,0.00324499588255134,0.00300434262725522,0.00181294346656349,,25,8.26456024169922,80.6934664916992,11.7958915710449,
,13840402.53,4370,9.44344997406006,0.13400000333786,0,8.26148067474365,9.98999977111816,80.6793710327148,9.98999977111816,11.7925436401367,9.98999977111816,,,0.00302166319219749,0.00293970954968052,0.00257464285959152,,25,8.26148067474365,80.6793710327148,11.7925436401367,
,13840449.73,4370,9.45040035247803,0.13400000333786,0,8.26185127258301,9.98999977111816,80.6826547241211,9.98999977111816,11.792890625,9.98999977111816,,,0.00333040566038808,0.0100760937277508,0.00281787183908166,,25,8.26185127258301,80.6826547241211,11.792890625,
,13840493.42,4370,9.45725011825562,0.13400000333786,0,8.26420589447022,9.98999977111816,80.7050289916992,9.98999977111816,11.7965726470947,9.98999977111816,,,0.00348292875285475,0.00216817766696701,0.00275959149098367,,25,8.26420589447022,80.7050289916992,11.7965726470947,
,13840530.84,4370,9.46449995040894,0.13400000333786,0,8.2624577331543,9.98999977111816,80.6936373901367,9.98999977111816,11.7934635925293,9.98999977111816,,,0.00292720119371904,0.00328161203034846,0.003222998755309,,25,8.2624577331543,80.6936373901367,11.7934635925293,
,13840571.50,4370,9.47004985809326,0.13400000333786,0,8.26172786712647,9.98999977111816,80.6933984375,9.98999977111816,11.7943962860107,9.98999977111816,,,0.00270765274483261,0.00355877202583217,0.0029799829903325,,25,8.26172786712647,80.6933984375,11.7943962860107,
,13840607.59,4370,9.47684955596924,0.13400000333786,0,8.26330764770508,9.98999977111816,80.6992028808594,9.98999977111816,11.7950743103027,9.98999977111816,,,0.00199767318680016,0.00354182687885352,0.00269491066739673,,25,8.26330764770508,80.6992028808594,11.7950743103027,
,13840642.16,4370,9.48294973373413,0.13400000333786,0,8.26455501556396,9.98999977111816,80.7120483398437,9.98999977111816,11.7963725280762,9.98999977111816,,,0.0035798775902915,0.00313778966473319,0.00298672701762892,,25,8.26455501556396,80.7120483398437,11.7963725280762,
,13840681.69,4370,9.48974990844727,0.13400000333786,0,8.26458560943603,9.98999977111816,80.711047668457,9.98999977111816,11.7979153823853,9.98999977111816,,,0.00276013717601117,0.00333488945239467,0.00357040213325491,,25,8.26458560943603,80.711047668457,11.7979153823853,
,13840716.19,4370,9.49315023422241,0.13400000333786,0,8.26284740447998,9.98999977111816,80.6902008056641,9.98999977111816,11.7933738708496,9.98999977111816,,,0.00307689796212376,0.00336906937941949,0.00318718683319302,,25,8.26284740447998,80.6902008056641,11.7933738708496,
,13840753.64,4370,9.49959993362427,0.13400000333786,0,8.26362216949463,9.98999977111816,80.6939117431641,9.98999977111816,11.7943161392212,9.98999977111816,,,0.00291118452527141,0.00792071434782266,0.00273774800309768,,25,8.26362216949463,80.6939117431641,11.7943161392212,