File: icepp/250309_3D_mh_photolitho_IV_plus_fineDown1.dat
[Header]
TITLE, IV scan 55 to 35 (0.1 scan)
FILEOPENTIME,13955995.11,3/9/2025,11:51 AM
BYAPP, Resistivity, 2.1, 1.0
INFO, APPNAME, PPMS MultiVu Application, 1.5.11
INFO, , Sample1 Name
INFO, 1, Sample1 Cross Section
INFO, 1, Sample1 Length
INFO, Ohm, Sample1 Units
INFO, , Sample2 Name
INFO, 1, Sample2 Cross Section
INFO, 1, Sample2 Length
INFO, Ohm, Sample2 Units
INFO, , Sample3 Name
INFO, 1, Sample3 Cross Section
INFO, 1, Sample3 Length
INFO, Ohm, Sample3 Units
INFO, , Sample4 Name
INFO, 1, Sample4 Cross Section
INFO, 1, Sample4 Length
INFO, Ohm, Sample4 Units
FIELDGROUP, Resistivity,2,3,4,5,6,7,8,9,10,11,12,13,14,15,16,17,18,19,20,21,22,23,24,25,26,27,28,29,30,31,32,33,34,35,36,37,38,39,40,41
STARTUPGROUP, Resistivity
STARTUPAXIS, X, 2, LINEAR, AUTO
STARTUPAXIS, Y1, 7, LINEAR, AUTO
STARTUPAXIS, Y2, 9, LINEAR, AUTO
STARTUPAXIS, Y3, 11, LINEAR, AUTO
PLOT_APPEARANCE, ALL, HORZ_GRID_ON, VERT_GRID_ON, MARKERS_AND_LINES, ALL_LINES
DATATYPE, TIME, 2
DATATYPE, COMMENT, 1
[Data]
Comment,Time Stamp (sec),Status (code),Temperature (K),Magnetic Field (Oe),Sample Position (deg),Bridge 1 Resistivity (Ohm),Bridge 1 Excitation (uA),Bridge 2 Resistivity (Ohm),Bridge 2 Excitation (uA),Bridge 3 Resistivity (Ohm),Bridge 3 Excitation (uA),Bridge 4 Resistivity (Ohm),Bridge 4 Excitation (uA),Bridge 1 Std. Dev. (Ohm),Bridge 2 Std. Dev. (Ohm),Bridge 3 Std. Dev. (Ohm),Bridge 4 Std. Dev. (Ohm),Number of Readings,Bridge 1 Resistance (Ohms),Bridge 2 Resistance (Ohms),Bridge 3 Resistance (Ohms),Bridge 4 Resistance (Ohms),Signal 1 Vin (V),Signal 2 Vin (V),Digital Inputs (code),Drive 1 Iout (mA),Drive 1 Ipower (watts),Drive 2 Iout (mA),Drive 2 Ipower (watts),Pressure (),Map 20 (),Map 21 (),Map 22 (),Map 23 (),Map 24 (),Map 25 (),Map 26 (),Map 27 (),Map 28 (),Map 29 ()
,13958092.27,4369,3.00024998188019,0.13400000333786,0,16.9157776641846,54.9580001831055,0.000272084290045314,54.9580001831055,452.059772949219,54.9580001831055,,,0.00568580974851801,0.000931413232953446,0.0442485138025107,,25,16.9157776641846,0.000272084290045314,452.059772949219,
,13958110.30,4369,3,0.13400000333786,0,16.8050666046143,54.7140007019043,-7.2507485456299e-005,54.7140007019043,452.332934570312,54.7140007019043,,,0.00554701461731909,0.000879557380542109,0.0356454722561145,,25,16.8050666046143,-7.2507485456299e-005,452.332934570312,
,13958127.20,4369,3.00129997730255,0.13400000333786,0,16.6910765075684,54.4700012207031,0.000154077826009598,54.4700012207031,452.353881835938,54.4700012207031,,,0.00814030873830658,0.000782392648306159,0.0402660376649189,,25,16.6910765075684,0.000154077826009598,452.353881835938,
,13958145.09,4369,3.00020003318787,0.13400000333786,0,16.5560521697998,54.226001739502,-0.000137887374730781,54.226001739502,452.431658935547,54.226001739502,,,0.0255085305480773,0.000775896468743673,0.0495665803769532,,25,16.5560521697998,-0.000137887374730781,452.431658935547,
,13958162.75,4369,2.99975001811981,0.13400000333786,0,16.2908843231201,53.9809989929199,0.00116463975631632,53.9809989929199,452.505830078125,53.9809989929199,,,0.0129770276189465,0.000723493994393428,0.0261158058567796,,25,16.2908843231201,0.00116463975631632,452.505830078125,
,13958180.36,4369,2.99950003623962,0.13400000333786,0,16.2880179595947,53.9809989929199,-0.00116181296063587,53.9809989929199,452.53947265625,53.9809989929199,,,0.0165798811585327,0.000753774443536806,0.070463495248909,,25,16.2880179595947,-0.00116181296063587,452.53947265625,
,13958197.81,4369,3.00129997730255,0.13400000333786,0,15.953763923645,53.7369995117188,-0.000732642360962927,53.7369995117188,452.701228027344,53.7369995117188,,,0.0203707095306749,0.000691721780607684,0.0270647294874218,,25,15.953763923645,-0.000732642360962927,452.701228027344,
,13958215.92,4369,3.00179994106293,0.13400000333786,0,15.6690721511841,53.4930000305176,0.00108106570784003,53.4930000305176,452.825043945312,53.4930000305176,,,0.0100759945399171,0.000670068920839978,0.0483537124838452,,25,15.6690721511841,0.00108106570784003,452.825043945312,
,13958233.56,4369,2.99935007095337,0.13400000333786,0,15.5054291915894,53.2490005493164,1.1462178081274e-005,53.2490005493164,452.956525878906,53.2490005493164,,,0.00732471826917185,0.00102834345081326,0.0344984432927233,,25,15.5054291915894,1.1462178081274e-005,452.956525878906,
,13958250.98,4369,2.99974989891052,0.13400000333786,0,15.3937857818604,53.0040016174316,0.000238951206556521,53.0040016174316,452.980174560547,53.0040016174316,,,0.00552094606760531,0.000978776938854963,0.0326451151853413,,25,15.3937857818604,0.000238951206556521,452.980174560547,
,13958267.75,4369,3.00064992904663,0.13400000333786,0,15.3124192047119,52.7599983215332,0.000503230112080928,52.7599983215332,453.183621826172,52.7599983215332,,,0.00796988187961026,0.00084182263702954,0.0400981659474753,,25,15.3124192047119,0.000503230112080928,453.183621826172,
,13958285.36,4369,3.00034999847412,0.13400000333786,0,15.3122138214111,52.7599983215332,0.000682542003050912,52.7599983215332,453.165396728516,52.7599983215332,,,0.00533654369912158,0.000867657434833164,0.0832644058937526,,25,15.3122138214111,0.000682542003050912,453.165396728516,
,13958303.17,4369,2.9988499879837,0.13400000333786,0,15.2313204193115,52.515998840332,0.00142069090419682,52.515998840332,453.324348144531,52.515998840332,,,0.00657719875373123,0.000977510974336265,0.0293141924816769,,25,15.2313204193115,0.00142069090419682,453.324348144531,
,13958321.19,4369,3.00034999847412,0.13400000333786,0,15.2586740112305,52.2719993591309,-0.000613042495388072,52.2719993591309,453.379155273438,52.2719993591309,,,0.317586222668093,0.000854597658652476,0.144909200718997,,25,15.2586740112305,-0.000613042495388072,453.379155273438,
,13958337.94,4369,2.99924993515015,0.13400000333786,0,15.0853929519653,52.0270004272461,-0.000436974200420082,52.0270004272461,453.522438964844,52.0270004272461,,,0.00388069266176343,0.000692294165015209,0.0883650179351417,,25,15.0853929519653,-0.000436974200420082,453.522438964844,
,13958356.47,4369,2.99989998340607,0.13400000333786,0,15.0183919143677,51.7830009460449,-0.000774945411249064,51.7830009460449,453.66220703125,51.7830009460449,,,0.00507595055869087,0.000801854346923815,0.0432672246578799,,25,15.0183919143677,-0.000774945411249064,453.66220703125,
,13958373.61,4369,3.00014996528625,0.13400000333786,0,15.0167419052124,51.7830009460449,0.000621724252123386,51.7830009460449,453.822260742188,51.7830009460449,,,0.00560225456846662,0.00075269482328441,0.0381045964426895,,25,15.0167419052124,0.000621724252123386,453.822260742188,
,13958390.97,4369,2.99985003471375,0.13400000333786,0,14.9431973648071,51.5390014648438,7.99336860654876e-005,51.5390014648438,453.984114990234,51.5390014648438,,,0.00272386023365663,0.000551052053032732,0.04876972431281,,25,14.9431973648071,7.99336860654876e-005,453.984114990234,
,13958408.52,4369,2.99995005130768,0.13400000333786,0,14.8726091766357,51.2949981689453,-0.00135344157548388,51.2949981689453,453.950350341797,51.2949981689453,,,0.00521081024370626,0.00084684637626099,0.0419994052794033,,25,14.8726091766357,-0.00135344157548388,453.950350341797,
,13958425.06,4369,2.99944996833801,0.13400000333786,0,14.7995224761963,51.0499992370605,-0.00208324765786529,51.0499992370605,454.045041503906,51.0499992370605,,,0.00611571488156049,0.000851782924317403,0.0365460290084888,,25,14.7995224761963,-0.00208324765786529,454.045041503906,
,13958441.63,4369,3.00045001506805,0.13400000333786,0,14.7685511398315,50.8059997558594,0.000831925468228292,50.8059997558594,454.204273681641,50.8059997558594,,,0.197990895082464,0.00105200998474699,0.134011668049936,,25,14.7685511398315,0.000831925468228292,454.204273681641,
,13958459.55,4369,3.00069999694824,0.13400000333786,0,14.64091381073,50.5620002746582,0.000446664390037768,50.5620002746582,454.227999267578,50.5620002746582,,,0.00425376155409792,0.000788998485502583,0.0804111543608622,,25,14.64091381073,0.000446664390037768,454.227999267578,
,13958477.30,4369,3.00045001506805,0.13400000333786,0,14.6392207336426,50.5620002746582,3.31980441114865e-005,50.5620002746582,454.244294433594,50.5620002746582,,,0.00376106980481792,0.000959867201369803,0.0435147815898484,,25,14.6392207336426,3.31980441114865e-005,454.244294433594,
,13958494.97,4369,2.99965000152588,0.13400000333786,0,14.5585586547852,50.318000793457,-0.00234422700712457,50.318000793457,454.509940185547,50.318000793457,,,0.00626957092745109,0.00106529703886313,0.0432988483102269,,25,14.5585586547852,-0.00234422700712457,454.509940185547,
,13958511.58,4369,2.99925005435944,0.13400000333786,0,14.4634373092651,50.0730018615723,-0.000274272152455524,50.0730018615723,454.588197021484,50.0730018615723,,,0.00604909515568078,0.000988432668998509,0.0341362093380729,,25,14.4634373092651,-0.000274272152455524,454.588197021484,
,13958528.92,4369,3.00069999694824,0.13400000333786,0,14.5165336608887,50,-0.000970581136643887,50,453.914532470703,50,,,0.00454062533237032,0.00110332292937807,0.0491425330805736,,25,14.5165336608887,-0.000970581136643887,453.914532470703,
,13958546.39,4369,2.99874997138977,0.13400000333786,0,14.4365198135376,49.7799987792969,-0.000466048558591865,49.7799987792969,454.341448974609,49.7799987792969,,,0.00325132830272598,0.000610117157742477,0.0488441283107598,,25,14.4365198135376,-0.000466048558591865,454.341448974609,
,13958563.88,4369,2.99944996833801,0.13400000333786,0,14.3714421463013,49.5849990844727,-0.000603325163247064,49.5849990844727,454.478128662109,49.5849990844727,,,0.0448971649143524,0.00138666889918629,0.0348804887545471,,25,14.3714421463013,-0.000603325163247064,454.478128662109,
,13958582.02,4369,3.00034999847412,0.13400000333786,0,14.2789282989502,49.3889999389648,0.000145232057548128,49.3889999389648,454.445665283203,49.3889999389648,,,0.0065656550495374,0.00100350800311751,0.0475039776553011,,25,14.2789282989502,0.000145232057548128,454.445665283203,
,13958599.14,4369,3.00125002861023,0.13400000333786,0,14.1929798126221,49.1940002441406,0.000918334879097529,49.1940002441406,454.537601318359,49.1940002441406,,,0.00646539576995269,0.000690495865655994,0.0400695782622942,,25,14.1929798126221,0.000918334879097529,454.537601318359,
,13958616.36,4369,3.00024998188019,0.13400000333786,0,14.1040780639648,48.9990005493164,0.000224244929559063,48.9990005493164,454.635614013672,48.9990005493164,,,0.00775420916907515,0.00109835059508871,0.0286603727253234,,25,14.1040780639648,0.000224244929559063,454.635614013672,
,13958634.47,4369,2.99935007095337,0.13400000333786,0,13.9967526245117,48.7789993286133,-0.000209625576389953,48.7789993286133,454.7251171875,48.7789993286133,,,0.00744995196742251,0.000980878632427293,0.030880189014841,,25,13.9967526245117,-0.000209625576389953,454.7251171875,
,13958652.50,4369,3.00174999237061,0.13400000333786,0,13.9021324539185,48.5830001831055,0.000870148995891213,48.5830001831055,454.809069824219,48.5830001831055,,,0.0107902440558188,0.00086939451367607,0.0466338257819723,,25,13.9021324539185,0.000870148995891213,454.809069824219,
,13958670.38,4369,2.99979996681213,0.13400000333786,0,13.8008391571045,48.3880004882813,-3.15422681160271e-005,48.3880004882813,454.983441162109,48.3880004882813,,,0.0077840459956205,0.000746759253206733,0.0471936850558063,,25,13.8008391571045,-3.15422681160271e-005,454.983441162109,
,13958687.14,4369,2.99930000305176,0.13400000333786,0,13.6853983688354,48.1920013427734,0.000579549456888344,48.1920013427734,455.027337646484,48.1920013427734,,,0.00860935687270206,0.00100015057344007,0.0410485887330358,,25,13.6853983688354,0.000579549456888344,455.027337646484,
,13958705.00,4369,2.99989998340607,0.13400000333786,0,13.5637142944336,47.9970016479492,-0.000251211340655573,47.9970016479492,455.120438232422,47.9970016479492,,,0.00831114393371096,0.000913542154038316,0.036053866491884,,25,13.5637142944336,-0.000251211340655573,455.120438232422,
,13958721.20,4369,3.00059998035431,0.13400000333786,0,13.4048370742798,47.7770004272461,-0.00124897178990068,47.7770004272461,455.30935546875,47.7770004272461,,,0.00982139271547589,0.00089551025073683,0.0413522241641,,25,13.4048370742798,-0.00124897178990068,455.30935546875,
,13958739.39,4369,2.9996999502182,0.13400000333786,0,13.2477951049805,47.5820007324219,0.00269110801804345,47.5820007324219,455.398801269531,47.5820007324219,,,0.177659019502365,0.00124166187681329,0.111844440604378,,25,13.2477951049805,0.00269110801804345,455.398801269531,
,13958756.02,4369,3.00024998188019,0.13400000333786,0,10.4069674301147,47.3860015869141,-0.000528225052403286,47.3860015869141,455.496785888672,47.3860015869141,,,0.268094100532462,0.00103972225770194,0.041555047082923,,25,10.4069674301147,-0.000528225052403286,455.496785888672,
,13958773.41,4369,3.00015008449554,0.13400000333786,0,9.58744441986084,47.1910018920898,-0.00184351917763706,47.1910018920898,455.567556152344,47.1910018920898,,,0.0330199662831401,0.00120668089328104,0.0672818644445759,,25,9.58744441986084,-0.00184351917763706,455.567556152344,
,13958789.53,4369,3.00114989280701,0.13400000333786,0,9.42451705932617,46.9959983825684,-0.000867083642515354,46.9959983825684,455.733486328125,46.9959983825684,,,0.0302432023972242,0.0010874824647201,0.0424467204857613,,25,9.42451705932617,-0.000867083642515354,455.733486328125,
,13958807.16,4369,3.00069999694824,0.13400000333786,0,9.29654300689697,46.7999992370605,-0.00231878392864019,46.7999992370605,455.730501708984,46.7999992370605,,,0.0290272344363925,0.00103287985517726,0.0400162448646062,,25,9.29654300689697,-0.00231878392864019,455.730501708984,
,13958823.25,4369,3.00129997730255,0.13400000333786,0,9.17846878051758,46.5800018310547,0.00170035716379061,46.5800018310547,455.822642822266,46.5800018310547,,,0.0277241723169101,0.000922090974942708,0.0503106178870522,,25,9.17846878051758,0.00170035716379061,455.822642822266,
,13958840.47,4369,2.9988499879837,0.13400000333786,0,9.07844024658203,46.3849983215332,0.00166155984130455,46.3849983215332,456.001605224609,46.3849983215332,,,0.0260100467835156,0.000985967918624235,0.0386297751635498,,25,9.07844024658203,0.00166155984130455,456.001605224609,
,13958857.16,4369,2.9985499382019,0.13400000333786,0,8.98589679718018,46.189998626709,0.000769872581586242,46.189998626709,456.126462402344,46.189998626709,,,0.015359392916046,0.00107238651228033,0.03730341334314,,25,8.98589679718018,0.000769872581586242,456.126462402344,
,13958873.97,4369,3.00024998188019,0.13400000333786,0,8.9052165222168,45.9939994812012,0.000136051588924602,45.9939994812012,456.139755859375,45.9939994812012,,,0.00677666280237421,0.00098685634901849,0.0359222350859027,,25,8.9052165222168,0.000136051588924602,456.139755859375,
,13958891.56,4369,3.00045001506805,0.13400000333786,0,8.82397090911865,45.798999786377,-0.00177953301405068,45.798999786377,456.29078125,45.798999786377,,,0.00664208348598327,0.000803212481261506,0.049447336109494,,25,8.82397090911865,-0.00177953301405068,456.29078125,
,13958908.92,4369,2.99950003623962,0.13400000333786,0,8.74413166046143,45.5789985656738,0.000204266154032666,45.5789985656738,456.378089599609,45.5789985656738,,,0.00699999359830592,0.000828431247563558,0.0526422544808106,,25,8.74413166046143,0.000204266154032666,456.378089599609,
,13958925.02,4369,3.00079989433289,0.13400000333786,0,8.67809711456299,45.382999420166,0.000655836874502711,45.382999420166,456.445263671875,45.382999420166,,,0.0335074361161779,0.000724469673259656,0.0464574801153009,,25,8.67809711456299,0.000655836874502711,456.445263671875,
,13958942.22,4369,2.99890005588531,0.13400000333786,0,8.60154109954834,45.1879997253418,0.00117203494650312,45.1879997253418,456.614047851562,45.1879997253418,,,0.00804747127854915,0.00106256156031141,0.0351704409058614,,25,8.60154109954834,0.00117203494650312,456.614047851562,
,13958959.14,4369,3.0003000497818,0.13400000333786,0,8.52426490783691,44.9930000305176,0.00171978078782558,44.9930000305176,456.679940185547,44.9930000305176,,,0.00843285242058293,0.0010953611091337,0.0507381782671296,,25,8.52426490783691,0.00171978078782558,456.679940185547,
,13958976.22,4369,3.00024998188019,0.13400000333786,0,8.45370777130127,44.7970008850098,-0.000705272097256966,44.7970008850098,456.795539550781,44.7970008850098,,,0.00923579461252807,0.000872819262795932,0.0394345310952605,,25,8.45370777130127,-0.000705272097256966,456.795539550781,
,13958993.98,4369,2.99989998340607,0.13400000333786,0,8.3686608505249,44.5769996643066,0.000893636668333784,44.5769996643066,456.85080078125,44.5769996643066,,,0.0100097589666093,0.000867563981863474,0.046848073939716,,25,8.3686608505249,0.000893636668333784,456.85080078125,
,13959011.06,4369,2.99940001964569,0.13400000333786,0,8.2910209274292,44.3819999694824,0.00193232549820095,44.3819999694824,456.987272949219,44.3819999694824,,,0.0127061442068648,0.00110991658093619,0.045447239872159,,25,8.2910209274292,0.00193232549820095,456.987272949219,
,13959028.13,4369,2.99909996986389,0.13400000333786,0,8.20717765808105,44.1870002746582,0.00160613442072645,44.1870002746582,457.056394042969,44.1870002746582,,,0.00664607722899675,0.001064050014553,0.0488852289193231,,25,8.20717765808105,0.00160613442072645,457.056394042969,
,13959046.06,4369,2.99925005435944,0.13400000333786,0,8.12678764343262,43.9910011291504,-0.00125233615632169,43.9910011291504,457.147735595703,43.9910011291504,,,0.0124624141637816,0.000846226843196034,0.0550616516594994,,25,8.12678764343262,-0.00125233615632169,457.147735595703,
,13959064.11,4369,2.99995005130768,0.13400000333786,0,8.04126022338867,43.7960014343262,-0.000766660682565998,43.7960014343262,457.289113769531,43.7960014343262,,,0.00789941717144642,0.000939610196198293,0.0514522376559746,,25,8.04126022338867,-0.000766660682565998,457.289113769531,
,13959080.25,4369,2.99890005588531,0.13400000333786,0,7.95593074798584,43.5999984741211,-0.000154012400016654,43.5999984741211,457.452193603516,43.5999984741211,,,0.00787248899265361,0.00107552677861251,0.0398850907725605,,25,7.95593074798584,-0.000154012400016654,457.452193603516,
,13959097.53,4369,3.00004994869232,0.13400000333786,0,7.85507411956787,43.3810005187988,0.000682419783261139,43.3810005187988,457.455122070312,43.3810005187988,,,0.0079388140836762,0.000778771327398292,0.0434208736925797,,25,7.85507411956787,0.000682419783261139,457.455122070312,
,13959114.67,4369,3.00004994869232,0.13400000333786,0,7.75772390365601,43.185001373291,-0.00149148873169906,43.185001373291,457.583739013672,43.185001373291,,,0.0103542024456803,0.00101464306568899,0.0554877826218623,,25,7.75772390365601,-0.00149148873169906,457.583739013672,
,13959132.00,4369,2.99975001811981,0.13400000333786,0,7.6677018737793,42.9900016784668,-0.00131352983415127,42.9900016784668,457.8577734375,42.9900016784668,,,0.010401733325843,0.000896702880689303,0.0440522545051822,,25,7.6677018737793,-0.00131352983415127,457.8577734375,
,13959148.52,4369,2.99940001964569,0.13400000333786,0,7.56160665512085,42.7939987182617,0.00123036858160049,42.7939987182617,457.826771240234,42.7939987182617,,,0.0141484327217599,0.000911323831602879,0.0610848813158806,,25,7.56160665512085,0.00123036858160049,457.826771240234,
,13959165.89,4369,2.99940001964569,0.13400000333786,0,7.4525825881958,42.5989990234375,-0.000247239826130681,42.5989990234375,457.952979736328,42.5989990234375,,,0.0111049401232869,0.00131270843531088,0.0432758532634229,,25,7.4525825881958,-0.000247239826130681,457.952979736328,
,13959183.34,4369,2.99895000457764,0.13400000333786,0,7.32198570251465,42.3790016174316,0.00161696912662592,42.3790016174316,458.06376953125,42.3790016174316,,,0.016075095160201,0.00107751947012609,0.048906913015294,,25,7.32198570251465,0.00161696912662592,458.06376953125,
,13959200.33,4369,2.9985499382019,0.13400000333786,0,7.18523483276367,42.1839981079102,-0.00122641110094264,42.1839981079102,458.193586425781,42.1839981079102,,,0.0161364997769347,0.00131415824218638,0.0524043131264346,,25,7.18523483276367,-0.00122641110094264,458.193586425781,
,13959217.59,4369,2.99944996833801,0.13400000333786,0,7.04648767471314,41.9879989624023,-0.000508896594110411,41.9879989624023,458.222991943359,41.9879989624023,,,0.0230151709274411,0.00108045027025517,0.0463226597569296,,25,7.04648767471314,-0.000508896594110411,458.222991943359,
,13959235.11,4369,3.00159990787506,0.13400000333786,0,6.89923522949219,41.7929992675781,-0.000602514086058363,41.7929992675781,458.39509765625,41.7929992675781,,,0.0261851281583247,0.00146155284391308,0.0528075289736543,,25,6.89923522949219,-0.000602514086058363,458.39509765625,
,13959251.58,4369,3.00004994869232,0.13400000333786,0,6.72651643753052,41.5970001220703,0.00227091380744241,41.5970001220703,458.464390869141,41.5970001220703,,,0.0299990359934562,0.00113914773648201,0.0438341330434505,,25,6.72651643753052,0.00227091380744241,458.464390869141,
,13959269.13,4369,2.99940001964569,0.13400000333786,0,6.32805995941162,41.3779983520508,-2.95064237434417e-005,41.3779983520508,458.575167236328,41.3779983520508,,,0.493347833336696,0.000994720703076508,0.0458930397917997,,25,6.32805995941162,-2.95064237434417e-005,458.575167236328,
,13959286.23,4369,2.9996999502182,0.13400000333786,0,5.96173013687134,41.181999206543,-0.00101542113814503,41.181999206543,458.677106933594,41.181999206543,,,0.551887737969352,0.00117322552826254,0.0477898507539252,,25,5.96173013687134,-0.00101542113814503,458.677106933594,
,13959304.22,4369,2.99949991703033,0.13400000333786,0,2.25370113968849,40.9869995117188,-0.000204785454552621,40.9869995117188,458.758831787109,40.9869995117188,,,1.66011770319892,0.000993170625018628,0.0402943938779212,,25,2.25370113968849,-0.000204785454552621,458.758831787109,
,13959321.91,4369,3.00065004825592,0.13400000333786,0,0.196601824155077,40.7910003662109,0.000987742105207872,40.7910003662109,458.882573242188,40.7910003662109,,,0.204736716465871,0.000848690250203796,0.052961612127468,,25,0.196601824155077,0.000987742105207872,458.882573242188,
,13959339.34,4369,3.00055003166199,0.13400000333786,0,0.148689720661496,40.5960006713867,-0.000488678155525122,40.5960006713867,458.945344238281,40.5960006713867,,,0.230415804390746,0.00104309755929564,0.0424365410510084,,25,0.148689720661496,-0.000488678155525122,458.945344238281,
,13959357.11,4369,3.00074994564056,0.13400000333786,0,0.0598524857149459,40.4010009765625,-0.00208524183020927,40.4010009765625,459.062108154297,40.4010009765625,,,0.0480336823030618,0.00110423937805464,0.0639112271481538,,25,0.0598524857149459,-0.00208524183020927,459.062108154297,
,13959375.70,4369,3.00064992904663,0.13400000333786,0,0.0517300279485062,40.1809997558594,0.0018838542184676,40.1809997558594,459.219757080078,40.1809997558594,,,0.0483784473047717,0.000895850978887078,0.0446827203673133,,25,0.0517300279485062,0.0018838542184676,459.219757080078,
,13959392.55,4369,3.00215005874634,0.13400000333786,0,0.0439200992882252,39.9850006103516,-0.00024425501585938,39.9850006103516,459.272436523437,39.9850006103516,,,0.0415988578363022,0.00124755266558034,0.0584512696850588,,25,0.0439200992882252,-0.00024425501585938,459.272436523437,
,13959410.36,4369,2.99985003471375,0.13400000333786,0,0.0260393390030367,39.7900009155273,-0.0010050540685188,39.7900009155273,459.491832275391,39.7900009155273,,,0.0344135778511977,0.00136898232196371,0.0400791487269083,,25,0.0260393390030367,-0.0010050540685188,459.491832275391,
,13959428.19,4369,2.99895000457764,0.13400000333786,0,0.0262091633491218,39.5950012207031,0.000508766107668635,39.5950012207031,459.490311279297,39.5950012207031,,,0.0348402013815077,0.00111492255725505,0.0562298211706866,,25,0.0262091633491218,0.000508766107668635,459.490311279297,
,13959446.05,4369,2.9996999502182,0.13400000333786,0,0.0197239571483806,39.398998260498,-0.0013211293052882,39.398998260498,459.564588623047,39.398998260498,,,0.0272792596029729,0.00101469148760618,0.0426360848074322,,25,0.0197239571483806,-0.0013211293052882,459.564588623047,
,13959463.69,4369,3.00014996528625,0.13400000333786,0,0.0513631049709511,39.1790008544922,-0.00057650077767903,39.1790008544922,459.660783691406,39.1790008544922,,,0.137430736361858,0.00140686870343141,0.0533696523935887,,25,0.0513631049709511,-0.00057650077767903,459.660783691406,
,13959480.78,4369,3.00064992904663,0.13400000333786,0,0.00575497298530536,38.984001159668,0.00102963120152708,38.984001159668,459.838618164063,38.984001159668,,,0.010137446744395,0.00110180563289012,0.0414430712384657,,25,0.00575497298530536,0.00102963120152708,459.838618164063,
,13959498.63,4369,3.00039994716644,0.13400000333786,0,0.00439123718999326,38.7879981994629,0.00184935613215202,38.7879981994629,459.948530273437,38.7879981994629,,,0.00487850821675749,0.000955354617438407,0.0521990757236706,,25,0.00439123718999326,0.00184935613215202,459.948530273437,
,13959516.27,4369,2.99825000762939,0.13400000333786,0,0.000506216454086825,38.5929985046387,0.00018983117537573,38.5929985046387,460.102208251953,38.5929985046387,,,0.00202301885126372,0.00127106579961668,0.05163241154726,,25,0.000506216454086825,0.00018983117537573,460.102208251953,
,13959534.22,4369,3.00045001506805,0.13400000333786,0,0.000576386090833694,38.3979988098145,-0.00220616753620561,38.3979988098145,460.155216064453,38.3979988098145,,,0.00120011768791917,0.00122874246352868,0.0543154091813807,,25,0.000576386090833694,-0.00220616753620561,460.155216064453,
,13959551.63,4369,2.99970006942749,0.13400000333786,0,0.000783584741875529,38.1780014038086,-0.000755599562544376,38.1780014038086,460.381224365234,38.1780014038086,,,0.00163514815784931,0.00131871919639802,0.0388882584251463,,25,0.000783584741875529,-0.000755599562544376,460.381224365234,
,13959570.20,4369,2.99890005588531,0.13400000333786,0,0.00185633478249656,37.9819984436035,-0.000124559263058472,37.9819984436035,460.436715087891,37.9819984436035,,,0.00108528757923336,0.00108497514918511,0.0475579050115066,,25,0.00185633478249656,-0.000124559263058472,460.436715087891,
,13959587.25,4369,3.00034999847412,0.13400000333786,0,-0.00022213249176275,37.7869987487793,0.000658319925423711,37.7869987487793,460.593609619141,37.7869987487793,,,0.00132758329437491,0.000917930463022895,0.0479728693209747,,25,-0.00022213249176275,0.000658319925423711,460.593609619141,
,13959604.64,4369,3.00094997882843,0.13400000333786,0,0.00105959191336297,37.5919990539551,-0.000263883047737181,37.5919990539551,460.675465087891,37.5919990539551,,,0.00110140955713513,0.00120362878696297,0.051384034471821,,25,0.00105959191336297,-0.000263883047737181,460.675465087891,
,13959622.08,4369,2.99995005130768,0.13400000333786,0,0.00137548223952763,37.3959999084473,-0.000404073403333314,37.3959999084473,460.791744384766,37.3959999084473,,,0.00121048057479994,0.00134210388343623,0.0565267707772635,,25,0.00137548223952763,-0.000404073403333314,460.791744384766,
,13959639.69,4369,2.9991500377655,0.13400000333786,0,0.194969259880891,37.201000213623,0.000336408536531962,37.201000213623,460.862259521484,37.201000213623,,,0.65720244804355,0.00116237435096508,0.0434993075485111,,25,0.194969259880891,0.000336408536531962,460.862259521484,
,13959657.72,4369,3.00019991397858,0.13400000333786,0,0.000231127984297927,36.9809989929199,-0.00038796482316684,36.9809989929199,460.99873046875,36.9809989929199,,,0.000819907839812691,0.00102406588697382,0.0478165906841296,,25,0.000231127984297927,-0.00038796482316684,460.99873046875,
,13959676.39,4369,2.99899995326996,0.13400000333786,0,-0.000717767897585873,36.7859992980957,0.000838087389711291,36.7859992980957,461.207109375,36.7859992980957,,,0.00122584371969142,0.00107589816301614,0.0437194563532603,,25,-0.000717767897585873,0.000838087389711291,461.207109375,
,13959694.16,4369,2.99935007095337,0.13400000333786,0,-0.000917579457163811,36.5900001525879,0.000746576024685055,36.5900001525879,461.188072509766,36.5900001525879,,,0.00225262675295242,0.00144049614426841,0.0656561887638871,,25,-0.000917579457163811,0.000746576024685055,461.188072509766,
,13959711.45,4369,2.9991500377655,0.13400000333786,0,-0.000805162178003229,36.3950004577637,0.000868065471295267,36.3950004577637,461.365270996094,36.3950004577637,,,0.00128664876477936,0.00104818694680407,0.0498530729023837,,25,-0.000805162178003229,0.000868065471295267,461.365270996094,
,13959729.11,4369,2.99914991855621,0.13400000333786,0,0.00146727871091571,36.1990013122559,0.00159376827476081,36.1990013122559,461.383631591797,36.1990013122559,,,0.0012407442868529,0.00104020936612531,0.0584622437224002,,25,0.00146727871091571,0.00159376827476081,461.383631591797,
,13959746.42,4369,2.99954998493195,0.13400000333786,0,-0.00208279184997082,35.9790000915527,0.000805968332861085,35.9790000915527,461.559963378906,35.9790000915527,,,0.00135804326096816,0.0011801436018147,0.0497910665604525,,25,-0.00208279184997082,0.000805968332861085,461.559963378906,
,13959765.16,4369,3.00034999847412,0.13400000333786,0,0.00196203865343705,35.7840003967285,0.00353593490319327,35.7840003967285,461.716949462891,35.7840003967285,,,0.000813208573773636,0.00141550186444362,0.0446390178998114,,25,0.00196203865343705,0.00353593490319327,461.716949462891,
,13959783.72,4369,2.99909996986389,0.13400000333786,0,0.00357682770583779,35.5890007019043,0.000561827855126467,35.5890007019043,461.818822021484,35.5890007019043,,,0.00166900643290263,0.00144241475304754,0.0551384065013673,,25,0.00357682770583779,0.000561827855126467,461.818822021484,
,13959801.42,4369,2.99979996681213,0.13400000333786,0,0.00125065348634962,35.3930015563965,0.0006641401143861,35.3930015563965,462.030395507813,35.3930015563965,,,0.00139644300953383,0.000920757365396031,0.0555052730206239,,25,0.00125065348634962,0.0006641401143861,462.030395507813,
,13959818.98,4369,3.00024998188019,0.13400000333786,0,0.00563294758088887,35.1980018615723,0.00137463001243304,35.1980018615723,462.054449462891,35.1980018615723,,,0.0100675058493152,0.00124579986627019,0.0507399664588963,,25,0.00563294758088887,0.00137463001243304,462.054449462891,
,13959836.52,4369,2.99845004081726,0.13400000333786,0,0.000117804901092313,34.9780006408691,-0.000510487901046872,34.9780006408691,462.180893554687,34.9780006408691,,,0.0013907141793949,0.00102960962022294,0.0555986885320913,,25,0.000117804901092313,-0.000510487901046872,462.180893554687,